File: Shimadzu/Grupo_A-CP28-D.txt
Nome do ensaio	Modo de ensaio	Tipo de ensaio	Título1	Comentário1	Palavra-chave	Nome do produto	Nome do arquivo do ensaio	Nome do arquivo do método	Data do relatório	Data do ensaio	Modo de ensaio	Tipo de ensaio	Velocidade	Placa	Lote No:	Sub-Lote No:
Extensometro SG25-50 - Placa - Sthil_20210601_1518.xtak	Simples	Tração	Grupo de Mecânica Aplicada - GMAp
UFRGS	Comentário	 	 	Extensometro SG25-50 - Placa - Sthil_20210601_1518.xtak	Extensometro SG25-50 - Placa - Sthil.xmak	01/06/2021	01/06/2021	Simples	Tração	5mm/min	Placa	1	1

Placa:	Lote No:	Sub-Lote No:
Placa	1	1
Nome	Espessura	Largura	Gauge Length
Unidade:	mm	mm	mm
Ga_D_28	3.3747	13.0313	115.0000

Nome	Elástico	Inclinação_Padrão	Ruptura_Força	Máx_Força	Max_Disp_Força	Max_Disp_SG-25-50 %	Max_Disp_Deslocamento	Espessura	Largura	Gauge_Length	Máx_Tensão	YS1_Tensão
Parâmetro	Tensão 40 - 60 N/mm2	Tensão 40 - 60 N/mm2	Sensibilidade: 10	Cálculo de áreas completas							Cálculo de áreas completas	0.2 %
Unidade	N/mm2	N/mm	kN	kN	kN	%	mm	mm	mm	mm	N/mm2	N/mm2
Ga_D_28	-.-	-.-	1.27737	1.31579	1.27737	5.30476	5.12057	3.3747	13.0313	115.0000	29.9202	-.-

Ga_D_28
Tempo	Força	Deslocamento	Desloc. SG25-50	Tensão	SG-25-50 %	Deformação
seg	kN	mm	mm	N/mm2	%	%
0	0.0111262	0	0	0.253002	0	0
0.08	0.01120567	0.003989583	0.0005940596	0.2548092	0.002376239	0.002376239
0.16	0.01120567	0.01058333	0.002207359	0.2548092	0.008829434	0.008829434
0.24	0.01120567	0.01723958	0.003671646	0.2548092	0.01468658	0.01468658
0.32	0.02908707	0.02391667	0.005102158	0.6614195	0.02040863	0.02040863
0.4	0.02864997	0.03055208	0.006928047	0.6514801	0.02771219	0.02771219
0.48	0.03504753	0.03721875	0.008346637	0.7969564	0.03338655	0.03338655
0.56	0.04124641	0.04390625	0.009808938	0.9379146	0.03923575	0.03923575
0.64	0.04692872	0.05054167	0.01124938	1.067126	0.04499753	0.04499753
0.72	0.04998843	0.05721875	0.01306335	1.136702	0.05225341	0.05225341
0.8	0.05404155	0.06391667	0.01421769	1.228867	0.05687078	0.05687078
0.88	0.05837281	0.07054166	0.01539191	1.327357	0.06156762	0.06156762
0.96	0.06520748	0.07723958	0.01704097	1.482772	0.06816387	0.06816387
1.04	0.06934007	0.08391666	0.01861652	1.576745	0.07446607	0.07446607
1.12	0.07446607	0.09055208	0.02008677	1.693306	0.08034706	0.08034706
1.2	0.07931391	0.09723958	0.02125104	1.803543	0.08500417	0.08500417
1.28	0.08459886	0.1038854	0.02293388	1.923719	0.09173552	0.09173552
1.36	0.08837382	0.1105521	0.02429684	2.009559	0.09718736	0.09718736
1.44	0.09342035	0.1172396	0.02600352	2.124314	0.1040141	0.1040141
1.52	0.0971953	0.1238958	0.02724131	2.210153	0.1089652	0.1089652
1.6	0.101765	0.1305521	0.02883871	2.314065	0.1153549	0.1153549
1.68	0.1077255	0.1372396	0.03021161	2.449602	0.1208464	0.1208464
1.76	0.1117388	0.1438958	0.03184478	2.540863	0.1273791	0.1273791
1.84	0.1175006	0.1505625	0.0331223	2.671882	0.1324892	0.1324892
1.92	0.1213551	0.1572396	0.0342528	2.759529	0.1370112	0.1370112
2	0.1274347	0.163875	0.03610849	2.897777	0.144434	0.144434
2.08	0.1311302	0.1705625	0.03741384	2.981809	0.1496553	0.1496553
2.16	0.1355012	0.1772188	0.03856222	3.081203	0.1542489	0.1542489
2.24	0.1411041	0.1838854	0.04036228	3.208608	0.1614491	0.1614491
2.32	0.1446009	0.1905833	0.04154245	3.288123	0.1661698	0.1661698
2.4	0.1510779	0.1972187	0.04315972	3.435406	0.1726389	0.1726389
2.48	0.1540184	0.2038958	0.04457831	3.502271	0.1783133	0.1783133
2.56	0.1600186	0.2105833	0.0458618	3.638711	0.1834472	0.1834472
2.64	0.1650254	0.2172083	0.04746516	3.752562	0.1898607	0.1898607
2.72	0.1675685	0.2238958	0.04912615	3.810391	0.1965046	0.1965046
2.8	0.1729727	0.2305729	0.05011161	3.933278	0.2004464	0.2004464
2.88	0.1772245	0.2372083	0.05153219	4.02996	0.2061288	0.2061288
2.96	0.1832247	0.2438958	0.05282958	4.166401	0.2113183	0.2113183
3.04	0.1893044	0.2505729	0.05467534	4.304648	0.2187014	0.2187014
3.12	0.1920064	0.2572083	0.05595485	4.366092	0.2238194	0.2238194
3.2	0.1972119	0.2639062	0.05736152	4.484461	0.2294461	0.2294461
3.28	0.2026955	0.2705625	0.05869269	4.609155	0.2347708	0.2347708
3.36	0.2047618	0.2772188	0.06013711	4.656141	0.2405484	0.2405484
3.44	0.2096494	0.2839063	0.06177425	4.767281	0.247097	0.247097
3.52	0.2167622	0.2905416	0.06307562	4.929021	0.2523025	0.2523025
3.6	0.2212922	0.2972187	0.06442865	5.03203	0.2577146	0.2577146
3.68	0.2250671	0.3039062	0.06566048	5.117869	0.2626419	0.2626419
3.76	0.2273719	0.3105521	0.06705125	5.170277	0.268205	0.268205
3.84	0.2367496	0.3172292	0.068597	5.383521	0.274388	0.274388
3.92	0.2394517	0.3238958	0.0698944	5.444965	0.2795776	0.2795776
4	0.2427101	0.3305625	0.07113417	5.519058	0.2845367	0.2845367
4.08	0.2485911	0.3372292	0.07227659	5.652788	0.2891064	0.2891064
4.16	0.2535582	0.3438958	0.07375082	5.765735	0.2950033	0.2950033
4.24	0.2588034	0.3505521	0.07511774	5.885007	0.300471	0.300471
4.32	0.2612273	0.3572396	0.07659992	5.940126	0.3063997	0.3063997
4.4	0.2669493	0.363875	0.07795493	6.070241	0.3118197	0.3118197
4.48	0.2707243	0.3705521	0.07954637	6.156081	0.3181855	0.3181855
4.56	0.2765656	0.37725	0.08090734	6.288907	0.3236294	0.3236294
4.64	0.2789497	0.383875	0.08221468	6.343122	0.3288587	0.3288587
4.72	0.283281	0.3905625	0.08373857	6.441612	0.3349543	0.3349543
4.8	0.2898375	0.39725	0.08492867	6.590702	0.3397147	0.3397147
4.88	0.2940893	0.403875	0.08642276	6.687386	0.3456911	0.3456911
4.96	0.298818	0.4105625	0.08756518	6.794911	0.3502607	0.3502607
5.04	0.3007253	0.4172292	0.08905331	6.838283	0.3562132	0.3562132
5.12	0.3066858	0.423875	0.0901401	6.97382	0.3605604	0.3605604
5.2	0.3105402	0.4305729	0.09139379	7.061467	0.3655752	0.3655752
5.28	0.3147523	0.4372292	0.09288192	7.157246	0.3715277	0.3715277
5.36	0.3189643	0.443875	0.09437998	7.253026	0.3775199	0.3775199
5.44	0.3250042	0.4505833	0.09570122	7.390369	0.3828049	0.3828049
5.52	0.3296534	0.4572292	0.09698272	7.496088	0.3879309	0.3879309
5.6	0.3336271	0.4638854	0.09841323	7.586446	0.3936529	0.3936529
5.68	0.3374418	0.4705729	0.09985963	7.67319	0.3994385	0.3994385
5.76	0.3417333	0.4772083	0.1011312	7.770776	0.4045248	0.4045248
5.84	0.3466209	0.4838854	0.1025379	7.881916	0.4101515	0.4101515
5.92	0.3513893	0.4905625	0.1036406	7.990346	0.4145622	0.4145622
6	0.3558795	0.4972188	0.1053055	8.09245	0.4212221	0.4212221
6.08	0.3578663	0.5038958	0.1063565	8.13763	0.4254262	0.4254262
6.16	0.363032	0.510552	0.1078765	8.255095	0.4315058	0.4315058
6.24	0.3682772	0.5172291	0.1092454	8.374366	0.4369815	0.4369815
6.32	0.3718535	0.5239062	0.1104196	8.455688	0.4416784	0.4416784
6.4	0.3782908	0.5305521	0.1119117	8.602068	0.4476468	0.4476468
6.48	0.38143	0.5372187	0.1131316	8.673451	0.4525264	0.4525264
6.56	0.3850063	0.5439063	0.1144111	8.754773	0.4576445	0.4576445
6.64	0.3908475	0.5505416	0.1159867	8.887599	0.4639467	0.4639467
6.72	0.3950596	0.5572187	0.117288	8.983378	0.4691521	0.4691521
6.8	0.3965298	0.5639167	0.1183887	9.016811	0.4735549	0.4735549
6.88	0.4066626	0.5705417	0.1197577	9.247223	0.4790306	0.4790306
6.96	0.4074971	0.5772396	0.1210928	9.266198	0.4843712	0.4843712
7.04	0.4132986	0.5839167	0.1224458	9.398122	0.4897833	0.4897833
7.12	0.4175901	0.5905417	0.1236518	9.495708	0.4946073	0.4946073
7.2	0.4220406	0.5972396	0.1250525	9.596909	0.5002101	0.5002101
7.28	0.4253785	0.6038854	0.1261294	9.672809	0.5045176	0.5045176
7.36	0.4291932	0.6105416	0.1277288	9.759553	0.5109151	0.5109151
7.44	0.4347563	0.6172396	0.1292288	9.886053	0.5169153	0.5169153
7.52	0.438571	0.6238854	0.1302938	9.972796	0.5211751	0.5211751
7.6	0.4432996	0.6305521	0.1316885	10.08032	0.5267541	0.5267541
7.68	0.4469951	0.6372396	0.1327713	10.16436	0.5310853	0.5310853
7.76	0.4512469	0.6438958	0.1342535	10.26104	0.537014	0.537014
7.84	0.45681	0.6505625	0.1357178	10.38754	0.5428712	0.5428712
7.92	0.459075	0.6572396	0.1370311	10.43904	0.5481243	0.5481243
8	0.4635652	0.663875	0.1383066	10.54115	0.5532265	0.5532265
8.08	0.4674991	0.6705625	0.1394093	10.6306	0.5576372	0.5576372
8.16	0.4709562	0.6772187	0.1410763	10.70921	0.564305	0.564305
8.24	0.4754464	0.6838854	0.14202	10.81132	0.5680799	0.5680799
8.32	0.4818439	0.6905833	0.1431584	10.95679	0.5726337	0.5726337
8.4	0.4851818	0.6972083	0.1448293	11.03269	0.5793174	0.5793174
8.48	0.4884402	0.7038958	0.1461148	11.10679	0.5844593	0.5844593
8.56	0.4921357	0.7105833	0.1472036	11.19082	0.5888144	0.5888144
8.64	0.4977385	0.7172083	0.1487176	11.31823	0.5948703	0.5948703
8.72	0.5011559	0.7238854	0.1495024	11.39593	0.5980094	0.5980094
8.8	0.505964	0.7305729	0.1509507	11.50527	0.603803	0.603803
8.88	0.5089442	0.7372083	0.1523415	11.57304	0.6093661	0.6093661
8.96	0.5125602	0.7438958	0.1534343	11.65526	0.6137371	0.6137371
9.04	0.5167723	0.7505729	0.1552145	11.75104	0.6208579	0.6208579
9.12	0.5202293	0.7572083	0.1559277	11.82965	0.6237109	0.6237109
9.2	0.5251567	0.7639062	0.1571536	11.9417	0.6286144	0.6286144
9.28	0.5280972	0.7705729	0.1586099	12.00856	0.6344398	0.6344398
9.36	0.531435	0.7772188	0.1597941	12.08446	0.6391764	0.6391764
9.44	0.5330642	0.7839062	0.1607021	12.12151	0.6428083	0.6428083
9.52	0.5370776	0.7905416	0.161916	12.21277	0.6476641	0.6476641
9.6	0.5424817	0.7972187	0.1630863	12.33566	0.652345	0.652345
9.68	0.5457401	0.8039063	0.1643896	12.40975	0.6575584	0.6575584
9.76	0.5484025	0.8105521	0.1653194	12.47029	0.6612778	0.6612778
9.84	0.5527337	0.8172292	0.1668076	12.56878	0.6672303	0.6672303
9.92	0.5588134	0.8238958	0.1676361	12.70703	0.6705443	0.6705443
10	0.5616744	0.8305625	0.1688143	12.77208	0.675257	0.675257
10.08	0.5653699	0.8372396	0.1704931	12.85612	0.6819725	0.6819725
10.16	0.5714099	0.8438959	0.1717051	12.99346	0.6868203	0.6868203
10.24	0.5725622	0.8505417	0.1725117	13.01966	0.690047	0.690047
10.32	0.5769332	0.8572395	0.1735707	13.11906	0.6942828	0.6942828
10.4	0.5795558	0.8638854	0.1749118	13.17869	0.6996472	0.6996472
10.48	0.5850792	0.8705521	0.1762609	13.30429	0.7050435	0.7050435
10.56	0.5868276	0.87725	0.1768887	13.34405	0.7075548	0.7075548
10.64	0.5897681	0.883875	0.1784523	13.41091	0.7138093	0.7138093
10.72	0.5948146	0.8905625	0.1791636	13.52567	0.7166545	0.7166545
10.8	0.5966027	0.89725	0.1807332	13.56633	0.7229328	0.7229328
10.88	0.6020069	0.903875	0.1817783	13.68922	0.7271131	0.7271131
10.96	0.6055434	0.9105625	0.1830161	13.76963	0.7320642	0.7320642
11.04	0.6103913	0.9172292	0.1839896	13.87987	0.7359584	0.7359584
11.12	0.6120999	0.923875	0.1851459	13.91873	0.7405837	0.7405837
11.2	0.6175836	0.9305729	0.1863221	14.04342	0.7452886	0.7452886
11.28	0.6197293	0.9372292	0.1872162	14.09221	0.7488648	0.7488648
11.36	0.6234248	0.9438854	0.1886348	14.17624	0.7545392	0.7545392
11.44	0.624299	0.9505729	0.1897891	14.19612	0.7591565	0.7591565
11.52	0.6299813	0.9572291	0.1907845	14.32533	0.7631381	0.7631381
11.6	0.6346703	0.9638854	0.1919111	14.43196	0.7676442	0.7676442
11.68	0.6378095	0.9705729	0.1930296	14.50334	0.7721186	0.7721186
11.76	0.6393194	0.9772083	0.1942297	14.53768	0.7769187	0.7769187
11.84	0.6437699	0.9838854	0.1954635	14.63888	0.781854	0.781854
11.92	0.6488562	0.9905625	0.1963298	14.75454	0.785319	0.785319
12	0.6488562	0.9972187	0.1974662	14.75454	0.7898648	0.7898648
12.08	0.6536245	1.003896	0.1987716	14.86296	0.7950862	0.7950862
12.16	0.6564856	1.010552	0.1999299	14.92802	0.7997195	0.7997195
12.24	0.6623666	1.017229	0.2010663	15.06175	0.8042653	0.8042653
12.32	0.6641547	1.023917	0.2023757	15.10241	0.8095026	0.8095026
12.4	0.667572	1.030552	0.2032777	15.18012	0.8131106	0.8131106
12.48	0.6717841	1.037219	0.2044678	15.2759	0.8178711	0.8178711
12.56	0.6748835	1.043906	0.2052923	15.34638	0.8211692	0.8211692
12.64	0.6781419	1.050542	0.2064983	15.42047	0.8259932	0.8259932
12.72	0.6810824	1.057219	0.2076725	15.48734	0.8306901	0.8306901
12.8	0.6851355	1.063917	0.2087573	15.5795	0.8350293	0.8350293
12.88	0.6871621	1.070542	0.2099752	15.62558	0.839901	0.839901
12.96	0.6933212	1.07724	0.2108574	15.76564	0.8434296	0.8434296
13.04	0.6948709	1.083917	0.2121627	15.80088	0.8486509	0.8486509
13.12	0.6982088	1.090542	0.2132932	15.87678	0.853173	0.853173
13.2	0.7011096	1.09724	0.2142648	15.94274	0.8570592	0.8570592
13.28	0.7058382	1.103885	0.2155244	16.05027	0.8620977	0.8620977
13.36	0.7097721	1.110542	0.216647	16.13972	0.8665879	0.8665879
13.44	0.7126331	1.11724	0.2177258	16.20478	0.8709033	0.8709033
13.52	0.7144213	1.123896	0.2189477	16.24544	0.8757909	0.8757909
13.6	0.7181565	1.130552	0.2198796	16.33038	0.8795182	0.8795182
13.68	0.7211764	1.13724	0.2210736	16.39905	0.8842945	0.8842945
13.76	0.726064	1.143896	0.2222339	16.51019	0.8889357	0.8889357
13.84	0.728488	1.150563	0.2235512	16.56531	0.8942048	0.8942048
13.92	0.7311106	1.15724	0.224479	16.62494	0.8979161	0.8979161
14	0.734369	1.163875	0.2257486	16.69904	0.9029945	0.9029945
14.08	0.7363558	1.170563	0.2268215	16.74422	0.907286	0.907286
14.16	0.7425149	1.177229	0.2280156	16.88427	0.9120623	0.9120623
14.24	0.7470449	1.183885	0.2292037	16.98728	0.9168148	0.9168148
14.32	0.7505019	1.190583	0.2300382	17.06589	0.9201527	0.9201527
14.4	0.7510185	1.197219	0.2313813	17.07764	0.925525	0.925525
14.48	0.7545948	1.203896	0.2327641	17.15896	0.9310563	0.9310563
14.56	0.7571777	1.210583	0.2333045	17.21769	0.933218	0.933218
14.64	0.7611911	1.217208	0.2345522	17.30895	0.9382089	0.9382089
14.72	0.7628997	1.223896	0.2360086	17.34781	0.9440343	0.9440343
14.8	0.769337	1.230573	0.2371788	17.49418	0.9487152	0.9487152
14.88	0.7712841	1.237208	0.238359	17.53846	0.9534359	0.9534359
14.96	0.773708	1.243896	0.239416	17.59358	0.9576638	0.9576638
15.04	0.7790327	1.250583	0.2403975	17.71466	0.9615898	0.9615898
15.12	0.7816553	1.257208	0.2417048	17.7743	0.9668191	0.9668191
15.2	0.7862647	1.263906	0.2425313	17.87911	0.9701252	0.9701252
15.28	0.7881721	1.270573	0.2438625	17.92248	0.9754499	0.9754499
15.36	0.7915894	1.277219	0.2454062	18.00019	0.9816249	0.9816249
15.44	0.7961591	1.283906	0.2462963	18.1041	0.9851853	0.9851853
15.52	0.7975499	1.290542	0.2473811	18.13573	0.9895245	0.9895245
15.6	0.8014441	1.297219	0.2486646	18.22428	0.9946585	0.9946585
15.68	0.8056561	1.303906	0.2495368	18.32006	0.9981473	0.9981473
15.76	0.8080006	1.310552	0.2506236	18.37337	1.002494	1.002494
15.84	0.8100669	1.317229	0.2518356	18.42035	1.007342	1.007342
15.92	0.8136432	1.323896	0.2527674	18.50168	1.01107	1.01107
16	0.8165836	1.330562	0.2542535	18.56854	1.017014	1.017014
16.08	0.8227031	1.337229	0.2554794	18.70769	1.021918	1.021918
16.16	0.8237759	1.343896	0.2565642	18.73209	1.026257	1.026257
16.24	0.8263588	1.350552	0.2577186	18.79082	1.030874	1.030874
16.32	0.8312861	1.35724	0.258704	18.90286	1.034816	1.034816
16.4	0.8334319	1.363885	0.2598723	18.95166	1.039489	1.039489
16.48	0.8385579	1.370552	0.2610008	19.06822	1.044003	1.044003
16.56	0.8404255	1.37725	0.2621929	19.11069	1.048772	1.048772
16.64	0.8431275	1.383875	0.2638022	19.17213	1.055209	1.055209
16.72	0.8454323	1.390563	0.2645334	19.22454	1.058133	1.058133
16.8	0.8490086	1.39725	0.2657473	19.30586	1.062989	1.062989
16.88	0.8527438	1.403875	0.2668281	19.3908	1.067313	1.067313
16.96	0.8562009	1.410563	0.2684335	19.46941	1.073734	1.073734
17.04	0.861605	1.417229	0.2691885	19.59229	1.076754	1.076754
17.12	0.8636315	1.423875	0.2705932	19.63838	1.082373	1.082373
17.2	0.8660555	1.430573	0.271531	19.69349	1.086124	1.086124
17.28	0.8709431	1.437229	0.2728125	19.80464	1.09125	1.09125
17.36	0.8726518	1.443885	0.2738535	19.84349	1.095414	1.095414
17.44	0.875632	1.450583	0.2749085	19.91126	1.099634	1.099634
17.52	0.8793275	1.45724	0.276204	19.99529	1.104816	1.104816
17.6	0.8818309	1.463885	0.2772272	20.05222	1.108909	1.108909
17.68	0.885884	1.470573	0.2783775	20.14438	1.11351	1.11351
17.76	0.8899371	1.477208	0.2797762	20.23655	1.119105	1.119105
17.84	0.8920431	1.483885	0.2807418	20.28444	1.122967	1.122967
17.92	0.8948247	1.490573	0.2820333	20.34769	1.128133	1.128133
18	0.8981228	1.497219	0.282826	20.42268	1.131304	1.131304
18.08	0.8995931	1.503906	0.2843618	20.45612	1.137447	1.137447
18.16	0.9045203	1.510552	0.2855261	20.56816	1.142105	1.142105
18.24	0.906388	1.517229	0.2867917	20.61063	1.147167	1.147167
18.32	0.9088516	1.523917	0.2875626	20.66665	1.15025	1.15025
18.4	0.9117921	1.530552	0.2889097	20.73351	1.155639	1.155639
18.48	0.9164016	1.537219	0.2900402	20.83833	1.160161	1.160161
18.56	0.9198983	1.543906	0.2913376	20.91784	1.16535	1.16535
18.64	0.923117	1.550542	0.2925793	20.99104	1.170317	1.170317
18.72	0.926137	1.557219	0.2936602	21.05971	1.174641	1.174641
18.8	0.9287198	1.563917	0.2948483	21.11844	1.179393	1.179393
18.88	0.9312232	1.570542	0.2961377	21.17536	1.184551	1.184551
18.96	0.9365082	1.57724	0.2971093	21.29554	1.188437	1.188437
19.04	0.9379387	1.583917	0.298359	21.32807	1.193436	1.193436
19.12	0.9415944	1.590552	0.2994736	21.4112	1.197894	1.197894
19.2	0.944535	1.59724	0.3005882	21.47806	1.202353	1.202353
19.28	0.9482701	1.603885	0.3020624	21.563	1.20825	1.20825
19.36	0.9506543	1.610552	0.3029267	21.61721	1.211707	1.211707
19.44	0.9542306	1.61724	0.3042559	21.69854	1.217023	1.217023
19.52	0.9565353	1.623896	0.3052393	21.75094	1.220957	1.220957
19.6	0.9598334	1.630552	0.3064533	21.82594	1.225813	1.225813
19.68	0.9635289	1.63724	0.308011	21.90998	1.232044	1.232044
19.76	0.9636481	1.643896	0.3088872	21.91269	1.235549	1.235549
19.84	0.9696484	1.650563	0.3102024	22.04913	1.24081	1.24081
19.92	0.9726683	1.65724	0.31118	22.1178	1.24472	1.24472
20	0.9756486	1.663875	0.3124932	22.18557	1.249973	1.249973
20.08	0.9793441	1.670563	0.3137847	22.2696	1.255139	1.255139
20.16	0.9802182	1.677229	0.3148457	22.28948	1.259383	1.259383
20.24	0.9832382	1.683885	0.3160675	22.35815	1.26427	1.26427
20.32	0.9873708	1.690583	0.3168961	22.45212	1.267584	1.267584
20.4	0.9886026	1.697219	0.3182987	22.48013	1.273195	1.273195
20.48	0.9913047	1.703896	0.3193895	22.54157	1.277558	1.277558
20.56	0.994126	1.710583	0.3208021	22.60573	1.283208	1.283208
20.64	0.9992123	1.717219	0.3216724	22.72139	1.286689	1.286689
20.72	1.00112	1.723885	0.3230691	22.76476	1.292276	1.292276
20.8	1.002431	1.730573	0.3238936	22.79458	1.295575	1.295575
20.88	1.004775	1.737208	0.3250559	22.84789	1.300224	1.300224
20.96	1.007676	1.743896	0.3257513	22.91385	1.303005	1.303005
21.04	1.01157	1.750583	0.3271481	23.0024	1.308592	1.308592
21.12	1.013795	1.757208	0.3286342	23.053	1.314537	1.314537
21.2	1.01463	1.763917	0.3296634	23.07198	1.318653	1.318653
21.28	1.019994	1.770573	0.3304501	23.19396	1.321801	1.321801
21.36	1.020789	1.777219	0.3317297	23.21203	1.326919	1.326919
21.44	1.025518	1.783906	0.3327171	23.31956	1.330868	1.330868
21.52	1.027147	1.790552	0.3340622	23.3566	1.336249	1.336249
21.6	1.028021	1.797219	0.3353218	23.37648	1.341287	1.341287
21.68	1.033227	1.803906	0.3360192	23.49485	1.344077	1.344077
21.76	1.036008	1.810552	0.3375014	23.5581	1.350006	1.350006
21.84	1.036286	1.817229	0.3385445	23.56443	1.354178	1.354178
21.92	1.040975	1.823906	0.3398677	23.67105	1.359471	1.359471
22	1.04173	1.830562	0.34102	23.68822	1.36408	1.36408
22.08	1.044273	1.837229	0.3419161	23.74605	1.367664	1.367664
22.16	1.049161	1.843896	0.3431698	23.85719	1.372679	1.372679
22.24	1.05087	1.850552	0.3443897	23.89604	1.377559	1.377559
22.32	1.05532	1.85724	0.3452718	23.99724	1.381087	1.381087
22.4	1.058857	1.863885	0.3463666	24.07766	1.385466	1.385466
22.48	1.059453	1.870552	0.3478011	24.09121	1.391204	1.391204
22.56	1.062274	1.87725	0.3489216	24.15537	1.395687	1.395687
22.64	1.064936	1.883875	0.3501376	24.21591	1.40055	1.40055
22.72	1.066248	1.890563	0.3514131	24.24572	1.405652	1.405652
22.8	1.068632	1.89725	0.3525595	24.29994	1.410238	1.410238
22.88	1.070539	1.903885	0.353545	24.34331	1.41418	1.41418
22.96	1.075665	1.910563	0.3548463	24.45987	1.419385	1.419385
23.04	1.077453	1.91724	0.3561139	24.50053	1.424456	1.424456
23.12	1.080314	1.923885	0.3570636	24.56559	1.428254	1.428254
23.2	1.080712	1.930573	0.3585259	24.57463	1.434104	1.434104
23.28	1.085242	1.937229	0.3593147	24.67764	1.437259	1.437259
23.36	1.08997	1.943885	0.3604611	24.78516	1.441844	1.441844
23.44	1.091838	1.950583	0.361832	24.82763	1.447328	1.447328
23.52	1.092752	1.957229	0.3629307	24.84841	1.451723	1.451723
23.6	1.095136	1.963885	0.3642082	24.90263	1.456833	1.456833
23.68	1.098792	1.970583	0.3651937	24.98575	1.460775	1.460775
23.76	1.101891	1.977219	0.3664394	25.05623	1.465758	1.465758
23.84	1.103202	1.983896	0.3673693	25.08605	1.469477	1.469477
23.92	1.105229	1.990573	0.3689369	25.13214	1.475747	1.475747
24	1.10662	1.997219	0.3700674	25.16376	1.480269	1.480269
24.08	1.110395	2.003906	0.3713886	25.2496	1.485554	1.485554
24.16	1.112183	2.010562	0.3724992	25.29026	1.489997	1.489997
24.24	1.115322	2.017229	0.3735602	25.36164	1.494241	1.494241
24.32	1.117229	2.023917	0.3746688	25.40502	1.498675	1.498675
24.4	1.120806	2.030542	0.3758371	25.48634	1.503348	1.503348
24.48	1.122912	2.037208	0.3768782	25.53423	1.507513	1.507513
24.56	1.122514	2.043896	0.3785094	25.52519	1.514037	1.514037
24.64	1.125693	2.050542	0.3796915	25.59748	1.518766	1.518766
24.72	1.131654	2.057219	0.3804743	25.73302	1.521897	1.521897
24.8	1.130462	2.063917	0.3819426	25.70591	1.52777	1.52777
24.88	1.134316	2.070542	0.3831724	25.79355	1.53269	1.53269
24.96	1.136661	2.077229	0.3842731	25.84687	1.537093	1.537093
25.04	1.138886	2.083906	0.3853599	25.89747	1.54144	1.54144
25.12	1.142422	2.090542	0.3867328	25.97788	1.546931	1.546931
25.2	1.143495	2.097229	0.3882428	26.00228	1.552971	1.552971
25.28	1.14731	2.103885	0.3891607	26.08902	1.556643	1.556643
25.36	1.147668	2.110542	0.3903786	26.09716	1.561514	1.561514
25.44	1.150767	2.117229	0.3914118	26.16764	1.565647	1.565647
25.52	1.153866	2.123885	0.3927231	26.23812	1.570892	1.570892
25.6	1.155853	2.130542	0.3938516	26.28329	1.575406	1.575406
25.68	1.157284	2.137229	0.3952781	26.31582	1.581113	1.581113
25.76	1.158277	2.143885	0.396651	26.33841	1.586604	1.586604
25.84	1.162887	2.150552	0.3974219	26.44323	1.589688	1.589688
25.92	1.163284	2.15724	0.3988326	26.45226	1.59533	1.59533
26	1.1669	2.163875	0.4000584	26.53449	1.600234	1.600234
26.08	1.16837	2.170552	0.4015684	26.56792	1.606274	1.606274
26.16	1.169682	2.177219	0.4024247	26.59774	1.609699	1.609699
26.24	1.172384	2.183875	0.4038791	26.65919	1.615516	1.615516
26.32	1.176	2.190573	0.4050156	26.74141	1.620062	1.620062
26.4	1.176437	2.197208	0.4062673	26.75135	1.625069	1.625069
26.48	1.177827	2.203896	0.4078011	26.78297	1.631204	1.631204
26.56	1.184265	2.210583	0.4089057	26.92935	1.635623	1.635623
26.64	1.184622	2.217208	0.4104594	26.93748	1.641838	1.641838
26.72	1.18645	2.223875	0.4113714	26.97905	1.645486	1.645486
26.8	1.188397	2.230573	0.412637	27.02333	1.650548	1.650548
26.88	1.191258	2.237208	0.4140258	27.08838	1.656103	1.656103
26.96	1.193166	2.243885	0.4154623	27.13176	1.661849	1.661849
27.04	1.195232	2.250573	0.4165014	27.17874	1.666005	1.666005
27.12	1.196663	2.257198	0.4179478	27.21127	1.671791	1.671791
27.2	1.198928	2.263896	0.4195253	27.26277	1.678101	1.678101
27.28	1.200676	2.270562	0.4204194	27.30253	1.681677	1.681677
27.36	1.202226	2.277208	0.4222115	27.33777	1.688846	1.688846
27.44	1.205762	2.283906	0.4233936	27.41819	1.693575	1.693575
27.52	1.207431	2.290542	0.4247785	27.45614	1.699114	1.699114
27.6	1.209497	2.297208	0.4257659	27.50313	1.703064	1.703064
27.68	1.20914	2.303896	0.4272898	27.49499	1.709159	1.709159
27.76	1.212875	2.310552	0.4284441	27.57993	1.713777	1.713777
27.84	1.214544	2.317219	0.4297753	27.61788	1.719101	1.719101
27.92	1.218518	2.323896	0.4312535	27.70824	1.725014	1.725014
28	1.218279	2.330563	0.4324416	27.70282	1.729766	1.729766
28.08	1.22114	2.337229	0.4338086	27.76788	1.735234	1.735234
28.16	1.22265	2.343885	0.4355887	27.80221	1.742355	1.742355
28.24	1.224796	2.350542	0.4366755	27.851	1.746702	1.746702
28.32	1.226902	2.357229	0.4384001	27.89889	1.7536	1.7536
28.4	1.229008	2.363875	0.4396737	27.94678	1.758695	1.758695
28.48	1.229326	2.370552	0.4413009	27.95401	1.765203	1.765203
28.56	1.23322	2.37725	0.4426956	28.04256	1.770782	1.770782
28.64	1.232068	2.383875	0.4436473	28.01636	1.774589	1.774589
28.72	1.233419	2.390552	0.4451016	28.04708	1.780407	1.780407
28.8	1.23783	2.39725	0.4465401	28.14738	1.78616	1.78616
28.88	1.237869	2.403875	0.4482369	28.14828	1.792947	1.792947
28.96	1.240492	2.410563	0.449582	28.20792	1.798328	1.798328
29.04	1.239777	2.417229	0.4508237	28.19165	1.803295	1.803295
29.12	1.244187	2.423875	0.4523377	28.29195	1.809351	1.809351
29.2	1.244903	2.430562	0.4536072	28.30821	1.814429	1.814429
29.28	1.245896	2.437229	0.4551709	28.3308	1.820683	1.820683
29.36	1.250188	2.443875	0.4567226	28.42839	1.82689	1.82689
29.44	1.249234	2.450573	0.4578948	28.4067	1.831579	1.831579
29.52	1.251856	2.457229	0.4597545	28.46634	1.839018	1.839018
29.6	1.252651	2.463875	0.4611909	28.48441	1.844764	1.844764
29.68	1.254559	2.470573	0.4628062	28.52778	1.851225	1.851225
29.76	1.257062	2.477208	0.464491	28.58471	1.857964	1.857964
29.84	1.257022	2.483885	0.465562	28.58381	1.862248	1.862248
29.92	1.258492	2.490562	0.467068	28.61724	1.868272	1.868272
30	1.258771	2.497219	0.4690826	28.62356	1.87633	1.87633
30.08	1.262387	2.503896	0.4702628	28.70579	1.881051	1.881051
30.16	1.264254	2.510552	0.4721542	28.74826	1.888617	1.888617
30.24	1.262983	2.517229	0.4733026	28.71934	1.89321	1.89321
30.32	1.266519	2.523906	0.4751027	28.79976	1.900411	1.900411
30.4	1.266837	2.530552	0.4765133	28.80699	1.906053	1.906053
30.48	1.271129	2.537208	0.4781584	28.90458	1.912634	1.912634
30.56	1.27097	2.543906	0.4800498	28.90096	1.920199	1.920199
30.64	1.269778	2.550542	0.4811327	28.87386	1.924531	1.924531
30.72	1.271764	2.557219	0.4830122	28.91903	1.932049	1.932049
30.8	1.274347	2.563906	0.4847308	28.97777	1.938923	1.938923
30.88	1.274149	2.570542	0.4862706	28.97325	1.945082	1.945082
30.96	1.276175	2.577229	0.487866	29.01933	1.951464	1.951464
31.04	1.276851	2.583917	0.4894952	29.03469	1.957981	1.957981
31.12	1.279116	2.590552	0.4911085	29.08619	1.964434	1.964434
31.2	1.278559	2.597229	0.4928509	29.07354	1.971404	1.971404
31.28	1.2815	2.603885	0.4944384	29.14041	1.977754	1.977754
31.36	1.281023	2.610542	0.4959603	29.12957	1.983841	1.983841
31.44	1.279871	2.617239	0.4979928	29.10336	1.991971	1.991971
31.52	1.285195	2.623896	0.4993061	29.22444	1.997224	1.997224
31.6	1.285076	2.630552	0.5012989	29.22173	2.005196	2.005196
31.68	1.285752	2.637239	0.5027831	29.23709	2.011132	2.011132
31.76	1.285513	2.643896	0.5047619	29.23167	2.019048	2.019048
31.84	1.286705	2.650563	0.5063395	29.25878	2.025358	2.025358
31.92	1.28746	2.657239	0.5079448	29.27595	2.031779	2.031779
32	1.288533	2.663875	0.5096316	29.30034	2.038527	2.038527
32.08	1.289209	2.670563	0.5113562	29.31571	2.045425	2.045425
32.16	1.289328	2.677219	0.5133967	29.31842	2.053587	2.053587
32.24	1.291116	2.683885	0.5151053	29.35908	2.060421	2.060421
32.32	1.29052	2.690573	0.516663	29.34552	2.066652	2.066652
32.4	1.292706	2.697208	0.5182783	29.39522	2.073113	2.073113
32.48	1.295686	2.703896	0.5200048	29.46299	2.080019	2.080019
32.56	1.293103	2.710583	0.5220532	29.40425	2.088213	2.088213
32.64	1.293778	2.717208	0.5238513	29.41962	2.095405	2.095405
32.72	1.2966	2.723885	0.5252858	29.48377	2.101143	2.101143
32.8	1.29807	2.730573	0.5271633	29.5172	2.108653	2.108653
32.88	1.296083	2.737208	0.5289813	29.47202	2.115925	2.115925
32.96	1.298428	2.743896	0.5309423	29.52534	2.123769	2.123769
33.04	1.299342	2.750573	0.5325139	29.54612	2.130055	2.130055
33.12	1.299342	2.757208	0.5348424	29.54612	2.13937	2.13937
33.2	1.29958	2.763906	0.5364378	29.55154	2.145751	2.145751
33.28	1.300216	2.770573	0.5381246	29.566	2.152498	2.152498
33.36	1.302083	2.777219	0.5399764	29.60847	2.159905	2.159905
33.44	1.301289	2.783906	0.5420645	29.59039	2.168258	2.168258
33.52	1.303236	2.790542	0.5438805	29.63467	2.175522	2.175522
33.6	1.302163	2.797219	0.5452593	29.61027	2.181037	2.181037
33.68	1.303315	2.803906	0.5472322	29.63647	2.188929	2.188929
33.76	1.302799	2.810552	0.5492429	29.62473	2.196972	2.196972
33.84	1.302282	2.817229	0.5509277	29.61298	2.203711	2.203711
33.92	1.304388	2.823896	0.5529165	29.66087	2.211666	2.211666
34	1.303792	2.830552	0.5550206	29.64732	2.220082	2.220082
34.08	1.305779	2.837229	0.5568365	29.6925	2.227346	2.227346
34.16	1.304984	2.843885	0.5584955	29.67443	2.233982	2.233982
34.24	1.306057	2.850542	0.560226	29.69882	2.240904	2.240904
34.32	1.306176	2.857239	0.5624771	29.70153	2.249908	2.249908
34.4	1.306534	2.863885	0.5641878	29.70967	2.256751	2.256751
34.48	1.306494	2.870552	0.5661368	29.70876	2.264547	2.264547
34.56	1.307527	2.87725	0.5681594	29.73225	2.272638	2.272638
34.64	1.307805	2.883875	0.5701562	29.73858	2.280625	2.280625
34.72	1.307845	2.890563	0.5722682	29.73948	2.289073	2.289073
34.8	1.308918	2.89725	0.5741497	29.76388	2.296599	2.296599
34.88	1.308242	2.903875	0.5758782	29.74852	2.303513	2.303513
34.96	1.307964	2.910563	0.5778849	29.7422	2.31154	2.31154
35.04	1.309951	2.917229	0.5797982	29.78737	2.319193	2.319193
35.12	1.309752	2.923875	0.5816996	29.78285	2.326798	2.326798
35.2	1.310309	2.930573	0.5836149	29.79551	2.33446	2.33446
35.28	1.309673	2.937229	0.5855759	29.78105	2.342304	2.342304
35.36	1.313607	2.943875	0.5873283	29.8705	2.349313	2.349313
35.44	1.310666	2.950583	0.5894542	29.80364	2.357817	2.357817
35.52	1.310547	2.957229	0.5913178	29.80093	2.365271	2.365271
35.6	1.311739	2.963885	0.5932848	29.82803	2.373139	2.373139
35.68	1.310945	2.970573	0.5954404	29.80996	2.381762	2.381762
35.76	1.308878	2.977208	0.5973101	29.76298	2.38924	2.38924
35.84	1.310349	2.983896	0.5993446	29.79641	2.397378	2.397378
35.92	1.312375	2.990562	0.6014228	29.84249	2.405691	2.405691
36	1.312494	2.997219	0.6031017	29.8452	2.412407	2.412407
36.08	1.312931	3.003896	0.6051064	29.85514	2.420425	2.420425
36.16	1.312216	3.010552	0.6070872	29.83888	2.428349	2.428349
36.24	1.312057	3.017229	0.6094535	29.83526	2.437814	2.437814
36.32	1.310905	3.023917	0.6110688	29.80906	2.444275	2.444275
36.4	1.312653	3.030552	0.613292	29.84882	2.453168	2.453168
36.48	1.311898	3.037219	0.6155292	29.83165	2.462117	2.462117
36.56	1.312335	3.043906	0.616914	29.84159	2.467656	2.467656
36.64	1.311421	3.050542	0.6189505	29.8208	2.475802	2.475802
36.72	1.312971	3.057219	0.6208877	29.85604	2.483551	2.483551
36.8	1.313964	3.063917	0.6232083	29.87863	2.492833	2.492833
36.88	1.313647	3.070542	0.6251017	29.87141	2.500407	2.500407
36.96	1.313527	3.077229	0.6270687	29.8687	2.508275	2.508275
37.04	1.314521	3.083917	0.628978	29.89128	2.515912	2.515912
37.12	1.312097	3.090542	0.6309966	29.83617	2.523987	2.523987
37.2	1.314481	3.097239	0.6331384	29.89038	2.532554	2.532554
37.28	1.313527	3.103885	0.6351332	29.8687	2.540533	2.540533
37.36	1.313488	3.110552	0.6371279	29.86779	2.548512	2.548512
37.44	1.314044	3.117239	0.6389419	29.88044	2.555768	2.555768
37.52	1.313249	3.123885	0.6410499	29.86237	2.5642	2.5642
37.6	1.312375	3.130552	0.6431063	29.84249	2.572425	2.572425
37.68	1.312733	3.137239	0.6452481	29.85062	2.580992	2.580992
37.76	1.314402	3.143896	0.6473501	29.88857	2.589401	2.589401
37.84	1.313527	3.150563	0.6493111	29.8687	2.597245	2.597245
37.92	1.313011	3.157239	0.6512761	29.85695	2.605104	2.605104
38	1.312653	3.163875	0.6531715	29.84882	2.612686	2.612686
38.08	1.312733	3.170563	0.6554067	29.85062	2.621627	2.621627
38.16	1.312812	3.177219	0.6572008	29.85243	2.628803	2.628803
38.24	1.312931	3.183885	0.659291	29.85514	2.637164	2.637164
38.32	1.312931	3.190573	0.6613652	29.85514	2.645461	2.645461
38.4	1.313011	3.197219	0.6635348	29.85695	2.654139	2.654139
38.48	1.313011	3.203896	0.6654461	29.85695	2.661784	2.661784
38.56	1.31313	3.210583	0.6675124	29.85966	2.67005	2.67005
38.64	1.31313	3.217208	0.6695549	29.85966	2.67822	2.67822
38.72	1.31313	3.223885	0.6714244	29.85966	2.685698	2.685698
38.8	1.31317	3.230573	0.6737073	29.86056	2.694829	2.694829
38.88	1.31321	3.237208	0.6754041	29.86147	2.701616	2.701616
38.96	1.31321	3.243896	0.6777465	29.86147	2.710986	2.710986
39.04	1.313249	3.250573	0.6796718	29.86237	2.718687	2.718687
39.12	1.313329	3.257208	0.6817877	29.86418	2.727151	2.727151
39.2	1.313329	3.263906	0.6838083	29.86418	2.735233	2.735233
39.28	1.313329	3.270573	0.6856878	29.86418	2.742751	2.742751
39.36	1.313408	3.277219	0.6877244	29.86599	2.750897	2.750897
39.44	1.313329	3.283906	0.6901741	29.86418	2.760696	2.760696
39.52	1.313408	3.290542	0.6920437	29.86599	2.768175	2.768175
39.6	1.313408	3.297219	0.6940007	29.86599	2.776003	2.776003
39.68	1.313408	3.303906	0.6961187	29.86599	2.784475	2.784475
39.76	1.313408	3.310552	0.698179	29.86599	2.792716	2.792716
39.84	1.313527	3.317229	0.7000903	29.8687	2.800361	2.800361
39.92	1.313527	3.323896	0.7024606	29.8687	2.809842	2.809842
40	1.313527	3.330562	0.704362	29.8687	2.817448	2.817448
40.08	1.313527	3.337229	0.7064819	29.8687	2.825928	2.825928
40.16	1.313527	3.343896	0.7086496	29.8687	2.834598	2.834598
40.24	1.313527	3.350552	0.7107715	29.8687	2.843086	2.843086
40.32	1.313488	3.357239	0.7127047	29.86779	2.850819	2.850819
40.4	1.313408	3.363885	0.7144828	29.86599	2.857931	2.857931
40.48	1.313408	3.370552	0.7167597	29.86599	2.867039	2.867039
40.56	1.313329	3.37725	0.7192711	29.86418	2.877084	2.877084
40.64	1.313329	3.383875	0.7209699	29.86418	2.883879	2.883879
40.72	1.31321	3.390563	0.7228732	29.86147	2.891493	2.891493
40.8	1.31313	3.39725	0.725158	29.85966	2.900632	2.900632
40.88	1.313011	3.403875	0.7268727	29.85695	2.907491	2.907491
40.96	1.313011	3.410563	0.7292708	29.85695	2.917083	2.917083
41.04	1.312931	3.417229	0.731508	29.85514	2.926032	2.926032
41.12	1.312812	3.423875	0.7331948	29.85243	2.932779	2.932779
41.2	1.312812	3.430573	0.7355034	29.85243	2.942014	2.942014
41.28	1.312733	3.437229	0.7373969	29.85062	2.949588	2.949588
41.36	1.312613	3.443885	0.739799	29.84791	2.959196	2.959196
41.44	1.312613	3.450573	0.7416248	29.84791	2.966499	2.966499
41.52	1.312613	3.457229	0.7435977	29.84791	2.974391	2.974391
41.6	1.312534	3.463885	0.745519	29.8461	2.982076	2.982076
41.68	1.312415	3.470573	0.747631	29.84339	2.990524	2.990524
41.76	1.312415	3.477208	0.7497311	29.84339	2.998924	2.998924
41.84	1.312415	3.483885	0.7519563	29.84339	3.007825	3.007825
41.92	1.312256	3.490562	0.7538855	29.83978	3.015542	3.015542
42	1.312137	3.497219	0.7559518	29.83707	3.023807	3.023807
42.08	1.312137	3.503896	0.758187	29.83707	3.032748	3.032748
42.16	1.312057	3.510552	0.7602811	29.83526	3.041124	3.041124
42.24	1.311938	3.517229	0.7623474	29.83255	3.04939	3.04939
42.32	1.311859	3.523917	0.7644693	29.83075	3.057877	3.057877
42.4	1.31166	3.530552	0.7667204	29.82623	3.066881	3.066881
42.48	1.311541	3.537219	0.7683913	29.82351	3.073565	3.073565
42.56	1.311461	3.543906	0.7706543	29.82171	3.082617	3.082617
42.64	1.311342	3.550542	0.7726411	29.819	3.090564	3.090564
42.72	1.311223	3.557219	0.774616	29.81629	3.098464	3.098464
42.8	1.311064	3.563917	0.7768373	29.81267	3.107349	3.107349
42.88	1.311064	3.570542	0.7788817	29.81267	3.115527	3.115527
42.96	1.310945	3.57724	0.7811387	29.80996	3.124555	3.124555
43.04	1.310746	3.583917	0.783366	29.80544	3.133464	3.133464
43.12	1.310666	3.590542	0.7853369	29.80364	3.141348	3.141348
43.2	1.310547	3.597239	0.7870873	29.80093	3.148349	3.148349
43.28	1.310547	3.603885	0.7894377	29.80093	3.157751	3.157751
43.36	1.310388	3.610552	0.7915397	29.79731	3.166159	3.166159
43.44	1.310269	3.617239	0.7935424	29.7946	3.17417	3.17417
43.52	1.31015	3.623885	0.7958651	29.79189	3.18346	3.18346
43.6	1.31007	3.630552	0.7975896	29.79008	3.190358	3.190358
43.68	1.309991	3.637239	0.7999082	29.78828	3.199633	3.199633
43.76	1.309872	3.643896	0.8022289	29.78557	3.208915	3.208915
43.84	1.309792	3.650563	0.8040707	29.78376	3.216283	3.216283
43.92	1.309594	3.657239	0.8063535	29.77924	3.225414	3.225414
44	1.309474	3.663875	0.8080264	29.77653	3.232105	3.232105
44.08	1.309395	3.670563	0.8104026	29.77472	3.241611	3.241611
44.16	1.309196	3.677219	0.8124431	29.7702	3.249772	3.249772
44.24	1.308998	3.683885	0.8140127	29.76569	3.256051	3.256051
44.32	1.308878	3.690583	0.8166671	29.76298	3.266668	3.266668
44.4	1.308799	3.697208	0.8184711	29.76117	3.273885	3.273885
44.48	1.3086	3.703896	0.8208056	29.75665	3.283222	3.283222
44.56	1.308481	3.710583	0.8229573	29.75394	3.291829	3.291829
44.64	1.308282	3.717219	0.8251071	29.74942	3.300428	3.300428
44.72	1.308203	3.723885	0.8266588	29.74761	3.306635	3.306635
44.8	1.308004	3.730573	0.8290331	29.7431	3.316132	3.316132
44.88	1.307925	3.737208	0.8307855	29.74129	3.323142	3.323142
44.96	1.307805	3.743896	0.8329034	29.73858	3.331614	3.331614
45.04	1.307726	3.750573	0.8350829	29.73677	3.340332	3.340332
45.12	1.307607	3.757208	0.8371572	29.73406	3.348629	3.348629
45.2	1.307527	3.763906	0.8394162	29.73225	3.357665	3.357665
45.28	1.307408	3.770573	0.841558	29.72954	3.366232	3.366232
45.36	1.307329	3.777219	0.8435269	29.72774	3.374108	3.374108
45.44	1.30713	3.783906	0.8453111	29.72322	3.381244	3.381244
45.52	1.307011	3.790542	0.8479416	29.72051	3.391767	3.391767
45.6	1.306931	3.797219	0.8496444	29.7187	3.398577	3.398577
45.68	1.306812	3.803906	0.8518974	29.71599	3.40759	3.40759
45.76	1.306733	3.810552	0.8539557	29.71418	3.415823	3.415823
45.84	1.306534	3.817229	0.8563082	29.70967	3.425233	3.425233
45.92	1.306415	3.823906	0.8582135	29.70695	3.432854	3.432854
46	1.306335	3.830562	0.8600871	29.70515	3.440348	3.440348
46.08	1.306136	3.837229	0.8622368	29.70063	3.448947	3.448947
46.16	1.305977	3.843885	0.8642673	29.69701	3.457069	3.457069
46.24	1.305819	3.850552	0.8664429	29.6934	3.465772	3.465772
46.32	1.305739	3.857239	0.8687258	29.69159	3.474903	3.474903
46.4	1.30554	3.863885	0.870804	29.68708	3.483216	3.483216
46.48	1.305342	3.870552	0.8729994	29.68256	3.491998	3.491998
46.56	1.305262	3.87725	0.8748015	29.68075	3.499206	3.499206
46.64	1.305064	3.883875	0.8768101	29.67624	3.507241	3.507241
46.72	1.304865	3.890563	0.8789023	29.67171	3.515609	3.515609
46.8	1.304746	3.89725	0.881054	29.669	3.524216	3.524216
46.88	1.304666	3.903875	0.883311	29.6672	3.533244	3.533244
46.96	1.304468	3.910563	0.8849601	29.66268	3.53984	3.53984
47.04	1.304269	3.917229	0.8871774	29.65816	3.54871	3.54871
47.12	1.30415	3.923875	0.8892298	29.65545	3.556919	3.556919
47.2	1.30407	3.930573	0.8915146	29.65364	3.566058	3.566058
47.28	1.303951	3.937229	0.8936624	29.65093	3.57465	3.57465
47.36	1.303872	3.943885	0.8957048	29.64913	3.582819	3.582819
47.44	1.303752	3.950583	0.8975903	29.64642	3.590361	3.590361
47.52	1.303593	3.957229	0.8999069	29.6428	3.599628	3.599628
47.6	1.303514	3.963885	0.9017885	29.64099	3.607154	3.607154
47.68	1.303395	3.970573	0.9039581	29.63828	3.615832	3.615832
47.76	1.303275	3.977208	0.9058316	29.63557	3.623327	3.623327
47.84	1.303196	3.983885	0.9081542	29.63376	3.632617	3.632617
47.92	1.303077	3.990573	0.9101312	29.63105	3.640525	3.640525
48	1.302958	3.997219	0.9118378	29.62834	3.647351	3.647351
48.08	1.302799	4.003906	0.91452	29.62473	3.65808	3.65808
48.16	1.3026	4.010552	0.9162486	29.62021	3.664994	3.664994
48.24	1.302481	4.017229	0.9184579	29.6175	3.673832	3.673832
48.32	1.302401	4.023917	0.9205461	29.61569	3.682184	3.682184
48.4	1.302203	4.030552	0.9227137	29.61118	3.690855	3.690855
48.48	1.302004	4.037219	0.9248893	29.60666	3.699557	3.699557
48.56	1.301805	4.043906	0.9269575	29.60214	3.70783	3.70783
48.64	1.301726	4.050541	0.9287457	29.60033	3.714983	3.714983
48.72	1.301607	4.057219	0.9311318	29.59762	3.724527	3.724527
48.8	1.301408	4.063917	0.9328703	29.5931	3.731481	3.731481
48.88	1.301209	4.070542	0.9352644	29.58858	3.741058	3.741058
48.96	1.30113	4.07724	0.9373963	29.58678	3.749585	3.749585
49.04	1.300931	4.083917	0.9392083	29.58226	3.756833	3.756833
49.12	1.300732	4.090552	0.9414613	29.57774	3.765845	3.765845
49.2	1.300534	4.097239	0.9433349	29.57323	3.77334	3.77334
49.28	1.300414	4.103885	0.9455164	29.57051	3.782066	3.782066
49.36	1.300216	4.110552	0.9475827	29.566	3.790331	3.790331
49.44	1.300136	4.117239	0.9496848	29.56419	3.798739	3.798739
49.52	1.299938	4.123885	0.9519557	29.55967	3.807823	3.807823
49.6	1.299739	4.130552	0.9539147	29.55515	3.815659	3.815659
49.68	1.29962	4.137239	0.9559889	29.55244	3.823956	3.823956
49.76	1.29954	4.143896	0.9581466	29.55063	3.832587	3.832587
49.84	1.299342	4.150562	0.959901	29.54612	3.839604	3.839604
49.92	1.299143	4.157239	0.9618759	29.5416	3.847504	3.847504
50	1.299063	4.163886	0.964133	29.53979	3.856532	3.856532
50.08	1.298944	4.170562	0.9661754	29.53708	3.864702	3.864702
50.16	1.298865	4.177219	0.9683172	29.53527	3.873269	3.873269
50.24	1.298666	4.183886	0.9704431	29.53076	3.881772	3.881772
50.32	1.298507	4.190583	0.9724597	29.52714	3.889839	3.889839
50.4	1.298348	4.197219	0.974371	29.52353	3.897484	3.897484
50.48	1.298189	4.203896	0.9764969	29.51991	3.905988	3.905988
50.56	1.29807	4.210583	0.9784858	29.5172	3.913943	3.913943
50.64	1.297871	4.217208	0.9806991	29.51268	3.922796	3.922796
50.72	1.297673	4.223886	0.9828706	29.50817	3.931483	3.931483
50.8	1.297474	4.230573	0.984782	29.50365	3.939128	3.939128
50.88	1.297355	4.237208	0.987188	29.50094	3.948752	3.948752
50.96	1.297156	4.243896	0.9887059	29.49642	3.954824	3.954824
51.04	1.296957	4.250583	0.990963	29.4919	3.963852	3.963852
51.12	1.296798	4.257208	0.9929379	29.48829	3.971751	3.971751
51.2	1.296679	4.263906	0.9950876	29.48558	3.98035	3.98035
51.28	1.2966	4.270573	0.9971559	29.48377	3.988624	3.988624
51.36	1.296401	4.277219	0.999409	29.47925	3.997636	3.997636
51.44	1.296202	4.283906	1.001132	29.47473	4.004526	4.004526
51.52	1.296083	4.290542	1.003309	29.47202	4.013237	4.013237
51.6	1.296004	4.297219	1.005612	29.47022	4.022447	4.022447
51.68	1.295805	4.303906	1.007402	29.4657	4.029608	4.029608
51.76	1.295686	4.310552	1.009538	29.46299	4.038151	4.038151
51.84	1.295606	4.317229	1.011936	29.46118	4.047743	4.047743
51.92	1.295408	4.323896	1.01373	29.45666	4.05492	4.05492
52	1.295288	4.330563	1.015762	29.45395	4.06305	4.06305
52.08	1.295209	4.33724	1.017902	29.45214	4.071609	4.071609
52.16	1.29501	4.343896	1.01973	29.44763	4.078921	4.078921
52.24	1.294851	4.350552	1.022089	29.44401	4.088354	4.088354
52.32	1.294732	4.35724	1.02373	29.4413	4.094919	4.094919
52.4	1.294613	4.363885	1.025728	29.43859	4.102913	4.102913
52.48	1.294533	4.370552	1.028099	29.43678	4.112395	4.112395
52.56	1.294335	4.37725	1.030091	29.43227	4.120366	4.120366
52.64	1.294216	4.383875	1.032084	29.42956	4.128337	4.128337
52.72	1.294136	4.390563	1.034162	29.42775	4.13665	4.13665
52.8	1.293977	4.39725	1.036012	29.42414	4.144049	4.144049
52.88	1.293818	4.403875	1.038227	29.42052	4.15291	4.15291
52.96	1.293739	4.410563	1.040381	29.41871	4.161525	4.161525
53.04	1.29354	4.417229	1.042819	29.4142	4.171276	4.171276
53.12	1.293421	4.423875	1.044554	29.41148	4.178214	4.178214
53.2	1.293222	4.430573	1.046316	29.40697	4.185263	4.185263
53.28	1.293143	4.43724	1.048539	29.40516	4.194156	4.194156
53.36	1.292944	4.443885	1.050756	29.40064	4.203025	4.203025
53.44	1.292825	4.450573	1.052827	29.39793	4.211307	4.211307
53.52	1.292626	4.457229	1.054527	29.39341	4.21811	4.21811
53.6	1.292547	4.463885	1.056747	29.39161	4.226986	4.226986
53.68	1.292348	4.470573	1.058664	29.38709	4.234656	4.234656
53.76	1.292268	4.477208	1.060969	29.38528	4.243875	4.243875
53.84	1.29207	4.483885	1.062822	29.38076	4.251289	4.251289
53.92	1.291951	4.490562	1.065044	29.37805	4.260174	4.260174
54	1.291871	4.497219	1.06683	29.37624	4.267319	4.267319
54.08	1.291672	4.503896	1.069031	29.37173	4.276124	4.276124
54.16	1.291474	4.510552	1.070986	29.36721	4.283945	4.283945
54.24	1.291355	4.517229	1.072729	29.3645	4.290915	4.290915
54.32	1.291275	4.523917	1.075228	29.36269	4.300912	4.300912
54.4	1.291076	4.530552	1.077058	29.35817	4.308232	4.308232
54.48	1.290917	4.537219	1.078769	29.35456	4.315074	4.315074
54.56	1.290758	4.543906	1.081204	29.35095	4.324818	4.324818
54.64	1.290679	4.550541	1.083151	29.34914	4.332606	4.332606
54.72	1.29056	4.557219	1.085224	29.34643	4.340895	4.340895
54.8	1.290361	4.563917	1.08731	29.34191	4.34924	4.34924
54.88	1.290202	4.570541	1.089056	29.33829	4.356225	4.356225
54.96	1.290083	4.57724	1.091375	29.33558	4.3655	4.3655
55.04	1.290003	4.583917	1.093413	29.33378	4.373654	4.373654
55.12	1.289884	4.590552	1.095412	29.33106	4.381649	4.381649
55.2	1.289686	4.597239	1.097468	29.32655	4.389874	4.389874
55.28	1.289606	4.603885	1.099322	29.32474	4.397289	4.397289
55.36	1.289487	4.610552	1.101249	29.32203	4.404998	4.404998
55.44	1.289288	4.617239	1.103377	29.31751	4.413509	4.413509
55.52	1.289209	4.623885	1.10545	29.31571	4.421798	4.421798
55.6	1.28901	4.630552	1.107389	29.31119	4.429555	4.429555
55.68	1.288851	4.637239	1.109674	29.30757	4.438694	4.438694
55.76	1.288692	4.643896	1.111398	29.30396	4.445592	4.445592
55.84	1.288613	4.650562	1.113445	29.30215	4.453778	4.453778
55.92	1.288414	4.657239	1.115825	29.29763	4.463299	4.463299
56	1.288215	4.663875	1.11768	29.29311	4.470722	4.470722
56.08	1.288096	4.670562	1.119904	29.2904	4.479615	4.479615
56.16	1.288017	4.677229	1.121696	29.2886	4.486784	4.486784
56.24	1.287818	4.683886	1.123706	29.28408	4.494826	4.494826
56.32	1.287619	4.690583	1.125729	29.27956	4.502916	4.502916
56.4	1.28754	4.697219	1.127652	29.27776	4.510609	4.510609
56.48	1.287421	4.703896	1.129452	29.27505	4.517809	4.517809
56.56	1.287222	4.710583	1.13192	29.27053	4.52768	4.52768
56.64	1.287023	4.717219	1.13373	29.26601	4.53492	4.53492
56.72	1.286944	4.723886	1.135679	29.2642	4.542717	4.542717
56.8	1.286745	4.730573	1.137453	29.25968	4.549813	4.549813
56.88	1.286626	4.737208	1.139899	29.25697	4.559597	4.559597
56.96	1.286507	4.743896	1.141443	29.25426	4.565772	4.565772
57.04	1.286348	4.750573	1.143489	29.25065	4.573957	4.573957
57.12	1.286149	4.757208	1.14581	29.24613	4.58324	4.58324
57.2	1.28603	4.763906	1.147272	29.24342	4.589089	4.589089
57.28	1.285871	4.770573	1.149696	29.23981	4.598784	4.598784
57.36	1.285752	4.777219	1.151597	29.23709	4.60639	4.60639
57.44	1.285553	4.783906	1.153638	29.23257	4.614552	4.614552
57.52	1.285473	4.790552	1.155649	29.23077	4.622594	4.622594
57.6	1.285354	4.797219	1.157536	29.22806	4.630145	4.630145
57.68	1.285156	4.803906	1.159445	29.22354	4.637782	4.637782
57.76	1.285076	4.810552	1.161428	29.22173	4.645713	4.645713
57.84	1.284917	4.817229	1.163648	29.21812	4.65459	4.65459
57.92	1.284758	4.823906	1.165126	29.2145	4.660503	4.660503
58	1.284639	4.830563	1.167627	29.21179	4.670509	4.670509
58.08	1.28448	4.83724	1.169431	29.20818	4.677725	4.677725
58.16	1.284361	4.843896	1.171585	29.20547	4.68634	4.68634
58.24	1.284162	4.850552	1.173576	29.20095	4.694303	4.694303
58.32	1.284083	4.85724	1.175568	29.19914	4.702274	4.702274
58.4	1.283884	4.863885	1.177472	29.19463	4.709888	4.709888
58.48	1.283765	4.870552	1.179161	29.19192	4.716643	4.716643
58.56	1.283566	4.87725	1.181368	29.1874	4.725472	4.725472
58.64	1.283407	4.883875	1.183321	29.18378	4.733284	4.733284
58.72	1.283288	4.890563	1.185276	29.18107	4.741105	4.741105
58.8	1.283089	4.89725	1.187052	29.17655	4.748209	4.748209
58.88	1.282891	4.903875	1.189395	29.17204	4.757579	4.757579
58.96	1.282692	4.910563	1.191306	29.16752	4.765224	4.765224
59.04	1.282493	4.91724	1.193146	29.163	4.772583	4.772583
59.12	1.282414	4.923875	1.194992	29.16119	4.779967	4.779967
59.2	1.282215	4.930562	1.196826	29.15668	4.787302	4.787302
59.28	1.282016	4.937229	1.199073	29.15216	4.79629	4.79629
59.36	1.281897	4.943885	1.200845	29.14944	4.80338	4.80338
59.44	1.281699	4.950573	1.202885	29.14493	4.811541	4.811541
59.52	1.2815	4.957229	1.204979	29.14041	4.819918	4.819918
59.6	1.28142	4.963885	1.206921	29.1386	4.827682	4.827682
59.68	1.281341	4.970583	1.208548	29.1368	4.834191	4.834191
59.76	1.281142	4.977208	1.210606	29.13228	4.842424	4.842424
59.84	1.281023	4.983896	1.212267	29.12957	4.849068	4.849068
59.92	1.280864	4.990573	1.214272	29.12596	4.857087	4.857087
60	1.280745	4.997219	1.216133	29.12324	4.864534	4.864534
60.08	1.280586	5.003906	1.218307	29.11963	4.873228	4.873228
60.16	1.280427	5.010562	1.220242	29.11601	4.880969	4.880969
60.24	1.280228	5.017229	1.222428	29.1115	4.889711	4.889711
60.32	1.280149	5.023917	1.223882	29.10969	4.895528	4.895528
60.4	1.27995	5.030562	1.226008	29.10517	4.904032	4.904032
60.48	1.279751	5.037219	1.227951	29.10065	4.911804	4.911804
60.56	1.279632	5.043906	1.230039	29.09794	4.920157	4.920157
60.64	1.279434	5.050552	1.231686	29.09343	4.926745	4.926745
60.72	1.279235	5.057219	1.233743	29.08891	4.93497	4.93497
60.8	1.279076	5.063927	1.235416	29.08529	4.941662	4.941662
60.88	1.278957	5.070552	1.237325	29.08258	4.949299	4.949299
60.96	1.278718	5.07724	1.238881	29.07716	4.955522	4.955522
61.04	1.278559	5.083917	1.240955	29.07354	4.963819	4.963819
61.12	1.278361	5.090552	1.242739	29.06903	4.970956	4.970956
61.2	1.278162	5.097239	1.244841	29.06451	4.979364	4.979364
61.28	1.277963	5.103896	1.246178	29.05999	4.984713	4.984713
61.36	1.277765	5.110552	1.247877	29.05548	4.991508	4.991508
61.44	1.277486	5.117239	1.249295	29.04915	4.997182	4.997182
61.52	0.0970761	5.123896	1.292837	2.207443	5.171347	5.171347
61.56	0.006198883	5.126823	1.273715	0.1409583	5.094862	5.094862