File: Shimadzu/Grupo_A-CP29-D.txt
Nome do ensaio	Modo de ensaio	Tipo de ensaio	Título1	Comentário1	Palavra-chave	Nome do produto	Nome do arquivo do ensaio	Nome do arquivo do método	Data do relatório	Data do ensaio	Modo de ensaio	Tipo de ensaio	Velocidade	Placa	Lote No:	Sub-Lote No:
Extensometro SG25-50 - Placa - Sthil_20210601_1525.xtak	Simples	Tração	Grupo de Mecânica Aplicada - GMAp
UFRGS	Comentário	 	 	Extensometro SG25-50 - Placa - Sthil_20210601_1525.xtak	Extensometro SG25-50 - Placa - Sthil.xmak	01/06/2021	01/06/2021	Simples	Tração	5mm/min	Placa	1	1

Placa:	Lote No:	Sub-Lote No:
Placa	1	1
Nome	Espessura	Largura	Gauge Length
Unidade:	mm	mm	mm
Ga_D_29	3.3850	13.0380	115.0000

Nome	Elástico	Inclinação_Padrão	Ruptura_Força	Máx_Força	Max_Disp_Força	Max_Disp_SG-25-50 %	Max_Disp_Deslocamento	Espessura	Largura	Gauge_Length	Máx_Tensão	YS1_Tensão
Parâmetro	Tensão 40 - 60 N/mm2	Tensão 40 - 60 N/mm2	Sensibilidade: 10	Cálculo de áreas completas							Cálculo de áreas completas	0.2 %
Unidade	N/mm2	N/mm	kN	kN	kN	%	mm	mm	mm	mm	N/mm2	N/mm2
Ga_D_29	-.-	-.-	1.26255	1.29374	1.26255	4.74483	4.93805	3.3850	13.0380	115.0000	29.3141	-.-

Ga_D_29
Tempo	Força	Deslocamento	Desloc. SG25-50	Tensão	SG-25-50 %	Deformação
seg	kN	mm	mm	N/mm2	%	%
0	0.01084805	0	0	0.2458	0	0
0.08	0.01084805	0.00396875	0.0003576279	0.2458	0.001430511	0.001430511
0.16	0.01092752	0.01059375	0.00209411	0.2476007	0.008376439	0.008376439
0.24	0.01092752	0.01727083	0.003554424	0.2476007	0.01421769	0.01421769
0.32	0.02642473	0.02388542	0.00491937	0.5987436	0.01967748	0.01967748
0.4	0.02896786	0.0305625	0.006335974	0.656367	0.02534389	0.02534389
0.48	0.03461043	0.03723958	0.007605553	0.784219	0.03042221	0.03042221
0.56	0.03842513	0.043875	0.008928776	0.8706542	0.0357151	0.0357151
0.64	0.04490216	0.0505625	0.01049439	1.017414	0.04197757	0.04197757
0.72	0.04887581	0.05723958	0.01186331	1.10745	0.04745324	0.04745324
0.8	0.05312761	0.06388541	0.01360377	1.20379	0.05441507	0.05441507
0.88	0.0585715	0.07057291	0.01519124	1.32714	0.06076495	0.06076495
0.96	0.06139278	0.07723958	0.01641512	1.391066	0.06566048	0.06566048
1.04	0.06691615	0.08388542	0.01766284	1.516217	0.07065137	0.07065137
1.12	0.07204214	0.09058333	0.01932383	1.632364	0.0772953	0.0772953
1.2	0.07494291	0.09721875	0.02058744	1.698091	0.08234978	0.08234978
1.28	0.07990996	0.1038854	0.02212524	1.810637	0.08850098	0.08850098
1.36	0.08833408	0.1105729	0.0234743	2.001514	0.09389719	0.09389719
1.44	0.09159247	0.1172187	0.02499421	2.075344	0.09997686	0.09997686
1.52	0.09342035	0.1238958	0.02631148	2.116761	0.1052459	0.1052459
1.6	0.09950002	0.1305729	0.02777576	2.254517	0.1111031	0.1111031
1.68	0.1028776	0.1372292	0.02940893	2.331048	0.1176357	0.1176357
1.76	0.1083612	0.1439063	0.03078779	2.455299	0.1231511	0.1231511
1.84	0.1107852	0.1505625	0.03247062	2.510221	0.1298825	0.1298825
1.92	0.1166264	0.1572188	0.0333786	2.642575	0.1335144	0.1335144
2	0.1213948	0.1639062	0.03468196	2.750619	0.1387278	0.1387278
2.08	0.1276334	0.1705521	0.03667275	2.891976	0.146691	0.146691
2.16	0.131766	0.1772188	0.03784497	2.985615	0.1513799	0.1513799
2.24	0.1352628	0.1839167	0.0392139	3.064847	0.1568556	0.1568556
2.32	0.1413822	0.1905417	0.04049937	3.203503	0.1619975	0.1619975
2.4	0.1453956	0.1972396	0.04243652	3.29444	0.1697461	0.1697461
2.48	0.1510382	0.2039167	0.04347563	3.422292	0.1739025	0.1739025
2.56	0.1549323	0.2105521	0.04497568	3.510528	0.1799027	0.1799027
2.64	0.158151	0.2172396	0.04615585	3.583457	0.1846234	0.1846234
2.72	0.1636744	0.2238958	0.04749298	3.708609	0.1899719	0.1899719
2.8	0.1671712	0.2305417	0.04903078	3.787841	0.1961231	0.1961231
2.88	0.1730521	0.2372292	0.05038381	3.921095	0.2015352	0.2015352
2.96	0.1777013	0.2438958	0.05180438	4.026438	0.2072175	0.2072175
3.04	0.1817544	0.2505521	0.05294879	4.118275	0.2117952	0.2117952
3.12	0.1862844	0.25725	0.05476276	4.220917	0.219051	0.219051
3.2	0.192523	0.2639062	0.05597472	4.362275	0.2238989	0.2238989
3.28	0.1947085	0.2705521	0.05746285	4.411795	0.2298514	0.2298514
3.36	0.2010266	0.27725	0.05872051	4.554953	0.234882	0.234882
3.44	0.2045234	0.283875	0.06002784	4.634185	0.2401114	0.2401114
3.52	0.2081394	0.2905521	0.06148617	4.716118	0.2459447	0.2459447
3.6	0.2140204	0.2972292	0.06271601	4.849373	0.250864	0.250864
3.68	0.217557	0.3038854	0.06418824	4.929505	0.256753	0.256753
3.76	0.2229214	0.3105729	0.065732	5.051054	0.262928	0.262928
3.84	0.227054	0.3172188	0.06694794	5.144692	0.2677917	0.2677917
3.92	0.2324581	0.3238958	0.06798506	5.267143	0.2719402	0.2719402
4	0.2378623	0.3305833	0.06997188	5.389593	0.2798875	0.2798875
4.08	0.2415578	0.3372187	0.07103284	5.473326	0.2841314	0.2841314
4.16	0.2460877	0.3438854	0.07256866	5.575968	0.2902746	0.2902746
4.24	0.2487898	0.3505833	0.07377466	5.637193	0.2950986	0.2950986
4.32	0.2539158	0.3572083	0.07510185	5.75334	0.3004074	0.3004074
4.4	0.2598365	0.3638854	0.0764966	5.887496	0.3059864	0.3059864
4.48	0.2630552	0.3705833	0.07766286	5.960425	0.3106515	0.3106515
4.56	0.2684593	0.3772083	0.07897814	6.082874	0.3159126	0.3159126
4.64	0.2728303	0.3839062	0.08044442	6.181915	0.3217777	0.3217777
4.72	0.2763669	0.3905729	0.08171201	6.262047	0.326848	0.326848
4.8	0.2806982	0.3972187	0.08288423	6.360187	0.3315369	0.3315369
4.88	0.2855062	0.4039063	0.08435646	6.469131	0.3374259	0.3374259
4.96	0.2916654	0.4105625	0.08575717	6.608688	0.3430287	0.3430287
5.04	0.2929767	0.4172187	0.08701285	6.638401	0.3480514	0.3480514
5.12	0.2997319	0.4239062	0.08851886	6.791462	0.3540754	0.3540754
5.2	0.3030697	0.4305625	0.08978248	6.867093	0.3591299	0.3591299
5.28	0.3061295	0.4372188	0.09117921	6.936421	0.3647169	0.3647169
5.36	0.3122489	0.4439062	0.09226799	7.075078	0.369072	0.369072
5.44	0.3167788	0.4505625	0.09380579	7.17772	0.3752232	0.3752232
5.52	0.3196398	0.4572292	0.09502967	7.242546	0.3801187	0.3801187
5.6	0.324448	0.4639063	0.09636084	7.35149	0.3854434	0.3854434
5.68	0.3298918	0.4705521	0.09773175	7.47484	0.390927	0.390927
5.76	0.3347	0.4772396	0.09905895	7.583786	0.3962358	0.3962358
5.84	0.3394286	0.4838854	0.1003305	7.690928	0.401322	0.401322
5.92	0.3426472	0.4905521	0.1018822	7.763858	0.4075289	0.4075289
6	0.3474156	0.49725	0.1032372	7.871902	0.4129489	0.4129489
6.08	0.3525019	0.503875	0.1042744	7.987149	0.4170974	0.4170974
6.16	0.3563166	0.5105625	0.1054545	8.073585	0.4218181	0.4218181
6.24	0.3591379	0.5172604	0.1069764	8.13751	0.4279057	0.4279057
6.32	0.3632704	0.5238854	0.1080334	8.231148	0.4321337	0.4321337
6.4	0.3677209	0.5305521	0.1093249	8.33199	0.4372994	0.4372994
6.48	0.3747543	0.5372396	0.1109819	8.491354	0.4439274	0.4439274
6.56	0.3798803	0.543875	0.1123488	8.607501	0.4493952	0.4493952
6.64	0.3818671	0.5505625	0.1137038	8.652519	0.4548152	0.4548152
6.72	0.3856421	0.55725	0.1146297	8.738055	0.4585187	0.4585187
6.8	0.3916422	0.563875	0.1159986	8.874009	0.4639944	0.4639944
6.88	0.3950596	0.5705729	0.1174966	8.951442	0.4699866	0.4699866
6.96	0.4002651	0.5772396	0.1187146	9.069389	0.4748583	0.4748583
7.04	0.4031658	0.5838958	0.1199027	9.135116	0.4796108	0.4796108
7.12	0.4065037	0.5905833	0.1209696	9.210747	0.4838785	0.4838785
7.2	0.4111131	0.5972188	0.1224438	9.315189	0.4897753	0.4897753
7.28	0.4140933	0.6038854	0.1238902	9.382717	0.495561	0.495561
7.36	0.4196167	0.6105729	0.1251737	9.507868	0.5006949	0.5006949
7.44	0.4256566	0.6172292	0.1266261	9.644724	0.5065044	0.5065044
7.52	0.4280011	0.6238958	0.12755	9.697845	0.5101998	0.5101998
7.6	0.4315774	0.6305729	0.1289407	9.778877	0.515763	0.515763
7.68	0.4377365	0.6372291	0.1304905	9.918434	0.5219619	0.5219619
7.76	0.4394452	0.6439062	0.1317004	9.95715	0.5268018	0.5268018
7.84	0.4467964	0.6505521	0.133117	10.12372	0.5324681	0.5324681
7.92	0.4493793	0.6572083	0.1341641	10.18224	0.5366564	0.5366564
8	0.4514456	0.6638958	0.13539	10.22906	0.5415599	0.5415599
8.08	0.4552603	0.6705312	0.1366019	10.3155	0.5464077	0.5464077
8.16	0.4616976	0.6772187	0.1380245	10.46136	0.552098	0.552098
8.24	0.4653533	0.6839063	0.1395563	10.54419	0.5582253	0.5582253
8.32	0.4701217	0.6905313	0.1406173	10.65223	0.5624692	0.5624692
8.4	0.474294	0.6972187	0.1418452	10.74677	0.5673806	0.5673806
8.48	0.4777113	0.7039167	0.1430114	10.8242	0.5720456	0.5720456
8.56	0.4819234	0.7105417	0.1443982	10.91964	0.5775928	0.5775928
8.64	0.48546	0.7172292	0.1455684	10.99977	0.5822738	0.5822738
8.72	0.4920959	0.7238854	0.1468221	11.15014	0.5872886	0.5872886
8.8	0.4936854	0.7305416	0.148056	11.18615	0.5922238	0.5922238
8.88	0.4966656	0.7372292	0.1494745	11.25368	0.5978982	0.5978982
8.96	0.502785	0.7438958	0.1506587	11.39233	0.6026347	0.6026347
9.04	0.505805	0.7505417	0.1517792	11.46076	0.607117	0.607117
9.12	0.5096197	0.7572396	0.1526634	11.5472	0.6106536	0.6106536
9.2	0.5125999	0.7638958	0.1540919	11.61473	0.6163676	0.6163676
9.28	0.5178849	0.7705417	0.1553873	11.73447	0.6215493	0.6215493
9.36	0.5215406	0.7772396	0.1563549	11.81731	0.6254196	0.6254196
9.44	0.5232096	0.783875	0.1576106	11.85512	0.6304423	0.6304423
9.52	0.5281766	0.7905521	0.1587749	11.96767	0.6350994	0.6350994
9.6	0.5335013	0.7972187	0.1600246	12.08832	0.6400983	0.6400983
9.68	0.5375544	0.803875	0.1612027	12.18015	0.644811	0.644811
9.76	0.5392631	0.8105625	0.1623174	12.21887	0.6492694	0.6492694
9.84	0.5442699	0.8172187	0.1635889	12.33232	0.6543557	0.6543557
9.92	0.5491972	0.8238958	0.1646042	12.44396	0.6584167	0.6584167
10	0.5508661	0.8305833	0.1657645	12.48178	0.663058	0.663058
10.08	0.5524556	0.8372188	0.1668235	12.51779	0.6672938	0.6672938
10.16	0.5582173	0.8438854	0.1678944	12.64834	0.6715775	0.6715775
10.24	0.560085	0.8505729	0.1692315	12.69066	0.676926	0.676926
10.32	0.566562	0.8572083	0.1704315	12.83742	0.6817262	0.6817262
10.4	0.5699396	0.8638854	0.171423	12.91395	0.6856918	0.6856918
10.48	0.5743901	0.8705729	0.1724581	13.01479	0.6898324	0.6898324
10.56	0.576973	0.8772084	0.1739264	13.07332	0.6957054	0.6957054
10.64	0.5800326	0.8838958	0.1748164	13.14264	0.6992658	0.6992658
10.72	0.5835295	0.8905729	0.1761119	13.22188	0.7044474	0.7044474
10.8	0.5899668	0.8972083	0.1768827	13.36774	0.707531	0.707531
10.88	0.5892913	0.9038958	0.1781225	13.35243	0.7124901	0.7124901
10.96	0.5925099	0.9105521	0.1793563	13.42536	0.7174253	0.7174253
11.04	0.5989472	0.9172083	0.180759	13.57122	0.7230361	0.7230361
11.12	0.6025632	0.9238958	0.1815657	13.65315	0.7262627	0.7262627
11.2	0.6067753	0.9305521	0.1830439	13.74859	0.7321755	0.7321755
11.28	0.6099145	0.9372083	0.1836558	13.81972	0.7346233	0.7346233
11.36	0.6113847	0.9439062	0.1850188	13.85303	0.7400751	0.7400751
11.44	0.6151597	0.950552	0.1860718	13.93857	0.7442872	0.7442872
11.52	0.620842	0.9572188	0.1871983	14.06732	0.7487933	0.7487933
11.6	0.6216764	0.9638958	0.188446	14.08623	0.7537842	0.7537842
11.68	0.6239812	0.9705417	0.1892626	14.13845	0.7570505	0.7570505
11.76	0.6301403	0.9772292	0.1907547	14.27801	0.7630189	0.7630189
11.84	0.6320477	0.9838854	0.1918197	14.32123	0.7672787	0.7672787
11.92	0.6378492	0.9905521	0.1928627	14.45268	0.771451	0.771451
12	0.6389618	0.9972396	0.1937747	14.47789	0.7750988	0.7750988
12.08	0.6433328	1.003875	0.1948098	14.57693	0.7792394	0.7792394
12.16	0.6457965	1.010563	0.1963973	14.63275	0.7855892	0.7855892
12.24	0.6490946	1.01725	0.1972039	14.70748	0.7888158	0.7888158
12.32	0.6535848	1.023875	0.1983762	14.80922	0.7935047	0.7935047
12.4	0.6564856	1.030552	0.1992802	14.87495	0.7971207	0.7971207
12.48	0.6608565	1.037229	0.2004166	14.97399	0.8016666	0.8016666
12.56	0.6646315	1.043875	0.2013981	15.05953	0.8055925	0.8055925
12.64	0.6657044	1.050552	0.2027512	15.08384	0.8110046	0.8110046
12.72	0.6689231	1.05724	0.2036591	15.15677	0.8146365	0.8146365
12.8	0.6722212	1.063875	0.2049565	15.2315	0.8198261	0.8198261
12.88	0.6773074	1.070573	0.205934	15.34674	0.8237362	0.8237362
12.96	0.6795327	1.077229	0.2074242	15.39716	0.8296967	0.8296967
13.04	0.6816785	1.083885	0.2082189	15.44578	0.8328755	0.8328755
13.12	0.6866058	1.090573	0.209413	15.55743	0.8376519	0.8376519
13.2	0.6873608	1.097208	0.2105375	15.57454	0.84215	0.84215
13.28	0.6942351	1.103875	0.2116024	15.7303	0.8464098	0.8464098
13.36	0.6943544	1.110562	0.2127171	15.733	0.8508682	0.8508682
13.44	0.7005135	1.117219	0.2140065	15.87256	0.856026	0.856026
13.52	0.7029374	1.123885	0.215135	15.92748	0.8605401	0.8605401
13.6	0.7069508	1.130563	0.2160927	16.01842	0.8643706	0.8643706
13.68	0.7109244	1.137229	0.2175232	16.10845	0.8700927	0.8700927
13.76	0.7119576	1.143896	0.2183676	16.13186	0.8734703	0.8734703
13.84	0.7166068	1.150552	0.2195935	16.23721	0.8783738	0.8783738
13.92	0.719587	1.157208	0.2205114	16.30473	0.8820454	0.8820454
14	0.7224481	1.163896	0.2216895	16.36956	0.8867581	0.8867581
14.08	0.7278919	1.170542	0.2226571	16.49291	0.8906285	0.8906285
14.16	0.7265806	1.177219	0.2238393	16.4632	0.8953571	0.8953571
14.24	0.7315477	1.183917	0.2251128	16.57574	0.9004514	0.9004514
14.32	0.7374684	1.190542	0.2260566	16.7099	0.9042263	0.9042263
14.4	0.7390976	1.197229	0.2271076	16.74681	0.9084304	0.9084304
14.48	0.741601	1.203917	0.2284447	16.80354	0.913779	0.913779
14.56	0.7454157	1.210552	0.2294918	16.88997	0.9179671	0.9179671
14.64	0.7495483	1.217229	0.2307475	16.98361	0.9229898	0.9229898
14.72	0.7509788	1.223896	0.2316992	17.01602	0.9267966	0.9267966
14.8	0.7559061	1.230542	0.2329091	17.12767	0.9316365	0.9316365
14.88	0.7598003	1.237229	0.2340615	17.2159	0.9362459	0.9362459
14.96	0.7611911	1.243896	0.2349357	17.24742	0.9397427	0.9397427
15.04	0.7668734	1.250542	0.2362549	17.37617	0.9450197	0.9450197
15.12	0.7701715	1.25724	0.237304	17.4509	0.9492159	0.9492159
15.2	0.7719994	1.263896	0.2384583	17.49232	0.9538333	0.9538333
15.28	0.7733901	1.270552	0.2396206	17.52383	0.9584824	0.9584824
15.36	0.7803838	1.27724	0.2406855	17.68229	0.9627421	0.9627421
15.44	0.7821719	1.283875	0.241967	17.72281	0.9678681	0.9678681
15.52	0.7871787	1.290552	0.2431035	17.83626	0.972414	0.972414
15.6	0.7881324	1.297229	0.2439559	17.85786	0.9758234	0.9758234
15.68	0.7941723	1.303885	0.245136	17.99472	0.9805441	0.9805441
15.76	0.7965565	1.310562	0.2462983	18.04874	0.9851933	0.9851933
15.84	0.797232	1.317219	0.2472281	18.06405	0.9889126	0.9889126
15.92	0.8014838	1.323885	0.2485693	18.16039	0.994277	0.994277
16	0.8052588	1.330583	0.2497097	18.24592	0.9988387	0.9988387
16.08	0.805378	1.337208	0.25087	18.24862	1.00348	1.00348
16.16	0.8113782	1.343885	0.2520263	18.38458	1.008105	1.008105
16.24	0.8140008	1.350573	0.2530535	18.444	1.012214	1.012214
16.32	0.8145968	1.357208	0.2539893	18.45751	1.015957	1.015957
16.4	0.8219878	1.363885	0.2551039	18.62498	1.020416	1.020416
16.48	0.8208752	1.370573	0.2563079	18.59977	1.025232	1.025232
16.56	0.8276303	1.377208	0.2575239	18.75283	1.030095	1.030095
16.64	0.8299351	1.383896	0.2585431	18.80505	1.034172	1.034172
16.72	0.8328755	1.390573	0.2597114	18.87168	1.038845	1.038845
16.8	0.8368095	1.397219	0.2609531	18.96081	1.043812	1.043812
16.88	0.8367698	1.403906	0.2622108	18.95991	1.048843	1.048843
16.96	0.8434455	1.410552	0.263238	19.11118	1.052952	1.052952
17.04	0.8450747	1.417219	0.2641479	19.14809	1.056592	1.056592
17.12	0.8474191	1.423906	0.2652864	19.20121	1.061145	1.061145
17.2	0.8497636	1.430552	0.266395	19.25433	1.06558	1.06558
17.28	0.854214	1.437219	0.26775	19.35517	1.071	1.071
17.36	0.8563598	1.443906	0.2687057	19.40379	1.074823	1.074823
17.44	0.8595784	1.450562	0.269709	19.47672	1.078836	1.078836
17.52	0.8611282	1.457229	0.2707561	19.51184	1.083024	1.083024
17.6	0.8658568	1.463896	0.2717873	19.61898	1.087149	1.087149
17.68	0.8674462	1.470552	0.2728303	19.65499	1.091321	1.091321
17.76	0.8725325	1.477229	0.273929	19.77024	1.095716	1.095716
17.84	0.872453	1.483885	0.2747655	19.76844	1.099062	1.099062
17.92	0.8777778	1.490552	0.2758721	19.88909	1.103489	1.103489
18	0.8800824	1.49724	0.277251	19.94131	1.109004	1.109004
18.08	0.8833408	1.503875	0.2780596	20.01514	1.112239	1.112239
18.16	0.8843343	1.510563	0.2793034	20.03765	1.117214	1.117214
18.24	0.8906126	1.51725	0.2802809	20.17991	1.121124	1.121124
18.32	0.8897384	1.523875	0.2814074	20.1601	1.12563	1.12563
18.4	0.8930762	1.530552	0.2823114	20.23573	1.129246	1.129246
18.48	0.8981228	1.53724	0.2834221	20.35008	1.133688	1.133688
18.56	0.8998315	1.543875	0.2848188	20.3888	1.139275	1.139275
18.64	0.9047191	1.550563	0.2855996	20.49954	1.142398	1.142398
18.72	0.9056727	1.55724	0.2862871	20.52115	1.145148	1.145148
18.8	0.9087324	1.563875	0.2877712	20.59048	1.151085	1.151085
18.88	0.9135008	1.570573	0.288713	20.69852	1.154852	1.154852
18.96	0.9150903	1.57724	0.290062	20.73454	1.160248	1.160248
19.04	0.918746	1.583885	0.2908687	20.81737	1.163475	1.163475
19.12	0.918587	1.590573	0.2919714	20.81377	1.167885	1.167885
19.2	0.921011	1.597208	0.2928297	20.86869	1.171319	1.171319
19.28	0.924468	1.603875	0.294135	20.94702	1.17654	1.17654
19.36	0.9285212	1.610573	0.2951642	21.03886	1.180657	1.180657
19.44	0.931859	1.617219	0.2961834	21.11449	1.184734	1.184734
19.52	0.9324551	1.623896	0.2975086	21.12799	1.190035	1.190035
19.6	0.9361506	1.630562	0.298359	21.21173	1.193436	1.193436
19.68	0.9388526	1.637229	0.2994776	21.27295	1.19791	1.19791
19.76	0.9405613	1.643896	0.3006597	21.31167	1.202639	1.202639
19.84	0.9427865	1.650552	0.3017366	21.36209	1.206946	1.206946
19.92	0.9471973	1.657219	0.3029366	21.46203	1.211747	1.211747
20	0.9487073	1.663906	0.3037135	21.49624	1.214854	1.214854
20.08	0.9520054	1.670552	0.3050387	21.57097	1.220155	1.220155
20.16	0.954469	1.677219	0.3062308	21.6268	1.224923	1.224923
20.24	0.9595553	1.683917	0.3070593	21.74204	1.228237	1.228237
20.32	0.9615421	1.690542	0.3082474	21.78706	1.23299	1.23299
20.4	0.9632905	1.697229	0.3091474	21.82668	1.23659	1.23659
20.48	0.9644826	1.703917	0.3100375	21.85369	1.24015	1.24015
20.56	0.9702444	1.710542	0.3113508	21.98424	1.245403	1.245403
20.64	0.9702444	1.717229	0.3126482	21.98424	1.250593	1.250593
20.72	0.9729068	1.723896	0.3133059	22.04457	1.253223	1.253223
20.8	0.9771983	1.730542	0.3143032	22.14181	1.257213	1.257213
20.88	0.9790261	1.73724	0.3158251	22.18322	1.263301	1.263301
20.96	0.9826422	1.743896	0.3166	22.26516	1.2664	1.2664
21.04	0.9830793	1.750552	0.3176848	22.27506	1.270739	1.270739
21.12	0.9864966	1.75724	0.3189842	22.35249	1.275937	1.275937
21.2	0.989	1.763896	0.3198763	22.40922	1.279505	1.279505
21.28	0.9940465	1.770552	0.3212194	22.52356	1.284877	1.284877
21.36	0.993212	1.77724	0.3224512	22.50465	1.289805	1.289805
21.44	0.9968281	1.783875	0.3234247	22.58659	1.293699	1.293699
21.52	1.00112	1.790552	0.3241539	22.68383	1.296616	1.296616
21.6	1.002312	1.797229	0.325487	22.71084	1.301948	1.301948
21.68	1.004736	1.803885	0.3262778	22.76576	1.305111	1.305111
21.76	1.008113	1.810573	0.3275633	22.84229	1.310253	1.310253
21.84	1.008391	1.817219	0.3285507	22.84859	1.314203	1.314203
21.92	1.012842	1.823896	0.3298899	22.94943	1.319559	1.319559
22	1.014431	1.830583	0.3307621	22.98545	1.323048	1.323048
22.08	1.01761	1.837208	0.3318071	23.05748	1.327229	1.327229
22.16	1.020948	1.843885	0.3330171	23.13311	1.332068	1.332068
22.24	1.022538	1.850573	0.3337363	23.16913	1.334945	1.334945
22.32	1.025359	1.857208	0.3349642	23.23305	1.339857	1.339857
22.4	1.028776	1.863885	0.3363371	23.31048	1.345348	1.345348
22.48	1.029491	1.870583	0.3372252	23.32669	1.348901	1.348901
22.56	1.032988	1.877208	0.3384551	23.40592	1.35382	1.35382
22.64	1.036048	1.883906	0.339512	23.47525	1.358048	1.358048
22.72	1.037836	1.890573	0.3408948	23.51577	1.363579	1.363579
22.8	1.039942	1.897208	0.3420591	23.56349	1.368237	1.368237
22.88	1.044711	1.903906	0.342826	23.67153	1.371304	1.371304
22.96	1.046578	1.910552	0.3442983	23.71385	1.377193	1.377193
23.04	1.047452	1.917219	0.345095	23.73366	1.38038	1.38038
23.12	1.050512	1.923906	0.3463705	23.80298	1.385482	1.385482
23.2	1.053969	1.930552	0.3475904	23.88132	1.390362	1.390362
23.28	1.056433	1.937219	0.348562	23.93714	1.394248	1.394248
23.36	1.057307	1.943906	0.3497561	23.95695	1.399024	1.399024
23.44	1.059016	1.950562	0.3508607	23.99566	1.403443	1.403443
23.52	1.063347	1.957229	0.3520946	24.0938	1.408378	1.408378
23.6	1.065532	1.963896	0.3530641	24.14332	1.412257	1.412257
23.68	1.067837	1.970542	0.3540715	24.19554	1.416286	1.416286
23.76	1.069347	1.977229	0.3556033	24.22976	1.422413	1.422413
23.84	1.072884	1.983885	0.3564139	24.30989	1.425656	1.425656
23.92	1.077255	1.990552	0.3574173	24.40893	1.429669	1.429669
24	1.078606	1.99725	0.3586451	24.43954	1.43458	1.43458
24.08	1.079639	2.003875	0.3599882	24.46295	1.439953	1.439953
24.16	1.082301	2.010562	0.3609439	24.52328	1.443776	1.443776
24.24	1.086712	2.01725	0.3621817	24.62322	1.448727	1.448727
24.32	1.088818	2.023875	0.3632625	24.67094	1.45305	1.45305
24.4	1.089811	2.030552	0.3643354	24.69345	1.457342	1.457342
24.48	1.092076	2.03724	0.3654102	24.74477	1.461641	1.461641
24.56	1.095096	2.043875	0.3665785	24.81319	1.466314	1.466314
24.64	1.095374	2.050562	0.3679097	24.8195	1.471639	1.471639
24.72	1.098673	2.05724	0.3690422	24.89423	1.476169	1.476169
24.8	1.099547	2.063885	0.3702899	24.91404	1.48116	1.48116
24.88	1.103083	2.070573	0.3714184	24.99417	1.485674	1.485674
24.96	1.107415	2.07724	0.3724495	25.09231	1.489798	1.489798
25.04	1.109362	2.083885	0.3736973	25.13643	1.494789	1.494789
25.12	1.109481	2.090573	0.3748695	25.13913	1.499478	1.499478
25.2	1.110474	2.097208	0.3762046	25.16163	1.504819	1.504819
25.28	1.114766	2.103885	0.3772418	25.25887	1.508967	1.508967
25.36	1.115839	2.110573	0.3785352	25.28318	1.514141	1.514141
25.44	1.118938	2.117219	0.3795405	25.35341	1.518162	1.518162
25.52	1.120687	2.123896	0.3808379	25.39303	1.523352	1.523352
25.6	1.122912	2.130563	0.3819565	25.44345	1.527826	1.527826
25.68	1.12621	2.137229	0.3831645	25.51818	1.532658	1.532658
25.76	1.127561	2.143906	0.3843129	25.54879	1.537251	1.537251
25.84	1.130939	2.150552	0.3852288	25.62532	1.540915	1.540915
25.92	1.133958	2.157219	0.3867825	25.69375	1.54713	1.54713
26	1.134316	2.163906	0.3881415	25.70185	1.552566	1.552566
26.08	1.137058	2.170542	0.3890455	25.76398	1.556182	1.556182
26.16	1.137733	2.177219	0.3906449	25.77929	1.56258	1.56258
26.24	1.140436	2.183917	0.3915111	25.84051	1.566044	1.566044
26.32	1.142422	2.190542	0.3928939	25.88553	1.571576	1.571576
26.4	1.146118	2.19724	0.3941278	25.96926	1.576511	1.576511
26.48	1.148065	2.203917	0.3951013	26.01338	1.580405	1.580405
26.56	1.14878	2.210542	0.3965994	26.02959	1.586398	1.586398
26.64	1.152039	2.21724	0.3976127	26.10342	1.590451	1.590451
26.72	1.153191	2.223896	0.3987928	26.12953	1.595171	1.595171
26.8	1.156012	2.230542	0.4000088	26.19345	1.600035	1.600035
26.88	1.159668	2.23724	0.4011551	26.27629	1.604621	1.604621
26.96	1.161496	2.243896	0.402681	26.31771	1.610724	1.610724
27.04	1.160344	2.250552	0.4038672	26.2916	1.615469	1.615469
27.12	1.16388	2.25724	0.4050156	26.37173	1.620062	1.620062
27.2	1.16539	2.263896	0.4060904	26.40594	1.624362	1.624362
27.28	1.16837	2.270552	0.4075587	26.47347	1.630235	1.630235
27.36	1.170198	2.27724	0.40887	26.51488	1.63548	1.63548
27.44	1.171112	2.283875	0.4101952	26.53559	1.640781	1.640781
27.52	1.172463	2.290552	0.4115442	26.56621	1.646177	1.646177
27.6	1.176993	2.297229	0.4125953	26.66885	1.650381	1.650381
27.68	1.179059	2.303885	0.4140655	26.71567	1.656262	1.656262
27.76	1.181006	2.310573	0.4152814	26.75978	1.661126	1.661126
27.84	1.183073	2.317219	0.4167557	26.8066	1.667023	1.667023
27.92	1.184344	2.323896	0.4176895	26.83541	1.670758	1.670758
28	1.185695	2.330583	0.4190981	26.86603	1.676393	1.676393
28.08	1.187483	2.337219	0.4204532	26.90654	1.681813	1.681813
28.16	1.189709	2.343885	0.4221281	26.95697	1.688512	1.688512
28.24	1.191815	2.350573	0.4233181	27.00468	1.693273	1.693273
28.32	1.193802	2.357208	0.4244348	27.0497	1.697739	1.697739
28.4	1.196504	2.363885	0.4258295	27.11093	1.703318	1.703318
28.48	1.195391	2.370583	0.4269282	27.08572	1.707713	1.707713
28.56	1.19857	2.377208	0.428319	27.15775	1.713276	1.713276
28.64	1.202186	2.383906	0.4297177	27.23968	1.718871	1.718871
28.72	1.20306	2.390573	0.4310926	27.25949	1.72437	1.72437
28.8	1.203219	2.397219	0.4324734	27.26309	1.729894	1.729894
28.88	1.20604	2.403906	0.4338404	27.32702	1.735361	1.735361
28.96	1.206994	2.410552	0.4349887	27.34863	1.739955	1.739955
29.04	1.209855	2.417219	0.4363656	27.41345	1.745462	1.745462
29.12	1.210054	2.423906	0.4377007	27.41795	1.750803	1.750803
29.2	1.214425	2.430552	0.4394452	27.51699	1.757781	1.757781
29.28	1.213829	2.437219	0.4404187	27.50349	1.761675	1.761675
29.36	1.217127	2.443906	0.442042	27.57822	1.768168	1.768168
29.44	1.216849	2.450562	0.443242	27.57192	1.772968	1.772968
29.52	1.218478	2.457229	0.4447401	27.60883	1.77896	1.77896
29.6	1.219908	2.463896	0.4460951	27.64124	1.78438	1.78438
29.68	1.221895	2.470542	0.4474223	27.68626	1.789689	1.789689
29.76	1.22269	2.477229	0.4486362	27.70427	1.794545	1.794545
29.84	1.22273	2.483885	0.4500469	27.70517	1.800187	1.800187
29.92	1.228571	2.490552	0.4516045	27.83752	1.806418	1.806418
30	1.228611	2.49725	0.4531125	27.83842	1.81245	1.81245
30.08	1.228015	2.503875	0.4546463	27.82492	1.818585	1.818585
30.16	1.230756	2.510562	0.4560272	27.88704	1.824109	1.824109
30.24	1.23167	2.51725	0.457267	27.90775	1.829068	1.829068
30.32	1.233021	2.523875	0.4585028	27.93836	1.834011	1.834011
30.4	1.235565	2.530562	0.4599968	27.99599	1.839987	1.839987
30.48	1.237154	2.53724	0.4614572	28.032	1.845829	1.845829
30.56	1.23783	2.543875	0.4628857	28.04731	1.851543	1.851543
30.64	1.237988	2.550562	0.4644593	28.05091	1.857837	1.857837
30.72	1.240452	2.55724	0.4656553	28.10673	1.862621	1.862621
30.8	1.242399	2.563875	0.4673421	28.15085	1.869369	1.869369
30.88	1.244068	2.570573	0.4685899	28.18867	1.874359	1.874359
30.96	1.244148	2.577229	0.4704873	28.19047	1.881949	1.881949
31.04	1.247446	2.583885	0.4716913	28.2652	1.886765	1.886765
31.12	1.248558	2.590573	0.4733244	28.29041	1.893298	1.893298
31.2	1.247803	2.597208	0.4746974	28.2733	1.898789	1.898789
31.28	1.250068	2.603885	0.4762073	28.32462	1.904829	1.904829
31.36	1.250903	2.610573	0.4777094	28.34353	1.910838	1.910838
31.44	1.251221	2.617219	0.4792134	28.35073	1.916854	1.916854
31.52	1.253366	2.623896	0.480475	28.39935	1.9219	1.9219
31.6	1.251499	2.630563	0.4822175	28.35703	1.92887	1.92887
31.68	1.254996	2.637229	0.4837493	28.43627	1.934997	1.934997
31.76	1.256982	2.643906	0.485601	28.48129	1.942404	1.942404
31.84	1.255711	2.650563	0.4870852	28.45247	1.948341	1.948341
31.92	1.256426	2.657219	0.4884183	28.46868	1.953673	1.953673
32	1.260638	2.663906	0.4899383	28.56412	1.959753	1.959753
32.08	1.259247	2.670552	0.4912575	28.53261	1.96503	1.96503
32.16	1.259287	2.677219	0.4930576	28.53351	1.97223	1.97223
32.24	1.260757	2.683917	0.4944324	28.56682	1.97773	1.97773
32.32	1.263777	2.690542	0.4959464	28.63525	1.983786	1.983786
32.4	1.263261	2.697229	0.4976451	28.62354	1.990581	1.990581
32.48	1.26338	2.703917	0.4991333	28.62624	1.996533	1.996533
32.56	1.264016	2.710542	0.5006552	28.64065	2.002621	2.002621
32.64	1.26493	2.717229	0.5024274	28.66136	2.00971	2.00971
32.72	1.267433	2.723896	0.5038877	28.71808	2.015551	2.015551
32.8	1.267672	2.730542	0.5057037	28.72348	2.022815	2.022815
32.88	1.267076	2.73724	0.5073011	28.70998	2.029204	2.029204
32.96	1.268466	2.743896	0.5087216	28.74149	2.034887	2.034887
33.04	1.268268	2.750552	0.5104582	28.73699	2.041833	2.041833
33.12	1.269182	2.75724	0.511982	28.7577	2.047928	2.047928
33.2	1.270533	2.763896	0.5137007	28.78831	2.054803	2.054803
33.28	1.271367	2.770552	0.5156815	28.80722	2.062726	2.062726
33.36	1.271168	2.77724	0.5167961	28.80272	2.067184	2.067184
33.44	1.271725	2.783875	0.5185505	28.81532	2.074202	2.074202
33.52	1.272281	2.790552	0.5201757	28.82793	2.080703	2.080703
33.6	1.273195	2.797229	0.5218526	28.84863	2.08741	2.08741
33.68	1.272798	2.803885	0.5235334	28.83963	2.094134	2.094134
33.76	1.274864	2.810573	0.5250613	28.88645	2.100245	2.100245
33.84	1.277725	2.817219	0.5269964	28.95128	2.107986	2.107986
33.92	1.276851	2.823896	0.5283793	28.93147	2.113517	2.113517
34	1.278082	2.830583	0.5301694	28.95938	2.120678	2.120678
34.08	1.277963	2.837208	0.5319834	28.95668	2.127934	2.127934
34.16	1.278043	2.843885	0.5333006	28.95848	2.133203	2.133203
34.24	1.278996	2.850573	0.5350371	28.98009	2.140148	2.140148
34.32	1.278361	2.857208	0.5370955	28.96568	2.148382	2.148382
34.4	1.278281	2.863885	0.538677	28.96388	2.154708	2.154708
34.48	1.27991	2.870583	0.5401393	29.0008	2.160557	2.160557
34.56	1.280745	2.877208	0.5420089	29.01971	2.168036	2.168036
34.64	1.280308	2.883906	0.5440474	29.0098	2.176189	2.176189
34.72	1.282255	2.890573	0.545458	29.05392	2.181832	2.181832
34.8	1.27995	2.897208	0.5472521	29.0017	2.189008	2.189008
34.88	1.282175	2.903906	0.5492032	29.05212	2.196813	2.196813
34.96	1.28142	2.910552	0.5507708	29.03501	2.203083	2.203083
35.04	1.27995	2.917219	0.5523999	29.0017	2.2096	2.2096
35.12	1.282454	2.923906	0.5544841	29.05842	2.217937	2.217937
35.2	1.284162	2.930552	0.5560319	29.09713	2.224128	2.224128
35.28	1.284242	2.937219	0.5578299	29.09894	2.23132	2.23132
35.36	1.284242	2.943906	0.5595366	29.09894	2.238147	2.238147
35.44	1.283805	2.950562	0.561289	29.08903	2.245156	2.245156
35.52	1.285235	2.957229	0.563091	29.12144	2.252364	2.252364
35.6	1.283844	2.963896	0.5649845	29.08993	2.259938	2.259938
35.68	1.28301	2.970542	0.5663474	29.07103	2.26539	2.26539
35.76	1.284838	2.977229	0.5681594	29.11244	2.272638	2.272638
35.84	1.284758	2.983885	0.5698383	29.11064	2.279353	2.279353
35.92	1.283805	2.990552	0.5715649	29.08903	2.286259	2.286259
36	1.284281	2.99725	0.573802	29.09984	2.295208	2.295208
36.08	1.286626	3.003875	0.5753994	29.15296	2.301598	2.301598
36.16	1.285672	3.010562	0.5771955	29.13135	2.308782	2.308782
36.24	1.288334	3.01725	0.5791128	29.19167	2.316451	2.316451
36.32	1.286507	3.023875	0.5804976	29.15026	2.32199	2.32199
36.4	1.287619	3.030562	0.5825778	29.17547	2.330311	2.330311
36.48	1.286427	3.03724	0.584356	29.14846	2.337424	2.337424
36.56	1.286745	3.043875	0.5859177	29.15566	2.343671	2.343671
36.64	1.28607	3.050562	0.5877773	29.14035	2.351109	2.351109
36.72	1.286785	3.05724	0.5896091	29.15656	2.358437	2.358437
36.8	1.287023	3.063885	0.5913774	29.16196	2.36551	2.36551
36.88	1.286745	3.070573	0.5929669	29.15566	2.371867	2.371867
36.96	1.288255	3.07724	0.5950173	29.18987	2.380069	2.380069
37.04	1.288255	3.083885	0.5967875	29.18987	2.38715	2.38715
37.12	1.288215	3.090573	0.5988519	29.18897	2.395407	2.395407
37.2	1.288613	3.097208	0.6004274	29.19798	2.40171	2.40171
37.28	1.290202	3.103885	0.602297	29.23399	2.409188	2.409188
37.36	1.289884	3.110573	0.604264	29.22679	2.417056	2.417056
37.44	1.28897	3.117219	0.605768	29.20608	2.423072	2.423072
37.52	1.289924	3.123896	0.6073813	29.22769	2.429525	2.429525
37.6	1.288613	3.130573	0.6093304	29.19798	2.437321	2.437321
37.68	1.290639	3.137229	0.6111503	29.2439	2.444601	2.444601
37.76	1.288295	3.143906	0.6132702	29.19077	2.453081	2.453081
37.84	1.290599	3.150563	0.6148239	29.24299	2.459296	2.459296
37.92	1.289447	3.157219	0.6166975	29.21688	2.46679	2.46679
38	1.291076	3.163906	0.6182869	29.2538	2.473148	2.473148
38.08	1.28905	3.170542	0.6203473	29.20788	2.481389	2.481389
38.16	1.289845	3.177219	0.62204	29.22589	2.48816	2.48816
38.24	1.289527	3.183917	0.6239593	29.21869	2.495837	2.495837
38.32	1.290957	3.190542	0.6257355	29.2511	2.502942	2.502942
38.4	1.289805	3.197229	0.6277144	29.22499	2.510858	2.510858
38.48	1.290202	3.203917	0.6295781	29.23399	2.518312	2.518312
38.56	1.290957	3.210542	0.6311814	29.2511	2.524726	2.524726
38.64	1.290162	3.217229	0.6330748	29.23309	2.532299	2.532299
38.72	1.290917	3.223896	0.6348908	29.2502	2.539563	2.539563
38.8	1.290719	3.230542	0.6366591	29.2457	2.546636	2.546636
38.88	1.289288	3.23724	0.6384154	29.21328	2.553662	2.553662
38.96	1.290798	3.243906	0.6402254	29.2475	2.560902	2.560902
39.04	1.291474	3.250552	0.6419917	29.2628	2.567967	2.567967
39.12	1.289725	3.25725	0.6437441	29.22319	2.574976	2.574976
39.2	1.289805	3.263896	0.6457587	29.22499	2.583035	2.583035
39.28	1.289924	3.270552	0.6472826	29.22769	2.58913	2.58913
39.36	1.290003	3.27724	0.6492118	29.22949	2.596847	2.596847
39.44	1.290123	3.283875	0.6507099	29.23219	2.602839	2.602839
39.52	1.290202	3.290552	0.6529291	29.23399	2.611717	2.611717
39.6	1.290202	3.297229	0.6546676	29.23399	2.61867	2.61867
39.68	1.290321	3.303885	0.6565352	29.23669	2.626141	2.626141
39.76	1.290401	3.310573	0.6583174	29.23849	2.63327	2.63327
39.84	1.290401	3.317229	0.6603141	29.23849	2.641257	2.641257
39.92	1.290401	3.323896	0.6619017	29.23849	2.647607	2.647607
40	1.29052	3.330583	0.6638487	29.2412	2.655395	2.655395
40.08	1.290599	3.337219	0.6655574	29.24299	2.66223	2.66223
40.16	1.290599	3.343885	0.6674707	29.24299	2.669883	2.669883
40.24	1.290599	3.350573	0.6690602	29.24299	2.676241	2.676241
40.32	1.290679	3.357219	0.6710152	29.24479	2.684061	2.684061
40.4	1.290679	3.363896	0.6728311	29.24479	2.691324	2.691324
40.48	1.290798	3.370583	0.6743292	29.2475	2.697317	2.697317
40.56	1.290798	3.377208	0.6761889	29.2475	2.704756	2.704756
40.64	1.290798	3.383906	0.6782472	29.2475	2.712989	2.712989
40.72	1.290798	3.390583	0.6802281	29.2475	2.720912	2.720912
40.8	1.290798	3.397219	0.6819407	29.2475	2.727763	2.727763
40.88	1.290798	3.403906	0.6836176	29.2475	2.73447	2.73447
40.96	1.290798	3.410552	0.6852309	29.2475	2.740924	2.740924
41.04	1.290679	3.417219	0.6872992	29.24479	2.749197	2.749197
41.12	1.290798	3.423906	0.6891112	29.2475	2.756445	2.756445
41.2	1.290798	3.430562	0.6911635	29.2475	2.764654	2.764654
41.28	1.290679	3.437219	0.6926537	29.24479	2.770615	2.770615
41.36	1.290679	3.443906	0.6946762	29.24479	2.778705	2.778705
41.44	1.290679	3.450562	0.6964485	29.24479	2.785794	2.785794
41.52	1.290679	3.457229	0.6984333	29.24479	2.793733	2.793733
41.6	1.290679	3.463906	0.700138	29.24479	2.800552	2.800552
41.68	1.290679	3.470552	0.7018447	29.24479	2.807379	2.807379
41.76	1.290679	3.477229	0.7040004	29.24479	2.816002	2.816002
41.84	1.290599	3.483896	0.7055362	29.24299	2.822145	2.822145
41.92	1.290599	3.490552	0.7073045	29.24299	2.829218	2.829218
42	1.290599	3.49725	0.7093847	29.24299	2.837539	2.837539
42.08	1.29052	3.503885	0.7112582	29.2412	2.845033	2.845033
42.16	1.290401	3.510573	0.7127623	29.23849	2.851049	2.851049
42.24	1.290401	3.51725	0.7147074	29.23849	2.858829	2.858829
42.32	1.290401	3.523885	0.7165074	29.23849	2.86603	2.86603
42.4	1.290321	3.530562	0.7181048	29.23669	2.872419	2.872419
42.48	1.290202	3.53724	0.7201414	29.23399	2.880565	2.880565
42.56	1.290123	3.543885	0.7219414	29.23219	2.887766	2.887766
42.64	1.290123	3.550562	0.7239659	29.23219	2.895864	2.895864
42.72	1.290003	3.55724	0.72577	29.22949	2.90308	2.90308
42.8	1.289924	3.563875	0.7275522	29.22769	2.910209	2.910209
42.88	1.289845	3.570573	0.7293602	29.22589	2.917441	2.917441
42.96	1.289805	3.57724	0.7310907	29.22499	2.924363	2.924363
43.04	1.289725	3.583875	0.7329126	29.22319	2.93165	2.93165
43.12	1.289606	3.590573	0.7349749	29.22049	2.9399	2.9399
43.2	1.289527	3.597208	0.7367154	29.21869	2.946862	2.946862
43.28	1.289527	3.603875	0.7384459	29.21869	2.953784	2.953784
43.36	1.289407	3.610563	0.7400553	29.21598	2.960221	2.960221
43.44	1.289328	3.617208	0.742201	29.21418	2.968804	2.968804
43.52	1.289209	3.623885	0.7439296	29.21148	2.975718	2.975718
43.6	1.289209	3.630563	0.7458885	29.21148	2.983554	2.983554
43.68	1.289129	3.637219	0.7472853	29.20968	2.989141	2.989141
43.76	1.28901	3.643896	0.7493019	29.20698	2.997208	2.997208
43.84	1.288931	3.650552	0.7511318	29.20518	3.004527	3.004527
43.92	1.288931	3.657208	0.7530868	29.20518	3.012347	3.012347
44	1.288811	3.663896	0.7547875	29.20248	3.01915	3.01915
44.08	1.288811	3.670542	0.7563829	29.20248	3.025532	3.025532
44.16	1.288732	3.677208	0.7582625	29.20068	3.03305	3.03305
44.24	1.288613	3.683917	0.7602612	29.19798	3.041045	3.041045
44.32	1.288613	3.690542	0.7620513	29.19798	3.048205	3.048205
44.4	1.288533	3.697219	0.7634799	29.19618	3.05392	3.05392
44.48	1.288414	3.703917	0.7655283	29.19348	3.062113	3.062113
44.56	1.288334	3.710542	0.7674296	29.19167	3.069719	3.069719
44.64	1.288255	3.717229	0.7694165	29.18987	3.077666	3.077666
44.72	1.288136	3.723896	0.770988	29.18717	3.083952	3.083952
44.8	1.288056	3.730531	0.7728815	29.18537	3.091526	3.091526
44.88	1.287937	3.737229	0.7746478	29.18267	3.098591	3.098591
44.96	1.287738	3.743896	0.7763605	29.17817	3.105442	3.105442
45.04	1.287659	3.750542	0.7779976	29.17637	3.11199	3.11199
45.12	1.28754	3.75724	0.7798473	29.17367	3.119389	3.119389
45.2	1.287341	3.763896	0.7817745	29.16916	3.127098	3.127098
45.28	1.287262	3.770552	0.7837892	29.16736	3.135157	3.135157
45.36	1.287142	3.77724	0.7851819	29.16466	3.140728	3.140728
45.44	1.287063	3.783875	0.7872065	29.16286	3.148826	3.148826
45.52	1.286864	3.790552	0.7889986	29.15836	3.155994	3.155994
45.6	1.286745	3.797229	0.7908503	29.15566	3.163401	3.163401
45.68	1.286666	3.803885	0.7925491	29.15386	3.170196	3.170196
45.76	1.286507	3.810562	0.7942875	29.15026	3.17715	3.17715
45.84	1.286348	3.817219	0.7960677	29.14666	3.184271	3.184271
45.92	1.286268	3.823896	0.7980943	29.14486	3.192377	3.192377
46	1.286189	3.830573	0.7994254	29.14305	3.197702	3.197702
46.08	1.28607	3.837208	0.8012295	29.14035	3.204918	3.204918
46.16	1.28599	3.843875	0.8032719	29.13855	3.213088	3.213088
46.24	1.285871	3.850573	0.8050998	29.13585	3.220399	3.220399
46.32	1.285672	3.857208	0.8069177	29.13135	3.227671	3.227671
46.4	1.285593	3.863885	0.8086681	29.12955	3.234673	3.234673
46.48	1.285473	3.870573	0.8104026	29.12685	3.241611	3.241611
46.56	1.285315	3.877198	0.8119464	29.12325	3.247786	3.247786
46.64	1.285195	3.883906	0.8141319	29.12055	3.256528	3.256528
46.72	1.285076	3.890573	0.8158962	29.11785	3.263585	3.263585
46.8	1.284997	3.897208	0.8176367	29.11604	3.270547	3.270547
46.88	1.284798	3.903896	0.819542	29.11154	3.278168	3.278168
46.96	1.284679	3.910552	0.8211672	29.10884	3.284669	3.284669
47.04	1.284599	3.917208	0.8229315	29.10704	3.291726	3.291726
47.12	1.284401	3.923906	0.8247356	29.10254	3.298942	3.298942
47.2	1.284281	3.930552	0.8268396	29.09984	3.307359	3.307359
47.28	1.284202	3.937208	0.8283158	29.09804	3.313263	3.313263
47.36	1.284003	3.943906	0.8298536	29.09353	3.319414	3.319414
47.44	1.283924	3.950562	0.8319398	29.09173	3.327759	3.327759
47.52	1.283805	3.957219	0.8338551	29.08903	3.33542	3.33542
47.6	1.283725	3.963896	0.8355777	29.08723	3.342311	3.342311
47.68	1.283606	3.970531	0.837183	29.08453	3.348732	3.348732
47.76	1.283526	3.977229	0.8390625	29.08273	3.35625	3.35625
47.84	1.283407	3.983885	0.8407215	29.08003	3.362886	3.362886
47.92	1.283208	3.990552	0.8425434	29.07553	3.370174	3.370174
48	1.283129	3.99724	0.8444329	29.07373	3.377732	3.377732
48.08	1.28301	4.003875	0.8459489	29.07103	3.383795	3.383795
48.16	1.28293	4.010562	0.8478801	29.06923	3.39152	3.39152
48.24	1.282811	4.01724	0.8493404	29.06652	3.397362	3.397362
48.32	1.282732	4.023875	0.8515537	29.06472	3.406215	3.406215
48.4	1.282533	4.030552	0.8532703	29.06022	3.413081	3.413081
48.48	1.282414	4.03724	0.8549213	29.05752	3.419685	3.419685
48.56	1.282334	4.043875	0.8569081	29.05572	3.427633	3.427633
48.64	1.282136	4.050552	0.8583605	29.05122	3.433442	3.433442
48.72	1.282016	4.05724	0.8604149	29.04852	3.44166	3.44166
48.8	1.281818	4.063865	0.8621414	29.04402	3.448566	3.448566
48.88	1.281738	4.070573	0.8639534	29.04221	3.455814	3.455814
48.96	1.281659	4.07724	0.86568	29.04041	3.46272	3.46272
49.04	1.28146	4.083885	0.8672873	29.03591	3.469149	3.469149
49.12	1.281341	4.090573	0.8688371	29.03321	3.475348	3.475348
49.2	1.281261	4.097208	0.8709709	29.03141	3.483884	3.483884
49.28	1.281142	4.103875	0.872602	29.02871	3.490408	3.490408
49.36	1.281063	4.110562	0.8743922	29.02691	3.497569	3.497569
49.44	1.280944	4.117218	0.8762221	29.02421	3.504888	3.504888
49.52	1.280745	4.123896	0.877883	29.01971	3.511532	3.511532
49.6	1.280665	4.130562	0.87955	29.0179	3.5182	3.5182
49.68	1.280546	4.137229	0.881664	29.0152	3.526656	3.526656
49.76	1.280467	4.143896	0.8832772	29.0134	3.533109	3.533109
49.84	1.280268	4.150552	0.8849164	29.0089	3.539665	3.539665
49.92	1.280149	4.157219	0.8866449	29.0062	3.54658	3.54658
50	1.28003	4.163896	0.8882542	29.0035	3.553017	3.553017
50.08	1.279871	4.170542	0.8899808	28.9999	3.559923	3.559923
50.16	1.279712	4.177219	0.8921186	28.99629	3.568475	3.568475
50.24	1.279553	4.183917	0.8935134	28.99269	3.574054	3.574054
50.32	1.279394	4.190542	0.8952796	28.98909	3.581119	3.581119
50.4	1.279195	4.197229	0.8972426	28.98459	3.58897	3.58897
50.48	1.279076	4.203917	0.8989076	28.98189	3.59563	3.59563
50.56	1.278877	4.210542	0.9006779	28.97739	3.602711	3.602711
50.64	1.278798	4.217229	0.9023547	28.97559	3.609419	3.609419
50.72	1.278679	4.223896	0.9041826	28.97289	3.61673	3.61673
50.8	1.27848	4.230542	0.9059966	28.96838	3.623986	3.623986
50.88	1.278281	4.237229	0.9074112	28.96388	3.629645	3.629645
50.96	1.278202	4.243896	0.9094159	28.96208	3.637664	3.637664
51.04	1.278082	4.250542	0.9111305	28.95938	3.644522	3.644522
51.12	1.277924	4.257239	0.9128928	28.95578	3.651571	3.651571
51.2	1.277804	4.263896	0.9146114	28.95308	3.658446	3.658446
51.28	1.277685	4.270552	0.91633	28.95038	3.66532	3.66532
51.36	1.277486	4.277239	0.9180467	28.94588	3.672187	3.672187
51.44	1.277407	4.283875	0.9197533	28.94407	3.679013	3.679013
51.52	1.277208	4.290552	0.921603	28.93957	3.686412	3.686412
51.6	1.277129	4.297229	0.9232978	28.93777	3.693191	3.693191
51.68	1.27693	4.303885	0.9253423	28.93327	3.701369	3.701369
51.76	1.276811	4.310563	0.9269913	28.93057	3.707965	3.707965
51.84	1.276731	4.317219	0.9288907	28.92877	3.715563	3.715563
51.92	1.276533	4.323896	0.930204	28.92426	3.720816	3.720816
52	1.276334	4.330583	0.9322326	28.91977	3.72893	3.72893
52.08	1.276215	4.337208	0.9337544	28.91706	3.735018	3.735018
52.16	1.276135	4.343885	0.9352426	28.91526	3.74097	3.74097
52.24	1.275937	4.350573	0.9371559	28.91076	3.748624	3.748624
52.32	1.275818	4.357208	0.9386857	28.90806	3.754743	3.754743
52.4	1.275619	4.363885	0.9407222	28.90356	3.762889	3.762889
52.48	1.275539	4.370583	0.9420137	28.90176	3.768055	3.768055
52.56	1.27542	4.377208	0.943925	28.89906	3.7757	3.7757
52.64	1.275341	4.383906	0.9457032	28.89725	3.782813	3.782813
52.72	1.275142	4.390573	0.9473979	28.89275	3.789592	3.789592
52.8	1.274983	4.397208	0.9486397	28.88915	3.794559	3.794559
52.88	1.274943	4.403906	0.9508927	28.88825	3.803571	3.803571
52.96	1.274745	4.410552	0.9524703	28.88375	3.809881	3.809881
53.04	1.274546	4.417219	0.9542425	28.87925	3.81697	3.81697
53.12	1.274467	4.423906	0.9561558	28.87745	3.824623	3.824623
53.2	1.274347	4.430552	0.9576996	28.87475	3.830798	3.830798
53.28	1.274228	4.437219	0.9593884	28.87205	3.837554	3.837554
53.36	1.274069	4.443906	0.961262	28.86844	3.845048	3.845048
53.44	1.27395	4.450562	0.9628991	28.86574	3.851597	3.851597
53.52	1.273751	4.457229	0.9648025	28.86124	3.85921	3.85921
53.6	1.273672	4.463896	0.9663503	28.85944	3.865401	3.865401
53.68	1.273553	4.470541	0.9678503	28.85674	3.871401	3.871401
53.76	1.273354	4.477229	0.9697258	28.85224	3.878903	3.878903
53.84	1.273155	4.483885	0.9711623	28.84773	3.884649	3.884649
53.92	1.273076	4.490552	0.9730299	28.84593	3.89212	3.89212
54	1.272877	4.49725	0.9747148	28.84143	3.898859	3.898859
54.08	1.272678	4.503875	0.9765049	28.83693	3.906019	3.906019
54.16	1.272599	4.510562	0.9778917	28.83513	3.911567	3.911567
54.24	1.2724	4.51725	0.9796639	28.83063	3.918656	3.918656
54.32	1.272202	4.523875	0.9814978	28.82612	3.925991	3.925991
54.4	1.272082	4.530552	0.9831886	28.82342	3.932754	3.932754
54.48	1.271884	4.53724	0.9851317	28.81892	3.940527	3.940527
54.56	1.271804	4.543875	0.9864807	28.81712	3.945923	3.945923
54.64	1.271685	4.550562	0.988398	28.81442	3.953592	3.953592
54.72	1.271486	4.55724	0.9901543	28.80992	3.960617	3.960617
54.8	1.271407	4.563875	0.9916266	28.80812	3.966506	3.966506
54.88	1.271288	4.570573	0.9934624	28.80542	3.97385	3.97385
54.96	1.271208	4.57724	0.9948571	28.80362	3.979429	3.979429
55.04	1.271089	4.583885	0.9965916	28.80092	3.986367	3.986367
55.12	1.27089	4.590573	0.9984831	28.79641	3.993932	3.993932
55.2	1.270811	4.597208	1.000229	28.79461	4.000918	4.000918
55.28	1.270692	4.603885	1.001537	28.79191	4.006147	4.006147
55.36	1.270612	4.610562	1.003621	28.79011	4.014484	4.014484
55.44	1.270413	4.617218	1.00502	28.78561	4.020079	4.020079
55.52	1.270334	4.623896	1.006945	28.78381	4.02778	4.02778
55.6	1.270215	4.630562	1.008219	28.78111	4.032874	4.032874
55.68	1.270016	4.637229	1.010414	28.77661	4.041656	4.041656
55.76	1.269937	4.643896	1.011797	28.77481	4.047187	4.047187
55.84	1.269738	4.650552	1.013726	28.7703	4.054904	4.054904
55.92	1.269539	4.657219	1.015288	28.7658	4.061151	4.061151
56	1.26942	4.663906	1.01702	28.7631	4.06808	4.06808
56.08	1.269221	4.670542	1.018961	28.7586	4.075845	4.075845
56.16	1.269142	4.677219	1.020175	28.7568	4.080701	4.080701
56.24	1.268864	4.683917	1.021912	28.7505	4.087647	4.087647
56.32	1.268744	4.690542	1.023543	28.74779	4.094172	4.094172
56.4	1.268546	4.697229	1.025462	28.74329	4.101849	4.101849
56.48	1.268387	4.703917	1.026901	28.73969	4.107603	4.107603
56.56	1.268268	4.710542	1.028728	28.73699	4.114914	4.114914
56.64	1.268069	4.717229	1.030405	28.73249	4.121622	4.121622
56.72	1.26787	4.723896	1.031713	28.72799	4.126851	4.126851
56.8	1.267672	4.730542	1.033405	28.72348	4.133622	4.133622
56.88	1.267552	4.737239	1.034991	28.72078	4.139964	4.139964
56.96	1.267354	4.743896	1.036614	28.71628	4.146457	4.146457
57.04	1.267234	4.750552	1.038422	28.71358	4.153689	4.153689
57.12	1.267076	4.757239	1.039916	28.70998	4.159665	4.159665
57.2	1.266956	4.763896	1.041808	28.70728	4.167231	4.167231
57.28	1.266758	4.770552	1.043302	28.70278	4.173207	4.173207
57.36	1.266559	4.777239	1.044895	28.69827	4.179581	4.179581
57.44	1.266479	4.783875	1.04686	28.69647	4.187441	4.187441
57.52	1.266281	4.790552	1.048078	28.69197	4.192313	4.192313
57.6	1.266082	4.797229	1.049854	28.68747	4.199418	4.199418
57.68	1.266003	4.803885	1.051346	28.68567	4.205386	4.205386
57.76	1.265804	4.810573	1.052944	28.68117	4.211775	4.211775
57.84	1.265605	4.817219	1.054798	28.67667	4.21919	4.21919
57.92	1.265486	4.823896	1.05594	28.67397	4.22376	4.22376
58	1.265287	4.830583	1.057758	28.66946	4.231032	4.231032
58.08	1.265089	4.837208	1.059488	28.66496	4.237954	4.237954
58.16	1.26493	4.843885	1.061036	28.66136	4.244145	4.244145
58.24	1.264811	4.850573	1.062326	28.65866	4.249302	4.249302
58.32	1.264612	4.857208	1.064334	28.65415	4.257337	4.257337
58.4	1.264413	4.863885	1.065864	28.64965	4.263457	4.263457
58.48	1.264294	4.870573	1.067317	28.64695	4.269266	4.269266
58.56	1.264095	4.877208	1.068946	28.64245	4.275783	4.275783
58.64	1.263936	4.883906	1.070474	28.63885	4.281894	4.281894
58.72	1.263777	4.890573	1.071825	28.63525	4.287299	4.287299
58.8	1.263618	4.897208	1.07349	28.63165	4.293958	4.293958
58.88	1.263539	4.903906	1.074984	28.62984	4.299935	4.299935
58.96	1.26334	4.910552	1.076416	28.62535	4.305665	4.305665
59.04	1.263142	4.917219	1.077855	28.62084	4.311419	4.311419
59.12	1.262943	4.923906	1.079671	28.61634	4.318682	4.318682
59.2	1.262784	4.930552	1.080682	28.61274	4.322728	4.322728
59.28	1.262625	4.937219	1.122832	28.60914	4.491329	4.491329
59.36	0.008781751	4.94349	1.1344	0.1989809	4.537598	4.537598