File: Shimadzu/Grupo_A-CP30-D.txt
Nome do ensaio	Modo de ensaio	Tipo de ensaio	Título1	Comentário1	Palavra-chave	Nome do produto	Nome do arquivo do ensaio	Nome do arquivo do método	Data do relatório	Data do ensaio	Modo de ensaio	Tipo de ensaio	Velocidade	Placa	Lote No:	Sub-Lote No:
Extensometro SG25-50 - Placa - Sthil_20210601_1531.xtak	Simples	Tração	Grupo de Mecânica Aplicada - GMAp
UFRGS	Comentário	 	 	Extensometro SG25-50 - Placa - Sthil_20210601_1531.xtak	Extensometro SG25-50 - Placa - Sthil.xmak	01/06/2021	01/06/2021	Simples	Tração	5mm/min	Placa	1	1

Placa:	Lote No:	Sub-Lote No:
Placa	1	1
Nome	Espessura	Largura	Gauge Length
Unidade:	mm	mm	mm
Ga_D_30	3.3813	13.0053	115.0000

Nome	Elástico	Inclinação_Padrão	Ruptura_Força	Máx_Força	Max_Disp_Força	Max_Disp_SG-25-50 %	Max_Disp_Deslocamento	Espessura	Largura	Gauge_Length	Máx_Tensão	YS1_Tensão
Parâmetro	Tensão 40 - 60 N/mm2	Tensão 40 - 60 N/mm2	Sensibilidade: 10	Cálculo de áreas completas							Cálculo de áreas completas	0.2 %
Unidade	N/mm2	N/mm	kN	kN	kN	%	mm	mm	mm	mm	N/mm2	N/mm2
Ga_D_30	123	-.-	1.27312	1.29592	1.27324	3.99630	4.61642	3.3813	13.0053	115.0000	29.4697	321

Ga_D_30
Tempo	Força	Deslocamento	Desloc. SG25-50	Tensão	SG-25-50 %	Deformação
seg	kN	mm	mm	N/mm2	%	%
0	0.01136462	0	0	0.2584347	0	0
0.07	0.01136462	0.003166667	0.0004967054	0.2584347	0.001986821	0.001986821
0.14	0.01136462	0.008916667	0.001863639	0.2584347	0.007454554	0.007454554
0.21	0.01136462	0.01473958	0.003290176	0.2584347	0.01316071	0.01316071
0.28	0.01136462	0.0205625	0.004299482	0.2584347	0.01719793	0.01719793
0.35	0.02566973	0.02638542	0.005304813	0.5837371	0.02121925	0.02121925
0.42	0.03151099	0.03225	0.006701549	0.7165689	0.0268062	0.0268062
0.49	0.03413359	0.03804167	0.007724762	0.7762077	0.03089905	0.03089905
0.56	0.03818671	0.04390625	0.009004275	0.8683767	0.0360171	0.0360171
0.63	0.04108747	0.04972916	0.01042684	0.9343408	0.04170736	0.04170736
0.7	0.04629294	0.0555625	0.01172821	1.052715	0.04691283	0.04691283
0.77	0.05022685	0.06138542	0.01307925	1.142173	0.05231698	0.05231698
0.84	0.05261103	0.06721875	0.01407663	1.19639	0.05630652	0.05630652
0.91	0.05729993	0.0730625	0.01521707	1.303017	0.06086826	0.06086826
0.98	0.06139278	0.078875	0.01634161	1.39609	0.06536642	0.06536642
1.05	0.06612142	0.08473958	0.01777411	1.50362	0.07109642	0.07109642
1.12	0.07077058	0.09055208	0.0190715	1.609343	0.076286	0.076286
1.19	0.07430712	0.09640625	0.02042452	1.689765	0.0816981	0.0816981
1.26	0.07649263	0.1022083	0.02163847	1.739464	0.08655389	0.08655389
1.33	0.08352598	0.1080625	0.022765	1.899405	0.09106001	0.09106001
1.4	0.086387	0.1139062	0.02392133	1.964465	0.09568533	0.09568533
1.47	0.09055933	0.1197187	0.02530018	2.059345	0.1012007	0.1012007
1.54	0.09381771	0.1255729	0.02627571	2.133442	0.1051029	0.1051029
1.61	0.09850661	0.1313854	0.02780755	2.240068	0.1112302	0.1112302
1.68	0.1009703	0.1372396	0.02889832	2.296093	0.1155933	0.1155933
1.75	0.106732	0.1430417	0.03028115	2.427117	0.1211246	0.1211246
1.82	0.111262	0.1488958	0.03149509	2.53013	0.1259804	0.1259804
1.89	0.1144012	0.1547187	0.032715	2.601516	0.13086	0.13086
1.96	0.1185735	0.1605521	0.03401637	2.696396	0.1360655	0.1360655
2.03	0.1233816	0.1663958	0.03518065	2.805733	0.1407226	0.1407226
2.1	0.1252095	0.1722292	0.03629525	2.8473	0.145181	0.145181
2.17	0.1315276	0.1780833	0.03775358	2.990975	0.1510143	0.1510143
2.24	0.1333952	0.1838854	0.0389119	3.033445	0.1556476	0.1556476
2.31	0.1365344	0.1897396	0.04003644	3.104831	0.1601458	0.1601458
2.38	0.1432498	0.1955417	0.04155834	3.257542	0.1662334	0.1662334
2.45	0.1453559	0.2013958	0.04253586	3.305434	0.1701434	0.1701434
2.52	0.1510779	0.2072188	0.04372001	3.435555	0.17488	0.17488
2.59	0.155886	0.2130521	0.04482865	3.544893	0.1793146	0.1793146
2.66	0.1564026	0.2189063	0.04608433	3.55664	0.1843373	0.1843373
2.73	0.1637538	0.2247187	0.04723271	3.723809	0.1889308	0.1889308
2.8	0.1655022	0.2305729	0.04865329	3.763568	0.1946131	0.1946131
2.87	0.1716614	0.2363958	0.04958113	3.903629	0.1983245	0.1983245
2.94	0.1763105	0.2422396	0.05112688	4.009352	0.2045075	0.2045075
3.01	0.1785755	0.2480417	0.05205274	4.060858	0.2082109	0.2082109
3.08	0.1829068	0.2538958	0.05332629	4.159353	0.2133052	0.2133052
3.15	0.1864831	0.2597187	0.05447467	4.240679	0.2178987	0.2178987
3.22	0.191013	0.2655521	0.05595684	4.343691	0.2238274	0.2238274
3.29	0.1933575	0.2713958	0.05705953	4.397005	0.2282381	0.2282381
3.36	0.1993577	0.2772188	0.05831122	4.533451	0.2332449	0.2332449
3.43	0.2025366	0.2830833	0.05964239	4.60574	0.2385696	0.2385696
3.5	0.204881	0.288875	0.06068945	4.659053	0.2427578	0.2427578
3.57	0.2103647	0.2947396	0.06177028	4.783752	0.2470811	0.2470811
3.64	0.2136628	0.3005625	0.06291866	4.858753	0.2516747	0.2516747
3.71	0.2184709	0.3063854	0.06403923	4.968091	0.2561569	0.2561569
3.78	0.2240737	0.3122292	0.06534854	5.0955	0.2613942	0.2613942
3.85	0.2250671	0.3180521	0.06671945	5.118091	0.2668778	0.2668778
3.92	0.229001	0.3239062	0.06787181	5.207549	0.2714872	0.2714872
3.99	0.232776	0.3297083	0.06865263	5.293393	0.2746105	0.2746105
4.06	0.240008	0.3355729	0.07025401	5.457851	0.281016	0.281016
4.13	0.2424717	0.3413854	0.07140636	5.513876	0.2856255	0.2856255
4.2	0.2449353	0.3472292	0.07258853	5.5699	0.2903541	0.2903541
4.27	0.248313	0.3530521	0.07368326	5.646708	0.294733	0.294733
4.34	0.2524853	0.3588958	0.0748376	5.741587	0.2993504	0.2993504
4.41	0.2565384	0.36475	0.07608533	5.833756	0.3043413	0.3043413
4.48	0.2615055	0.3705521	0.07742842	5.946709	0.3097137	0.3097137
4.55	0.2650817	0.3764063	0.0785927	6.028035	0.3143708	0.3143708
4.62	0.2674262	0.3822083	0.07960001	6.081348	0.3184001	0.3184001
4.69	0.2718767	0.3880729	0.08086363	6.182553	0.3234545	0.3234545
4.76	0.2766053	0.393875	0.08189082	6.290083	0.3275633	0.3275633
4.83	0.2801418	0.3997187	0.08309086	6.370506	0.3323635	0.3323635
4.9	0.2818902	0.4055625	0.08455714	6.410265	0.3382286	0.3382286
4.97	0.2867778	0.4113854	0.08526643	6.52141	0.3410657	0.3410657
5.04	0.2912283	0.4172292	0.08692741	6.622615	0.3477097	0.3477097
5.11	0.2953211	0.4230625	0.0877142	6.715687	0.3508568	0.3508568
5.18	0.2990961	0.4289167	0.08890033	6.801531	0.3556013	0.3556013
5.25	0.3022353	0.4347083	0.09003282	6.872917	0.3601313	0.3601313
5.32	0.3091494	0.4405625	0.09122491	7.030146	0.3648996	0.3648996
5.39	0.3112157	0.446375	0.09260575	7.077135	0.370423	0.370423
5.46	0.3151099	0.4522187	0.0936985	7.165689	0.374794	0.374794
5.53	0.3181696	0.4580625	0.09507934	7.235268	0.3803174	0.3803174
5.6	0.3217061	0.4638854	0.09577274	7.31569	0.383091	0.383091
5.67	0.325799	0.46975	0.09712378	7.408762	0.3884951	0.3884951
5.74	0.3304482	0.4755417	0.0982523	7.514486	0.3930092	0.3930092
5.81	0.3328721	0.4814062	0.0994126	7.569606	0.3976504	0.3976504
5.88	0.3377994	0.4872292	0.1004398	7.681655	0.4017591	0.4017591
5.95	0.3423294	0.4930625	0.1019736	7.784668	0.4078945	0.4078945
6.02	0.3447135	0.4988854	0.1029988	7.838884	0.4119953	0.4119953
6.09	0.3489256	0.5047187	0.1041432	7.934668	0.4165729	0.4165729
6.16	0.3509919	0.5105625	0.1051744	7.981656	0.4206975	0.4206975
6.23	0.3569523	0.5163854	0.1065791	8.117199	0.4263163	0.4263163
6.3	0.3600121	0.5222396	0.1072605	8.186777	0.4290422	0.4290422
6.37	0.3636281	0.5280521	0.1087129	8.269007	0.4348516	0.4348516
6.44	0.3687541	0.5339062	0.109752	8.385573	0.4390081	0.4390081
6.51	0.3731251	0.5397083	0.1107275	8.484972	0.4429102	0.4429102
6.58	0.3745556	0.5455625	0.1121441	8.517502	0.4485766	0.4485766
6.65	0.3788074	0.5514063	0.1132846	8.614189	0.4531384	0.4531384
6.72	0.3830194	0.5572187	0.1146436	8.709971	0.4585743	0.4585743
6.79	0.3858407	0.5630625	0.1155893	8.774129	0.4623572	0.4623572
6.86	0.391523	0.5688854	0.1166523	8.903346	0.466609	0.466609
6.93	0.3937086	0.5747396	0.1178364	8.953045	0.4713456	0.4713456
7	0.3977219	0.5805417	0.1189768	9.04431	0.4759073	0.4759073
7.07	0.4023711	0.5863958	0.1197716	9.150034	0.4790863	0.4790863
7.14	0.4033645	0.5922292	0.1214206	9.172625	0.4856825	0.4856825
7.21	0.4078547	0.5980521	0.122569	9.274734	0.490276	0.490276
7.28	0.412027	0.6038854	0.1236022	9.369613	0.4944086	0.4944086
7.35	0.4163186	0.6097292	0.1248042	9.467203	0.4992167	0.4992167
7.42	0.4206499	0.6155833	0.1258373	9.565698	0.5033493	0.5033493
7.49	0.423789	0.621375	0.1270294	9.637084	0.5081177	0.5081177
7.56	0.4273653	0.6272396	0.1282056	9.71841	0.5128224	0.5128224
7.63	0.4299084	0.6330417	0.1291871	9.776241	0.5167484	0.5167484
7.7	0.4342794	0.6388958	0.1302044	9.875639	0.5208175	0.5208175
7.77	0.4378954	0.6447188	0.1314064	9.957868	0.5256255	0.5256255
7.84	0.4430612	0.6505521	0.1322905	10.07534	0.5291621	0.5291621
7.91	0.4437765	0.6564062	0.1334508	10.0916	0.5338033	0.5338033
7.98	0.4494985	0.6622187	0.1345634	10.22173	0.5382538	0.5382538
8.05	0.452439	0.6680729	0.1359344	10.28859	0.5437374	0.5437374
8.12	0.4555384	0.6738958	0.136888	10.35907	0.5475521	0.5475521
8.19	0.46134	0.67975	0.1381596	10.491	0.5526384	0.5526384
8.26	0.462691	0.6855416	0.1392245	10.52173	0.5568981	0.5568981
8.33	0.4672209	0.6913958	0.1401226	10.62474	0.5604903	0.5604903
8.4	0.4698833	0.6972187	0.1414974	10.68528	0.5659898	0.5659898
8.47	0.4733404	0.7030521	0.1423359	10.7639	0.5693436	0.5693436
8.54	0.4782677	0.7088958	0.1439591	10.87594	0.5758365	0.5758365
8.61	0.4794598	0.7147188	0.1447519	10.90305	0.5790074	0.5790074
8.68	0.48546	0.7205833	0.145932	11.0395	0.5837281	0.5837281
8.75	0.488917	0.726375	0.1470387	11.11811	0.5881548	0.5881548
8.82	0.4914204	0.7322396	0.1482328	11.17504	0.5929311	0.5929311
8.89	0.4930496	0.7380625	0.1495699	11.21209	0.5982797	0.5982797
8.96	0.4992882	0.7438854	0.1502395	11.35396	0.6009579	0.6009579
9.03	0.5025069	0.7497187	0.1514455	11.42715	0.6057819	0.6057819
9.1	0.5064408	0.7555521	0.1523594	11.51661	0.6094376	0.6094376
9.17	0.5092223	0.7614062	0.1538535	11.57986	0.615414	0.615414
9.24	0.5125999	0.7672083	0.1547555	11.65667	0.6190221	0.6190221
9.31	0.5170901	0.7730729	0.1558761	11.75878	0.6235043	0.6235043
9.38	0.520587	0.7788854	0.1567165	11.8383	0.626866	0.626866
9.45	0.5212625	0.7847292	0.1579106	11.85366	0.6316423	0.6316423
9.52	0.5284945	0.7905416	0.1589139	12.01812	0.6356557	0.6356557
9.59	0.5297661	0.7963958	0.1600464	12.04703	0.6401857	0.6401857
9.66	0.5342563	0.8022396	0.1613935	12.14914	0.6455739	0.6455739
9.73	0.5390247	0.8080521	0.1623134	12.25758	0.6492535	0.6492535
9.8	0.5412499	0.8139063	0.1634081	12.30818	0.6536325	0.6536325
9.87	0.5447467	0.8197083	0.1645088	12.3877	0.6580353	0.6580353
9.94	0.5472501	0.8255729	0.1653314	12.44462	0.6613255	0.6613255
10.01	0.5531311	0.831375	0.1667221	12.57836	0.6668885	0.6668885
10.08	0.5549192	0.8372291	0.1677374	12.61902	0.6709496	0.6709496
10.15	0.5580981	0.8430625	0.1685103	12.69131	0.6740411	0.6740411
10.22	0.5613565	0.8488854	0.169903	12.76541	0.6796122	0.6796122
10.29	0.5640586	0.8547395	0.1707911	12.82685	0.6831646	0.6831646
10.36	0.5673965	0.8605625	0.1719495	12.90276	0.6877978	0.6877978
10.43	0.5710919	0.8664166	0.1728376	12.9868	0.6913503	0.6913503
10.5	0.5735159	0.8722083	0.1738648	13.04192	0.6954591	0.6954591
10.57	0.5779266	0.8780729	0.1750251	13.14222	0.7001002	0.7001002
10.64	0.5801122	0.8838854	0.1761119	13.19192	0.7044474	0.7044474
10.71	0.5841653	0.8897187	0.1769761	13.28409	0.7079045	0.7079045
10.78	0.5868673	0.8955625	0.1779775	13.34553	0.7119099	0.7119099
10.85	0.588576	0.9013854	0.1789153	13.38439	0.715661	0.715661
10.92	0.5926688	0.90725	0.1799424	13.47746	0.7197698	0.7197698
10.99	0.5966425	0.9130417	0.1810491	13.56782	0.7241964	0.7241964
11.06	0.5979936	0.9189062	0.18212	13.59854	0.72848	0.72848
11.13	0.6015301	0.9247292	0.1831174	13.67897	0.7324696	0.7324696
11.2	0.6044309	0.9305625	0.1839181	13.74493	0.7356723	0.7356723
11.27	0.6085634	0.936375	0.1853625	13.83891	0.74145	0.74145
11.34	0.612855	0.9422187	0.1862983	13.9365	0.7451932	0.7451932
11.41	0.6142855	0.9480625	0.1873632	13.96903	0.7494529	0.7494529
11.48	0.6165504	0.953875	0.1881957	14.02053	0.7527828	0.7527828
11.55	0.6221533	0.9597396	0.1889209	14.14794	0.7556836	0.7556836
11.62	0.6251335	0.9655521	0.1900812	14.21572	0.7603248	0.7603248
11.69	0.6266435	0.9714062	0.1914759	14.25005	0.7659038	0.7659038
11.76	0.6300609	0.9772083	0.1924415	14.32776	0.7697662	0.7697662
11.83	0.6338755	0.9830729	0.1932462	14.41451	0.7729848	0.7729848
11.9	0.6371737	0.9889063	0.1944304	14.48951	0.7777214	0.7777214
11.97	0.6396373	0.9947187	0.1950145	14.54554	0.7800579	0.7800579
12.04	0.6436507	1.000573	0.1962702	14.6368	0.7850806	0.7850806
12.11	0.6455978	1.006385	0.1972357	14.68108	0.788943	0.788943
12.18	0.6492138	1.01224	0.1980046	14.76331	0.7920186	0.7920186
12.25	0.6508827	1.018042	0.1992881	14.80126	0.7971525	0.7971525
12.32	0.6543398	1.023896	0.2001504	14.87988	0.8006017	0.8006017
12.39	0.657479	1.029719	0.201118	14.95126	0.804472	0.804472
12.46	0.6619294	1.035563	0.202324	15.05246	0.809296	0.809296
12.53	0.6618897	1.041385	0.2030889	15.05156	0.8123557	0.8123557
12.6	0.6655852	1.047229	0.2037923	15.1356	0.815169	0.815169
12.67	0.6710688	1.053083	0.2048612	15.2603	0.8194447	0.8194447
12.74	0.6732941	1.058875	0.2059519	15.3109	0.8238077	0.8238077
12.81	0.6736119	1.06474	0.2065281	15.31813	0.8261124	0.8261124
12.88	0.6786187	1.070542	0.2078613	15.43198	0.831445	0.831445
12.95	0.6810824	1.076396	0.2088249	15.48801	0.8352995	0.8352995
13.02	0.6846189	1.082208	0.2097885	15.56843	0.8391539	0.8391539
13.09	0.6866455	1.088052	0.2107422	15.61452	0.8429686	0.8429686
13.16	0.690937	1.093906	0.2116064	15.71211	0.8464257	0.8464257
13.23	0.6916125	1.099719	0.2125025	15.72747	0.8500099	0.8500099
13.3	0.6958644	1.105573	0.2136628	15.82416	0.8546512	0.8546512
13.37	0.6976922	1.111396	0.2145092	15.86572	0.8580367	0.8580367
13.44	0.6994009	1.11725	0.2155602	15.90458	0.8622408	0.8622408
13.51	0.7032951	1.123042	0.2166708	15.99313	0.8666833	0.8666833
13.58	0.7052422	1.128896	0.2178232	16.03741	0.8712928	0.8712928
13.65	0.7077456	1.134719	0.2184888	16.09434	0.8739551	0.8739551
13.72	0.7119179	1.140552	0.2195517	16.18922	0.8782069	0.8782069
13.79	0.7147789	1.146396	0.2205948	16.25428	0.8823792	0.8823792
13.86	0.7183552	1.152219	0.2211074	16.3356	0.8844296	0.8844296
13.93	0.7222493	1.158083	0.2222935	16.42416	0.8891742	0.8891742
14	0.7238786	1.163875	0.223281	16.46121	0.8931239	0.8931239
14.07	0.7267793	1.16974	0.224187	16.52717	0.8967479	0.8967479
14.14	0.7301569	1.175563	0.2251685	16.60398	0.9006739	0.9006739
14.21	0.7344087	1.181385	0.2262811	16.70066	0.9051244	0.9051244
14.28	0.7360379	1.187229	0.2270937	16.73771	0.9083748	0.9083748
14.35	0.7373095	1.193052	0.2281149	16.76663	0.9124597	0.9124597
14.42	0.7399321	1.198906	0.2291501	16.82627	0.9166002	0.9166002
14.49	0.7454951	1.204708	0.2298017	16.95277	0.9192069	0.9192069
14.56	0.7439454	1.210573	0.2311389	16.91753	0.9245555	0.9245555
14.63	0.7478396	1.216385	0.231868	17.00609	0.9274721	0.9274721
14.7	0.7519722	1.22224	0.2328098	17.10006	0.9312391	0.9312391
14.77	0.757138	1.228042	0.2339562	17.21753	0.9358247	0.9358247
14.84	0.7572969	1.233896	0.2350708	17.22115	0.9402831	0.9402831
14.91	0.759681	1.23975	0.2359827	17.27537	0.9439309	0.9439309
14.98	0.7651647	1.245552	0.2368768	17.40006	0.9475072	0.9475072
15.05	0.7661581	1.251406	0.2375682	17.42266	0.9502729	0.9502729
15.12	0.7682641	1.257208	0.2385855	17.47055	0.9543419	0.9543419
15.19	0.7709662	1.263073	0.2395252	17.53199	0.958101	0.958101
15.26	0.7742643	1.268875	0.2406756	17.60699	0.9627025	0.9627025
15.33	0.7772048	1.274729	0.2417465	17.67386	0.966986	0.966986
15.4	0.7797877	1.280563	0.2424379	17.7326	0.9697517	0.9697517
15.47	0.7822514	1.286385	0.2435764	17.78862	0.9743055	0.9743055
15.54	0.78547	1.29224	0.2445777	17.86181	0.9783109	0.9783109
15.61	0.78849	1.298062	0.2454281	17.93049	0.9817123	0.9817123
15.68	0.7903973	1.303917	0.2463897	17.97386	0.9855588	0.9855588
15.75	0.7935762	1.309708	0.2471765	18.04615	0.9887059	0.9887059
15.82	0.7943313	1.315562	0.2483686	18.06332	0.9934743	0.9934743
15.89	0.8001328	1.321385	0.2491891	18.19525	0.9967566	0.9967566
15.96	0.7998943	1.327219	0.2500355	18.18983	1.000142	1.000142
16.03	0.8038282	1.333063	0.2511958	18.27928	1.004783	1.004783
16.1	0.8061727	1.338885	0.251925	18.3326	1.0077	1.0077
16.17	0.8111795	1.34475	0.2530992	18.44645	1.012397	1.012397
16.24	0.811855	1.350542	0.2540827	18.46182	1.016331	1.016331
16.31	0.8164247	1.356417	0.2552986	18.56573	1.021194	1.021194
16.38	0.8198023	1.362229	0.2558013	18.64254	1.023205	1.023205
16.45	0.8208752	1.368062	0.2570947	18.66694	1.028379	1.028379
16.52	0.8226633	1.373885	0.2583007	18.7076	1.033203	1.033203
16.59	0.8263588	1.379719	0.2585193	18.79164	1.034077	1.034077
16.66	0.8286238	1.385563	0.2598186	18.84314	1.039275	1.039275
16.73	0.831763	1.391385	0.2607942	18.91453	1.043177	1.043177
16.8	0.8333524	1.39724	0.2615829	18.95067	1.046332	1.046332
16.87	0.8376439	1.403052	0.2626459	19.04826	1.050583	1.050583
16.94	0.8404652	1.408917	0.2637088	19.11242	1.054835	1.054835
17.01	0.8423328	1.414708	0.2646824	19.15489	1.05873	1.05873
17.08	0.8422931	1.420563	0.2654473	19.15399	1.061789	1.061789
17.15	0.8484523	1.426406	0.2664348	19.29405	1.065739	1.065739
17.22	0.8503199	1.432219	0.2677023	19.33652	1.070809	1.070809
17.29	0.8511941	1.438073	0.2688448	19.3564	1.075379	1.075379
17.36	0.8553267	1.443885	0.2696753	19.45037	1.078701	1.078701
17.43	0.8580287	1.44974	0.2705455	19.51182	1.082182	1.082182
17.5	0.8600553	1.455542	0.2717296	19.5579	1.086918	1.086918
17.57	0.8622408	1.461396	0.2723972	19.6076	1.089589	1.089589
17.64	0.8679231	1.467229	0.2732495	19.73682	1.092998	1.092998
17.71	0.8684794	1.473063	0.2743999	19.74947	1.0976	1.0976
17.78	0.870347	1.478896	0.2754569	19.79194	1.101828	1.101828
17.85	0.8730094	1.484729	0.2763987	19.85248	1.105595	1.105595
17.92	0.8767446	1.490594	0.2770702	19.93742	1.108281	1.108281
17.99	0.8792877	1.496375	0.2780139	19.99525	1.112056	1.112056
18.06	0.8794864	1.50224	0.2789775	19.99977	1.11591	1.11591
18.13	0.88346	1.508042	0.2800147	20.09014	1.120059	1.120059
18.2	0.8863608	1.513896	0.2808233	20.1561	1.123293	1.123293
18.27	0.8907716	1.519719	0.2815545	20.2564	1.126218	1.126218
18.34	0.8893411	1.525552	0.2827823	20.22387	1.131129	1.131129
18.41	0.8929968	1.531417	0.2834658	20.307	1.133863	1.133863
18.48	0.8938313	1.537219	0.2844711	20.32598	1.137884	1.137884
18.55	0.8983214	1.543073	0.2855202	20.42809	1.142081	1.142081
18.62	0.9000301	1.548896	0.2859274	20.46694	1.14371	1.14371
18.69	0.9036064	1.55475	0.2868394	20.54827	1.147358	1.147358
18.76	0.9044409	1.560552	0.28796	20.56725	1.15184	1.15184
18.83	0.9076198	1.566396	0.2889296	20.63953	1.155718	1.155718
18.9	0.9096861	1.572219	0.2899249	20.68652	1.1597	1.1597
18.97	0.9127061	1.578052	0.2908309	20.7552	1.163324	1.163324
19.04	0.9119511	1.583896	0.2918065	20.73803	1.167226	1.167226
19.11	0.9162426	1.589719	0.2922475	20.83562	1.16899	1.16899
19.18	0.9177526	1.595583	0.2936423	20.86996	1.174569	1.174569
19.25	0.9225607	1.601375	0.2946794	20.97929	1.178718	1.178718
19.32	0.9246667	1.60724	0.2951463	21.02719	1.180585	1.180585
19.39	0.9284814	1.613063	0.2959669	21.11393	1.183867	1.183867
19.46	0.927488	1.618896	0.2970954	21.09134	1.188382	1.188382
19.53	0.9300311	1.624729	0.2979437	21.14918	1.191775	1.191775
19.6	0.9332498	1.630552	0.2990186	21.22237	1.196074	1.196074
19.67	0.934283	1.636406	0.2998511	21.24586	1.199404	1.199404
19.74	0.9377797	1.642208	0.3005663	21.32538	1.202265	1.202265
19.81	0.9387334	1.648073	0.3015717	21.34707	1.206287	1.206287
19.88	0.942111	1.653885	0.3025969	21.42387	1.210388	1.210388
19.95	0.9463628	1.65974	0.3034333	21.52056	1.213733	1.213733
20.02	0.9468794	1.665552	0.304395	21.53231	1.21758	1.21758
20.09	0.9491046	1.671396	0.3053546	21.58291	1.221418	1.221418
20.16	0.9514093	1.67725	0.3061553	21.63532	1.224621	1.224621
20.23	0.9527206	1.683052	0.3070235	21.66514	1.228094	1.228094
20.3	0.9534757	1.688906	0.3080984	21.68231	1.232394	1.232394
20.37	0.9590785	1.694708	0.3089627	21.80972	1.235851	1.235851
20.44	0.9608269	1.700573	0.3095845	21.84948	1.238338	1.238338
20.51	0.9635687	1.706375	0.3109217	21.91183	1.243687	1.243687
20.58	0.9650787	1.712229	0.3120204	21.94617	1.248082	1.248082
20.65	0.9663105	1.718063	0.3126681	21.97418	1.250672	1.250672
20.72	0.9690523	1.723885	0.3136635	22.03653	1.254654	1.254654
20.79	0.9711583	1.72974	0.3145734	22.08442	1.258294	1.258294
20.86	0.9738207	1.735562	0.315696	22.14496	1.262784	1.262784
20.93	0.975728	1.741417	0.3165126	22.18834	1.26605	1.26605
21	0.9771983	1.747208	0.3174603	22.22177	1.269841	1.269841
21.07	0.9835164	1.753073	0.3178636	22.36545	1.271454	1.271454
21.14	0.984629	1.758885	0.3189703	22.39075	1.275881	1.275881
21.21	0.9860595	1.764719	0.3201564	22.42327	1.280626	1.280626
21.28	0.9887616	1.770563	0.3210982	22.48472	1.284393	1.284393
21.35	0.9917021	1.776385	0.3220955	22.55159	1.288382	1.288382
21.42	0.9934902	1.78225	0.3229638	22.59225	1.291855	1.291855
21.49	0.9936889	1.788042	0.3240407	22.59677	1.296163	1.296163
21.56	0.9960731	1.793906	0.3248672	22.65099	1.299469	1.299469
21.63	1.000603	1.799729	0.3257255	22.754	1.302902	1.302902
21.7	1.000881	1.805562	0.3266712	22.76033	1.306685	1.306685
21.77	1.003424	1.811385	0.3274044	22.81816	1.309617	1.309617
21.84	1.004974	1.817219	0.3286024	22.8534	1.31441	1.31441
21.91	1.009107	1.823063	0.3293951	22.94737	1.317581	1.317581
21.98	1.012484	1.828885	0.3303448	23.02418	1.321379	1.321379
22.05	1.012802	1.83474	0.3312409	23.03141	1.324964	1.324964
22.12	1.013517	1.840552	0.3320316	23.04768	1.328127	1.328127
22.19	1.017888	1.846406	0.333031	23.14707	1.332124	1.332124
22.26	1.019081	1.852208	0.3344158	23.17418	1.337663	1.337663
22.33	1.021942	1.858073	0.3352185	23.23924	1.340874	1.340874
22.4	1.022975	1.863906	0.3359914	23.26274	1.343966	1.343966
22.47	1.026392	1.869719	0.3367504	23.34045	1.347001	1.347001
22.54	1.028061	1.875573	0.3379623	23.3784	1.351849	1.351849
22.61	1.030803	1.881385	0.3387272	23.44075	1.354909	1.354909
22.68	1.034379	1.88724	0.3396074	23.52208	1.35843	1.35843
22.75	1.034737	1.893042	0.3406247	23.53021	1.362499	1.362499
22.82	1.034617	1.898906	0.3414472	23.5275	1.365789	1.365789
22.89	1.037161	1.904729	0.3425678	23.58533	1.370271	1.370271
22.96	1.041094	1.910563	0.3436486	23.67479	1.374594	1.374594
23.03	1.041611	1.916396	0.344485	23.68653	1.37794	1.37794
23.1	1.045982	1.922229	0.3453513	23.78593	1.381405	1.381405
23.17	1.04634	1.928094	0.3462771	23.79406	1.385109	1.385109
23.24	1.048843	1.933885	0.3473023	23.85099	1.389209	1.389209
23.31	1.050393	1.93974	0.3480971	23.88623	1.392388	1.392388
23.38	1.051784	1.945542	0.3492335	23.91786	1.396934	1.396934
23.45	1.05536	1.951396	0.3500402	23.99919	1.400161	1.400161
23.52	1.057585	1.957219	0.3508767	24.04979	1.403507	1.403507
23.59	1.057903	1.963052	0.3516495	24.05702	1.406598	1.406598
23.66	1.061996	1.968917	0.3530463	24.15009	1.412185	1.412185
23.73	1.063546	1.974719	0.3539463	24.18533	1.415785	1.415785
23.8	1.066208	1.980573	0.3548642	24.24587	1.419457	1.419457
23.87	1.067479	1.986396	0.3555874	24.27479	1.42235	1.42235
23.94	1.069546	1.99225	0.3568908	24.32178	1.427563	1.427563
24.01	1.072844	1.998052	0.3577749	24.39678	1.4311	1.4311
24.08	1.073559	2.003896	0.3586769	24.41304	1.434708	1.434708
24.15	1.075029	2.009719	0.3599783	24.44648	1.439913	1.439913
24.22	1.076698	2.015552	0.3608008	24.48443	1.443203	1.443203
24.29	1.078208	2.021406	0.3617525	24.51877	1.44701	1.44701
24.36	1.08242	2.027219	0.362734	24.61455	1.450936	1.450936
24.43	1.084963	2.033094	0.3636559	24.67238	1.454624	1.454624
24.5	1.088262	2.038875	0.3644308	24.74738	1.457723	1.457723
24.57	1.087745	2.044739	0.3654778	24.73564	1.461911	1.461911
24.64	1.093109	2.050573	0.3665288	24.85762	1.466115	1.466115
24.71	1.093109	2.056396	0.3673991	24.85762	1.469596	1.469596
24.78	1.093467	2.062229	0.3683984	24.86576	1.473594	1.473594
24.85	1.096765	2.068052	0.3694832	24.94076	1.477933	1.477933
24.92	1.099626	2.073906	0.3705939	25.00582	1.482376	1.482376
24.99	1.099984	2.079719	0.3715436	25.01395	1.486174	1.486174
25.06	1.102328	2.085573	0.3724754	25.06726	1.489902	1.489902
25.13	1.105309	2.091385	0.3735125	25.13503	1.49405	1.49405
25.2	1.10813	2.097239	0.3743788	25.19919	1.497515	1.497515
25.27	1.10817	2.103052	0.375398	25.20009	1.501592	1.501592
25.34	1.109997	2.108896	0.3763954	25.24166	1.505581	1.505581
25.41	1.111229	2.11475	0.3775438	25.26967	1.510175	1.510175
25.48	1.113296	2.120542	0.3783047	25.31666	1.513219	1.513219
25.55	1.115322	2.126406	0.379469	25.36275	1.517876	1.517876
25.62	1.117508	2.132219	0.3804108	25.41244	1.521643	1.521643
25.69	1.120369	2.138062	0.3813247	25.4775	1.525299	1.525299
25.76	1.12315	2.143875	0.3824016	25.54076	1.529606	1.529606
25.83	1.125177	2.149729	0.383389	25.58684	1.533556	1.533556
25.9	1.124978	2.155573	0.3844678	25.58232	1.537871	1.537871
25.97	1.125971	2.161385	0.3856222	25.60491	1.542489	1.542489
26.04	1.13225	2.16724	0.3865043	25.74769	1.546017	1.546017
26.11	1.131614	2.173073	0.3875395	25.73323	1.550158	1.550158
26.18	1.134952	2.178917	0.388515	25.80913	1.55406	1.55406
26.25	1.135508	2.184708	0.3894249	25.82178	1.5577	1.5577
26.32	1.13678	2.190573	0.3905992	25.8507	1.562397	1.562397
26.39	1.139084	2.196385	0.3914932	25.90311	1.565973	1.565973
26.46	1.141667	2.202219	0.3926257	25.96184	1.570503	1.570503
26.53	1.14572	2.208062	0.39409	26.05401	1.57636	1.57636
26.6	1.146158	2.213896	0.3949185	26.06395	1.579674	1.579674
26.67	1.147588	2.21975	0.3958205	26.09648	1.583282	1.583282
26.74	1.14882	2.225542	0.3968815	26.12449	1.587526	1.587526
26.81	1.152913	2.231417	0.3979802	26.21757	1.591921	1.591921
26.88	1.151919	2.237229	0.3988365	26.19498	1.595346	1.595346
26.95	1.153429	2.243073	0.3998558	26.22931	1.599423	1.599423
27.02	1.155734	2.248896	0.4010975	26.28172	1.60439	1.60439
27.09	1.160105	2.254729	0.4018962	26.38112	1.607585	1.607585
27.16	1.158913	2.260562	0.4032215	26.35402	1.612886	1.612886
27.23	1.163205	2.266375	0.4044334	26.4516	1.617734	1.617734
27.3	1.163006	2.272229	0.4050851	26.44709	1.62034	1.62034
27.37	1.166463	2.278042	0.4062613	26.5257	1.625045	1.625045
27.44	1.166979	2.283906	0.4071236	26.53745	1.628494	1.628494
27.51	1.169721	2.289708	0.4085839	26.5998	1.634336	1.634336
27.58	1.171033	2.295563	0.409468	26.62962	1.637872	1.637872
27.65	1.171033	2.301406	0.4103899	26.62962	1.64156	1.64156
27.72	1.173496	2.307208	0.4118741	26.68564	1.647496	1.647496
27.79	1.176039	2.313062	0.4129887	26.74347	1.651955	1.651955
27.86	1.178304	2.318875	0.4138271	26.79498	1.655308	1.655308
27.93	1.179338	2.324739	0.4149795	26.81847	1.659918	1.659918
28	1.181563	2.330531	0.4159292	26.86908	1.663717	1.663717
28.07	1.183351	2.336396	0.4170636	26.90974	1.668254	1.668254
28.14	1.186649	2.342219	0.4182359	26.98474	1.672943	1.672943
28.21	1.184384	2.348042	0.4194379	26.93323	1.677752	1.677752
28.28	1.186808	2.353885	0.4204532	26.98835	1.681813	1.681813
28.35	1.189351	2.359719	0.4214088	27.04618	1.685635	1.685635
28.42	1.189868	2.365583	0.4224221	27.05793	1.689688	1.689688
28.49	1.194437	2.371365	0.4236738	27.16185	1.694695	1.694695
28.56	1.194	2.377229	0.4246076	27.15191	1.69843	1.69843
28.63	1.195113	2.383042	0.4257361	27.17721	1.702944	1.702944
28.7	1.196941	2.388885	0.4269063	27.21878	1.707625	1.707625
28.77	1.199603	2.394708	0.4281183	27.27932	1.712473	1.712473
28.84	1.200517	2.400542	0.4290243	27.3001	1.716097	1.716097
28.91	1.20163	2.406406	0.4302064	27.3254	1.720826	1.720826
28.98	1.202703	2.412208	0.4311403	27.3498	1.724561	1.724561
29.05	1.20306	2.418062	0.4324178	27.35793	1.729671	1.729671
29.12	1.207232	2.423885	0.4336635	27.45281	1.734654	1.734654
29.19	1.209696	2.429729	0.4350007	27.50884	1.740003	1.740003
29.26	1.209656	2.435542	0.4360358	27.50793	1.744143	1.744143
29.33	1.211206	2.441386	0.4371464	27.54317	1.748586	1.748586
29.4	1.213789	2.447219	0.438271	27.60191	1.753084	1.753084
29.47	1.212438	2.453042	0.4395863	27.57119	1.758345	1.758345
29.54	1.21673	2.458896	0.4407962	27.66878	1.763185	1.763185
29.61	1.217445	2.464719	0.4418751	27.68504	1.7675	1.7675
29.68	1.219312	2.470573	0.4430334	27.72751	1.772133	1.772133
29.75	1.220703	2.476365	0.4444242	27.75914	1.777697	1.777697
29.82	1.220425	2.482239	0.4453977	27.75282	1.781591	1.781591
29.89	1.221538	2.488062	0.4467388	27.77811	1.786955	1.786955
29.96	1.223604	2.493885	0.4480302	27.8251	1.792121	1.792121
30.03	1.224359	2.499729	0.4489283	27.84227	1.795713	1.795713
30.1	1.225273	2.505542	0.4502535	27.86305	1.801014	1.801014
30.17	1.22869	2.511396	0.4513522	27.94077	1.805409	1.805409
30.24	1.230478	2.517208	0.4524986	27.98143	1.809994	1.809994
30.31	1.231352	2.523073	0.4537424	28.00131	1.814969	1.814969
30.38	1.23175	2.528885	0.4550993	28.01035	1.820397	1.820397
30.45	1.235247	2.534729	0.4564901	28.08986	1.825961	1.825961
30.52	1.233737	2.540542	0.4575968	28.05552	1.830387	1.830387
30.59	1.236876	2.546385	0.4587988	28.12691	1.835195	1.835195
30.66	1.2362	2.55225	0.4598339	28.11155	1.839336	1.839336
30.73	1.238624	2.558052	0.4612247	28.16667	1.844899	1.844899
30.8	1.240571	2.563906	0.4625559	28.21095	1.850224	1.850224
30.87	1.241167	2.569708	0.4636745	28.2245	1.854698	1.854698
30.94	1.242995	2.575573	0.4647732	28.26607	1.859093	1.859093
31.01	1.243393	2.581375	0.4662851	28.2751	1.865141	1.865141
31.08	1.244187	2.587219	0.4673719	28.29318	1.869488	1.869488
31.15	1.244148	2.593062	0.4688462	28.29227	1.875385	1.875385
31.22	1.247803	2.598875	0.4698078	28.37541	1.879231	1.879231
31.29	1.248837	2.604729	0.4712442	28.3989	1.884977	1.884977
31.36	1.24979	2.610563	0.4726231	28.42059	1.890492	1.890492
31.43	1.250744	2.616417	0.4738569	28.44227	1.895428	1.895428
31.5	1.249234	2.622208	0.4752517	28.40793	1.901007	1.901007
31.57	1.251499	2.628062	0.4761954	28.45944	1.904782	1.904782
31.64	1.253565	2.633875	0.4778186	28.50643	1.911275	1.911275
31.71	1.254519	2.639708	0.4788478	28.52812	1.915391	1.915391
31.78	1.256069	2.645552	0.4802307	28.56336	1.920923	1.920923
31.85	1.255671	2.651385	0.4811128	28.55432	1.924451	1.924451
31.92	1.258294	2.65725	0.482899	28.61396	1.931596	1.931596
31.99	1.257141	2.663042	0.483942	28.58776	1.935768	1.935768
32.06	1.259367	2.668906	0.4851997	28.63836	1.940799	1.940799
32.13	1.262228	2.674729	0.486811	28.70342	1.947244	1.947244
32.2	1.261711	2.680562	0.488162	28.69167	1.952648	1.952648
32.27	1.260678	2.686385	0.4893263	28.66818	1.957305	1.957305
32.34	1.260042	2.692219	0.4904628	28.65372	1.961851	1.961851
32.41	1.262426	2.698062	0.4918575	28.70794	1.96743	1.96743
32.48	1.264731	2.703875	0.4933774	28.76035	1.97351	1.97351
32.55	1.265883	2.709739	0.4948755	28.78655	1.979502	1.979502
32.62	1.265566	2.715552	0.4957994	28.77932	1.983198	1.983198
32.69	1.26783	2.721406	0.4972041	28.83083	1.988816	1.988816
32.76	1.267632	2.727208	0.4986843	28.82631	1.994737	1.994737
32.83	1.269619	2.733063	0.5001644	28.87149	2.000658	2.000658
32.9	1.269261	2.738906	0.5011161	28.86336	2.004464	2.004464
32.97	1.270533	2.744708	0.5025446	28.89228	2.010179	2.010179
33.04	1.270811	2.750562	0.5041202	28.8986	2.016481	2.016481
33.11	1.270016	2.756375	0.5052726	28.88053	2.02109	2.02109
33.18	1.271248	2.762239	0.5071163	28.90854	2.028465	2.028465
33.25	1.269857	2.768042	0.5082031	28.87691	2.032812	2.032812
33.32	1.272202	2.773896	0.509572	28.93023	2.038288	2.038288
33.39	1.272519	2.779719	0.511237	28.93746	2.044948	2.044948
33.46	1.273274	2.785552	0.512292	28.95462	2.049168	2.049168
33.53	1.272996	2.791385	0.5138476	28.9483	2.055391	2.055391
33.6	1.275341	2.797219	0.515151	29.00161	2.060604	2.060604
33.67	1.276453	2.803083	0.516669	29.02692	2.066676	2.066676
33.74	1.274904	2.808875	0.5179604	28.99167	2.071841	2.071841
33.81	1.27689	2.814739	0.5194783	29.03685	2.077913	2.077913
33.88	1.276135	2.820542	0.5209069	29.01969	2.083627	2.083627
33.95	1.277884	2.826385	0.5221327	29.05945	2.088531	2.088531
34.02	1.277407	2.832219	0.5239348	29.0486	2.095739	2.095739
34.09	1.278838	2.838052	0.5252858	29.08113	2.101143	2.101143
34.16	1.276811	2.843906	0.5268176	29.03505	2.10727	2.10727
34.23	1.280785	2.849719	0.5280316	29.12541	2.112126	2.112126
34.3	1.281659	2.855573	0.5291204	29.14529	2.116482	2.116482
34.37	1.28142	2.861396	0.5311549	29.13987	2.124619	2.124619
34.44	1.28305	2.867239	0.5325655	29.17691	2.130262	2.130262
34.51	1.281023	2.873042	0.5341272	29.13083	2.136509	2.136509
34.58	1.282493	2.878885	0.535665	29.16426	2.14266	2.14266
34.65	1.282096	2.884719	0.5368412	29.15523	2.147365	2.147365
34.72	1.282255	2.890552	0.5383313	29.15884	2.153325	2.153325
34.79	1.282851	2.896396	0.540028	29.1724	2.160112	2.160112
34.86	1.283368	2.902219	0.5415062	29.18414	2.166025	2.166025
34.93	1.284719	2.908083	0.5427063	29.21487	2.170825	2.170825
35	1.284321	2.913875	0.5444467	29.20583	2.177787	2.177787
35.07	1.283566	2.919739	0.5458315	29.18866	2.183326	2.183326
35.14	1.285911	2.925562	0.5473733	29.24198	2.189493	2.189493
35.21	1.286904	2.931385	0.5486349	29.26457	2.19454	2.19454
35.28	1.28758	2.937229	0.5502085	29.27993	2.200834	2.200834
35.35	1.285076	2.943052	0.5518298	29.223	2.207319	2.207319
35.42	1.284599	2.948906	0.5531947	29.21216	2.212779	2.212779
35.49	1.287659	2.954708	0.5550385	29.28173	2.220154	2.220154
35.56	1.286705	2.960573	0.5563557	29.26005	2.225423	2.225423
35.63	1.287262	2.966385	0.5577207	29.2727	2.230883	2.230883
35.7	1.287818	2.972229	0.5594711	29.28535	2.237884	2.237884
35.77	1.287619	2.978042	0.5610506	29.28083	2.244202	2.244202
35.84	1.28909	2.983896	0.5625407	29.31427	2.250163	2.250163
35.91	1.286944	2.98975	0.564003	29.26547	2.256012	2.256012
35.98	1.28897	2.995542	0.5657117	29.31156	2.262847	2.262847
36.05	1.289725	3.001406	0.5670528	29.32872	2.268211	2.268211
36.12	1.289646	3.007208	0.5685647	29.32692	2.274259	2.274259
36.19	1.291275	3.013073	0.5700966	29.36396	2.280386	2.280386
36.26	1.291474	3.018875	0.5717357	29.36848	2.286943	2.286943
36.33	1.290878	3.024719	0.5732219	29.35493	2.292887	2.292887
36.4	1.290838	3.030562	0.5750696	29.35402	2.300278	2.300278
36.47	1.289646	3.036385	0.5764703	29.32692	2.305881	2.305881
36.54	1.291474	3.042229	0.5778452	29.36848	2.311381	2.311381
36.61	1.290401	3.048063	0.5796492	29.34409	2.318597	2.318597
36.68	1.290679	3.053917	0.5808492	29.35041	2.323397	2.323397
36.75	1.289129	3.059708	0.5823891	29.31517	2.329556	2.329556
36.82	1.291196	3.065573	0.5841215	29.36216	2.336486	2.336486
36.89	1.290202	3.071375	0.5858104	29.33957	2.343241	2.343241
36.96	1.291951	3.077219	0.5870084	29.37933	2.348034	2.348034
37.03	1.291871	3.083052	0.588876	29.37752	2.355504	2.355504
37.1	1.291394	3.088885	0.59038	29.36668	2.36152	2.36152
37.17	1.291474	3.09475	0.591888	29.36848	2.367552	2.367552
37.24	1.290798	3.100542	0.5936046	29.35312	2.374418	2.374418
37.31	1.292467	3.106406	0.5948882	29.39107	2.379553	2.379553
37.38	1.292944	3.112219	0.5966882	29.40192	2.386753	2.386753
37.45	1.294653	3.118062	0.5982995	29.44077	2.393198	2.393198
37.52	1.292109	3.123885	0.5998353	29.38294	2.399341	2.399341
37.59	1.292229	3.129719	0.6016493	29.38565	2.406597	2.406597
37.66	1.291871	3.135562	0.6028593	29.37752	2.411437	2.411437
37.73	1.29346	3.141375	0.6047308	29.41366	2.418923	2.418923
37.8	1.291752	3.147239	0.6060322	29.37481	2.424129	2.424129
37.87	1.292109	3.153052	0.6075005	29.38294	2.430002	2.430002
37.94	1.293063	3.158917	0.6094456	29.40463	2.437782	2.437782
38.01	1.293421	3.164708	0.6106992	29.41276	2.442797	2.442797
38.08	1.293898	3.170563	0.6125093	29.4236	2.450037	2.450037
38.15	1.294176	3.176406	0.6142755	29.42993	2.457102	2.457102
38.22	1.29501	3.182219	0.6155093	29.4489	2.462037	2.462037
38.29	1.291831	3.188073	0.617075	29.37662	2.4683	2.4683
38.36	1.29203	3.193875	0.6186386	29.38113	2.474554	2.474554
38.43	1.292229	3.199739	0.6203751	29.38565	2.4815	2.4815
38.5	1.292308	3.205542	0.6219447	29.38746	2.487779	2.487779
38.57	1.292308	3.211396	0.6235738	29.38746	2.494295	2.494295
38.64	1.292507	3.217229	0.6251375	29.39198	2.50055	2.50055
38.71	1.292626	3.223063	0.6268601	29.39469	2.50744	2.50744
38.78	1.292706	3.228885	0.6283482	29.39649	2.513393	2.513393
38.85	1.292825	3.234729	0.6298065	29.3992	2.519226	2.519226
38.92	1.292944	3.240583	0.6313245	29.40192	2.525298	2.525298
38.99	1.293023	3.246375	0.6328106	29.40372	2.531242	2.531242
39.06	1.293222	3.252239	0.6343762	29.40824	2.537505	2.537505
39.13	1.293302	3.258042	0.6360014	29.41005	2.544006	2.544006
39.2	1.2935	3.263896	0.6378154	29.41457	2.551262	2.551262
39.27	1.29362	3.269719	0.6392896	29.41728	2.557158	2.557158
39.34	1.293659	3.275552	0.6409168	29.41818	2.563667	2.563667
39.41	1.293818	3.281406	0.6427904	29.42179	2.571162	2.571162
39.48	1.293977	3.287219	0.6443799	29.42541	2.577519	2.577519
39.55	1.294096	3.293073	0.645713	29.42812	2.582852	2.582852
39.62	1.294176	3.298885	0.6473462	29.42993	2.589385	2.589385
39.69	1.294295	3.304739	0.6489456	29.43264	2.595782	2.595782
39.76	1.294454	3.310542	0.6506383	29.43625	2.602553	2.602553
39.83	1.294494	3.316396	0.6521543	29.43716	2.608617	2.608617
39.9	1.294573	3.322229	0.6536205	29.43896	2.614482	2.614482
39.97	1.294692	3.328052	0.6553988	29.44168	2.621595	2.621595
40.04	1.294692	3.333896	0.6568452	29.44168	2.627381	2.627381
40.11	1.294772	3.339719	0.6584128	29.44348	2.633651	2.633651
40.18	1.294772	3.345583	0.6598453	29.44348	2.639381	2.639381
40.25	1.294891	3.351375	0.6617109	29.44619	2.646844	2.646844
40.32	1.294891	3.357239	0.662909	29.44619	2.651636	2.651636
40.39	1.294891	3.363062	0.6651819	29.44619	2.660728	2.660728
40.46	1.294891	3.368885	0.6664435	29.44619	2.665774	2.665774
40.53	1.294971	3.374729	0.6682158	29.448	2.672863	2.672863
40.6	1.294971	3.380552	0.6696145	29.448	2.678458	2.678458
40.67	1.294971	3.386406	0.6713529	29.448	2.685412	2.685412
40.74	1.294891	3.392208	0.6729007	29.44619	2.691603	2.691603
40.81	1.294971	3.398073	0.6748438	29.448	2.699375	2.699375
40.88	1.294971	3.403885	0.6764432	29.448	2.705773	2.705773
40.95	1.294971	3.409729	0.6779988	29.448	2.711995	2.711995
41.02	1.294971	3.415542	0.6793678	29.448	2.717471	2.717471
41.09	1.294891	3.421396	0.6809811	29.44619	2.723924	2.723924
41.16	1.294891	3.42724	0.6825725	29.44619	2.73029	2.73029
41.23	1.294891	3.433052	0.684158	29.44619	2.736632	2.736632
41.3	1.294891	3.438906	0.6860356	29.44619	2.744142	2.744142
41.37	1.294891	3.444708	0.6872435	29.44619	2.748974	2.748974
41.44	1.294772	3.450573	0.6888489	29.44348	2.755396	2.755396
41.51	1.294772	3.456375	0.6906112	29.44348	2.762445	2.762445
41.58	1.294772	3.462219	0.6922345	29.44348	2.768938	2.768938
41.65	1.294772	3.468062	0.6936848	29.44348	2.774739	2.774739
41.72	1.294772	3.473885	0.6954094	29.44348	2.781637	2.781637
41.79	1.294692	3.479729	0.6969571	29.44168	2.787828	2.787828
41.86	1.294692	3.485563	0.6988049	29.44168	2.795219	2.795219
41.93	1.294692	3.491417	0.699987	29.44168	2.799948	2.799948
42	1.294692	3.497208	0.7016917	29.44168	2.806767	2.806767
42.07	1.294692	3.503062	0.7032871	29.44168	2.813148	2.813148
42.14	1.294692	3.508875	0.7050931	29.44168	2.820373	2.820373
42.21	1.294573	3.514719	0.7066647	29.43896	2.826659	2.826659
42.28	1.294573	3.520562	0.7082482	29.43896	2.832993	2.832993
42.35	1.294573	3.526385	0.7097741	29.43896	2.839096	2.839096
42.42	1.294573	3.53225	0.7113973	29.43896	2.845589	2.845589
42.49	1.294494	3.538042	0.7133107	29.43716	2.853243	2.853243
42.56	1.294454	3.543906	0.7148405	29.43625	2.859362	2.859362
42.63	1.294374	3.549729	0.7162492	29.43445	2.864997	2.864997
42.7	1.294295	3.555573	0.7179479	29.43264	2.871792	2.871792
42.77	1.294295	3.561385	0.7192731	29.43264	2.877092	2.877092
42.84	1.294176	3.567219	0.7213712	29.42993	2.885485	2.885485
42.91	1.294096	3.573062	0.7227361	29.42812	2.890944	2.890944
42.98	1.294057	3.578875	0.7242084	29.42722	2.896833	2.896833
43.05	1.293977	3.584739	0.7258475	29.42541	2.90339	2.90339
43.12	1.293898	3.590552	0.7276893	29.4236	2.910757	2.910757
43.19	1.293858	3.596417	0.729094	29.4227	2.916376	2.916376
43.26	1.293818	3.602208	0.7307251	29.42179	2.9229	2.9229
43.33	1.293699	3.608073	0.7321417	29.41908	2.928567	2.928567
43.4	1.29362	3.613906	0.7340809	29.41728	2.936323	2.936323
43.47	1.29362	3.619719	0.7355213	29.41728	2.942085	2.942085
43.54	1.2935	3.625573	0.737079	29.41457	2.948316	2.948316
43.61	1.293421	3.631385	0.7387042	29.41276	2.954817	2.954817
43.68	1.293302	3.637239	0.7401724	29.41005	2.96069	2.96069
43.75	1.293302	3.643042	0.7421355	29.41005	2.968542	2.968542
43.82	1.293302	3.648896	0.7434447	29.41005	2.973779	2.973779
43.89	1.293222	3.654729	0.7451932	29.40824	2.980773	2.980773
43.96	1.293103	3.660563	0.7470806	29.40553	2.988322	2.988322
44.03	1.293103	3.666396	0.7483661	29.40553	2.993464	2.993464
44.1	1.293023	3.672229	0.7500231	29.40372	3.000093	3.000093
44.17	1.292904	3.678083	0.7516961	29.40101	3.006784	3.006784
44.24	1.292904	3.683875	0.7531245	29.40101	3.012498	3.012498
44.31	1.292825	3.689739	0.7545372	29.3992	3.018149	3.018149
44.38	1.292706	3.695542	0.756377	29.39649	3.025508	3.025508
44.45	1.292626	3.701396	0.7580022	29.39469	3.032009	3.032009
44.52	1.292507	3.707219	0.7597148	29.39198	3.038859	3.038859
44.59	1.292467	3.713052	0.7614791	29.39107	3.045917	3.045917
44.66	1.292308	3.718906	0.7627289	29.38746	3.050915	3.050915
44.73	1.292229	3.724719	0.764523	29.38565	3.058092	3.058092
44.8	1.292109	3.730573	0.7657428	29.38294	3.062971	3.062971
44.87	1.29203	3.736396	0.7675111	29.38113	3.070045	3.070045
44.94	1.291911	3.74225	0.7693708	29.37842	3.077483	3.077483
45.01	1.291831	3.748042	0.7707854	29.37662	3.083142	3.083142
45.08	1.291633	3.753885	0.7722616	29.3721	3.089046	3.089046
45.15	1.291553	3.759719	0.7738173	29.37029	3.095269	3.095269
45.22	1.291434	3.765552	0.7758319	29.36758	3.103328	3.103328
45.29	1.291355	3.771406	0.7768412	29.36577	3.107365	3.107365
45.36	1.291235	3.777219	0.7788261	29.36306	3.115304	3.115304
45.43	1.291156	3.783083	0.7802188	29.36125	3.120875	3.120875
45.5	1.291037	3.788875	0.7819474	29.35854	3.127789	3.127789
45.57	1.290957	3.794739	0.7833938	29.35674	3.133575	3.133575
45.64	1.290838	3.800562	0.7854164	29.35402	3.141665	3.141665
45.71	1.290758	3.806396	0.7866521	29.35222	3.146609	3.146609
45.78	1.290639	3.812229	0.7880628	29.34951	3.152251	3.152251
45.85	1.29056	3.818052	0.7896225	29.3477	3.15849	3.15849
45.92	1.290441	3.823906	0.7914404	29.34499	3.165762	3.165762
45.99	1.290361	3.829708	0.7929166	29.34318	3.171666	3.171666
46.06	1.290242	3.835573	0.7946213	29.34047	3.178485	3.178485
46.13	1.290162	3.841385	0.7960717	29.33866	3.184287	3.184287
46.2	1.290162	3.847239	0.7976691	29.33866	3.190676	3.190676
46.27	1.290043	3.853052	0.7993062	29.33595	3.197225	3.197225
46.34	1.289964	3.858896	0.8011003	29.33414	3.204401	3.204401
46.41	1.289964	3.86474	0.8026262	29.33414	3.210505	3.210505
46.48	1.289845	3.870542	0.8041183	29.33143	3.216473	3.216473
46.55	1.289765	3.876406	0.8057256	29.32963	3.222903	3.222903
46.62	1.289646	3.882208	0.8072158	29.32692	3.228863	3.228863
46.69	1.289606	3.888073	0.8090138	29.32601	3.236055	3.236055
46.76	1.289487	3.893875	0.8106907	29.3233	3.242763	3.242763
46.83	1.289368	3.899729	0.8119047	29.32059	3.247619	3.247619
46.9	1.289288	3.905573	0.8137961	29.31878	3.255184	3.255184
46.97	1.289169	3.911385	0.8152068	29.31607	3.260827	3.260827
47.04	1.28909	3.917229	0.8167763	29.31427	3.267105	3.267105
47.11	1.288891	3.923063	0.8186201	29.30975	3.274481	3.274481
47.18	1.288772	3.928917	0.8200745	29.30704	3.280298	3.280298
47.25	1.288692	3.934708	0.8214613	29.30523	3.285845	3.285845
47.32	1.288573	3.940573	0.8233011	29.30252	3.293204	3.293204
47.39	1.288374	3.946375	0.8248945	29.298	3.299578	3.299578
47.46	1.288295	3.952219	0.8262892	29.29619	3.305157	3.305157
47.53	1.288176	3.958062	0.8281251	29.29348	3.3125	3.3125
47.6	1.287977	3.963885	0.8298278	29.28896	3.319311	3.319311
47.67	1.287897	3.96975	0.8313477	29.28716	3.325391	3.325391
47.74	1.287778	3.975542	0.8329074	29.28445	3.33163	3.33163
47.81	1.287699	3.981406	0.834173	29.28264	3.336692	3.336692
47.88	1.28758	3.987229	0.835979	29.27993	3.343916	3.343916
47.95	1.287381	3.993073	0.8373618	29.27541	3.349447	3.349447
48.02	1.287301	3.998885	0.8390169	29.2736	3.356067	3.356067
48.09	1.287222	4.004719	0.8406878	29.2718	3.362751	3.362751
48.16	1.287103	4.010573	0.8425057	29.26908	3.370023	3.370023
48.23	1.286944	4.016375	0.8437415	29.26547	3.374966	3.374966
48.3	1.286825	4.02224	0.8452932	29.26276	3.381173	3.381173
48.37	1.286705	4.028052	0.8467138	29.26005	3.386855	3.386855
48.44	1.286546	4.033916	0.8485456	29.25643	3.394182	3.394182
48.51	1.286427	4.039708	0.8499503	29.25372	3.399801	3.399801
48.58	1.286308	4.045562	0.8517146	29.25101	3.406858	3.406858
48.65	1.286229	4.051406	0.8534729	29.24921	3.413892	3.413892
48.72	1.28603	4.057219	0.8547644	29.24469	3.419058	3.419058
48.79	1.285831	4.063073	0.8561929	29.24017	3.424772	3.424772
48.86	1.285712	4.068885	0.8577188	29.23746	3.430875	3.430875
48.93	1.285632	4.074739	0.8596023	29.23565	3.438409	3.438409
49	1.285513	4.080542	0.8611401	29.23294	3.44456	3.44456
49.07	1.285315	4.086396	0.8624911	29.22842	3.449965	3.449965
49.14	1.285235	4.092219	0.864327	29.22661	3.457308	3.457308
49.21	1.285116	4.098052	0.8658628	29.2239	3.463451	3.463451
49.28	1.284957	4.103885	0.8669336	29.22029	3.467735	3.467735
49.35	1.284838	4.109729	0.8688172	29.21758	3.475269	3.475269
49.42	1.284758	4.115583	0.870492	29.21577	3.481968	3.481968
49.49	1.28456	4.121375	0.8721411	29.21125	3.488564	3.488564
49.56	1.28444	4.12724	0.8735816	29.20854	3.494326	3.494326
49.63	1.284361	4.133042	0.8752326	29.20673	3.500931	3.500931
49.7	1.284162	4.138896	0.8766472	29.20222	3.506589	3.506589
49.77	1.284043	4.144719	0.878038	29.1995	3.512152	3.512152
49.84	1.283924	4.150552	0.8796136	29.19679	3.518454	3.518454
49.91	1.283765	4.156406	0.8814156	29.19318	3.525662	3.525662
49.98	1.283685	4.162219	0.8824746	29.19137	3.529898	3.529898
50.05	1.283566	4.168073	0.8846183	29.18866	3.538473	3.538473
50.12	1.283447	4.173896	0.8858005	29.18595	3.543202	3.543202
50.19	1.283248	4.17975	0.8875668	29.18143	3.550267	3.550267
50.26	1.283169	4.185542	0.8892755	29.17963	3.557102	3.557102
50.33	1.28305	4.191396	0.8908709	29.17691	3.563483	3.563483
50.4	1.28297	4.197219	0.8923371	29.17511	3.569349	3.569349
50.47	1.282771	4.203042	0.8936405	29.17059	3.574562	3.574562
50.54	1.282692	4.208896	0.89583	29.16878	3.58332	3.58332
50.61	1.282573	4.214719	0.8967797	29.16607	3.587119	3.587119
50.68	1.282493	4.220583	0.8983433	29.16426	3.593373	3.593373
50.75	1.282295	4.226375	0.8999527	29.15975	3.599811	3.599811
50.82	1.282175	4.23224	0.9015977	29.15704	3.606391	3.606391
50.89	1.281977	4.238062	0.9030302	29.15252	3.612121	3.612121
50.96	1.281897	4.243886	0.9049197	29.15071	3.619679	3.619679
51.03	1.281778	4.249729	0.9063562	29.148	3.625425	3.625425
51.1	1.281619	4.255552	0.9080033	29.14439	3.632013	3.632013
51.17	1.2815	4.261406	0.9096702	29.14167	3.638681	3.638681
51.24	1.281381	4.267208	0.9110729	29.13896	3.644292	3.644292
51.31	1.281301	4.273073	0.9121835	29.13716	3.648734	3.648734
51.38	1.281103	4.278885	0.9139975	29.13264	3.65599	3.65599
51.45	1.280983	4.284729	0.9155869	29.12993	3.662348	3.662348
51.52	1.280904	4.290552	0.9170592	29.12812	3.668237	3.668237
51.59	1.280785	4.296396	0.9184758	29.12541	3.673903	3.673903
51.66	1.280705	4.30225	0.9203454	29.1236	3.681381	3.681381
51.73	1.280626	4.308052	0.9218991	29.1218	3.687596	3.687596
51.8	1.280427	4.313906	0.9232342	29.11728	3.692937	3.692937
51.87	1.280308	4.319719	0.9247403	29.11457	3.698961	3.698961
51.94	1.280228	4.325573	0.9262283	29.11276	3.704913	3.704913
52.01	1.280109	4.331385	0.9280384	29.11005	3.712153	3.712153
52.08	1.27995	4.337229	0.929447	29.10643	3.717788	3.717788
52.15	1.279831	4.343073	0.9311576	29.10372	3.724631	3.724631
52.22	1.279712	4.348886	0.9325643	29.10101	3.730257	3.730257
52.29	1.279553	4.35474	0.9340445	29.0974	3.736178	3.736178
52.36	1.279434	4.360562	0.935332	29.09469	3.741328	3.741328
52.43	1.279235	4.366416	0.9366472	29.09017	3.746589	3.746589
52.5	1.279116	4.372208	0.9385745	29.08746	3.754298	3.754298
52.57	1.279036	4.378073	0.940146	29.08565	3.760584	3.760584
52.64	1.278838	4.383885	0.9415865	29.08113	3.766346	3.766346
52.71	1.278718	4.389719	0.9432177	29.07842	3.772871	3.772871
52.78	1.278639	4.395563	0.9444177	29.07661	3.777671	3.777671
52.85	1.27844	4.401385	0.9463072	29.07209	3.785229	3.785229
52.92	1.278361	4.40725	0.9475112	29.07029	3.790045	3.790045
52.99	1.278242	4.413042	0.9490848	29.06758	3.796339	3.796339
53.06	1.278043	4.418906	0.9507279	29.06306	3.802912	3.802912
53.13	1.277963	4.424729	0.952214	29.06125	3.808856	3.808856
53.2	1.277844	4.430562	0.9535928	29.05854	3.814371	3.814371
53.27	1.277765	4.436385	0.955538	29.05674	3.822152	3.822152
53.34	1.277645	4.442219	0.9566545	29.05403	3.826618	3.826618
53.41	1.277447	4.448062	0.9583374	29.04951	3.833349	3.833349
53.48	1.277367	4.453875	0.9596686	29.0477	3.838674	3.838674
53.55	1.277248	4.45974	0.9613355	29.04499	3.845342	3.845342
53.62	1.277169	4.465552	0.9630541	29.04318	3.852216	3.852216
53.69	1.27697	4.471416	0.9645164	29.03866	3.858066	3.858066
53.76	1.276851	4.477208	0.9659688	29.03595	3.863875	3.863875
53.83	1.276652	4.483073	0.9674708	29.03143	3.869883	3.869883
53.9	1.276652	4.488906	0.9687781	29.03143	3.875113	3.875113
53.97	1.276453	4.494719	0.9702663	29.02692	3.881065	3.881065
54.04	1.276374	4.500573	0.9717663	29.02511	3.887065	3.887065
54.11	1.276175	4.506385	0.9733419	29.02059	3.893368	3.893368
54.18	1.276096	4.512239	0.9747744	29.01878	3.899097	3.899097
54.25	1.275977	4.518042	0.9759645	29.01607	3.903858	3.903858
54.32	1.275778	4.523896	0.9777904	29.01155	3.911161	3.911161
54.39	1.275619	4.529729	0.9791533	29.00794	3.916613	3.916613
54.46	1.2755	4.535563	0.9805719	29.00523	3.922288	3.922288
54.53	1.275341	4.541396	0.9824077	29.00161	3.929631	3.929631
54.6	1.275182	4.547229	0.9834568	28.998	3.933827	3.933827
54.67	1.275102	4.553083	0.9851436	28.99619	3.940574	3.940574
54.74	1.274904	4.558886	0.9863337	28.99167	3.945335	3.945335
54.81	1.274705	4.56474	0.988255	28.98716	3.95302	3.95302
54.88	1.274586	4.570541	0.9894748	28.98444	3.957899	3.957899
54.95	1.274387	4.576396	0.9908299	28.97993	3.96332	3.96332
55.02	1.274308	4.582219	0.9923856	28.97812	3.969542	3.969542
55.09	1.274109	4.588052	0.9935935	28.9736	3.974374	3.974374
55.16	1.27391	4.593916	0.9948015	28.96908	3.979206	3.979206
55.23	1.273712	4.599719	0.9962042	28.96457	3.984817	3.984817
55.3	1.273632	4.605573	0.9974201	28.96276	3.989681	3.989681
55.37	1.273433	4.611396	0.9984096	28.95824	3.993638	3.993638
55.44	1.273235	4.61725	0.9988884	28.95372	3.995554	3.995554
55.51	1.248757	4.623063	0.8762777	28.39709	3.505111	3.505111
55.56	0.008940697	4.626823	0.8626084	0.203314	3.450433	3.450433