File: Shimadzu/Grupo_A-CP27-D.txt
Nome do ensaio	Modo de ensaio	Tipo de ensaio	Título1	Comentário1	Palavra-chave	Nome do produto	Nome do arquivo do ensaio	Nome do arquivo do método	Data do relatório	Data do ensaio	Modo de ensaio	Tipo de ensaio	Velocidade	Placa	Lote No:	Sub-Lote No:
Extensometro SG25-50 - Placa - Sthil_20210601_1512.xtak	Simples	Tração	Grupo de Mecânica Aplicada - GMAp
UFRGS	Comentário	 	 	Extensometro SG25-50 - Placa - Sthil_20210601_1512.xtak	Extensometro SG25-50 - Placa - Sthil.xmak	01/06/2021	01/06/2021	Simples	Tração	5mm/min	Placa	1	1

Placa:	Lote No:	Sub-Lote No:
Placa	1	1
Nome	Espessura	Largura	Gauge Length
Unidade:	mm	mm	mm
Ga_D_27	3.3613	13.0583	115.0000

Nome	Elástico	Inclinação_Padrão	Ruptura_Força	Máx_Força	Max_Disp_Força	Max_Disp_SG-25-50 %	Max_Disp_Deslocamento	Espessura	Largura	Gauge_Length	Máx_Tensão	YS1_Tensão
Parâmetro	Tensão 40 - 60 N/mm2	Tensão 40 - 60 N/mm2	Sensibilidade: 10	Cálculo de áreas completas							Cálculo de áreas completas	0.2 %
Unidade	N/mm2	N/mm	kN	kN	kN	%	mm	mm	mm	mm	N/mm2	N/mm2
Ga_D_27	-.-	-.-	1.29533	1.33816	1.29525	4.79826	4.81140	3.3613	13.0583	115.0000	30.4871	-.-

Ga_D_27
Tempo	Força	Deslocamento	Desloc. SG25-50	Tensão	SG-25-50 %	Deformação
seg	kN	mm	mm	N/mm2	%	%
0	0.0111262	0	0	0.2534854	0	0
0.08	0.01104673	0.003989583	0.0007927418	0.2516748	0.003170967	0.003170967
0.16	0.01104673	0.01057292	0.002501408	0.2516748	0.01000563	0.01000563
0.24	0.0111262	0.01725	0.003647804	0.2534854	0.01459122	0.01459122
0.32	0.02618631	0.02388542	0.004980961	0.596596	0.01992385	0.01992385
0.4	0.03051758	0.0305625	0.006502867	0.6952743	0.02601147	0.02601147
0.48	0.03445148	0.03725	0.007841985	0.7848995	0.03136794	0.03136794
0.56	0.04084905	0.043875	0.009143353	0.9306535	0.03657341	0.03657341
0.64	0.04386902	0.05055208	0.01033545	0.9994568	0.04134178	0.04134178
0.72	0.04975001	0.05723958	0.01223683	1.133442	0.04894733	0.04894733
0.8	0.05451838	0.063875	0.01353423	1.242079	0.05413691	0.05413691
0.88	0.0582536	0.0705625	0.01511176	1.327177	0.06044706	0.06044706
0.96	0.06266435	0.07723958	0.0166436	1.427666	0.06657442	0.06657442
1.04	0.06993612	0.083875	0.01766483	1.593337	0.07065932	0.07065932
1.12	0.07168452	0.09057292	0.01903772	1.63317	0.07615089	0.07615089
1.2	0.07903576	0.09723958	0.02057155	1.800652	0.0822862	0.0822862
1.28	0.08277098	0.1038854	0.02224048	1.88575	0.08896192	0.08896192
1.36	0.08753935	0.1105833	0.02358556	1.994387	0.09434223	0.09434223
1.44	0.09183089	0.1172083	0.02500216	2.09216	0.1000086	0.1000086
1.52	0.09600321	0.1238854	0.02661745	2.187217	0.1064698	0.1064698
1.6	0.1013279	0.1305729	0.02804796	2.308528	0.1121918	0.1121918
1.68	0.1084805	0.1372187	0.02937118	2.471483	0.1174847	0.1174847
1.76	0.1122157	0.1438958	0.03058116	2.556581	0.1223246	0.1223246
1.84	0.1174609	0.1505729	0.03209909	2.676082	0.1283963	0.1283963
1.92	0.121673	0.1572292	0.03358523	2.772044	0.1343409	0.1343409
2	0.1284281	0.1638958	0.03531178	2.925946	0.1412471	0.1412471
2.08	0.1329978	0.1705625	0.03668666	3.030056	0.1467466	0.1467466
2.16	0.1375278	0.1772188	0.03792048	3.13326	0.1516819	0.1516819
2.24	0.1402299	0.1839062	0.03928741	3.194822	0.1571496	0.1571496
2.32	0.1460711	0.1905521	0.04085898	3.327901	0.1634359	0.1634359
2.4	0.1510779	0.1972187	0.04212856	3.44197	0.1685143	0.1685143
2.48	0.1572768	0.2039167	0.04366835	3.583197	0.1746734	0.1746734
2.56	0.1633565	0.2105417	0.04527569	3.721709	0.1811028	0.1811028
2.64	0.1671314	0.2172292	0.04664262	3.807713	0.1865705	0.1865705
2.72	0.170509	0.2239167	0.04818439	3.884664	0.1927376	0.1927376
2.8	0.1744827	0.2305417	0.04961093	3.975194	0.1984437	0.1984437
2.88	0.1805226	0.2372292	0.05078514	4.112801	0.2031406	0.2031406
2.96	0.1859665	0.2438958	0.05228519	4.236827	0.2091408	0.2091408
3.04	0.1914899	0.2505417	0.05354484	4.362665	0.2141794	0.2141794
3.12	0.1948674	0.2572396	0.05517801	4.439616	0.220712	0.220712
3.2	0.1986424	0.2638958	0.05661448	4.52562	0.2264579	0.2264579
3.28	0.2050002	0.2705521	0.05801718	4.670469	0.2320687	0.2320687
3.36	0.2098481	0.2772396	0.05960862	4.780916	0.2384345	0.2384345
3.44	0.213623	0.2838958	0.06089211	4.86692	0.2435684	0.2435684
3.52	0.2171199	0.2905521	0.06224513	4.946587	0.2489805	0.2489805
3.6	0.2226035	0.2972396	0.06372333	5.071519	0.2548933	0.2548933
3.68	0.2274513	0.303875	0.0651598	5.181966	0.2606392	0.2606392
3.76	0.2325773	0.3105521	0.06638964	5.29875	0.2655586	0.2655586
3.84	0.2371073	0.3172292	0.06786386	5.401955	0.2714554	0.2714554
3.92	0.2438227	0.3238854	0.06930232	5.554952	0.2772093	0.2772093
4	0.2481143	0.3305625	0.07077257	5.652725	0.2830903	0.2830903
4.08	0.2518892	0.3372187	0.07204811	5.738729	0.2881924	0.2881924
4.16	0.2559026	0.3438958	0.07371704	5.830164	0.2948681	0.2948681
4.24	0.2604723	0.3505833	0.07477006	5.934274	0.2990802	0.2990802
4.32	0.2670685	0.3572187	0.07622242	6.084555	0.3048897	0.3048897
4.4	0.2704859	0.3638854	0.07748207	6.162411	0.3099283	0.3099283
4.48	0.2764861	0.3705729	0.07942915	6.299112	0.3177166	0.3177166
4.56	0.2787908	0.3772083	0.08031925	6.35162	0.321277	0.321277
4.64	0.2858241	0.3838854	0.08156499	6.511859	0.3262599	0.3262599
4.72	0.2888838	0.3905833	0.0829955	6.581567	0.331982	0.331982
4.8	0.2946059	0.3972083	0.08440813	6.711931	0.3376325	0.3376325
4.88	0.2983809	0.4039063	0.08596778	6.797935	0.3438711	0.3438711
4.96	0.3029505	0.4105833	0.0872016	6.902045	0.3488064	0.3488064
5.04	0.3087918	0.4172083	0.08895794	7.035125	0.3558318	0.3558318
5.12	0.3122886	0.4239062	0.09034475	7.114792	0.361379	0.361379
5.2	0.3178517	0.4305521	0.09151498	7.241535	0.3660599	0.3660599
5.28	0.3222227	0.4372188	0.09298325	7.341118	0.371933	0.371933
5.36	0.3271898	0.4439062	0.09432634	7.454282	0.3773054	0.3773054
5.44	0.3323555	0.4505521	0.09533564	7.571971	0.3813426	0.3813426
5.52	0.3367662	0.4572187	0.09718934	7.67246	0.3887574	0.3887574
5.6	0.3418922	0.4639063	0.09810925	7.789244	0.392437	0.392437
5.68	0.3461838	0.4705625	0.09970665	7.887017	0.3988266	0.3988266
5.76	0.3503561	0.4772291	0.1009444	7.982074	0.4037777	0.4037777
5.84	0.3538132	0.4839062	0.1021703	8.060836	0.4086812	0.4086812
5.92	0.3621181	0.4905417	0.1038094	8.250045	0.4152378	0.4152378
6	0.3653367	0.4972292	0.105087	8.323374	0.4203478	0.4203478
6.08	0.3670851	0.5038958	0.1065731	8.363208	0.4262924	0.4262924
6.16	0.3738403	0.510552	0.1080751	8.51711	0.4323006	0.4323006
6.24	0.3794432	0.51725	0.1092613	8.644758	0.4370451	0.4370451
6.32	0.3832579	0.523875	0.1106997	8.731667	0.4427989	0.4427989
6.4	0.38445	0.5305625	0.1121481	8.758826	0.4485925	0.4485925
6.48	0.3893375	0.53725	0.1134117	8.870179	0.453647	0.453647
6.56	0.3949801	0.543875	0.1146317	8.998732	0.4585266	0.4585266
6.64	0.401338	0.5505521	0.1161635	9.14358	0.464654	0.464654
6.72	0.4056692	0.5572396	0.1175801	9.242259	0.4703204	0.4703204
6.8	0.4096826	0.563875	0.1187384	9.333695	0.4749537	0.4749537
6.88	0.4142523	0.5705625	0.1200636	9.437805	0.4802545	0.4802545
6.96	0.4185041	0.5772396	0.1214941	9.534673	0.4859765	0.4859765
7.04	0.4228751	0.583875	0.1228849	9.634255	0.4915396	0.4915396
7.12	0.4264116	0.5905729	0.123928	9.714828	0.495712	0.495712
7.2	0.4345179	0.5972396	0.1255989	9.89951	0.5023956	0.5023956
7.28	0.4360676	0.6038854	0.1266559	9.934817	0.5066236	0.5066236
7.36	0.4418294	0.6105729	0.1283328	10.06609	0.5133311	0.5133311
7.44	0.4449288	0.6172083	0.1294315	10.1367	0.5177259	0.5177259
7.52	0.4489819	0.6238854	0.1309931	10.22904	0.5239725	0.5239725
7.6	0.4553398	0.6305729	0.1321932	10.37389	0.5287727	0.5287727
7.68	0.4582405	0.6372187	0.1336197	10.43998	0.5344788	0.5344788
7.76	0.463446	0.6438958	0.1350919	10.55857	0.5403678	0.5403678
7.84	0.467062	0.6505625	0.1362582	10.64096	0.5450328	0.5450328
7.92	0.4718304	0.6572292	0.1378715	10.74959	0.551486	0.551486
8	0.4776319	0.6639062	0.1388311	10.88177	0.5553246	0.5553246
8.08	0.4820824	0.6705625	0.1401901	10.98316	0.5607605	0.5607605
8.16	0.4856189	0.6772187	0.1418114	11.06373	0.5672455	0.5672455
8.24	0.4918178	0.6839063	0.142773	11.20496	0.5710919	0.5710919
8.32	0.4938444	0.6905521	0.1443942	11.25113	0.5775769	0.5775769
8.4	0.4980167	0.6972187	0.1454135	11.34619	0.5816539	0.5816539
8.48	0.5019109	0.7039167	0.1470089	11.43491	0.5880356	0.5880356
8.56	0.5074342	0.7105417	0.148199	11.56074	0.592796	0.592796
8.64	0.5115271	0.7172292	0.1494249	11.65399	0.5976995	0.5976995
8.72	0.5131562	0.7239166	0.1508991	11.69111	0.6035964	0.6035964
8.8	0.5206267	0.7305416	0.1523038	11.86131	0.6092151	0.6092151
8.88	0.5262693	0.7372292	0.1534681	11.98986	0.6138722	0.6138722
8.96	0.5283753	0.7438958	0.1549105	12.03784	0.619642	0.619642
9.04	0.5317529	0.7505417	0.1561761	12.11479	0.6247044	0.6247044
9.12	0.5375544	0.7572291	0.1577576	12.24697	0.6310304	0.6310304
9.2	0.5422433	0.7638958	0.1588901	12.35379	0.6355603	0.6355603
9.28	0.5452235	0.7705417	0.1601954	12.42169	0.6407817	0.6407817
9.36	0.549833	0.7772396	0.1617153	12.52671	0.6468614	0.6468614
9.44	0.5540848	0.7838959	0.1627862	12.62357	0.651145	0.651145
9.52	0.5592505	0.7905521	0.1640081	12.74126	0.6560326	0.6560326
9.6	0.5633036	0.7972396	0.165389	12.8336	0.6615559	0.6615559
9.68	0.5687475	0.803875	0.1666188	12.95763	0.6664753	0.6664753
9.76	0.5712509	0.8105521	0.1678407	13.01466	0.6713629	0.6713629
9.84	0.5770127	0.8172292	0.1693825	13.14594	0.67753	0.67753
9.92	0.5788406	0.8238854	0.170513	13.18758	0.682052	0.682052
10	0.5838473	0.8305729	0.1720031	13.30165	0.6880124	0.6880124
10.08	0.5873839	0.8372188	0.1733859	13.38222	0.6935437	0.6935437
10.16	0.5932649	0.8438959	0.1746953	13.5162	0.698781	0.698781
10.24	0.5968015	0.8505833	0.1759012	13.59678	0.703605	0.703605
10.32	0.5994638	0.8572187	0.1771212	13.65743	0.7084846	0.7084846
10.4	0.6029208	0.8638854	0.1783053	13.73619	0.7132213	0.7132213
10.48	0.6080866	0.8705729	0.1795709	13.85388	0.7182837	0.7182837
10.56	0.6122192	0.8772084	0.1810531	13.94803	0.7242123	0.7242123
10.64	0.6181796	0.8838854	0.1823326	14.08383	0.7293304	0.7293304
10.72	0.6194115	0.8905833	0.1835068	14.11189	0.7340272	0.7340272
10.8	0.6248951	0.8972083	0.1846373	14.23683	0.7385492	0.7385492
10.88	0.6285508	0.9039062	0.1858791	14.32012	0.7435163	0.7435163
10.96	0.6338755	0.9105833	0.1872003	14.44143	0.7488012	0.7488012
11.04	0.6369352	0.9172083	0.1881997	14.51113	0.7527987	0.7527987
11.12	0.6407897	0.9239063	0.1897752	14.59895	0.7591009	0.7591009
11.2	0.6437699	0.9305521	0.1906753	14.66685	0.762701	0.762701
11.28	0.6479819	0.9372083	0.1920303	14.76281	0.7681211	0.7681211
11.36	0.6525517	0.9439062	0.193276	14.86692	0.773104	0.773104
11.44	0.6575187	0.950552	0.1942515	14.98008	0.7770061	0.7770061
11.52	0.6601413	0.9572188	0.1955489	15.03983	0.7821957	0.7821957
11.6	0.6626447	0.9639167	0.1970748	15.09687	0.7882993	0.7882993
11.68	0.6652673	0.9705625	0.1980146	15.15662	0.7920583	0.7920583
11.76	0.6695191	0.9772292	0.1993795	15.25348	0.7975181	0.7975181
11.84	0.6745259	0.9838958	0.2006749	15.36755	0.8026997	0.8026997
11.92	0.6786187	0.9905416	0.20172	15.4608	0.80688	0.80688
12	0.6803274	0.9972292	0.2030512	15.49973	0.8122047	0.8122047
12.08	0.6860892	1.003896	0.2041201	15.631	0.8164803	0.8164803
12.16	0.6897847	1.010552	0.2052128	15.71519	0.8208513	0.8208513
12.24	0.6916921	1.01725	0.2065063	15.75865	0.826025	0.826025
12.32	0.6946723	1.023885	0.2077719	15.82654	0.8310874	0.8310874
12.4	0.6994804	1.030563	0.2089858	15.93608	0.8359432	0.8359432
12.48	0.7043679	1.03725	0.2102752	16.04744	0.841101	0.841101
12.56	0.7067521	1.043875	0.211364	16.10176	0.8454561	0.8454561
12.64	0.7117987	1.050552	0.2125303	16.21673	0.8501212	0.8501212
12.72	0.7157326	1.05724	0.2135416	16.30635	0.8541663	0.8541663
12.8	0.7191102	1.063875	0.2150436	16.3833	0.8601745	0.8601745
12.88	0.7216136	1.070562	0.2161264	16.44034	0.8645058	0.8645058
12.96	0.7259846	1.07724	0.2173007	16.53992	0.8692026	0.8692026
13.04	0.7293622	1.083875	0.2185683	16.61687	0.874273	0.874273
13.12	0.7335742	1.090573	0.2194087	16.71284	0.8776347	0.8776347
13.2	0.7374287	1.09724	0.2207617	16.80065	0.8830468	0.8830468
13.28	0.7401307	1.103885	0.2218366	16.86221	0.8873463	0.8873463
13.36	0.7453759	1.110573	0.2229591	16.98171	0.8918365	0.8918365
13.44	0.7487138	1.117208	0.2243201	17.05776	0.8972804	0.8972804
13.52	0.7520517	1.123885	0.2254526	17.1338	0.9018103	0.9018103
13.6	0.7550716	1.130573	0.2264321	17.20261	0.9057283	0.9057283
13.68	0.7574956	1.137219	0.22735	17.25783	0.9094	0.9094
13.76	0.7618666	1.143896	0.2286514	17.35741	0.9146054	0.9146054
13.84	0.7666747	1.150563	0.2300839	17.46696	0.9203355	0.9203355
13.92	0.7697741	1.157229	0.2313693	17.53757	0.9254773	0.9254773
14	0.7707278	1.163906	0.2322833	17.5593	0.9291331	0.9291331
14.08	0.7749796	1.170563	0.2336621	17.65616	0.9346485	0.9346485
14.16	0.7794301	1.177219	0.2348224	17.75756	0.9392897	0.9392897
14.24	0.7840395	1.183906	0.2358019	17.86257	0.9432077	0.9432077
14.32	0.784874	1.190552	0.2370179	17.88159	0.9480715	0.9480715
14.4	0.7907947	1.197219	0.238051	18.01647	0.952204	0.952204
14.48	0.79302	1.203917	0.2388974	18.06717	0.9555896	0.9555896
14.56	0.7963975	1.210542	0.2402385	18.14412	0.960954	0.960954
14.64	0.8001328	1.217229	0.2415299	18.22922	0.9661198	0.9661198
14.72	0.8040269	1.223927	0.2428353	18.31794	0.9713411	0.9713411
14.8	0.8062919	1.230542	0.2438128	18.36954	0.9752512	0.9752512
14.88	0.8089542	1.237229	0.2450188	18.4302	0.9800752	0.9800752
14.96	0.8161068	1.243896	0.2463977	18.59315	0.9855906	0.9855906
15.04	0.8170207	1.250542	0.2471844	18.61398	0.9887378	0.9887378
15.12	0.8192062	1.257229	0.2484163	18.66377	0.993665	0.993665
15.2	0.8232991	1.263896	0.2496044	18.75702	0.9984176	0.9984176
15.28	0.8273522	1.270542	0.2509832	18.84936	1.003933	1.003933
15.36	0.8302529	1.27724	0.252078	18.91544	1.008312	1.008312
15.44	0.8342266	1.283896	0.2531946	19.00597	1.012778	1.012778
15.52	0.8374055	1.290552	0.2542953	19.0784	1.017181	1.017181
15.6	0.8396705	1.29724	0.2556264	19.13	1.022506	1.022506
15.68	0.8440415	1.303875	0.25659	19.22958	1.02636	1.02636
15.76	0.8493264	1.310552	0.2578477	19.34999	1.031391	1.031391
15.84	0.8523464	1.317229	0.2588411	19.41879	1.035365	1.035365
15.92	0.8540551	1.323885	0.2602657	19.45772	1.041063	1.041063
16	0.8583069	1.330573	0.261418	19.55459	1.045672	1.045672
16.08	0.8598964	1.337229	0.2624373	19.5908	1.049749	1.049749
16.16	0.8656184	1.343896	0.2636929	19.72116	1.054772	1.054772
16.24	0.8687575	1.350583	0.2647221	19.79268	1.058888	1.058888
16.32	0.8700688	1.357219	0.266099	19.82256	1.064396	1.064396
16.4	0.874877	1.363885	0.266844	19.9321	1.067376	1.067376
16.48	0.8771817	1.370573	0.2681553	19.98461	1.072621	1.072621
16.56	0.8805593	1.377208	0.2692799	20.06156	1.077119	1.077119
16.64	0.8855264	1.383885	0.2705336	20.17472	1.082134	1.082134
16.72	0.8859634	1.390583	0.2719263	20.18468	1.087705	1.087705
16.8	0.892957	1.397208	0.2726932	20.34401	1.090773	1.090773
16.88	0.8927981	1.403896	0.2736072	20.34039	1.094429	1.094429
16.96	0.8978844	1.410583	0.2750596	20.45627	1.100238	1.100238
17.04	0.9022157	1.417208	0.2763709	20.55495	1.105483	1.105483
17.12	0.905633	1.423906	0.2776305	20.63281	1.110522	1.110522
17.2	0.9075006	1.430552	0.2787789	20.67536	1.115116	1.115116
17.28	0.9113948	1.437219	0.2800047	20.76407	1.120019	1.120019
17.36	0.9133418	1.443906	0.2810895	20.80844	1.124358	1.124358
17.44	0.9192228	1.450552	0.2823015	20.94242	1.129206	1.129206
17.52	0.9208123	1.457219	0.2835512	20.97863	1.134205	1.134205
17.6	0.9268522	1.463906	0.2844155	21.11624	1.137662	1.137662
17.68	0.9278854	1.470562	0.2859314	21.13978	1.143726	1.143726
17.76	0.9309451	1.477229	0.2874652	21.20949	1.149861	1.149861
17.84	0.93472	1.483906	0.2881666	21.29549	1.152666	1.152666
17.92	0.9387334	1.490542	0.2894322	21.38692	1.157729	1.157729
18	0.939091	1.497229	0.2903938	21.39507	1.161575	1.161575
18.08	0.942111	1.503896	0.2916634	21.46388	1.166654	1.166654
18.16	0.947396	1.510552	0.293227	21.58428	1.172908	1.172908
18.24	0.9514093	1.51725	0.2942781	21.67572	1.177112	1.177112
18.32	0.9550254	1.523885	0.2953669	21.7581	1.181467	1.181467
18.4	0.9551048	1.530563	0.2967993	21.75991	1.187197	1.187197
18.48	0.9584824	1.53725	0.2976636	21.83686	1.190654	1.190654
18.56	0.962615	1.543875	0.2987107	21.93101	1.194843	1.194843
18.64	0.9681384	1.550552	0.2999663	22.05685	1.199865	1.199865
18.72	0.9690126	1.55724	0.3016015	22.07677	1.206406	1.206406
18.8	0.9731849	1.563875	0.302879	22.17183	1.211516	1.211516
18.88	0.9775956	1.570562	0.303785	22.27231	1.21514	1.21514
18.96	0.9782712	1.57724	0.3048996	22.2877	1.219598	1.219598
19.04	0.9834369	1.583875	0.3062765	22.40539	1.225106	1.225106
19.12	0.9845893	1.590573	0.3076255	22.43165	1.230502	1.230502
19.2	0.988086	1.59724	0.3088633	22.51131	1.235453	1.235453
19.28	0.9924173	1.603885	0.3094772	22.60999	1.237909	1.237909
19.36	0.9967089	1.610573	0.3106296	22.70777	1.242518	1.242518
19.44	0.997901	1.617208	0.3122846	22.73492	1.249138	1.249138
19.52	0.9996891	1.623885	0.3130833	22.77566	1.252333	1.252333
19.6	1.003106	1.630573	0.3146529	22.85352	1.258612	1.258612
19.68	1.01006	1.637219	0.3160655	23.01195	1.264262	1.264262
19.76	1.012047	1.643896	0.3168921	23.05721	1.267568	1.267568
19.84	1.015425	1.650563	0.3180861	23.13416	1.272345	1.272345
19.92	1.015981	1.657229	0.3192902	23.14684	1.277161	1.277161
20	1.018921	1.663906	0.3206412	23.21383	1.282565	1.282565
20.08	1.023968	1.670563	0.3217399	23.32881	1.28696	1.28696
20.16	1.025399	1.677219	0.3232062	23.3614	1.292825	1.292825
20.24	1.027544	1.683906	0.3243546	23.41028	1.297418	1.297418
20.32	1.0312	1.690552	0.3252963	23.49357	1.301185	1.301185
20.4	1.035333	1.697219	0.3264288	23.58772	1.305715	1.305715
20.48	1.036843	1.703917	0.3282011	23.62213	1.312804	1.312804
20.56	1.042525	1.710542	0.3291011	23.75158	1.316404	1.316404
20.64	1.044353	1.717229	0.3304998	23.79323	1.321999	1.321999
20.72	1.047889	1.723927	0.3320416	23.8738	1.328166	1.328166
20.8	1.051346	1.730542	0.3329416	23.95256	1.331766	1.331766
20.88	1.054128	1.737229	0.3337363	24.01593	1.334945	1.334945
20.96	1.055638	1.743896	0.3353198	24.05033	1.341279	1.341279
21.04	1.058976	1.750542	0.3360967	24.12638	1.344387	1.344387
21.12	1.062592	1.757229	0.3375828	24.20876	1.350331	1.350331
21.2	1.06438	1.763896	0.3390094	24.2495	1.356037	1.356037
21.28	1.068155	1.770552	0.3401538	24.3355	1.360615	1.360615
21.36	1.071334	1.77725	0.3411929	24.40793	1.364771	1.364771
21.44	1.073678	1.783896	0.3425618	24.46134	1.370247	1.370247
21.52	1.07789	1.790552	0.3438175	24.5573	1.37527	1.37527
21.6	1.082023	1.79724	0.34495	24.65146	1.3798	1.3798
21.68	1.082222	1.803875	0.3462136	24.65598	1.384854	1.384854
21.76	1.087467	1.810552	0.3475964	24.77548	1.390386	1.390386
21.84	1.08846	1.817229	0.3488342	24.79811	1.395337	1.395337
21.92	1.092235	1.823885	0.3499468	24.88412	1.399787	1.399787
22	1.095533	1.830573	0.3511151	24.95926	1.40446	1.40446
22.08	1.098633	1.837229	0.3524224	25.02987	1.40969	1.40969
22.16	1.100222	1.843896	0.3534655	25.06608	1.413862	1.413862
22.24	1.104196	1.850583	0.3549516	25.15662	1.419806	1.419806
22.32	1.107415	1.857219	0.3561636	25.22995	1.424654	1.424654
22.4	1.108487	1.863885	0.3573596	25.25439	1.429439	1.429439
22.48	1.113534	1.870573	0.3586551	25.36936	1.43462	1.43462
22.56	1.116554	1.877208	0.3598571	25.43817	1.439428	1.439428
22.64	1.116792	1.883885	0.3612777	25.4436	1.445111	1.445111
22.72	1.118024	1.890583	0.3624062	25.47166	1.449625	1.449625
22.8	1.1247	1.897208	0.3637036	25.62375	1.454814	1.454814
22.88	1.128117	1.903906	0.3649732	25.70161	1.459893	1.459893
22.96	1.129468	1.910583	0.3662487	25.73239	1.464995	1.464995
23.04	1.13217	1.917208	0.3671865	25.79395	1.468746	1.468746
23.12	1.134475	1.923906	0.3683925	25.84646	1.47357	1.47357
23.2	1.13821	1.930552	0.3697018	25.93156	1.478807	1.478807
23.28	1.140634	1.937208	0.3712237	25.98678	1.484895	1.484895
23.36	1.140714	1.943906	0.3723542	25.98859	1.489417	1.489417
23.44	1.145363	1.950562	0.3739357	26.09451	1.495743	1.495743
23.52	1.149297	1.957229	0.3750006	26.18414	1.500003	1.500003
23.6	1.148939	1.963917	0.3762206	26.17599	1.504882	1.504882
23.68	1.152635	1.970562	0.3777365	26.26018	1.510946	1.510946
23.76	1.154939	1.977229	0.3788312	26.31269	1.515325	1.515325
23.84	1.15784	1.983906	0.3800909	26.37878	1.520363	1.520363
23.92	1.160463	1.990552	0.3812293	26.43853	1.524917	1.524917
24	1.162807	1.997229	0.3824254	26.49194	1.529702	1.529702
24.08	1.166344	2.003886	0.3839771	26.57251	1.535908	1.535908
24.16	1.169086	2.010552	0.3850242	26.63498	1.540097	1.540097
24.24	1.170158	2.01725	0.3862083	26.65942	1.544833	1.544833
24.32	1.17147	2.023885	0.3874799	26.6893	1.549919	1.549919
24.4	1.175364	2.030562	0.3886262	26.77802	1.554505	1.554505
24.48	1.178344	2.03725	0.390017	26.84591	1.560068	1.560068
24.56	1.178861	2.043875	0.3911456	26.85768	1.564582	1.564582
24.64	1.183669	2.050552	0.3921767	26.96723	1.568707	1.568707
24.72	1.185258	2.05725	0.3935556	27.00344	1.574222	1.574222
24.8	1.189192	2.063875	0.3948987	27.09306	1.579595	1.579595
24.88	1.190305	2.070562	0.3960291	27.11841	1.584117	1.584117
24.96	1.190464	2.07725	0.3974855	27.12203	1.589942	1.589942
25.04	1.193762	2.083875	0.3988842	27.19717	1.595537	1.595537
25.12	1.19702	2.090573	0.3999631	27.27141	1.599852	1.599852
25.2	1.200279	2.097239	0.4013459	27.34564	1.605384	1.605384
25.28	1.20163	2.103885	0.4025082	27.37642	1.610033	1.610033
25.36	1.205206	2.110573	0.4037777	27.4579	1.615111	1.615111
25.44	1.205365	2.117219	0.4051129	27.46152	1.620452	1.620452
25.52	1.209339	2.123875	0.4062692	27.55205	1.625077	1.625077
25.6	1.209617	2.130573	0.4075368	27.55839	1.630147	1.630147
25.68	1.214147	2.137229	0.4089852	27.66159	1.635941	1.635941
25.76	1.217087	2.143896	0.4103681	27.72859	1.641472	1.641472
25.84	1.218001	2.150573	0.4118085	27.74941	1.647234	1.647234
25.92	1.218359	2.157229	0.4129767	27.75756	1.651907	1.651907
26	1.222014	2.163906	0.4141986	27.84085	1.656795	1.656795
26.08	1.221975	2.170563	0.4155437	27.83994	1.662175	1.662175
26.16	1.225233	2.177219	0.4166563	27.91417	1.666625	1.666625
26.24	1.226505	2.183906	0.4181147	27.94315	1.672459	1.672459
26.32	1.229684	2.190552	0.4195472	28.01557	1.678189	1.678189
26.4	1.233975	2.197229	0.4206081	28.11334	1.682433	1.682433
26.48	1.235604	2.203917	0.4220823	28.15046	1.688329	1.688329
26.56	1.236558	2.210542	0.4234076	28.17219	1.69363	1.69363
26.64	1.237949	2.217229	0.4247347	28.20387	1.698939	1.698939
26.72	1.241525	2.223917	0.4261216	28.28535	1.704486	1.704486
26.8	1.242081	2.230552	0.4273415	28.29802	1.709366	1.709366
26.88	1.245221	2.237229	0.4286905	28.36954	1.714762	1.714762
26.96	1.246572	2.243906	0.4298747	28.40032	1.719499	1.719499
27.04	1.250227	2.250542	0.4315515	28.48361	1.726206	1.726206
27.12	1.250823	2.25724	0.4328489	28.49719	1.731396	1.731396
27.2	1.251578	2.263906	0.4341265	28.51439	1.736506	1.736506
27.28	1.254996	2.270552	0.4356325	28.59225	1.74253	1.74253
27.36	1.255512	2.27725	0.436908	28.60402	1.747632	1.747632
27.44	1.257102	2.283896	0.4383365	28.64023	1.753346	1.753346
27.52	1.260837	2.290552	0.4396856	28.72533	1.758742	1.758742
27.6	1.261036	2.29725	0.4409373	28.72985	1.763749	1.763749
27.68	1.262108	2.303885	0.4424433	28.7543	1.769773	1.769773
27.76	1.265287	2.310552	0.4436274	28.82672	1.77451	1.77451
27.84	1.265844	2.31724	0.4451156	28.8394	1.780462	1.780462
27.92	1.26795	2.323885	0.4467785	28.88738	1.787114	1.787114
28	1.269897	2.330573	0.4478137	28.93174	1.791255	1.791255
28.08	1.2724	2.337229	0.449127	28.98877	1.796508	1.796508
28.16	1.27391	2.343896	0.4507681	29.02317	1.803072	1.803072
28.24	1.274904	2.350583	0.4521946	29.04581	1.808778	1.808778
28.32	1.274824	2.357229	0.4537642	29.04399	1.815057	1.815057
28.4	1.277407	2.363885	0.4550537	29.10284	1.820215	1.820215
28.48	1.28142	2.370583	0.4565338	29.19427	1.826135	1.826135
28.56	1.281182	2.377219	0.4579425	29.18884	1.83177	1.83177
28.64	1.283685	2.383896	0.459369	29.24588	1.837476	1.837476
28.72	1.284321	2.390583	0.4609028	29.26036	1.843611	1.843611
28.8	1.28607	2.397198	0.4621506	29.3002	1.848602	1.848602
28.88	1.288056	2.403896	0.4637102	29.34546	1.854841	1.854841
28.96	1.289407	2.410573	0.4653076	29.37624	1.86123	1.86123
29.04	1.291196	2.417208	0.4667997	29.41698	1.867199	1.867199
29.12	1.292507	2.423896	0.4683157	29.44686	1.873263	1.873263
29.2	1.294533	2.430542	0.4697104	29.49303	1.878842	1.878842
29.28	1.295527	2.437208	0.470827	29.51566	1.883308	1.883308
29.36	1.296481	2.443896	0.4722973	29.53739	1.889189	1.889189
29.44	1.299977	2.450552	0.473841	29.61705	1.895364	1.895364
29.52	1.299739	2.457208	0.4755239	29.61162	1.902095	1.902095
29.6	1.3026	2.463906	0.4770259	29.6768	1.908104	1.908104
29.68	1.30415	2.470552	0.4787167	29.71211	1.914867	1.914867
29.76	1.30407	2.477219	0.4801174	29.7103	1.92047	1.92047
29.84	1.304746	2.483896	0.4818121	29.72569	1.927249	1.927249
29.92	1.303514	2.490542	0.4832725	29.69763	1.93309	1.93309
30	1.305223	2.497219	0.4847566	29.73656	1.939026	1.939026
30.08	1.308163	2.503886	0.4862746	29.80355	1.945098	1.945098
30.16	1.308918	2.510552	0.4878461	29.82075	1.951385	1.951385
30.24	1.309196	2.51724	0.489519	29.82708	1.958076	1.958076
30.32	1.31158	2.523875	0.4913012	29.8814	1.965205	1.965205
30.4	1.31313	2.530552	0.4928052	29.91671	1.971221	1.971221
30.48	1.312852	2.53724	0.4942536	29.91037	1.977015	1.977015
30.56	1.313806	2.543875	0.4957795	29.9321	1.983118	1.983118
30.64	1.314004	2.550552	0.4976431	29.93663	1.990573	1.990573
30.72	1.314441	2.55724	0.4994313	29.94658	1.997725	1.997725
30.8	1.316349	2.563875	0.5007406	29.99004	2.002962	2.002962
30.88	1.317104	2.570552	0.502338	30.00724	2.009352	2.009352
30.96	1.318177	2.57724	0.5041162	30.03168	2.016465	2.016465
31.04	1.317263	2.583875	0.5056222	30.01086	2.022489	2.022489
31.12	1.317541	2.590563	0.5074799	30.0172	2.02992	2.02992
31.2	1.320084	2.597229	0.5088568	30.07514	2.035427	2.035427
31.28	1.321197	2.603875	0.5105655	30.10049	2.042262	2.042262
31.36	1.321038	2.610573	0.5125701	30.09687	2.050281	2.050281
31.44	1.319647	2.617208	0.5139391	30.06518	2.055756	2.055756
31.52	1.322786	2.623875	0.5157431	30.1367	2.062972	2.062972
31.6	1.325091	2.630573	0.5172114	30.18921	2.068846	2.068846
31.68	1.321435	2.637208	0.5189677	30.10592	2.075871	2.075871
31.76	1.32517	2.643885	0.5204618	30.19102	2.081847	2.081847
31.84	1.323859	2.650563	0.5224248	30.16114	2.089699	2.089699
31.92	1.325607	2.657219	0.5240659	30.20098	2.096264	2.096264
32	1.325885	2.663896	0.5258341	30.20731	2.103337	2.103337
32.08	1.327435	2.670563	0.5275865	30.24262	2.110346	2.110346
32.16	1.326839	2.677208	0.5292932	30.22904	2.117173	2.117173
32.24	1.328309	2.683896	0.5309761	30.26254	2.123904	2.123904
32.32	1.327713	2.690552	0.5328655	30.24896	2.131462	2.131462
32.4	1.328309	2.697219	0.534308	30.26254	2.137232	2.137232
32.48	1.329144	2.703906	0.5362113	30.28155	2.144845	2.144845
32.56	1.330296	2.710542	0.53792	30.3078	2.15168	2.15168
32.64	1.329104	2.717229	0.5393704	30.28064	2.157481	2.157481
32.72	1.328627	2.723917	0.5412419	30.26978	2.164968	2.164968
32.8	1.331607	2.730542	0.5432109	30.33768	2.172844	2.172844
32.88	1.329422	2.737229	0.5447547	30.28788	2.179019	2.179019
32.96	1.334031	2.743896	0.5465527	30.3929	2.186211	2.186211
33.04	1.330932	2.750531	0.5485098	30.32229	2.194039	2.194039
33.12	1.331607	2.757219	0.5497853	30.33768	2.199141	2.199141
33.2	1.330098	2.763896	0.5518854	30.30328	2.207541	2.207541
33.28	1.333594	2.770542	0.553596	30.38294	2.214384	2.214384
33.36	1.333078	2.77724	0.5553663	30.37117	2.221465	2.221465
33.44	1.332402	2.783896	0.5571842	30.35578	2.228737	2.228737
33.52	1.333515	2.790542	0.558873	30.38113	2.235492	2.235492
33.6	1.334349	2.79724	0.5608122	30.40014	2.243249	2.243249
33.68	1.333555	2.803875	0.5624871	30.38204	2.249948	2.249948
33.76	1.334508	2.810552	0.5640984	30.40376	2.256393	2.256393
33.84	1.334945	2.817229	0.5660931	30.41372	2.264373	2.264373
33.92	1.332919	2.823875	0.5677025	30.36755	2.27081	2.27081
34	1.332561	2.830562	0.5698581	30.3594	2.279433	2.279433
34.08	1.334548	2.837219	0.5714536	30.40467	2.285814	2.285814
34.16	1.334508	2.843885	0.5734563	30.40376	2.293825	2.293825
34.24	1.333594	2.850573	0.575457	30.38294	2.301828	2.301828
34.32	1.332084	2.857219	0.5768836	30.34854	2.307534	2.307534
34.4	1.333594	2.863885	0.5789439	30.38294	2.315776	2.315776
34.48	1.335382	2.870563	0.5807042	30.42368	2.322817	2.322817
34.56	1.3357	2.877208	0.5820255	30.43092	2.328102	2.328102
34.64	1.334826	2.883885	0.5842785	30.41101	2.337114	2.337114
34.72	1.334588	2.890583	0.5859852	30.40557	2.343941	2.343941
34.8	1.336177	2.897208	0.5880415	30.44179	2.352166	2.352166
34.88	1.335303	2.903896	0.5895833	30.42187	2.358333	2.358333
34.96	1.334349	2.910573	0.5913417	30.40014	2.365367	2.365367
35.04	1.335303	2.917208	0.5934954	30.42187	2.373981	2.373981
35.12	1.335025	2.923896	0.5949835	30.41553	2.379934	2.379934
35.2	1.336098	2.930552	0.5968451	30.43997	2.387381	2.387381
35.28	1.336336	2.937208	0.5990903	30.44541	2.396361	2.396361
35.36	1.335303	2.943906	0.6005923	30.42187	2.402369	2.402369
35.44	1.336058	2.950552	0.602299	30.43907	2.409196	2.409196
35.52	1.335263	2.957208	0.6041308	30.42097	2.416523	2.416523
35.6	1.33582	2.963906	0.6059011	30.43364	2.423604	2.423604
35.68	1.335899	2.970562	0.6076753	30.43545	2.430701	2.430701
35.76	1.338164	2.977229	0.609827	30.48705	2.439308	2.439308
35.84	1.334906	2.983896	0.6113768	30.41282	2.445507	2.445507
35.92	1.334985	2.990542	0.6134848	30.41463	2.453939	2.453939
36	1.335104	2.997219	0.6154914	30.41734	2.461966	2.461966
36.08	1.335104	3.003885	0.617063	30.41734	2.468252	2.468252
36.16	1.335184	3.010552	0.6191691	30.41915	2.476676	2.476676
36.24	1.335303	3.01724	0.6207645	30.42187	2.483058	2.483058
36.32	1.335382	3.023875	0.6223619	30.42368	2.489448	2.489448
36.4	1.335382	3.030562	0.6243666	30.42368	2.497466	2.497466
36.48	1.335502	3.03725	0.6263077	30.4264	2.505231	2.505231
36.56	1.335541	3.043875	0.6278475	30.4273	2.51139	2.51139
36.64	1.335581	3.050542	0.6298999	30.42821	2.5196	2.5196
36.72	1.3357	3.05724	0.6317536	30.43092	2.527014	2.527014
36.8	1.3357	3.063875	0.6336908	30.43092	2.534763	2.534763
36.88	1.3357	3.070562	0.6352405	30.43092	2.540962	2.540962
36.96	1.33578	3.07724	0.6370167	30.43273	2.548067	2.548067
37.04	1.33578	3.083875	0.6389717	30.43273	2.555887	2.555887
37.12	1.33578	3.090573	0.6408314	30.43273	2.563326	2.563326
37.2	1.33578	3.097239	0.6424665	30.43273	2.569866	2.569866
37.28	1.33578	3.103875	0.644513	30.43273	2.578052	2.578052
37.36	1.33578	3.110573	0.6465574	30.43273	2.58623	2.58623
37.44	1.33578	3.117208	0.6481349	30.43273	2.59254	2.59254
37.52	1.33578	3.123885	0.6500602	30.43273	2.600241	2.600241
37.6	1.33578	3.130573	0.6516377	30.43273	2.606551	2.606551
37.68	1.3357	3.137219	0.653859	30.43092	2.615436	2.615436
37.76	1.3357	3.143885	0.6557505	30.43092	2.623002	2.623002
37.84	1.3357	3.150563	0.6572108	30.43092	2.628843	2.628843
37.92	1.3357	3.157229	0.6591101	30.43092	2.636441	2.636441
38	1.3357	3.163896	0.6610135	30.43092	2.644054	2.644054
38.08	1.335661	3.170563	0.6631871	30.43002	2.652748	2.652748
38.16	1.335581	3.177219	0.6648521	30.42821	2.659408	2.659408
38.24	1.335581	3.183906	0.6666243	30.42821	2.666497	2.666497
38.32	1.335502	3.190542	0.6685714	30.4264	2.674286	2.674286
38.4	1.335502	3.197219	0.67059	30.4264	2.68236	2.68236
38.48	1.335382	3.203917	0.6722589	30.42368	2.689036	2.689036
38.56	1.335303	3.210542	0.674206	30.42187	2.696824	2.696824
38.64	1.335184	3.217229	0.6760975	30.41915	2.70439	2.70439
38.72	1.334985	3.223917	0.6777942	30.41463	2.711177	2.711177
38.8	1.334906	3.230542	0.6798804	30.41282	2.719522	2.719522
38.88	1.334786	3.237229	0.6815612	30.4101	2.726245	2.726245
38.96	1.334707	3.243896	0.6836494	30.40829	2.734597	2.734597
39.04	1.334508	3.250542	0.6853481	30.40376	2.741392	2.741392
39.12	1.33431	3.257229	0.6873707	30.39924	2.749483	2.749483
39.2	1.33419	3.263896	0.6888528	30.39652	2.755411	2.755411
39.28	1.334151	3.270542	0.6909172	30.39562	2.763669	2.763669
39.36	1.333992	3.27724	0.6924312	30.39199	2.769725	2.769725
39.44	1.333912	3.283896	0.6943762	30.39018	2.777505	2.777505
39.52	1.333833	3.290552	0.6964386	30.38837	2.785754	2.785754
39.6	1.333714	3.29724	0.6982486	30.38566	2.792994	2.792994
39.68	1.333634	3.303875	0.7000526	30.38385	2.80021	2.80021
39.76	1.333515	3.310552	0.7016878	30.38113	2.806751	2.806751
39.84	1.333435	3.317229	0.7036507	30.37932	2.814603	2.814603
39.92	1.333276	3.323885	0.7053773	30.3757	2.821509	2.821509
40	1.333157	3.330562	0.7073839	30.37298	2.829536	2.829536
40.08	1.333038	3.337219	0.7092674	30.37027	2.83707	2.83707
40.16	1.332919	3.343896	0.7109503	30.36755	2.843801	2.843801
40.24	1.332839	3.350573	0.7129709	30.36574	2.851884	2.851884
40.32	1.33268	3.357219	0.7148306	30.36212	2.859322	2.859322
40.4	1.332521	3.363885	0.7165353	30.3585	2.866141	2.866141
40.48	1.332442	3.370573	0.71823	30.35669	2.87292	2.87292
40.56	1.332323	3.377208	0.7202506	30.35397	2.881002	2.881002
40.64	1.332164	3.383885	0.7220129	30.35035	2.888052	2.888052
40.72	1.332045	3.390583	0.7237852	30.34763	2.895141	2.895141
40.8	1.331925	3.397208	0.7256488	30.34492	2.902595	2.902595
40.88	1.331846	3.403906	0.7278402	30.34311	2.911361	2.911361
40.96	1.331647	3.410583	0.7292112	30.33858	2.916845	2.916845
41.04	1.331568	3.417208	0.7310351	30.33677	2.92414	2.92414
41.12	1.331369	3.423896	0.7328947	30.33224	2.931579	2.931579
41.2	1.33125	3.430552	0.7348835	30.32953	2.939534	2.939534
41.28	1.331051	3.437208	0.7366319	30.325	2.946528	2.946528
41.36	1.330892	3.443906	0.7386506	30.32138	2.954602	2.954602
41.44	1.330773	3.450552	0.7403989	30.31866	2.961596	2.961596
41.52	1.330574	3.457219	0.7423401	30.31414	2.96936	2.96936
41.6	1.330376	3.463906	0.7443209	30.30961	2.977284	2.977284
41.68	1.330217	3.470562	0.7460058	30.30599	2.984023	2.984023
41.76	1.330058	3.477229	0.7477164	30.30237	2.990866	2.990866
41.84	1.329859	3.483896	0.7496377	30.29784	2.998551	2.998551
41.92	1.32966	3.490552	0.7514198	30.29332	3.005679	3.005679
42	1.329502	3.497229	0.7532477	30.2897	3.012991	3.012991
42.08	1.329303	3.503885	0.7552028	30.28517	3.020811	3.020811
42.16	1.329104	3.510552	0.7573466	30.28064	3.029386	3.029386
42.24	1.328985	3.51724	0.7588148	30.27793	3.035259	3.035259
42.32	1.328707	3.523875	0.7607659	30.27159	3.043063	3.043063
42.4	1.328548	3.530562	0.7621229	30.26797	3.048491	3.048491
42.48	1.328389	3.53726	0.7644534	30.26435	3.057814	3.057814
42.56	1.328309	3.543875	0.7659475	30.26254	3.06379	3.06379
42.64	1.328111	3.550552	0.7680674	30.25801	3.07227	3.07227
42.72	1.327912	3.55724	0.7697125	30.25348	3.07885	3.07885
42.8	1.327793	3.563875	0.7714311	30.25076	3.085725	3.085725
42.88	1.327713	3.570562	0.77341	30.24896	3.09364	3.09364
42.96	1.327515	3.57724	0.7754247	30.24443	3.101699	3.101699
43.04	1.327395	3.583875	0.7772088	30.24171	3.108835	3.108835
43.12	1.327237	3.590573	0.7786234	30.23809	3.114494	3.114494
43.2	1.327038	3.597239	0.7807255	30.23357	3.122902	3.122902
43.28	1.326919	3.603885	0.7825673	30.23085	3.130269	3.130269
43.36	1.32672	3.610573	0.7843216	30.22632	3.137286	3.137286
43.44	1.326521	3.617208	0.7862369	30.2218	3.144948	3.144948
43.52	1.326323	3.623885	0.7879933	30.21727	3.151973	3.151973
43.6	1.326243	3.630573	0.7900755	30.21546	3.160302	3.160302
43.68	1.326044	3.637219	0.7917802	30.21093	3.167121	3.167121
43.76	1.325846	3.643896	0.7936776	30.20641	3.17471	3.17471
43.84	1.325647	3.650563	0.7955174	30.20188	3.18207	3.18207
43.92	1.325448	3.657229	0.7972916	30.19735	3.189166	3.189166
44	1.32525	3.663906	0.7992943	30.19283	3.197177	3.197177
44.08	1.325091	3.670563	0.8010586	30.18921	3.204234	3.204234
44.16	1.324972	3.677219	0.8029322	30.18649	3.211729	3.211729
44.24	1.324773	3.683906	0.8045335	30.18196	3.218134	3.218134
44.32	1.324574	3.690542	0.8063018	30.17744	3.225207	3.225207
44.4	1.324455	3.697219	0.8081575	30.17472	3.23263	3.23263
44.48	1.324256	3.703917	0.8100848	30.17019	3.240339	3.240339
44.56	1.324177	3.710542	0.8118947	30.16838	3.247579	3.247579
44.64	1.323978	3.717229	0.8138776	30.16386	3.25551	3.25551
44.72	1.323859	3.723917	0.8154213	30.16114	3.261685	3.261685
44.8	1.32366	3.730542	0.8173247	30.15662	3.269299	3.269299
44.88	1.323462	3.737229	0.8191128	30.15209	3.276451	3.276451
44.96	1.323382	3.743896	0.8209348	30.15028	3.283739	3.283739
45.04	1.323183	3.750542	0.8228262	30.14575	3.291305	3.291305
45.12	1.322985	3.757229	0.8246899	30.14123	3.298759	3.298759
45.2	1.322786	3.763896	0.8263846	30.1367	3.305538	3.305538
45.28	1.322667	3.770542	0.8281946	30.13398	3.312778	3.312778
45.36	1.322508	3.77725	0.8301914	30.13036	3.320765	3.320765
45.44	1.322309	3.783896	0.8319139	30.12583	3.327656	3.327656
45.52	1.322111	3.790552	0.8335292	30.12131	3.334117	3.334117
45.6	1.321912	3.79724	0.8357306	30.11678	3.342922	3.342922
45.68	1.321793	3.803875	0.8374234	30.11407	3.349694	3.349694
45.76	1.321594	3.810552	0.8391579	30.10954	3.356632	3.356632
45.84	1.321395	3.817229	0.8408904	30.10501	3.363562	3.363562
45.92	1.321197	3.823885	0.8428931	30.10049	3.371572	3.371572
46	1.321117	3.830562	0.8447647	30.09867	3.379059	3.379059
46.08	1.320918	3.837219	0.8466224	30.09415	3.38649	3.38649
46.16	1.32072	3.843896	0.8485198	30.08962	3.394079	3.394079
46.24	1.320521	3.850583	0.8503497	30.08509	3.401399	3.401399
46.32	1.320322	3.857219	0.8519809	30.08057	3.407923	3.407923
46.4	1.320163	3.863885	0.8537273	30.07695	3.414909	3.414909
46.48	1.320044	3.870573	0.8557598	30.07423	3.423039	3.423039
46.56	1.319846	3.877208	0.8574287	30.06971	3.429715	3.429715
46.64	1.319647	3.883896	0.8595129	30.06518	3.438051	3.438051
46.72	1.319448	3.890583	0.8611739	30.06065	3.444695	3.444695
46.8	1.31925	3.897208	0.8630137	30.05613	3.452055	3.452055
46.88	1.319051	3.903906	0.8650243	30.0516	3.460097	3.460097
46.96	1.318892	3.910573	0.8665602	30.04798	3.466241	3.466241
47.04	1.318733	3.917208	0.868233	30.04436	3.472932	3.472932
47.12	1.318534	3.923896	0.8702238	30.03983	3.480895	3.480895
47.2	1.318375	3.930552	0.8720537	30.03621	3.488215	3.488215
47.28	1.318177	3.937219	0.8738101	30.03168	3.49524	3.49524
47.36	1.318057	3.943906	0.8755406	30.02897	3.502162	3.502162
47.44	1.317859	3.950552	0.877728	30.02444	3.510912	3.510912
47.52	1.31766	3.957219	0.8790473	30.01991	3.516189	3.516189
47.6	1.317581	3.963906	0.8809705	30.0181	3.523882	3.523882
47.68	1.317382	3.970562	0.8828859	30.01358	3.531543	3.531543
47.76	1.317263	3.977229	0.8846005	30.01086	3.538402	3.538402
47.84	1.317143	3.983896	0.88648	30.00814	3.54592	3.54592
47.92	1.316985	3.990542	0.8882622	30.00453	3.553049	3.553049
48	1.316786	3.997229	0.8900623	30	3.560249	3.560249
48.08	1.316667	4.003896	0.891916	29.99728	3.567664	3.567664
48.16	1.316468	4.010552	0.893565	29.99275	3.57426	3.57426
48.24	1.316269	4.01724	0.8954763	29.98823	3.581905	3.581905
48.32	1.31615	4.023885	0.8971711	29.98551	3.588684	3.588684
48.4	1.315991	4.030562	0.8993308	29.98189	3.597323	3.597323
48.48	1.315792	4.03725	0.9006162	29.97737	3.602465	3.602465
48.56	1.315594	4.043875	0.9028773	29.97284	3.611509	3.611509
48.64	1.315395	4.050552	0.9044905	29.96831	3.617962	3.617962
48.72	1.315196	4.05724	0.9060701	29.96379	3.62428	3.62428
48.8	1.314998	4.063875	0.9081125	29.95926	3.63245	3.63245
48.88	1.314799	4.070562	0.9099225	29.95473	3.63969	3.63969
48.96	1.31472	4.07724	0.9118259	29.95292	3.647304	3.647304
49.04	1.314521	4.083875	0.9136637	29.94839	3.654655	3.654655
49.12	1.314322	4.090573	0.9154737	29.94387	3.661895	3.661895
49.2	1.314203	4.097239	0.9169757	29.94115	3.667903	3.667903
49.28	1.314124	4.103885	0.9189963	29.93934	3.675985	3.675985
49.36	1.313925	4.110573	0.9205202	29.93482	3.682081	3.682081
49.44	1.313726	4.117208	0.9223878	29.93029	3.689551	3.689551
49.52	1.313647	4.123885	0.9243349	29.92848	3.69734	3.69734
49.6	1.313448	4.130573	0.9257913	29.92395	3.703165	3.703165
49.68	1.313249	4.137218	0.9278615	29.91943	3.711446	3.711446
49.76	1.313051	4.143885	0.9297649	29.9149	3.71906	3.71906
49.84	1.312931	4.150562	0.9314339	29.91218	3.725735	3.725735
49.92	1.312733	4.157229	0.9332518	29.90766	3.733007	3.733007
50	1.312534	4.163906	0.9349326	29.90313	3.739731	3.739731
50.08	1.312335	4.170562	0.9365936	29.8986	3.746374	3.746374
50.16	1.312256	4.177219	0.9384831	29.89679	3.753932	3.753932
50.24	1.311938	4.183906	0.9402911	29.88955	3.761164	3.761164
50.32	1.311859	4.190552	0.9420097	29.88774	3.768039	3.768039
50.4	1.31166	4.197219	0.9437919	29.88321	3.775167	3.775167
50.48	1.311461	4.203917	0.9453754	29.87868	3.781502	3.781502
50.56	1.311262	4.210542	0.9474714	29.87416	3.789886	3.789886
50.64	1.311103	4.217229	0.9494841	29.87054	3.797936	3.797936
50.72	1.310984	4.223917	0.950865	29.86782	3.80346	3.80346
50.8	1.310786	4.230552	0.952822	29.8633	3.811288	3.811288
50.88	1.310587	4.237229	0.9545684	29.85877	3.818274	3.818274
50.96	1.310388	4.243896	0.9563546	29.85424	3.825418	3.825418
51.04	1.31019	4.250542	0.9583791	29.84972	3.833516	3.833516
51.12	1.309991	4.257229	0.9598534	29.84519	3.839413	3.839413
51.2	1.309792	4.263896	0.9616196	29.84066	3.846478	3.846478
51.28	1.309594	4.270552	0.9634177	29.83614	3.853671	3.853671
51.36	1.309514	4.277239	0.9653489	29.83433	3.861396	3.861396
51.44	1.309315	4.283896	0.9670039	29.8298	3.868016	3.868016
51.52	1.309156	4.290552	0.9684563	29.82618	3.873825	3.873825
51.6	1.308998	4.297239	0.9706517	29.82256	3.882607	3.882607
51.68	1.308799	4.303875	0.9721379	29.81803	3.888551	3.888551
51.76	1.308719	4.310552	0.9740313	29.81622	3.896125	3.896125
51.84	1.3086	4.31724	0.9757836	29.8135	3.903135	3.903135
51.92	1.308401	4.323885	0.9777864	29.80898	3.911145	3.911145
52	1.308203	4.330573	0.9792785	29.80445	3.917114	3.917114
52.08	1.308123	4.337229	0.9810964	29.80264	3.924386	3.924386
52.16	1.308004	4.343896	0.9828866	29.79992	3.931546	3.931546
52.24	1.307805	4.350583	0.9848495	29.7954	3.939398	3.939398
52.32	1.307607	4.357219	0.9861529	29.79087	3.944612	3.944612
52.4	1.307527	4.363885	0.9881675	29.78906	3.95267	3.95267
52.48	1.307329	4.370573	0.9900491	29.78454	3.960196	3.960196
52.56	1.307209	4.377208	0.9914438	29.78182	3.965775	3.965775
52.64	1.30705	4.383885	0.9935538	29.7782	3.974215	3.974215
52.72	1.306891	4.390584	0.9952803	29.77458	3.981121	3.981121
52.8	1.306653	4.397208	0.9971182	29.76914	3.988473	3.988473
52.88	1.306534	4.403906	0.9986202	29.76643	3.994481	3.994481
52.96	1.306335	4.410583	1.000516	29.7619	4.002062	4.002062
53.04	1.306136	4.417208	1.002145	29.75738	4.008579	4.008579
53.12	1.305938	4.423906	1.003891	29.75285	4.015565	4.015565
53.2	1.305739	4.430552	1.005789	29.74832	4.023155	4.023155
53.28	1.30554	4.437208	1.007382	29.7438	4.029528	4.029528
53.36	1.305342	4.443906	1.009127	29.73927	4.036506	4.036506
53.44	1.305143	4.450552	1.010837	29.73474	4.043349	4.043349
53.52	1.305024	4.457219	1.012641	29.73203	4.050565	4.050565
53.6	1.304785	4.463906	1.01432	29.72659	4.05728	4.05728
53.68	1.304626	4.470562	1.016444	29.72297	4.065776	4.065776
53.76	1.304468	4.477219	1.017835	29.71935	4.071339	4.071339
53.84	1.304309	4.483906	1.019587	29.71573	4.078349	4.078349
53.92	1.30407	4.490552	1.0213	29.7103	4.085199	4.085199
54	1.303991	4.497229	1.023132	29.70849	4.092526	4.092526
54.08	1.303792	4.503885	1.024588	29.70396	4.098352	4.098352
54.16	1.303673	4.510552	1.026285	29.70125	4.105139	4.105139
54.24	1.303474	4.51725	1.028176	29.69672	4.112705	4.112705
54.32	1.303275	4.523885	1.030197	29.6922	4.120787	4.120787
54.4	1.303196	4.530562	1.031645	29.69038	4.126581	4.126581
54.48	1.302997	4.53725	1.033173	29.68586	4.132692	4.132692
54.56	1.302799	4.543875	1.035211	29.68133	4.140846	4.140846
54.64	1.3026	4.550552	1.036857	29.6768	4.147426	4.147426
54.72	1.30252	4.55724	1.038539	29.67499	4.154158	4.154158
54.8	1.302322	4.563875	1.040067	29.67047	4.160269	4.160269
54.88	1.302123	4.570562	1.041901	29.66594	4.167604	4.167604
54.96	1.301924	4.57724	1.043459	29.66141	4.173835	4.173835
55.04	1.301726	4.583875	1.045424	29.65689	4.181695	4.181695
55.12	1.301607	4.590573	1.04695	29.65417	4.187799	4.187799
55.2	1.301408	4.597239	1.048656	29.64964	4.194625	4.194625
55.28	1.301328	4.603885	1.050532	29.64783	4.202127	4.202127
55.36	1.30113	4.610573	1.052169	29.64331	4.208676	4.208676
55.44	1.300931	4.617208	1.054315	29.63878	4.217259	4.217259
55.52	1.300812	4.623885	1.055741	29.63606	4.222965	4.222965
55.6	1.300653	4.630573	1.057378	29.63244	4.229514	4.229514
55.68	1.300534	4.637218	1.059109	29.62973	4.236436	4.236436
55.76	1.300454	4.643896	1.060995	29.62792	4.243978	4.243978
55.84	1.300255	4.650562	1.06257	29.62339	4.25028	4.25028
55.92	1.300057	4.657229	1.064032	29.61886	4.256129	4.256129
56	1.299858	4.663906	1.065626	29.61434	4.262503	4.262503
56.08	1.299739	4.670562	1.067587	29.61162	4.270347	4.270347
56.16	1.29954	4.677219	1.069345	29.6071	4.27738	4.27738
56.24	1.299342	4.683906	1.071012	29.60257	4.284048	4.284048
56.32	1.299143	4.690552	1.072641	29.59804	4.290565	4.290565
56.4	1.298944	4.697219	1.073978	29.59351	4.295913	4.295913
56.48	1.298746	4.703917	1.075979	29.58899	4.303916	4.303916
56.56	1.298547	4.710542	1.077473	29.58446	4.309893	4.309893
56.64	1.298388	4.717229	1.079265	29.58084	4.317061	4.317061
56.72	1.298189	4.723917	1.080986	29.57631	4.323944	4.323944
56.8	1.29799	4.730542	1.082478	29.57179	4.329912	4.329912
56.88	1.297792	4.737229	1.084449	29.56726	4.337796	4.337796
56.96	1.297593	4.743896	1.085969	29.56274	4.343875	4.343875
57.04	1.297275	4.750542	1.087445	29.55549	4.34978	4.34978
57.12	1.297156	4.757229	1.089221	29.55278	4.356885	4.356885
57.2	1.296878	4.763896	1.090682	29.54644	4.362726	4.362726
57.28	1.296679	4.770552	1.092428	29.54191	4.369712	4.369712
57.36	1.296441	4.777239	1.093773	29.53648	4.375092	4.375092
57.44	1.296242	4.783896	1.095468	29.53196	4.381871	4.381871
57.52	1.296004	4.790552	1.096642	29.52652	4.386568	4.386568
57.6	1.295765	4.797239	1.098373	29.52109	4.39349	4.39349
57.68	1.295527	4.803885	1.099497	29.51566	4.397988	4.397988
57.76	1.295328	4.810563	1.18133	29.51113	4.725321	4.725321
57.84	0.006159147	4.816813	1.150336	0.1403223	4.601344	4.601344