File: Shimadzu/Grupo_A-CP26-D.txt
Nome do ensaio	Modo de ensaio	Tipo de ensaio	Título1	Comentário1	Palavra-chave	Nome do produto	Nome do arquivo do ensaio	Nome do arquivo do método	Data do relatório	Data do ensaio	Modo de ensaio	Tipo de ensaio	Velocidade	Placa	Lote No:	Sub-Lote No:
Extensometro SG25-50 - Placa - Sthil_20210601_1509.xtak	Simples	Tração	Grupo de Mecânica Aplicada - GMAp
UFRGS	Comentário	 	 	Extensometro SG25-50 - Placa - Sthil_20210601_1509.xtak	Extensometro SG25-50 - Placa - Sthil.xmak	01/06/2021	01/06/2021	Simples	Tração	5mm/min	Placa	1	1

Placa:	Lote No:	Sub-Lote No:
Placa	1	1
Nome	Espessura	Largura	Gauge Length
Unidade:	mm	mm	mm
Ga_D_26	3.3467	13.0327	115.0000

Nome	Elástico	Inclinação_Padrão	Ruptura_Força	Máx_Força	Max_Disp_Força	Max_Disp_SG-25-50 %	Max_Disp_Deslocamento	Espessura	Largura	Gauge_Length	Máx_Tensão	YS1_Tensão
Parâmetro	Tensão 40 - 60 N/mm2	Tensão 40 - 60 N/mm2	Sensibilidade: 10	Cálculo de áreas completas							Cálculo de áreas completas	0.2 %
Unidade	N/mm2	N/mm	kN	kN	kN	%	mm	mm	mm	mm	N/mm2	N/mm2
Ga_D_26	-.-	-.-	1.31114	1.34822	1.31114	4.25417	4.49976	3.3467	13.0327	115.0000	30.9107	-.-

Ga_D_26
Tempo	Força	Deslocamento	Desloc. SG25-50	Tensão	SG-25-50 %	Deformação
seg	kN	mm	mm	N/mm2	%	%
0	0.01267592	0	0	0.2906219	0	0
0.07	0.01259645	0.003197917	0.0003834566	0.2887999	0.001533826	0.001533826
0.14	0.01259645	0.008958333	0.001841784	0.2887999	0.007367134	0.007367134
0.21	0.01259645	0.01472917	0.003004074	0.2887999	0.0120163	0.0120163
0.28	0.01259645	0.02059375	0.004216035	0.2887999	0.01686414	0.01686414
0.35	0.02773603	0.02640625	0.005173683	0.6359063	0.02069473	0.02069473
0.42	0.03274282	0.03223958	0.006745259	0.7506973	0.02698104	0.02698104
0.49	0.0367562	0.03807292	0.007148584	0.8427125	0.02859434	0.02859434
0.56	0.04009406	0.04390625	0.008793672	0.9192399	0.03517469	0.03517469
0.63	0.0431935	0.04975	0.009862582	0.990301	0.03945033	0.03945033
0.7	0.04971027	0.05555208	0.01160304	1.139712	0.04641215	0.04641215
0.77	0.05320708	0.06141667	0.01256665	1.219883	0.05026658	0.05026658
0.84	0.05869071	0.06722917	0.01385013	1.345607	0.05540053	0.05540053
0.91	0.06318092	0.07308333	0.01525879	1.448554	0.06103516	0.06103516
0.98	0.06628036	0.07889583	0.01636545	1.519616	0.06546179	0.06546179
1.05	0.06874403	0.08473958	0.0175337	1.5761	0.0701348	0.0701348
1.12	0.07589658	0.09058333	0.01908143	1.740087	0.07632574	0.07632574
1.19	0.07764498	0.09639584	0.0202775	1.780173	0.08111	0.08111
1.26	0.08428097	0.10225	0.02140005	1.932317	0.08560022	0.08560022
1.33	0.0843207	0.1080625	0.02247492	1.933228	0.0898997	0.0898997
1.4	0.09083748	0.1139271	0.02390345	2.082639	0.0956138	0.0956138
1.47	0.09687742	0.1197292	0.0251174	2.221117	0.1004696	0.1004696
1.54	0.0996987	0.1255729	0.02636909	2.285801	0.1054764	0.1054764
1.61	0.1047055	0.1314062	0.02767046	2.400592	0.1106819	0.1106819
1.68	0.1103083	0.1372292	0.02903541	2.529048	0.1161416	0.1161416
1.75	0.1138449	0.1430729	0.02998114	2.610131	0.1199245	0.1199245
1.82	0.1172225	0.1489062	0.0309507	2.687569	0.1238028	0.1238028
1.89	0.1193682	0.1547604	0.03243685	2.736766	0.1297474	0.1297474
1.96	0.12513	0.1605521	0.03373821	2.868866	0.1349529	0.1349529
2.03	0.130256	0.1664167	0.0351429	2.986391	0.1405716	0.1405716
2.1	0.1325607	0.1722188	0.03624757	3.039231	0.1449903	0.1449903
2.17	0.1377662	0.1780729	0.03758867	3.158577	0.1503547	0.1503547
2.24	0.1399914	0.1839062	0.03868739	3.209596	0.1547496	0.1547496
2.31	0.1470248	0.1897292	0.03992915	3.37085	0.1597166	0.1597166
2.38	0.1501242	0.1955937	0.04126032	3.441911	0.1650413	0.1650413
2.45	0.1552502	0.2013958	0.04269679	3.559435	0.1707872	0.1707872
2.52	0.1582305	0.20725	0.0436465	3.627763	0.174586	0.174586
2.59	0.1622836	0.2130729	0.04478097	3.72069	0.1791239	0.1791239
2.66	0.1650254	0.2189167	0.04613598	3.783551	0.1845439	0.1845439
2.73	0.1705885	0.2247292	0.04729827	3.911097	0.1891931	0.1891931
2.8	0.174125	0.2305729	0.04832149	3.992179	0.1932859	0.1932859
2.87	0.1774629	0.2364063	0.04964272	4.068707	0.1985709	0.1985709
2.94	0.1828671	0.2422187	0.05108913	4.192608	0.2043565	0.2043565
3.01	0.1864433	0.2480833	0.05237858	4.274602	0.2095143	0.2095143
3.08	0.191013	0.2538958	0.0532647	4.379372	0.2130588	0.2130588
3.15	0.1941919	0.2597604	0.05467137	4.452255	0.2186855	0.2186855
3.22	0.1996358	0.2655521	0.05599856	4.577067	0.2239943	0.2239943
3.29	0.2051989	0.2714167	0.0571986	4.704613	0.2287944	0.2287944
3.36	0.207146	0.27725	0.05794168	4.749254	0.2317667	0.2317667
3.43	0.2111991	0.2830625	0.05948544	4.84218	0.2379417	0.2379417
3.5	0.2171199	0.2889167	0.06076892	4.977925	0.2430757	0.2430757
3.57	0.2191067	0.2947292	0.06178021	5.023477	0.2471209	0.2471209
3.64	0.2231598	0.3005833	0.06310145	5.116404	0.2524058	0.2524058
3.71	0.2285242	0.3063854	0.06417235	5.239394	0.2566894	0.2566894
3.78	0.2302726	0.3122396	0.06536046	5.27948	0.2614419	0.2614419
3.85	0.2336502	0.3180625	0.06646713	5.356918	0.2658685	0.2658685
3.92	0.2395709	0.3239062	0.06789764	5.492663	0.2715906	0.2715906
3.99	0.2437035	0.3297292	0.06904006	5.587411	0.2761602	0.2761602
4.06	0.2453725	0.3355729	0.07019838	5.625675	0.2807935	0.2807935
4.13	0.2501011	0.3414271	0.07148584	5.734089	0.2859434	0.2859434
4.2	0.256141	0.3472188	0.07257462	5.872567	0.2902985	0.2902985
4.27	0.2611478	0.3530833	0.07354617	5.987358	0.2941847	0.2941847
4.34	0.2637704	0.3588854	0.07476807	6.047487	0.2990723	0.2990723
4.41	0.2665122	0.36475	0.07623235	6.110349	0.3049294	0.3049294
4.48	0.2714396	0.3705521	0.07708073	6.223318	0.3083229	0.3083229
4.55	0.2755722	0.3764063	0.07834832	6.318066	0.3133933	0.3133933
4.62	0.2781153	0.38225	0.07969538	6.376373	0.3187815	0.3187815
4.69	0.28344	0.3880625	0.08050203	6.498452	0.3220081	0.3220081
4.76	0.2865791	0.3939167	0.08145174	6.570424	0.3258069	0.3258069
4.83	0.2894402	0.3997396	0.0825882	6.636019	0.3303528	0.3303528
4.9	0.2930164	0.4055938	0.08391539	6.718012	0.3356616	0.3356616
4.97	0.2991756	0.4113854	0.08515915	6.859224	0.3406366	0.3406366
5.04	0.2997319	0.4172396	0.08615255	6.871978	0.3446102	0.3446102
5.11	0.3049374	0.4230625	0.08736452	6.991325	0.3494581	0.3494581
5.18	0.311176	0.4288958	0.0882864	7.134358	0.3531456	0.3531456
5.25	0.3135602	0.4347396	0.08961558	7.189021	0.3584623	0.3584623
5.32	0.3178517	0.4405625	0.09066065	7.287413	0.3626426	0.3626426
5.39	0.3180504	0.4464271	0.09175738	7.291968	0.3670295	0.3670295
5.46	0.3216267	0.4522187	0.09298921	7.373961	0.3719568	0.3719568
5.53	0.3255606	0.4580833	0.09430051	7.464155	0.377202	0.377202
5.6	0.3292163	0.4639063	0.09508133	7.547971	0.3803253	0.3803253
5.67	0.3341039	0.4697396	0.09625554	7.660028	0.3850222	0.3850222
5.74	0.3386736	0.4755625	0.09724299	7.764798	0.388972	0.388972
5.81	0.3412565	0.4813958	0.09856025	7.824016	0.394241	0.394241
5.88	0.3456672	0.48725	0.09917021	7.925142	0.3966808	0.3966808
5.95	0.3488461	0.4930521	0.1006663	7.998024	0.4026651	0.4026651
6.02	0.3545284	0.4989167	0.1017094	8.128304	0.4068375	0.4068375
6.09	0.3549655	0.5047292	0.1027028	8.138325	0.4108111	0.4108111
6.16	0.3596544	0.5105833	0.1040856	8.245828	0.4163424	0.4163424
6.23	0.3626347	0.5163854	0.1049678	8.314156	0.419871	0.419871
6.3	0.3670057	0.5222396	0.1060764	8.41437	0.4243056	0.4243056
6.37	0.3701051	0.5280833	0.1070837	8.485432	0.4283349	0.4283349
6.44	0.3736814	0.5338959	0.10794	8.567426	0.4317602	0.4317602
6.51	0.3751914	0.53975	0.1092116	8.602044	0.4368464	0.4368464
6.58	0.38143	0.5455625	0.110201	8.745078	0.4408042	0.4408042
6.65	0.383695	0.5514166	0.1111786	8.797008	0.4447142	0.4447142
6.72	0.3875494	0.5572187	0.1124243	8.885378	0.4496972	0.4496972
6.79	0.3898144	0.5630729	0.1132627	8.937307	0.4530509	0.4530509
6.86	0.3933907	0.5689062	0.1142621	9.019301	0.4570484	0.4570484
6.93	0.3978809	0.5747291	0.1156151	9.122249	0.4624605	0.4624605
7	0.3992319	0.5805833	0.1161138	9.153224	0.4644553	0.4644553
7.07	0.4053911	0.5864062	0.1173278	9.294436	0.4693111	0.4693111
7.14	0.4074574	0.5922604	0.1183867	9.341809	0.473547	0.473547
7.21	0.4101594	0.5980521	0.1197656	9.403761	0.4790624	0.4790624
7.28	0.414451	0.6039166	0.1204987	9.502152	0.481995	0.481995
7.35	0.4187028	0.6097187	0.1213849	9.599633	0.4855394	0.4855394
7.42	0.4223585	0.6155625	0.1226584	9.68345	0.4906336	0.4906336
7.49	0.4241864	0.6213958	0.123481	9.725357	0.4939238	0.4939238
7.56	0.4257759	0.6272292	0.1241068	9.761799	0.4964272	0.4964272
7.63	0.4303853	0.6330937	0.125432	9.867479	0.5017281	0.5017281
7.7	0.4340013	0.6388854	0.1263599	9.950384	0.5054395	0.5054395
7.77	0.4394849	0.64475	0.1274387	10.07611	0.5097548	0.5097548
7.84	0.4422665	0.6505729	0.128597	10.13988	0.5143881	0.5143881
7.91	0.443538	0.6564167	0.1298487	10.16903	0.5193949	0.5193949
7.98	0.4481872	0.6622292	0.1306415	10.27563	0.5225658	0.5225658
8.05	0.4525979	0.6680729	0.1316349	10.37675	0.5265395	0.5265395
8.12	0.4562537	0.6739063	0.1325448	10.46057	0.5301793	0.5301793
8.19	0.4578432	0.6797292	0.1335442	10.49701	0.5341768	0.5341768
8.26	0.4601081	0.6855834	0.1346151	10.54894	0.5384604	0.5384604
8.33	0.464042	0.6913958	0.1358251	10.63913	0.5433003	0.5433003
8.4	0.4674594	0.6972604	0.1369298	10.71748	0.547719	0.547719
8.47	0.4715522	0.7030521	0.1379232	10.81132	0.5516927	0.5516927
8.54	0.4743735	0.7089167	0.138845	10.876	0.5553802	0.5553802
8.61	0.4789432	0.71475	0.1398385	10.98077	0.5593538	0.5593538
8.68	0.4820824	0.7205625	0.1408378	11.05274	0.5633513	0.5633513
8.75	0.4848639	0.7264166	0.1419504	11.11652	0.5678018	0.5678018
8.82	0.4885197	0.7322292	0.1430432	11.20033	0.5721728	0.5721728
8.89	0.4909833	0.7380833	0.14382	11.25682	0.5752802	0.5752802
8.96	0.4930893	0.7438854	0.1449307	11.3051	0.5797227	0.5797227
9.03	0.4971027	0.74975	0.1458724	11.39712	0.5834897	0.5834897
9.1	0.4998446	0.7555625	0.1469394	11.45998	0.5877574	0.5877574
9.17	0.5062819	0.7614062	0.1477261	11.60757	0.5909045	0.5909045
9.24	0.5062024	0.7672291	0.148948	11.60575	0.5957921	0.5957921
9.31	0.5118847	0.7730729	0.1498838	11.73602	0.5995353	0.5995353
9.38	0.5141497	0.7789271	0.150754	11.78795	0.6030162	0.6030162
9.45	0.5163749	0.7847292	0.1518746	11.83897	0.6074985	0.6074985
9.52	0.5185604	0.7905833	0.1528879	11.88908	0.6115516	0.6115516
9.59	0.5212625	0.7963854	0.15377	11.95103	0.6150802	0.6150802
9.66	0.5254745	0.8022396	0.1548648	12.0476	0.6194592	0.6194592
9.73	0.5301635	0.8080521	0.1560589	12.1551	0.6242355	0.6242355
9.8	0.5333424	0.8138958	0.1566311	12.22799	0.6265243	0.6265243
9.87	0.5361239	0.81975	0.1576841	12.29176	0.6307364	0.6307364
9.94	0.5393823	0.8255625	0.158753	12.36646	0.635012	0.635012
10.01	0.5445878	0.8314167	0.1596451	12.48581	0.6385803	0.6385803
10.08	0.5453427	0.8372396	0.1605292	12.50312	0.6421168	0.6421168
10.15	0.5483627	0.8430938	0.1617173	12.57236	0.6468694	0.6468694
10.22	0.5512635	0.8488854	0.1625041	12.63887	0.6500165	0.6500165
10.29	0.5530517	0.8547395	0.1635055	12.67986	0.6540219	0.6540219
10.36	0.555714	0.8605625	0.1645784	12.7409	0.6583135	0.6583135
10.43	0.5604426	0.8663958	0.1653949	12.84932	0.6615798	0.6615798
10.5	0.5627473	0.8722396	0.1662095	12.90215	0.6648381	0.6648381
10.57	0.5673965	0.8780625	0.1676341	13.00875	0.6705363	0.6705363
10.64	0.5693833	0.883927	0.1683275	13.0543	0.67331	0.67331
10.71	0.5724828	0.8897187	0.1691818	13.12536	0.6767273	0.6767273
10.78	0.5768538	0.8955938	0.1701891	13.22558	0.6807566	0.6807566
10.85	0.5790393	0.9014062	0.1712441	13.27568	0.6849766	0.6849766
10.92	0.5817811	0.9072396	0.1722018	13.33854	0.6888072	0.6888072
10.99	0.5854766	0.9130729	0.1732429	13.42327	0.6929715	0.6929715
11.06	0.5875031	0.9188958	0.17398	13.46973	0.69592	0.69592
11.13	0.5902449	0.92475	0.1751145	13.5326	0.7004579	0.7004579
11.2	0.5955696	0.9305521	0.1759529	13.65468	0.7038116	0.7038116
11.27	0.5977948	0.9364167	0.1767735	13.70569	0.7070939	0.7070939
11.34	0.5992253	0.9422292	0.1780013	13.73849	0.7120053	0.7120053
11.41	0.6042719	0.9480833	0.1792272	13.85419	0.7169088	0.7169088
11.48	0.6058216	0.9538958	0.1800954	13.88972	0.7203817	0.7203817
11.55	0.6087224	0.9597396	0.1811663	13.95623	0.7246653	0.7246653
11.62	0.6132523	0.9655833	0.1817922	14.06009	0.7271687	0.7271687
11.69	0.6159544	0.9713959	0.1828015	14.12204	0.7312059	0.7312059
11.76	0.6198089	0.97725	0.1838346	14.21041	0.7353385	0.7353385
11.83	0.6232659	0.9830521	0.1846532	14.28967	0.7386128	0.7386128
11.9	0.6239017	0.9889166	0.1858274	14.30425	0.7433097	0.7433097
11.97	0.6291469	0.9947187	0.1869162	14.4245	0.7476647	0.7476647
12.04	0.6298224	1.000573	0.1877189	14.43999	0.7508755	0.7508755
12.11	0.634551	1.006406	0.1889427	14.54841	0.755771	0.755771
12.18	0.6382068	1.012229	0.1898706	14.63222	0.7594824	0.7594824
12.25	0.6423394	1.018073	0.1907627	14.72697	0.7630507	0.7630507
12.32	0.6417831	1.023906	0.1915614	14.71422	0.7662455	0.7662455
12.39	0.6478627	1.02976	0.1929263	14.8536	0.7717053	0.7717053
12.46	0.6503661	1.035552	0.1936297	14.911	0.7745187	0.7745187
12.53	0.6531477	1.041417	0.1948814	14.97477	0.7795255	0.7795255
12.6	0.6548166	1.047229	0.1959344	15.01304	0.7837375	0.7837375
12.67	0.659426	1.053062	0.1963516	15.11872	0.7854064	0.7854064
12.74	0.6620486	1.058896	0.1975934	15.17885	0.7903735	0.7903735
12.81	0.6646315	1.064729	0.1988391	15.23806	0.7953565	0.7953565
12.88	0.6676515	1.070594	0.1994212	15.3073	0.797685	0.797685
12.95	0.6731351	1.076385	0.2004981	15.43303	0.8019924	0.8019924
13.02	0.6740888	1.08225	0.2016068	15.45489	0.806427	0.806427
13.09	0.6784995	1.088073	0.2026538	15.55602	0.8106152	0.8106152
13.16	0.6789764	1.093917	0.2037088	15.56695	0.8148353	0.8148353
13.23	0.6846189	1.099729	0.2047618	15.69632	0.8190473	0.8190473
13.3	0.6862481	1.105562	0.2056519	15.73367	0.8226077	0.8226077
13.37	0.6896257	1.111406	0.2068381	15.81111	0.8273522	0.8273522
13.44	0.6939967	1.117229	0.2078831	15.91132	0.8315325	0.8315325
13.51	0.6951094	1.123083	0.2087017	15.93683	0.8348067	0.8348067
13.58	0.6976525	1.128896	0.209703	15.99514	0.8388122	0.8388122
13.65	0.7002751	1.13476	0.2107799	16.05527	0.8431196	0.8431196
13.72	0.7048845	1.140552	0.2118766	16.16095	0.8475065	0.8475065
13.79	0.7088979	1.146417	0.2128184	16.25296	0.8512735	0.8512735
13.86	0.7094939	1.15225	0.2137542	16.26663	0.8550167	0.8550167
13.93	0.7136266	1.158062	0.2147277	16.36138	0.8589109	0.8589109
14	0.7185538	1.163906	0.2156218	16.47435	0.8624871	0.8624871
14.07	0.7187526	1.169729	0.2169967	16.4789	0.8679867	0.8679867
14.14	0.7218122	1.175583	0.2176563	16.54905	0.8706252	0.8706252
14.21	0.7261038	1.181385	0.2188186	16.64744	0.8752744	0.8752744
14.28	0.7282495	1.18725	0.219816	16.69664	0.8792639	0.8792639
14.35	0.7324219	1.193063	0.2206067	16.7923	0.8824269	0.8824269
14.42	0.7354419	1.198906	0.2217333	16.86154	0.886933	0.886933
14.49	0.7367532	1.20474	0.2227028	16.8916	0.8908113	0.8908113
14.56	0.7410049	1.210573	0.2237896	16.98908	0.8951585	0.8951585
14.63	0.7447402	1.216427	0.2250056	17.07472	0.9000222	0.9000222
14.7	0.7459323	1.222229	0.2254764	17.10205	0.9019057	0.9019057
14.77	0.7527272	1.228094	0.2266228	17.25784	0.9064913	0.9064913
14.84	0.7528464	1.233885	0.2277931	17.26057	0.9111722	0.9111722
14.91	0.7543961	1.23975	0.2290567	17.2961	0.9162267	0.9162267
14.98	0.7602771	1.245562	0.229617	17.43094	0.9184678	0.9184678
15.05	0.7648468	1.251396	0.2306044	17.53571	0.9224176	0.9224176
15.12	0.7673502	1.25725	0.2318998	17.5931	0.9275993	0.9275993
15.19	0.7689397	1.263062	0.232627	17.62955	0.930508	0.930508
15.26	0.7693768	1.268917	0.2338072	17.63957	0.9352286	0.9352286
15.33	0.7759333	1.27474	0.2346615	17.78989	0.938646	0.938646
15.4	0.7751386	1.280594	0.2359867	17.77167	0.9439468	0.9439468
15.47	0.7805824	1.286385	0.2368768	17.89648	0.9475072	0.9475072
15.54	0.7817745	1.29224	0.2377927	17.92381	0.9511709	0.9511709
15.61	0.7870595	1.298062	0.2390305	18.04498	0.9561221	0.9561221
15.68	0.7879734	1.303896	0.2401173	18.06593	0.9604692	0.9604692
15.75	0.792106	1.30974	0.240761	18.16068	0.9630442	0.9630442
15.82	0.794967	1.315562	0.2420227	18.22627	0.9680907	0.9680907
15.89	0.798742	1.321427	0.2429307	18.31282	0.9717226	0.9717226
15.96	0.8007686	1.327219	0.2440274	18.35929	0.9761095	0.9761095
16.03	0.8037885	1.333094	0.2448579	18.42853	0.9794315	0.9794315
16.1	0.8072456	1.338906	0.2462824	18.50779	0.9851297	0.9851297
16.17	0.8102258	1.34474	0.2469261	18.57611	0.9877046	0.9877046
16.24	0.8128087	1.350573	0.2479573	18.63533	0.9918292	0.9918292
16.31	0.8153915	1.356396	0.2489487	18.69455	0.995795	0.995795
16.38	0.818491	1.36225	0.2501825	18.76561	1.00073	1.00073
16.45	0.8203586	1.368052	0.2509713	18.80843	1.003885	1.003885
16.52	0.8238156	1.373917	0.2520919	18.88769	1.008368	1.008368
16.59	0.8282661	1.379729	0.2530118	18.98973	1.012047	1.012047
16.66	0.8311669	1.385583	0.2542257	19.05623	1.016903	1.016903
16.73	0.8324782	1.391396	0.2549628	19.0863	1.019851	1.019851
16.8	0.8369287	1.39724	0.2561589	19.18834	1.024636	1.024636
16.87	0.839591	1.403083	0.2571424	19.24937	1.02857	1.02857
16.94	0.8412997	1.408896	0.2584259	19.28855	1.033703	1.033703
17.01	0.8457899	1.41475	0.2593497	19.3915	1.037399	1.037399
17.08	0.8481741	1.420563	0.2601644	19.44616	1.040657	1.040657
17.15	0.8517504	1.426417	0.2613226	19.52815	1.045291	1.045291
17.22	0.8562406	1.432219	0.2623042	19.6311	1.049217	1.049217
17.29	0.8574327	1.438073	0.2634525	19.65843	1.05381	1.05381
17.36	0.8612077	1.443906	0.2643883	19.74498	1.057553	1.057553
17.43	0.8616447	1.44974	0.2654572	19.755	1.061829	1.061829
17.5	0.8676052	1.455573	0.266399	19.89166	1.065596	1.065596
17.57	0.868082	1.461406	0.2673586	19.90259	1.069435	1.069435
17.64	0.8737246	1.46726	0.2686898	20.03196	1.074759	1.074759
17.71	0.8720954	1.473063	0.2697011	19.99461	1.078804	1.078804
17.78	0.8781751	1.478917	0.2705792	20.134	1.082317	1.082317
17.85	0.8800427	1.484729	0.2716044	20.17682	1.086418	1.086418
17.92	0.8826653	1.490573	0.2727648	20.23694	1.091059	1.091059
17.99	0.8862019	1.496396	0.2735615	20.31803	1.094246	1.094246
18.06	0.8904139	1.502229	0.2748013	20.4146	1.099205	1.099205
18.13	0.8937915	1.508094	0.2757212	20.49203	1.102885	1.102885
18.2	0.8939902	1.513896	0.2770205	20.49659	1.108082	1.108082
18.27	0.8987188	1.51976	0.2777199	20.605	1.11088	1.11088
18.34	0.8985996	1.525573	0.2788365	20.60227	1.115346	1.115346
18.41	0.9034078	1.531417	0.2800842	20.71251	1.120337	1.120337
18.48	0.9053946	1.537229	0.2812644	20.75806	1.125058	1.125058
18.55	0.9106795	1.543073	0.2822995	20.87923	1.129198	1.129198
18.62	0.913461	1.548906	0.2830068	20.943	1.132027	1.132027
18.69	0.9148915	1.554729	0.2842466	20.9758	1.136986	1.136986
18.76	0.9162824	1.560583	0.2850811	21.00768	1.140324	1.140324
18.83	0.9224017	1.566396	0.2863268	21.14798	1.145307	1.145307
18.9	0.9240707	1.57226	0.2874533	21.18624	1.149813	1.149813
18.97	0.9254615	1.578052	0.2882739	21.21813	1.153096	1.153096
19.04	0.9307464	1.583917	0.2893488	21.3393	1.157395	1.157395
19.11	0.9341637	1.58975	0.290511	21.41765	1.162044	1.162044
19.18	0.9352763	1.595562	0.2916574	21.44316	1.16663	1.16663
19.25	0.9388129	1.601417	0.2927542	21.52424	1.171017	1.171017
19.32	0.9425879	1.607229	0.2934694	21.61079	1.173878	1.173878
19.39	0.9442965	1.613094	0.2946675	21.64997	1.17867	1.17867
19.46	0.9459257	1.618885	0.2956132	21.68732	1.182453	1.182453
19.53	0.9497007	1.62475	0.296998	21.77387	1.187992	1.187992
19.6	0.952522	1.630573	0.297598	21.83855	1.190392	1.190392
19.67	0.9558598	1.636406	0.2985438	21.91508	1.194175	1.194175
19.74	0.9583235	1.642229	0.29972	21.97156	1.19888	1.19888
19.81	0.962615	1.648073	0.3013432	22.06996	1.205373	1.205373
19.88	0.9641647	1.653927	0.3020883	22.10549	1.208353	1.208353
19.95	0.9686152	1.659719	0.3032446	22.20752	1.212978	1.212978
20.02	0.9686152	1.665583	0.30424	22.20752	1.21696	1.21696
20.09	0.9717544	1.671396	0.3056169	22.2795	1.222467	1.222467
20.16	0.9772778	1.67724	0.3061831	22.40613	1.224732	1.224732
20.23	0.9794235	1.683062	0.3074765	22.45533	1.229906	1.229906
20.3	0.9821256	1.688906	0.308611	22.51728	1.234444	1.234444
20.37	0.9844303	1.69475	0.3096998	22.57012	1.238799	1.238799
20.44	0.9870529	1.700562	0.3105958	22.63025	1.242383	1.242383
20.51	0.9881656	1.706417	0.311774	22.65576	1.247096	1.247096
20.58	0.9924968	1.71224	0.3127337	22.75506	1.250935	1.250935
20.65	0.9945631	1.718094	0.3137271	22.80243	1.254908	1.254908
20.72	0.9957154	1.723896	0.3148913	22.82885	1.259565	1.259565
20.79	1.001318	1.72974	0.3159285	22.95731	1.263714	1.263714
20.86	1.002828	1.735562	0.317347	22.99193	1.269388	1.269388
20.93	1.00557	1.741396	0.3182153	23.05479	1.272861	1.272861
21	1.0101	1.74725	0.3189067	23.15865	1.275627	1.275627
21.07	1.009425	1.753073	0.3201922	23.14316	1.280769	1.280769
21.14	1.015464	1.758927	0.3213922	23.28164	1.285569	1.285569
21.21	1.016657	1.764719	0.322336	23.30897	1.289344	1.289344
21.28	1.020511	1.770583	0.3235539	23.39734	1.294216	1.294216
21.35	1.021544	1.776417	0.3245672	23.42103	1.298269	1.298269
21.42	1.024644	1.78224	0.3257612	23.49209	1.303045	1.303045
21.49	1.024803	1.788083	0.3266295	23.49574	1.306518	1.306518
21.56	1.031041	1.793896	0.3278911	23.63877	1.311564	1.311564
21.63	1.033107	1.79975	0.3290435	23.68614	1.316174	1.316174
21.7	1.034935	1.805552	0.3297865	23.72805	1.319146	1.319146
21.77	1.038631	1.811417	0.3311912	23.81278	1.324765	1.324765
21.84	1.040141	1.817229	0.3322184	23.84739	1.328874	1.328874
21.91	1.044551	1.823083	0.3335675	23.94852	1.33427	1.33427
21.98	1.045863	1.828885	0.3342807	23.97859	1.337123	1.337123
22.05	1.048803	1.83474	0.3351728	24.046	1.340691	1.340691
22.12	1.052976	1.840594	0.3366371	24.14166	1.346548	1.346548
22.19	1.053492	1.846396	0.3376484	24.15351	1.350594	1.350594
22.26	1.058896	1.85226	0.3387173	24.27741	1.354869	1.354869
22.33	1.060168	1.858052	0.3398776	24.30656	1.35951	1.35951
22.4	1.063744	1.863927	0.3409088	24.38855	1.363635	1.363635
22.47	1.065691	1.869729	0.3416637	24.4332	1.366655	1.366655
22.54	1.067638	1.875573	0.3430565	24.47784	1.372226	1.372226
22.61	1.070221	1.881417	0.3441771	24.53705	1.376708	1.376708
22.68	1.073639	1.887229	0.3450195	24.6154	1.380078	1.380078
22.75	1.075347	1.893083	0.3462692	24.65458	1.385077	1.385077
22.82	1.07801	1.898906	0.3473938	24.71562	1.389575	1.389575
22.89	1.080275	1.904771	0.348566	24.76755	1.394264	1.394264
22.96	1.085003	1.910552	0.3493726	24.87596	1.397491	1.397491
23.03	1.087348	1.916417	0.3506064	24.92971	1.402426	1.402426
23.1	1.088699	1.922229	0.3517826	24.96069	1.407131	1.407131
23.17	1.089652	1.928062	0.352482	24.98255	1.409928	1.409928
23.24	1.093189	1.933896	0.3539701	25.06363	1.415881	1.415881
23.31	1.096368	1.939729	0.3549258	25.13652	1.419703	1.419703
23.38	1.098752	1.945594	0.355792	25.19118	1.423168	1.423168
23.45	1.101613	1.951385	0.3572285	25.25677	1.428914	1.428914
23.52	1.104474	1.95724	0.3583829	25.32237	1.433531	1.433531
23.59	1.105309	1.963063	0.3594061	25.3415	1.437624	1.437624
23.66	1.108209	1.968906	0.3602525	25.40801	1.44101	1.44101
23.73	1.111507	1.974708	0.361528	25.48363	1.446112	1.446112
23.8	1.114806	1.980552	0.3623883	25.55924	1.449553	1.449553
23.87	1.116872	1.986396	0.3638466	25.60662	1.455387	1.455387
23.94	1.120051	1.992219	0.3647009	25.6795	1.458804	1.458804
24.01	1.121759	1.998073	0.3658473	25.71867	1.463389	1.463389
24.08	1.124303	2.003886	0.3669043	25.77698	1.467617	1.467617
24.15	1.125336	2.00975	0.368019	25.80067	1.472076	1.472076
24.22	1.130462	2.015552	0.3689766	25.91819	1.475906	1.475906
24.29	1.13229	2.021406	0.3701905	25.9601	1.480762	1.480762
24.36	1.131177	2.02724	0.3714859	25.93459	1.485944	1.485944
24.43	1.136541	2.033062	0.3726244	26.05758	1.490498	1.490498
24.5	1.139084	2.038906	0.3735145	26.11589	1.494058	1.494058
24.57	1.142144	2.044719	0.374792	26.18604	1.499168	1.499168
24.64	1.14282	2.050583	0.3756205	26.20153	1.502482	1.502482
24.71	1.145363	2.056375	0.3766159	26.25983	1.506464	1.506464
24.78	1.14886	2.06224	0.3780445	26.34	1.512178	1.512178
24.85	1.15184	2.068063	0.3792922	26.40833	1.517169	1.517169
24.92	1.156489	2.073896	0.3802021	26.51492	1.520809	1.520809
24.99	1.155972	2.079729	0.3813048	26.50308	1.525219	1.525219
25.06	1.158317	2.085562	0.3826857	26.55683	1.530743	1.530743
25.13	1.16094	2.091427	0.3835599	26.61696	1.534239	1.534239
25.2	1.161416	2.097219	0.3849685	26.62789	1.539874	1.539874
25.27	1.164277	2.103073	0.3859778	26.69349	1.543911	1.543911
25.34	1.167456	2.108875	0.3870448	26.76637	1.548179	1.548179
25.41	1.169602	2.11474	0.3881296	26.81557	1.552518	1.552518
25.48	1.171748	2.120552	0.3896594	26.86476	1.558638	1.558638
25.55	1.173655	2.126396	0.3901998	26.90849	1.560799	1.560799
25.62	1.175165	2.13225	0.3915608	26.94311	1.566243	1.566243
25.69	1.177033	2.138052	0.3931383	26.98593	1.572553	1.572553
25.76	1.181046	2.143917	0.3941357	27.07795	1.576543	1.576543
25.83	1.183271	2.149729	0.3950755	27.12897	1.580302	1.580302
25.9	1.184861	2.155583	0.3963252	27.16541	1.585301	1.585301
25.97	1.185814	2.161385	0.3971875	27.18727	1.58875	1.58875
26.04	1.189907	2.167229	0.3986796	27.28111	1.594718	1.594718
26.11	1.190782	2.173063	0.3997048	27.30115	1.598819	1.598819
26.18	1.19257	2.178885	0.4008552	27.34215	1.603421	1.603421
26.25	1.19559	2.18474	0.4020651	27.41139	1.608261	1.608261
26.32	1.197974	2.190552	0.4032493	27.46605	1.612997	1.612997
26.39	1.19857	2.196417	0.4045447	27.47971	1.618179	1.618179
26.46	1.202305	2.202208	0.4051983	27.56535	1.620793	1.620793
26.53	1.204411	2.208073	0.4066487	27.61364	1.626595	1.626595
26.6	1.208186	2.213906	0.4076878	27.70019	1.630751	1.630751
26.67	1.209339	2.219729	0.4085541	27.72661	1.634216	1.634216
26.74	1.209855	2.225563	0.4099786	27.73845	1.639915	1.639915
26.81	1.212716	2.231396	0.4113635	27.80404	1.645454	1.645454
26.88	1.215537	2.23725	0.4126032	27.86873	1.650413	1.650413
26.95	1.217842	2.243052	0.4133324	27.92157	1.653329	1.653329
27.02	1.218557	2.248917	0.4149596	27.93797	1.659838	1.659838
27.09	1.222968	2.254729	0.4159888	28.03909	1.663955	1.663955
27.16	1.224438	2.260573	0.4169186	28.0728	1.667674	1.667674
27.23	1.225789	2.266385	0.4181584	28.10378	1.672634	1.672634
27.3	1.226107	2.272239	0.4193167	28.11106	1.677267	1.677267
27.37	1.229525	2.278083	0.4206041	28.18941	1.682417	1.682417
27.44	1.232823	2.283885	0.421683	28.26503	1.686732	1.686732
27.51	1.23473	2.28975	0.4230539	28.30876	1.692216	1.692216
27.58	1.235286	2.295552	0.424246	28.32152	1.696984	1.696984
27.65	1.237273	2.301417	0.4253844	28.36707	1.701538	1.701538
27.72	1.240651	2.307208	0.4266182	28.44451	1.706473	1.706473
27.79	1.239856	2.313073	0.4278779	28.42629	1.711512	1.711512
27.86	1.244187	2.318906	0.4290799	28.52559	1.71632	1.71632
27.93	1.246254	2.324719	0.4302005	28.57296	1.720802	1.720802
28	1.24685	2.330573	0.4313131	28.58663	1.725253	1.725253
28.07	1.249472	2.336406	0.4324833	28.64676	1.729933	1.729933
28.14	1.250227	2.34226	0.4338304	28.66407	1.735322	1.735322
28.21	1.250664	2.348052	0.4347126	28.67409	1.73885	1.73885
28.28	1.254121	2.353917	0.4361331	28.75335	1.744533	1.744533
28.35	1.257578	2.359719	0.437369	28.83261	1.749476	1.749476
28.42	1.259486	2.365562	0.4383365	28.87634	1.753346	1.753346
28.49	1.26044	2.371396	0.4399538	28.8982	1.759815	1.759815
28.56	1.261195	2.377229	0.4408062	28.91552	1.763225	1.763225
28.63	1.26342	2.383094	0.4422804	28.96653	1.769122	1.769122
28.7	1.266479	2.388885	0.443242	29.03668	1.772968	1.772968
28.77	1.266559	2.39475	0.4446189	29.03851	1.778475	1.778475
28.84	1.270175	2.400563	0.4458229	29.12141	1.783291	1.783291
28.91	1.270692	2.406406	0.4473269	29.13325	1.789308	1.789308
28.98	1.271367	2.412229	0.448515	29.14874	1.79406	1.79406
29.05	1.273155	2.418062	0.4494309	29.18974	1.797724	1.797724
29.12	1.273354	2.423906	0.4506926	29.19429	1.80277	1.80277
29.19	1.277049	2.429719	0.4518151	29.27902	1.807261	1.807261
29.26	1.276692	2.435573	0.4530331	29.27082	1.812132	1.812132
29.33	1.279593	2.441386	0.4549046	29.33733	1.819619	1.819619
29.4	1.280467	2.44725	0.4559616	29.35737	1.823846	1.823846
29.47	1.28305	2.453052	0.4570623	29.41659	1.828249	1.828249
29.54	1.283685	2.458906	0.4579544	29.43116	1.831818	1.831818
29.61	1.286666	2.46475	0.4594922	29.49949	1.837969	1.837969
29.68	1.289248	2.470552	0.4607538	29.55871	1.843015	1.843015
29.75	1.287738	2.476406	0.4617353	29.52409	1.846941	1.846941
29.82	1.289884	2.482219	0.4628817	29.57328	1.851527	1.851527
29.89	1.29207	2.488083	0.4643778	29.62339	1.857511	1.857511
29.96	1.289527	2.493885	0.4655222	29.56508	1.862089	1.862089
30.03	1.292189	2.49974	0.4667839	29.62613	1.867135	1.867135
30.1	1.293858	2.505563	0.4679104	29.66439	1.871642	1.871642
30.17	1.296679	2.511406	0.4694641	29.72907	1.877856	1.877856
30.24	1.296163	2.517229	0.4707495	29.71723	1.882998	1.882998
30.31	1.29799	2.523073	0.4720429	29.75914	1.888172	1.888172
30.38	1.300414	2.528927	0.4730681	29.81471	1.892273	1.892273
30.45	1.301567	2.534719	0.4745126	29.84113	1.89805	1.89805
30.52	1.302401	2.540583	0.4755398	29.86026	1.902159	1.902159
30.59	1.305103	2.546385	0.4772902	29.92221	1.909161	1.909161
30.66	1.306653	2.55224	0.4785538	29.95774	1.914215	1.914215
30.73	1.306534	2.558052	0.4793982	29.95501	1.917593	1.917593
30.8	1.307885	2.563896	0.4810214	29.98599	1.924086	1.924086
30.87	1.308799	2.56975	0.4821301	30.00694	1.92852	1.92852
30.94	1.309395	2.575562	0.4836877	30.02061	1.934751	1.934751
31.01	1.309315	2.581417	0.4847288	30.01878	1.938915	1.938915
31.08	1.309991	2.58724	0.4862607	30.03427	1.945043	1.945043
31.15	1.31309	2.593083	0.4873733	30.10533	1.949493	1.949493
31.22	1.312931	2.598885	0.4889131	30.10169	1.955652	1.955652
31.29	1.313925	2.604729	0.490282	30.12447	1.961128	1.961128
31.36	1.314282	2.610563	0.4915217	30.13266	1.966087	1.966087
31.43	1.316667	2.616385	0.4927357	30.18733	1.970943	1.970943
31.5	1.317143	2.62224	0.4944205	30.19826	1.977682	1.977682
31.57	1.318415	2.628062	0.4957398	30.22741	1.982959	1.982959
31.64	1.319408	2.633927	0.497065	30.25019	1.98826	1.98826
31.71	1.320879	2.639708	0.4983048	30.2839	1.993219	1.993219
31.78	1.32219	2.645583	0.499932	30.31396	1.999728	1.999728
31.85	1.320561	2.651406	0.500993	30.27661	2.003972	2.003972
31.92	1.320759	2.657229	0.5026619	30.28116	2.010648	2.010648
31.99	1.324892	2.663063	0.5041599	30.37591	2.01664	2.01664
32.06	1.325568	2.668896	0.5053739	30.3914	2.021496	2.021496
32.13	1.324972	2.67474	0.5066812	30.37774	2.026725	2.026725
32.2	1.325846	2.680552	0.5081713	30.39778	2.032685	2.032685
32.27	1.326203	2.686417	0.5095899	30.40598	2.03836	2.03836
32.34	1.325727	2.692229	0.5110006	30.39504	2.044002	2.044002
32.41	1.329303	2.698073	0.511996	30.47704	2.047984	2.047984
32.48	1.328349	2.703885	0.5136073	30.45517	2.054429	2.054429
32.55	1.329184	2.709739	0.5151312	30.4743	2.060525	2.060525
32.62	1.329899	2.715583	0.5163808	30.4907	2.065523	2.065523
32.69	1.330614	2.721385	0.5178551	30.5071	2.07142	2.07142
32.76	1.331011	2.72725	0.5195658	30.51621	2.078263	2.078263
32.83	1.332839	2.733063	0.5209565	30.55812	2.083826	2.083826
32.9	1.332323	2.738917	0.5222619	30.54628	2.089047	2.089047
32.97	1.333157	2.744719	0.5237977	30.56541	2.095191	2.095191
33.04	1.334389	2.750573	0.5252202	30.59365	2.100881	2.100881
33.11	1.332839	2.756406	0.5269189	30.55812	2.107676	2.107676
33.18	1.334468	2.762219	0.5283932	30.59547	2.113573	2.113573
33.25	1.336575	2.768073	0.5296986	30.64376	2.118794	2.118794
33.32	1.337528	2.773906	0.5310158	30.66562	2.124063	2.124063
33.39	1.337528	2.77976	0.5328317	30.66562	2.131327	2.131327
33.46	1.337965	2.785552	0.5342563	30.67565	2.137025	2.137025
33.53	1.337926	2.791417	0.5356431	30.67473	2.142572	2.142572
33.6	1.336773	2.797219	0.5372484	30.64831	2.148994	2.148994
33.67	1.337528	2.803062	0.5386333	30.66562	2.154533	2.154533
33.74	1.338998	2.808896	0.5401134	30.69933	2.160454	2.160454
33.81	1.339157	2.814729	0.5418956	30.70298	2.167583	2.167583
33.88	1.339157	2.820583	0.5432288	30.70298	2.172915	2.172915
33.95	1.339237	2.826385	0.5450487	30.7048	2.180195	2.180195
34.02	1.34035	2.83225	0.5462885	30.73031	2.185154	2.185154
34.09	1.339674	2.838063	0.5479117	30.71482	2.191647	2.191647
34.16	1.34035	2.843906	0.5495489	30.73031	2.198195	2.198195
34.23	1.341025	2.849729	0.5511324	30.74579	2.20453	2.20453
34.3	1.342297	2.855562	0.552394	30.77495	2.209576	2.209576
34.37	1.343807	2.861406	0.5540431	30.80957	2.216172	2.216172
34.44	1.342654	2.867229	0.5556841	30.78315	2.222737	2.222737
34.51	1.344204	2.873083	0.5570054	30.81868	2.228022	2.228022
34.58	1.342177	2.878896	0.5586922	30.77221	2.234769	2.234769
34.65	1.340548	2.88476	0.5602598	30.73486	2.241039	2.241039
34.72	1.344442	2.890552	0.5618711	30.82414	2.247484	2.247484
34.79	1.343966	2.896417	0.5634487	30.81321	2.253795	2.253795
34.86	1.342773	2.90224	0.5649487	30.78588	2.259795	2.259795
34.93	1.343966	2.908062	0.5665203	30.81321	2.266081	2.266081
35	1.344403	2.913906	0.5681356	30.82323	2.272542	2.272542
35.07	1.343886	2.919729	0.5698184	30.81139	2.279274	2.279274
35.14	1.343528	2.925583	0.571543	30.80319	2.286172	2.286172
35.21	1.343091	2.931385	0.5729079	30.79317	2.291632	2.291632
35.28	1.345118	2.93725	0.5744338	30.83963	2.297735	2.297735
35.35	1.345356	2.943063	0.5763491	30.8451	2.305396	2.305396
35.42	1.343131	2.948906	0.5777757	30.79408	2.311103	2.311103
35.49	1.346668	2.954729	0.5792618	30.87516	2.317047	2.317047
35.56	1.346548	2.960573	0.580885	30.87243	2.32354	2.32354
35.63	1.345515	2.966427	0.5825202	30.84874	2.330081	2.330081
35.7	1.342694	2.972219	0.5839149	30.78406	2.33566	2.33566
35.77	1.344005	2.978083	0.585407	30.81412	2.341628	2.341628
35.84	1.344522	2.983885	0.5871952	30.82597	2.348781	2.348781
35.91	1.347105	2.98974	0.5888005	30.88518	2.355202	2.355202
35.98	1.345714	2.995552	0.5904019	30.8533	2.361608	2.361608
36.05	1.345754	3.001396	0.5919715	30.85421	2.367886	2.367886
36.12	1.345515	3.00725	0.5939801	30.84874	2.375921	2.375921
36.19	1.344681	3.013052	0.5952914	30.82961	2.381166	2.381166
36.26	1.347582	3.018917	0.5970001	30.89612	2.388	2.388
36.33	1.346469	3.02474	0.5986392	30.87061	2.394557	2.394557
36.4	1.345674	3.030583	0.6002585	30.85238	2.401034	2.401034
36.47	1.344999	3.036385	0.6017228	30.8369	2.406891	2.406891
36.54	1.348019	3.04224	0.6034315	30.90614	2.413726	2.413726
36.61	1.344959	3.048063	0.6049335	30.83599	2.419734	2.419734
36.68	1.344601	3.053896	0.6067872	30.82779	2.427149	2.427149
36.75	1.345754	3.05974	0.6083627	30.85421	2.433451	2.433451
36.82	1.347939	3.065562	0.6096343	30.90432	2.438537	2.438537
36.89	1.345118	3.071427	0.6114364	30.83963	2.445745	2.445745
36.96	1.344283	3.077219	0.6132384	30.8205	2.452954	2.452954
37.03	1.348217	3.083083	0.6146769	30.91069	2.458708	2.458708
37.1	1.346787	3.088906	0.6162246	30.8779	2.464898	2.464898
37.17	1.345118	3.094739	0.6183048	30.83963	2.473219	2.473219
37.24	1.345237	3.100573	0.6194453	30.84237	2.477781	2.477781
37.31	1.345317	3.106396	0.6213347	30.84418	2.485339	2.485339
37.38	1.345436	3.11225	0.6230096	30.84692	2.492038	2.492038
37.45	1.345515	3.118052	0.6247719	30.84874	2.499088	2.499088
37.52	1.345634	3.123906	0.6264448	30.85148	2.505779	2.505779
37.59	1.345634	3.129719	0.6278336	30.85148	2.511334	2.511334
37.66	1.345714	3.135573	0.6296654	30.8533	2.518662	2.518662
37.73	1.345833	3.141385	0.6311774	30.85603	2.52471	2.52471
37.8	1.345833	3.147239	0.632457	30.85603	2.529828	2.529828
37.87	1.345833	3.153083	0.6341974	30.85603	2.53679	2.53679
37.94	1.345833	3.158896	0.6361445	30.85603	2.544578	2.544578
38.01	1.345913	3.16475	0.6377776	30.85785	2.551111	2.551111
38.08	1.345913	3.170552	0.6394267	30.85785	2.557707	2.557707
38.15	1.345833	3.176417	0.6411393	30.85603	2.564557	2.564557
38.22	1.345833	3.182219	0.6428977	30.85603	2.571591	2.571591
38.29	1.345833	3.188073	0.6444256	30.85603	2.577702	2.577702
38.36	1.345913	3.193906	0.6459256	30.85785	2.583702	2.583702
38.43	1.345913	3.199729	0.6474853	30.85785	2.589941	2.589941
38.5	1.345913	3.205573	0.6492178	30.85785	2.596871	2.596871
38.57	1.345913	3.211406	0.6508629	30.85785	2.603451	2.603451
38.64	1.345913	3.21726	0.6526371	30.85785	2.610548	2.610548
38.71	1.345913	3.223052	0.6543338	30.85785	2.617335	2.617335
38.78	1.345913	3.228917	0.6559372	30.85785	2.623749	2.623749
38.85	1.345913	3.234719	0.6574253	30.85785	2.629701	2.629701
38.92	1.345833	3.240562	0.6592115	30.85603	2.636846	2.636846
38.99	1.345833	3.246396	0.6607354	30.85603	2.642941	2.642941
39.06	1.345833	3.252229	0.6624718	30.85603	2.649887	2.649887
39.13	1.345833	3.258094	0.6640494	30.85603	2.656198	2.656198
39.2	1.345833	3.263896	0.6658554	30.85603	2.663422	2.663422
39.27	1.345714	3.26975	0.6675701	30.8533	2.67028	2.67028
39.34	1.345634	3.275573	0.6687601	30.85148	2.67504	2.67504
39.41	1.345634	3.281417	0.6706715	30.85148	2.682686	2.682686
39.48	1.345555	3.287219	0.6725093	30.84965	2.690037	2.690037
39.55	1.345436	3.293062	0.6739855	30.84692	2.695942	2.695942
39.62	1.345436	3.298906	0.6756365	30.84692	2.702546	2.702546
39.69	1.345317	3.304719	0.6773214	30.84418	2.709285	2.709285
39.76	1.345237	3.310583	0.6787638	30.84237	2.715055	2.715055
39.83	1.345118	3.316396	0.6806214	30.83963	2.722486	2.722486
39.9	1.345038	3.32226	0.6819884	30.83781	2.727954	2.727954
39.97	1.344919	3.328052	0.6837348	30.83508	2.734939	2.734939
40.04	1.34484	3.333917	0.6853799	30.83325	2.74152	2.74152
40.11	1.34472	3.33974	0.6871085	30.83052	2.748434	2.748434
40.18	1.344641	3.345562	0.688529	30.8287	2.754116	2.754116
40.25	1.344482	3.351406	0.6905039	30.82505	2.762016	2.762016
40.32	1.344323	3.357229	0.6921272	30.82141	2.768509	2.768509
40.39	1.344244	3.363083	0.6936471	30.81959	2.774588	2.774588
40.46	1.344124	3.368885	0.6956935	30.81685	2.782774	2.782774
40.53	1.344045	3.37475	0.6970902	30.81503	2.788361	2.788361
40.6	1.343846	3.380563	0.6987234	30.81048	2.794894	2.794894
40.67	1.343727	3.386406	0.7003307	30.80774	2.801323	2.801323
40.74	1.343648	3.392229	0.7019401	30.80592	2.80776	2.80776
40.81	1.343568	3.398073	0.7032573	30.8041	2.813029	2.813029
40.88	1.343409	3.403927	0.7052163	30.80046	2.820865	2.820865
40.95	1.34325	3.409729	0.7071118	30.79681	2.828447	2.828447
41.02	1.34325	3.415583	0.7085482	30.79681	2.834193	2.834193
41.09	1.343131	3.421385	0.7099767	30.79408	2.839907	2.839907
41.16	1.342972	3.42724	0.7117927	30.79044	2.847171	2.847171
41.23	1.342853	3.433052	0.7137795	30.7877	2.855118	2.855118
41.3	1.342773	3.438896	0.7151027	30.78588	2.860411	2.860411
41.37	1.342654	3.44475	0.7168114	30.78315	2.867246	2.867246
41.44	1.342575	3.450562	0.7186949	30.78132	2.87478	2.87478
41.51	1.342456	3.456417	0.7201095	30.77859	2.880438	2.880438
41.58	1.342376	3.46224	0.7218758	30.77677	2.887503	2.887503
41.65	1.342257	3.468094	0.7233103	30.77404	2.893241	2.893241
41.72	1.342177	3.473885	0.7248203	30.77221	2.899281	2.899281
41.79	1.342058	3.479739	0.7265349	30.76948	2.90614	2.90614
41.86	1.341979	3.485563	0.7283588	30.76766	2.913435	2.913435
41.93	1.341859	3.491385	0.7300854	30.76493	2.920341	2.920341
42	1.341661	3.49724	0.7317345	30.76037	2.926938	2.926938
42.07	1.341581	3.503062	0.7334371	30.75855	2.933748	2.933748
42.14	1.341462	3.508927	0.7350683	30.75582	2.940273	2.940273
42.21	1.341303	3.514719	0.7363339	30.75217	2.945336	2.945336
42.28	1.341144	3.520583	0.7381976	30.74853	2.95279	2.95279
42.35	1.340985	3.526406	0.7398387	30.74488	2.959355	2.959355
42.42	1.340906	3.532239	0.7415891	30.74306	2.966356	2.966356
42.49	1.340707	3.538063	0.7432739	30.73851	2.973096	2.973096
42.56	1.340508	3.543896	0.7447978	30.73395	2.979191	2.979191
42.63	1.340389	3.54975	0.7461429	30.73122	2.984571	2.984571
42.7	1.340191	3.555552	0.7481297	30.72666	2.992519	2.992519
42.77	1.340111	3.561417	0.7498463	30.72484	2.999385	2.999385
42.84	1.339912	3.567229	0.7514377	30.72029	3.005751	3.005751
42.91	1.339714	3.573083	0.7531067	30.71573	3.012427	3.012427
42.98	1.339594	3.578885	0.7548789	30.713	3.019516	3.019516
43.05	1.339396	3.584739	0.7565737	30.70844	3.026295	3.026295
43.12	1.339197	3.590583	0.7578174	30.70389	3.03127	3.03127
43.19	1.339078	3.596396	0.7593036	30.70115	3.037214	3.037214
43.26	1.338919	3.60225	0.761344	30.69751	3.045376	3.045376
43.33	1.338681	3.608063	0.7629295	30.69205	3.051718	3.051718
43.4	1.338522	3.613917	0.7645746	30.6884	3.058298	3.058298
43.47	1.338323	3.619719	0.7659991	30.68385	3.063997	3.063997
43.54	1.338164	3.625573	0.7679145	30.6802	3.071658	3.071658
43.61	1.337965	3.631406	0.7692993	30.67565	3.077197	3.077197
43.68	1.337846	3.637229	0.770992	30.67291	3.083968	3.083968
43.75	1.337647	3.643073	0.7726033	30.66836	3.090413	3.090413
43.82	1.337449	3.648906	0.7743001	30.6638	3.0972	3.0972
43.89	1.33725	3.65476	0.7758021	30.65925	3.103209	3.103209
43.96	1.337131	3.660552	0.7774552	30.65651	3.109821	3.109821
44.03	1.336972	3.666417	0.7789473	30.65287	3.115789	3.115789
44.1	1.336773	3.672219	0.7809202	30.64831	3.123681	3.123681
44.17	1.336614	3.678062	0.7826507	30.64467	3.130603	3.130603
44.24	1.336455	3.683896	0.7841964	30.64103	3.136786	3.136786
44.31	1.336336	3.689729	0.7857938	30.63829	3.143175	3.143175
44.38	1.336177	3.695583	0.7873873	30.63465	3.149549	3.149549
44.45	1.335979	3.701385	0.7888655	30.63009	3.155462	3.155462
44.52	1.335859	3.70725	0.7906039	30.62736	3.162416	3.162416
44.59	1.335661	3.713073	0.7922809	30.6228	3.169123	3.169123
44.66	1.335581	3.718917	0.793757	30.62098	3.175028	3.175028
44.73	1.335382	3.724729	0.7953961	30.61643	3.181585	3.181585
44.8	1.335263	3.730562	0.797228	30.6137	3.188912	3.188912
44.87	1.335065	3.736406	0.7984321	30.60914	3.193728	3.193728
44.94	1.334866	3.742229	0.8003652	30.60458	3.201461	3.201461
45.01	1.334786	3.748083	0.8021633	30.60276	3.208653	3.208653
45.08	1.334588	3.753896	0.8037408	30.5982	3.214963	3.214963
45.15	1.334468	3.75976	0.8052289	30.59547	3.220916	3.220916
45.22	1.33427	3.765552	0.8066515	30.59092	3.226606	3.226606
45.29	1.334111	3.771406	0.8084754	30.58727	3.233902	3.233902
45.36	1.333912	3.77725	0.8104642	30.58272	3.241857	3.241857
45.43	1.333793	3.783073	0.8116086	30.57999	3.246434	3.246434
45.5	1.333594	3.788906	0.8134127	30.57543	3.253651	3.253651
45.57	1.333396	3.794729	0.8152207	30.57087	3.260883	3.260883
45.64	1.333237	3.800583	0.8166492	30.56723	3.266597	3.266597
45.71	1.333117	3.806385	0.8180777	30.5645	3.272311	3.272311
45.78	1.332919	3.81224	0.8194387	30.55994	3.277755	3.277755
45.85	1.33272	3.818063	0.8215289	30.55539	3.286115	3.286115
45.92	1.332601	3.823906	0.8230527	30.55266	3.292211	3.292211
45.99	1.332442	3.829729	0.8245111	30.54901	3.298044	3.298044
46.06	1.332243	3.835573	0.8263151	30.54446	3.30526	3.30526
46.13	1.332124	3.841427	0.8276244	30.54172	3.310498	3.310498
46.2	1.331925	3.847219	0.8292575	30.53717	3.31703	3.31703
46.27	1.331727	3.853083	0.8312384	30.53261	3.324954	3.324954
46.34	1.331568	3.858885	0.832959	30.52897	3.331836	3.331836
46.41	1.331449	3.86474	0.834173	30.52623	3.336692	3.336692
46.48	1.33125	3.870563	0.8361558	30.52168	3.344623	3.344623
46.55	1.331051	3.876396	0.8375247	30.51712	3.350099	3.350099
46.62	1.330932	3.88225	0.8388996	30.51439	3.355598	3.355598
46.69	1.330733	3.888062	0.8404891	30.50983	3.361956	3.361956
46.76	1.330535	3.893917	0.842456	30.50528	3.369824	3.369824
46.83	1.330336	3.89974	0.8441627	30.50072	3.376651	3.376651
46.9	1.330177	3.905594	0.8454919	30.49708	3.381968	3.381968
46.97	1.329978	3.911385	0.8467992	30.49253	3.387197	3.387197
47.04	1.32978	3.917239	0.8488635	30.48797	3.395454	3.395454
47.11	1.329581	3.923063	0.8503616	30.48341	3.401446	3.401446
47.18	1.329382	3.928896	0.8520623	30.47886	3.408249	3.408249
47.25	1.329184	3.93474	0.8536558	30.4743	3.414623	3.414623
47.32	1.328985	3.940562	0.8550783	30.46975	3.420313	3.420313
47.39	1.328786	3.946427	0.856779	30.46519	3.427116	3.427116
47.46	1.328588	3.952219	0.8581559	30.46064	3.432624	3.432624
47.53	1.328389	3.958083	0.8598248	30.45608	3.439299	3.439299
47.6	1.32819	3.963906	0.8617203	30.45153	3.446881	3.446881
47.67	1.327991	3.969739	0.8630415	30.44697	3.452166	3.452166
47.74	1.327912	3.975563	0.8645872	30.44515	3.458349	3.458349
47.81	1.327713	3.981396	0.8663515	30.4406	3.465406	3.465406
47.88	1.327515	3.98724	0.8678854	30.43604	3.471541	3.471541
47.95	1.327395	3.993052	0.8695483	30.43331	3.478193	3.478193
48.02	1.327197	3.998917	0.8709788	30.42875	3.483915	3.483915
48.09	1.326998	4.004729	0.873065	30.4242	3.49226	3.49226
48.16	1.326919	4.010583	0.8745114	30.42237	3.498046	3.498046
48.23	1.32672	4.016386	0.8757393	30.41782	3.502957	3.502957
48.3	1.326521	4.02225	0.8773764	30.41327	3.509506	3.509506
48.37	1.326362	4.028083	0.8790731	30.40962	3.516293	3.516293
48.44	1.326203	4.033885	0.8804043	30.40598	3.521617	3.521617
48.51	1.326005	4.03975	0.8820971	30.40142	3.528388	3.528388
48.58	1.325846	4.045562	0.8838773	30.39778	3.535509	3.535509
48.65	1.325727	4.051416	0.8852462	30.39504	3.540985	3.540985
48.72	1.325528	4.057219	0.8869748	30.39049	3.547899	3.547899
48.79	1.325329	4.063073	0.888598	30.38593	3.554392	3.554392
48.86	1.32513	4.068906	0.8900464	30.38138	3.560185	3.560185
48.93	1.324932	4.074729	0.891457	30.37682	3.565828	3.565828
49	1.324852	4.080583	0.8931438	30.375	3.572575	3.572575
49.07	1.324654	4.086406	0.8948942	30.37045	3.579577	3.579577
49.14	1.324455	4.09226	0.8964837	30.36589	3.585935	3.585935
49.21	1.324256	4.098052	0.8980811	30.36134	3.592324	3.592324
49.28	1.324137	4.103917	0.8994659	30.3586	3.597863	3.597863
49.35	1.323938	4.109719	0.9009838	30.35405	3.603935	3.603935
49.42	1.32374	4.115573	0.9029348	30.34949	3.611739	3.611739
49.49	1.323581	4.121396	0.9042144	30.34585	3.616858	3.616858
49.56	1.323382	4.127229	0.9055178	30.34129	3.622071	3.622071
49.63	1.323263	4.133094	0.9074092	30.33856	3.629637	3.629637
49.7	1.323064	4.138885	0.908937	30.33401	3.635748	3.635748
49.77	1.322865	4.14475	0.9103219	30.32945	3.641288	3.641288
49.84	1.322667	4.150573	0.9120941	30.32489	3.648376	3.648376
49.91	1.322587	4.156416	0.9135346	30.32307	3.654138	3.654138
49.98	1.322389	4.162219	0.9151558	30.31852	3.660623	3.660623
50.05	1.32219	4.168063	0.9166896	30.31396	3.666759	3.666759
50.12	1.322031	4.173906	0.918134	30.31032	3.672536	3.672536
50.19	1.321872	4.179729	0.9198546	30.30667	3.679419	3.679419
50.26	1.321673	4.185583	0.9212633	30.30212	3.685053	3.685053
50.33	1.321475	4.191396	0.9230276	30.29756	3.69211	3.69211
50.4	1.321316	4.19726	0.9243667	30.29392	3.697467	3.697467
50.47	1.321157	4.203052	0.9260316	30.29028	3.704127	3.704127
50.54	1.320998	4.208917	0.9275556	30.28663	3.710222	3.710222
50.61	1.320799	4.21475	0.9288688	30.28208	3.715475	3.715475
50.68	1.320601	4.220562	0.9304861	30.27752	3.721945	3.721945
50.75	1.320402	4.226406	0.9320001	30.27296	3.728	3.728
50.82	1.320203	4.232229	0.9337882	30.26841	3.735153	3.735153
50.89	1.320004	4.238083	0.9353678	30.26385	3.741471	3.741471
50.96	1.319806	4.243886	0.936995	30.2593	3.74798	3.74798
51.03	1.319607	4.24975	0.9381493	30.25474	3.752597	3.752597
51.1	1.319408	4.255562	0.9398937	30.25019	3.759575	3.759575
51.17	1.31925	4.261406	0.9413282	30.24654	3.765313	3.765313
51.24	1.319051	4.267229	0.9428282	30.24199	3.771313	3.771313
51.31	1.318892	4.273073	0.9443681	30.23835	3.777472	3.777472
51.38	1.318733	4.278927	0.9458025	30.2347	3.78321	3.78321
51.45	1.318534	4.284729	0.947551	30.23015	3.790204	3.790204
51.52	1.318336	4.290583	0.9489496	30.22559	3.795799	3.795799
51.59	1.318137	4.296385	0.9504278	30.22103	3.801711	3.801711
51.66	1.317938	4.302239	0.9515186	30.21648	3.806074	3.806074
51.73	1.317859	4.308052	0.9533405	30.21466	3.813362	3.813362
51.8	1.31766	4.313896	0.9547889	30.2101	3.819156	3.819156
51.87	1.317422	4.31975	0.9562214	30.20464	3.824886	3.824886
51.94	1.317143	4.325562	0.9578844	30.19826	3.831537	3.831537
52.01	1.317064	4.331417	0.9594242	30.19644	3.837697	3.837697
52.08	1.316826	4.33724	0.9610037	30.19097	3.844015	3.844015
52.15	1.316587	4.343094	0.9621541	30.1855	3.848616	3.848616
52.22	1.316388	4.348886	0.9640316	30.18095	3.856127	3.856127
52.29	1.31619	4.35474	0.9653032	30.17639	3.861213	3.861213
52.36	1.315991	4.360562	0.9667893	30.17184	3.867157	3.867157
52.43	1.315753	4.366396	0.9682338	30.16637	3.872935	3.872935
52.5	1.315594	4.37224	0.9693126	30.16273	3.87725	3.87725
52.57	1.315355	4.378062	0.9710829	30.15726	3.884331	3.884331
52.64	1.315196	4.383927	0.9728134	30.15362	3.891253	3.891253
52.71	1.314878	4.389719	0.9742339	30.14633	3.896936	3.896936
52.78	1.314759	4.395583	0.9755909	30.1436	3.902364	3.902364
52.85	1.3146	4.401406	0.9770532	30.13995	3.908213	3.908213
52.92	1.314402	4.407239	0.9786626	30.1354	3.91465	3.91465
52.99	1.314203	4.413073	0.979956	30.13084	3.919824	3.919824
53.06	1.314004	4.418896	0.9814143	30.12629	3.925657	3.925657
53.13	1.313925	4.42475	0.9826779	30.12447	3.930712	3.930712
53.2	1.313726	4.430552	0.9842197	30.11991	3.936879	3.936879
53.27	1.313527	4.436417	0.9852449	30.11535	3.94098	3.94098
53.34	1.313329	4.442229	0.9868125	30.1108	3.94725	3.94725
53.41	1.31321	4.448083	0.9881397	30.10807	3.952559	3.952559
53.48	1.312931	4.453896	0.9890477	30.10169	3.956191	3.956191
53.55	1.312733	4.45974	0.9909153	30.09713	3.963661	3.963661
53.62	1.312534	4.465594	0.9923379	30.09258	3.969352	3.969352
53.69	1.312335	4.471396	0.9932637	30.08802	3.973055	3.973055
53.76	1.312137	4.47725	0.9944062	30.08347	3.977625	3.977625
53.83	1.311859	4.483062	0.9958148	30.07709	3.983259	3.983259
53.9	1.31166	4.488916	0.9966413	30.07254	3.986565	3.986565
53.97	1.311421	4.494719	0.9971082	30.06707	3.988433	3.988433
54.04	1.311143	4.500583	1.051376	30.06069	4.205505	4.205505
54.11	0.01096725	4.505979	1.014537	0.2514472	4.058146	4.058146