File: Shimadzu/todos.txt
Nome do ensaio	Modo de ensaio	Tipo de ensaio	Título1	Comentário1	Palavra-chave	Nome do produto	Nome do arquivo do ensaio	Nome do arquivo do método	Data do relatório	Data do ensaio	Modo de ensaio	Tipo de ensaio	Velocidade	Placa	Lote No:	Sub-Lote No:
	Simples	Tração	Grupo de Mecânica Aplicada - GMAp
UFRGS	Comentário	 	 	 	 	04/06/2021	31/05/2021	Simples	Tração	5mm/min	Placa	5	1

Placa:	Lote No:	Sub-Lote No:
Placa	5	1
Nome	Espessura	Largura	Gauge Length
Unidade:	mm	mm	mm
GA_D_26	3.3373	13.0470	115.0000
GA_D_27	3.0873	13.0997	115.0000
GA_D_28	3.3160	12.9950	115.0000
GA_D_29	3.3497	12.9750	115.0000
GA_D_30	3.3563	13.0163	115.0000

Nome	Elástico	Inclinação_Padrão	Ruptura_Força	Máx_Força	Max_Disp_Força	Max_Disp_SG-25-50 %	Max_Disp_Deslocamento	Espessura	Largura	Gauge_Length	Máx_Tensão	YS1_Tensão
Parâmetro	Tensão 0.75 - 5 N/mm2	Tensão 0.75 - 5 N/mm2	Sensibilidade: 10	Cálculo de áreas completas							Cálculo de áreas completas	0.2 %
Unidade	N/mm2	N/mm	kN	kN	kN	%	mm	mm	mm	mm	N/mm2	N/mm2
Grupo_A-CP26-D	2063.08	3593.20	1.37325	1.62367	1.37031	14.2075	8.44057	3.3373	13.0470	115.0000	37.2900	36.1903
Grupo_A-CP27-D	2193.94	3549.15	1.31889	1.63337	0.01784	20.3071	10.2493	3.0873	13.0997	115.0000	40.3872	38.4693
Grupo_A-CP28-D	2062.80	3555.55	-.-	1.60035	1.17167	12.7450	9.16555	3.3160	12.9950	115.0000	37.1384	35.7432
Grupo_A-CP29-D	2035.89	3539.39	-.-	1.60237	0.01506	16.7215	10.2702	3.3497	12.9750	115.0000	36.8680	35.8367
Grupo_A-CP30-D	2024.81	3538.29	1.29807	1.56065	1.29406	14.9418	9.79473	3.3563	13.0163	115.0000	35.7237	35.5300

GC_N_11
Tempo	Força	Deslocamento	Desloc. SG25-50	Tensão	SG-25-50 %	Deformação
seg	kN	mm	mm	N/mm2	%	%
0	0.01259645	0	0	0.2892959	0	0
0.13	0.01259645	0.008125	0.001869599	0.2892959	0.007478396	0.007478396
0.26	0.01271566	0.01892708	0.004412731	0.2920336	0.01765092	0.01765092
0.39	0.03457069	0.02975	0.006790956	0.7939665	0.02716382	0.02716382
0.52	0.04243851	0.04057292	0.009250641	0.9746624	0.03700256	0.03700256
0.65	0.05439917	0.05139583	0.01174013	1.249357	0.04696051	0.04696051
0.78	0.05956491	0.06222917	0.01391768	1.367995	0.05567074	0.05567074
0.91	0.07104874	0.0730625	0.01692375	1.631738	0.06769498	0.06769498
1.04	0.07740656	0.08390625	0.01909932	1.777755	0.07639726	0.07639726
1.17	0.08742014	0.09472916	0.02134244	2.007731	0.08536974	0.08536974
1.3	0.09552637	0.1055625	0.02395908	2.193903	0.09583632	0.09583632
1.43	0.1035929	0.1163854	0.02621214	2.379162	0.1048485	0.1048485
1.56	0.1130501	0.1272292	0.02895594	2.596362	0.1158237	0.1158237
1.69	0.123024	0.1380521	0.03147523	2.825426	0.1259009	0.1259009
1.82	0.1296202	0.1489062	0.03354152	2.976918	0.1341661	0.1341661
1.95	0.1394351	0.1597292	0.03602306	3.202332	0.1440922	0.1440922
2.08	0.147899	0.1705625	0.0383536	3.396716	0.1534144	0.1534144
2.21	0.1569589	0.1813958	0.04077554	3.60479	0.1631021	0.1631021
2.34	0.1658599	0.19225	0.04342794	3.809214	0.1737118	0.1737118
2.47	0.1772642	0.2030729	0.04585981	4.071132	0.1834393	0.1834393
2.6	0.1831055	0.2139271	0.04799167	4.205285	0.1919667	0.1919667
2.73	0.1933575	0.22475	0.05054672	4.440737	0.2021869	0.2021869
2.86	0.2017021	0.2355833	0.05296469	4.632384	0.2118587	0.2118587
2.99	0.2106826	0.2464167	0.05519986	4.838633	0.2207994	0.2207994
3.12	0.2169212	0.2572604	0.05789797	4.981912	0.2315919	0.2315919
3.25	0.226895	0.2680833	0.0601093	5.210976	0.2404372	0.2404372
3.38	0.233531	0.2789271	0.06253918	5.363381	0.2501567	0.2501567
3.51	0.2417167	0.28975	0.06467899	5.551377	0.258716	0.258716
3.64	0.251015	0.3005729	0.06732742	5.764927	0.2693097	0.2693097
3.77	0.2594789	0.3114063	0.06944736	5.959312	0.2777894	0.2777894
3.9	0.2676646	0.3222292	0.07204413	6.147308	0.2881765	0.2881765
4.03	0.2758106	0.3330729	0.07427732	6.334393	0.2971093	0.2971093
4.16	0.285546	0.3438958	0.07653832	6.557981	0.3061533	0.3061533
4.29	0.2921422	0.3547292	0.07889271	6.709474	0.3155708	0.3155708
4.42	0.3033082	0.3655625	0.08145571	6.965915	0.3258228	0.3258228
4.55	0.3135602	0.3763958	0.08386771	7.201367	0.3354708	0.3354708
4.68	0.3179312	0.3872187	0.08599758	7.301754	0.3439903	0.3439903
4.81	0.3264348	0.3980729	0.0883917	7.497052	0.3535668	0.3535668
4.94	0.3358126	0.4088854	0.09106597	7.712427	0.3642639	0.3642639
5.07	0.3454288	0.4197187	0.09292364	7.933278	0.3716946	0.3716946
5.2	0.3534158	0.4305625	0.0957946	8.116711	0.3831784	0.3831784
5.33	0.3612439	0.4414063	0.09782513	8.296494	0.3913005	0.3913005
5.46	0.3701846	0.4522292	0.1002371	8.501829	0.4009485	0.4009485
5.59	0.3790061	0.4630833	0.1021405	8.704429	0.408562	0.408562
5.72	0.3859997	0.4739166	0.1050671	8.865047	0.4202684	0.4202684
5.85	0.3949404	0.48475	0.107189	9.070383	0.4287561	0.4287561
5.98	0.4014572	0.4955833	0.1096129	9.220051	0.4384518	0.4384518
6.11	0.410676	0.506427	0.1117349	9.431775	0.4469395	0.4469395
6.24	0.4193783	0.51725	0.1141767	9.631636	0.4567067	0.4567067
6.37	0.4270474	0.5280938	0.1162628	9.807768	0.4650513	0.4650513
6.5	0.4353921	0.5389166	0.1186093	9.999414	0.4744371	0.4744371
6.63	0.4448096	0.54975	0.1208882	10.2157	0.4835526	0.4835526
6.76	0.4529953	0.5605834	0.1232922	10.4037	0.4931688	0.4931688
6.89	0.4589955	0.5714167	0.1260658	10.5415	0.5042632	0.5042632
7.02	0.467817	0.5822396	0.1278301	10.7441	0.5113204	0.5113204
7.15	0.4765193	0.5930625	0.1302461	10.94396	0.5209844	0.5209844
7.28	0.4857779	0.6038958	0.1326442	11.1566	0.5305767	0.5305767
7.41	0.4944007	0.6147292	0.1349588	11.35463	0.5398353	0.5398353
7.54	0.5014737	0.6255729	0.1369238	11.51708	0.5476952	0.5476952
7.67	0.5105336	0.6363854	0.1398563	11.72515	0.5594254	0.5594254
7.8	0.5183617	0.6472396	0.1416683	11.90493	0.5666733	0.5666733
7.93	0.5268256	0.6580521	0.1439691	12.09932	0.5758762	0.5758762
8.06	0.5299647	0.6688958	0.1461228	12.17142	0.5844911	0.5844911
8.19	0.541846	0.6797187	0.1484255	12.44428	0.593702	0.593702
8.32	0.5501509	0.6905625	0.1508653	12.63502	0.6034613	0.6034613
8.45	0.55631	0.7013854	0.1530627	12.77647	0.612251	0.612251
8.58	0.5637805	0.7122396	0.1555562	12.94804	0.6222248	0.6222248
8.71	0.5743106	0.7230625	0.1578093	13.18988	0.631237	0.631237
8.84	0.5813439	0.7339063	0.1600524	13.35141	0.6402095	0.6402095
8.97	0.5902449	0.7447396	0.1622816	13.55584	0.6491264	0.6491264
9.1	0.5989075	0.7555937	0.1643737	13.75479	0.6574948	0.6574948
9.23	0.6046295	0.7664167	0.1668195	13.8862	0.667278	0.667278
9.36	0.6136894	0.7772604	0.1691083	14.09427	0.6764333	0.6764333
9.49	0.6208817	0.7880937	0.1710852	14.25946	0.6843408	0.6843408
9.62	0.6289482	0.7989166	0.1734575	14.44472	0.6938298	0.6938298
9.75	0.6356239	0.8097604	0.1758436	14.59803	0.7033746	0.7033746
9.88	0.643452	0.8205937	0.1781444	14.77782	0.7125775	0.7125775
10.01	0.6509622	0.8314167	0.1797934	14.9503	0.7191737	0.7191737
10.14	0.6593466	0.84225	0.1825631	15.14286	0.7302523	0.7302523
10.27	0.6678899	0.8530729	0.184379	15.33907	0.7375161	0.7375161
10.4	0.6745656	0.8638958	0.186795	15.49238	0.74718	0.74718
10.53	0.6833474	0.8747396	0.1889904	15.69407	0.7559617	0.7559617
10.66	0.6912549	0.8855625	0.1912316	15.87568	0.7649263	0.7649263
10.79	0.6978512	0.8964062	0.1934369	16.02717	0.7737477	0.7737477
10.92	0.7061164	0.9072292	0.1959105	16.217	0.7836421	0.7836421
11.05	0.7147391	0.9180521	0.1979411	16.41503	0.7917643	0.7917643
11.18	0.7199447	0.928875	0.1998186	16.53458	0.7992744	0.7992744
11.31	0.7299185	0.9397292	0.2026061	16.76365	0.8104245	0.8104245
11.44	0.7351637	0.950552	0.2046684	16.88411	0.8186738	0.8186738
11.57	0.7450581	0.9613958	0.2066652	17.11135	0.8266608	0.8266608
11.7	0.7530848	0.9722188	0.2090355	17.29569	0.8361419	0.8361419
11.83	0.7581711	0.9830521	0.2111872	17.41251	0.8447488	0.8447488
11.96	0.7670323	0.9938854	0.2134919	17.61602	0.8539677	0.8539677
12.09	0.7742246	1.00474	0.2155443	17.7812	0.8621772	0.8621772
12.22	0.7814169	1.015563	0.2176046	17.94638	0.8704185	0.8704185
12.35	0.7899205	1.026417	0.2202531	18.14168	0.8810123	0.8810123
12.48	0.7964373	1.03725	0.2220154	18.29135	0.8880615	0.8880615
12.61	0.8039872	1.048073	0.2244274	18.46474	0.8977095	0.8977095
12.74	0.8108616	1.058906	0.226595	18.62262	0.90638	0.90638
12.87	0.8194844	1.06975	0.2288878	18.82066	0.9155512	0.9155512
13	0.8263588	1.080583	0.230666	18.97854	0.922664	0.922664
13.13	0.8336306	1.091417	0.2331515	19.14554	0.932606	0.932606
13.26	0.8403857	1.10224	0.2349675	19.30069	0.9398699	0.9398699
13.39	0.8480549	1.113063	0.2372165	19.47682	0.9488662	0.9488662
13.52	0.8549293	1.123896	0.2393484	19.6347	0.9573936	0.9573936
13.65	0.8604129	1.134729	0.2412617	19.76064	0.9650469	0.9650469
13.78	0.8677642	1.145563	0.2439022	19.92947	0.9756088	0.9756088
13.91	0.8740425	1.156385	0.245291	20.07366	0.981164	0.981164
14.04	0.8834203	1.167219	0.2474964	20.28904	0.9899855	0.9899855
14.17	0.8910497	1.178052	0.2497057	20.46426	0.9988229	0.9988229
14.3	0.8946657	1.188896	0.2514243	20.54731	1.005697	1.005697
14.43	0.9029706	1.199719	0.2537549	20.73804	1.015019	1.015019
14.56	0.9095271	1.210562	0.2557675	20.88862	1.02307	1.02307
14.69	0.9154479	1.221375	0.2578577	21.0246	1.031431	1.031431
14.82	0.9227594	1.232219	0.2598266	21.19252	1.039306	1.039306
14.95	0.9302695	1.243052	0.2619505	21.365	1.047802	1.047802
15.08	0.93774	1.253896	0.2640704	21.53657	1.056282	1.056282
15.21	0.9446542	1.264719	0.2659539	21.69536	1.063816	1.063816
15.34	0.9480715	1.275573	0.2676904	21.77385	1.070762	1.070762
15.47	0.9548267	1.286406	0.2699336	21.92899	1.079734	1.079734
15.6	0.9635687	1.29724	0.2719939	22.12976	1.087976	1.087976
15.73	0.9704034	1.308073	0.27378	22.28673	1.09512	1.09512
15.86	0.9749333	1.318917	0.276041	22.39077	1.104164	1.104164
15.99	0.9814501	1.32975	0.2779901	22.54044	1.11196	1.11196
16.12	0.9868145	1.340583	0.2797365	22.66364	1.118946	1.118946
16.25	0.9955962	1.351406	0.2821386	22.86532	1.128554	1.128554
16.38	0.9996096	1.36224	0.2842406	22.9575	1.136963	1.136963
16.51	1.006206	1.373073	0.2860606	23.10899	1.144242	1.144242
16.64	1.014431	1.383896	0.2880752	23.2979	1.152301	1.152301
16.77	1.020829	1.39474	0.2897044	23.44483	1.158818	1.158818
16.9	1.027346	1.405563	0.2919833	23.5945	1.167933	1.167933
17.03	1.032551	1.416396	0.2937257	23.71405	1.174903	1.174903
17.16	1.039545	1.427219	0.2957404	23.87466	1.182961	1.182961
17.29	1.046538	1.438062	0.2978961	24.03528	1.191584	1.191584
17.42	1.050909	1.448885	0.2995729	24.13567	1.198292	1.198292
17.55	1.057863	1.459729	0.3016929	24.29538	1.206771	1.206771
17.68	1.064897	1.470552	0.303479	24.45691	1.213916	1.213916
17.81	1.070301	1.481385	0.3054142	24.58102	1.221657	1.221657
17.94	1.073798	1.492219	0.3072977	24.66133	1.229191	1.229191
18.07	1.081626	1.503062	0.3095865	24.84111	1.238346	1.238346
18.2	1.08699	1.513885	0.311172	24.96431	1.244688	1.244688
18.33	1.093467	1.52474	0.3130496	25.11307	1.252198	1.252198
18.46	1.100063	1.535563	0.3150364	25.26456	1.260146	1.260146
18.59	1.105666	1.546396	0.3166278	25.39324	1.266511	1.266511
18.72	1.113892	1.55724	0.3186226	25.58215	1.27449	1.27449
18.85	1.118859	1.568083	0.3207803	25.69623	1.283121	1.283121
18.98	1.124859	1.578906	0.3225207	25.83403	1.290083	1.290083
19.11	1.12919	1.58976	0.3244499	25.9335	1.2978	1.2978
19.24	1.137416	1.600583	0.326101	26.12241	1.304404	1.304404
19.37	1.143257	1.611417	0.3282448	26.25656	1.312979	1.312979
19.5	1.14731	1.62225	0.3301978	26.34965	1.320791	1.320791
19.63	1.15486	1.633083	0.3320654	26.52305	1.328262	1.328262
19.76	1.162251	1.643906	0.3339291	26.69279	1.335716	1.335716
19.89	1.1669	1.65474	0.3359993	26.79956	1.343997	1.343997
20.02	1.17139	1.665563	0.3378689	26.90269	1.351476	1.351476
20.15	1.178622	1.676396	0.3395955	27.06878	1.358382	1.358382
20.28	1.183232	1.687229	0.3416339	27.17465	1.366536	1.366536
20.41	1.190821	1.698063	0.3434936	27.34895	1.373974	1.373974
20.54	1.194795	1.708906	0.3453473	27.44021	1.381389	1.381389
20.67	1.20159	1.719719	0.347203	27.59627	1.388812	1.388812
20.8	1.205722	1.730552	0.3492495	27.69118	1.396998	1.396998
20.93	1.213551	1.741385	0.3511727	27.87096	1.404691	1.404691
21.06	1.218677	1.752229	0.3528893	27.98869	1.411557	1.411557
21.19	1.22718	1.763042	0.3546536	28.18398	1.418614	1.418614
21.32	1.231988	1.773896	0.3565987	28.29441	1.426395	1.426395
21.45	1.236161	1.784719	0.3586908	28.39024	1.434763	1.434763
21.58	1.241962	1.795552	0.3605207	28.52348	1.442083	1.442083
21.71	1.248519	1.806396	0.3623784	28.67406	1.449513	1.449513
21.84	1.253565	1.81724	0.3643036	28.78996	1.457214	1.457214
21.97	1.259486	1.828063	0.3661811	28.92594	1.464725	1.464725
22.1	1.265407	1.838927	0.3684262	29.06191	1.473705	1.473705
22.23	1.269301	1.84975	0.3699243	29.15135	1.479697	1.479697
22.36	1.276334	1.860583	0.3719211	29.31288	1.487684	1.487684
22.49	1.280308	1.871417	0.3736655	29.40414	1.494662	1.494662
22.62	1.287023	1.88226	0.3759603	29.55837	1.503841	1.503841
22.75	1.292109	1.893083	0.3776689	29.67518	1.510676	1.510676
22.88	1.298706	1.903917	0.3793856	29.82668	1.517542	1.517542
23.01	1.305262	1.91474	0.3817141	29.97725	1.526856	1.526856
23.14	1.312852	1.925563	0.3833135	30.15157	1.533254	1.533254
23.27	1.316269	1.936396	0.3854314	30.23005	1.541726	1.541726
23.4	1.320561	1.947229	0.3871699	30.32861	1.54868	1.54868
23.53	1.326839	1.958073	0.3889898	30.4728	1.555959	1.555959
23.66	1.333475	1.968896	0.3909131	30.62521	1.563652	1.563652
23.79	1.337767	1.979729	0.3931284	30.72377	1.572514	1.572514
23.92	1.345396	1.990552	0.3950556	30.89899	1.580222	1.580222
24.05	1.348933	2.001396	0.3969073	30.98021	1.587629	1.587629
24.18	1.357277	2.012219	0.3991505	31.17186	1.596602	1.596602
24.31	1.362244	2.023062	0.4008651	31.28593	1.60346	1.60346
24.44	1.367172	2.033885	0.4025936	31.3991	1.610374	1.610374
24.57	1.372337	2.044719	0.4048467	31.51773	1.619387	1.619387
24.7	1.37953	2.055552	0.4066308	31.68292	1.626523	1.626523
24.83	1.383662	2.066406	0.4085958	31.77782	1.634383	1.634383
24.96	1.389225	2.077219	0.4105727	31.90559	1.642291	1.642291
25.09	1.395226	2.088083	0.4127642	32.04339	1.651057	1.651057
25.22	1.399875	2.098906	0.4145583	32.15017	1.658233	1.658233
25.35	1.406034	2.10974	0.4165351	32.29163	1.666141	1.666141
25.48	1.412034	2.120573	0.4187028	32.42943	1.674811	1.674811
25.61	1.418591	2.131427	0.4203657	32.58001	1.681463	1.681463
25.74	1.422763	2.14225	0.4225115	32.67583	1.690046	1.690046
25.87	1.42765	2.153094	0.4246155	32.78808	1.698462	1.698462
26	1.433849	2.163917	0.4264295	32.93045	1.705718	1.705718
26.13	1.440247	2.17474	0.4285773	33.07738	1.714309	1.714309
26.26	1.443505	2.185583	0.4303733	33.15221	1.721493	1.721493
26.39	1.44879	2.196406	0.4324853	33.27359	1.729941	1.729941
26.52	1.45483	2.20724	0.4344443	33.4123	1.737777	1.737777
26.65	1.460671	2.218073	0.4364828	33.54646	1.745931	1.745931
26.78	1.464844	2.228896	0.4383922	33.64228	1.753569	1.753569
26.91	1.469413	2.239729	0.4403154	33.74723	1.761262	1.761262
27.04	1.476129	2.250562	0.4426698	33.90146	1.770679	1.770679
27.17	1.480301	2.261385	0.4447003	33.99728	1.778801	1.778801
27.3	1.485666	2.272239	0.4464308	34.12048	1.785723	1.785723
27.43	1.490196	2.283052	0.4482965	34.22452	1.793186	1.793186
27.56	1.495838	2.293885	0.4505813	34.35411	1.802325	1.802325
27.69	1.502196	2.304719	0.4526536	34.50013	1.810614	1.810614
27.82	1.50466	2.315562	0.4546543	34.55671	1.818617	1.818617
27.95	1.512965	2.326385	0.4567882	34.74744	1.827153	1.827153
28.08	1.518408	2.33724	0.4588107	34.87247	1.835243	1.835243
28.21	1.520912	2.348063	0.4607101	34.92997	1.842841	1.842841
28.34	1.526952	2.358896	0.462983	35.06868	1.851932	1.851932
28.47	1.53331	2.36974	0.4651169	35.21469	1.860468	1.860468
28.6	1.536568	2.380583	0.4670978	35.28953	1.868391	1.868391
28.73	1.540462	2.391406	0.4690945	35.37897	1.876378	1.876378
28.86	1.545588	2.40226	0.4712701	35.49669	1.88508	1.88508
28.99	1.55131	2.413083	0.4734218	35.62811	1.893687	1.893687
29.12	1.554847	2.423917	0.4753192	35.70933	1.901277	1.901277
29.25	1.559933	2.43475	0.4776597	35.82614	1.910639	1.910639
29.38	1.562715	2.445583	0.4793406	35.89002	1.917362	1.917362
29.51	1.56939	2.456417	0.4818459	36.04334	1.927384	1.927384
29.64	1.574079	2.46724	0.4841149	36.15103	1.93646	1.93646
29.77	1.578689	2.478073	0.4862646	36.25689	1.945058	1.945058
29.9	1.582821	2.488896	0.4884163	36.3518	1.953665	1.953665
30.03	1.586	2.499729	0.4904787	36.42481	1.961915	1.961915
30.16	1.590927	2.510562	0.4929662	36.53798	1.971865	1.971865
30.29	1.593987	2.521406	0.4949411	36.60825	1.979764	1.979764
30.42	1.59653	2.532219	0.4969915	36.66665	1.987966	1.987966
30.55	1.601656	2.543062	0.4995167	36.78438	1.998067	1.998067
30.68	1.606584	2.553896	0.5016426	36.89754	2.006571	2.006571
30.81	1.61008	2.564729	0.5039374	36.97785	2.01575	2.01575
30.94	1.61167	2.575552	0.5066236	37.01435	2.026494	2.026494
31.07	1.615326	2.586406	0.5085925	37.09832	2.03437	2.03437
31.2	1.615365	2.597219	0.5111555	37.09923	2.044622	2.044622
31.33	1.618505	2.608052	0.5135596	37.17132	2.054238	2.054238
31.46	1.618862	2.618896	0.5159478	37.17954	2.063791	2.063791
31.59	1.62228	2.62974	0.5186081	37.25802	2.074432	2.074432
31.72	1.62367	2.640563	0.5212923	37.28996	2.085169	2.085169
31.85	1.621803	2.651417	0.5243997	37.24707	2.097599	2.097599
31.98	1.61771	2.66225	0.5275428	37.15307	2.110171	2.110171
32.11	1.616955	2.673083	0.5309343	37.13573	2.123737	2.123737
32.24	1.609524	2.683917	0.5342662	36.96508	2.137065	2.137065
32.37	1.604994	2.69476	0.5386114	36.86104	2.154446	2.154446
32.5	1.598954	2.705583	0.5425513	36.72232	2.170205	2.170205
32.63	1.589815	2.716417	0.5466421	36.51242	2.186568	2.186568
32.76	1.584331	2.72725	0.5518834	36.38648	2.207534	2.207534
32.89	1.575788	2.738073	0.5562027	36.19027	2.224811	2.224811
33.02	1.563668	2.748906	0.5611996	35.91193	2.244798	2.244798
33.15	1.55743	2.759729	0.5660852	35.76865	2.264341	2.264341
33.28	1.548052	2.770573	0.5709072	35.55327	2.283629	2.283629
33.41	1.541336	2.781396	0.5758007	35.39904	2.303203	2.303203
33.54	1.533071	2.792229	0.5808651	35.20922	2.323461	2.323461
33.67	1.525044	2.803062	0.5858004	35.02488	2.343202	2.343202
33.8	1.518528	2.813896	0.5904734	34.87521	2.361894	2.361894
33.93	1.511057	2.824719	0.595512	34.70364	2.382048	2.382048
34.06	1.50462	2.835573	0.6003479	34.5558	2.401392	2.401392
34.19	1.50164	2.846385	0.6049593	34.48735	2.419837	2.419837
34.32	1.493931	2.857219	0.6097655	34.31031	2.439062	2.439062
34.45	1.489083	2.868052	0.6143351	34.19897	2.45734	2.45734
34.58	1.483401	2.878906	0.6189167	34.06847	2.475667	2.475667
34.71	1.47891	2.889729	0.6232083	33.96534	2.492833	2.492833
34.84	1.474659	2.900583	0.6282668	33.86769	2.513067	2.513067
34.97	1.470447	2.911406	0.6326556	33.77096	2.530622	2.530622
35.1	1.468658	2.92224	0.6367028	33.72989	2.546811	2.546811
35.23	1.464566	2.933073	0.6415248	33.63589	2.566099	2.566099
35.36	1.461148	2.943927	0.6452898	33.55741	2.581159	2.581159
35.49	1.458685	2.95475	0.6500403	33.50082	2.600161	2.600161
35.62	1.454274	2.965594	0.6544014	33.39952	2.617605	2.617605
35.75	1.452168	2.976417	0.658375	33.35116	2.6335	2.6335
35.88	1.448552	2.98725	0.6625573	33.26811	2.650229	2.650229
36.01	1.446406	2.998073	0.6670793	33.21883	2.668317	2.668317
36.14	1.445135	3.008906	0.6709874	33.18963	2.683949	2.683949
36.27	1.443108	3.01975	0.6753345	33.14309	2.701338	2.701338
36.4	1.442512	3.030573	0.6792088	33.12939	2.716835	2.716835
36.53	1.438101	3.041396	0.6836752	33.0281	2.734701	2.734701
36.66	1.438578	3.052229	0.6875713	33.03905	2.750285	2.750285
36.79	1.434525	3.063062	0.6914834	32.94596	2.765934	2.765934
36.92	1.435359	3.073896	0.6955981	32.96513	2.782393	2.782393
37.05	1.433492	3.084739	0.6994824	32.92223	2.79793	2.79793
37.18	1.432618	3.095552	0.7035534	32.90216	2.814214	2.814214
37.31	1.430353	3.106385	0.7076383	32.85014	2.830553	2.830553
37.44	1.430432	3.117219	0.7116715	32.85196	2.846686	2.846686
37.57	1.428286	3.128062	0.7158458	32.80268	2.863383	2.863383
37.7	1.428326	3.138885	0.719579	32.8036	2.878316	2.878316
37.83	1.426299	3.14974	0.7231414	32.75705	2.892566	2.892566
37.96	1.422524	3.160563	0.7276873	32.67035	2.910749	2.910749
38.09	1.422524	3.171396	0.7315318	32.67035	2.926127	2.926127
38.22	1.42165	3.18224	0.7353882	32.65028	2.941553	2.941553
38.35	1.420339	3.193083	0.7394711	32.62016	2.957885	2.957885
38.48	1.421054	3.203917	0.7432182	32.63659	2.972873	2.972873
38.61	1.420776	3.21476	0.7472436	32.6302	2.988974	2.988974
38.74	1.417359	3.225583	0.7511298	32.55172	3.004519	3.004519
38.87	1.416802	3.236417	0.7549087	32.53894	3.019635	3.019635
39	1.417915	3.24725	0.7593115	32.56449	3.037246	3.037246
39.13	1.416365	3.258094	0.7629395	32.5289	3.051758	3.051758
39.26	1.414339	3.268917	0.7669866	32.48236	3.067946	3.067946
39.39	1.416564	3.27974	0.7707934	32.53346	3.083174	3.083174
39.52	1.415412	3.290573	0.7751445	32.507	3.100578	3.100578
39.65	1.41565	3.301396	0.7788857	32.51247	3.115543	3.115543
39.78	1.415133	3.31224	0.7827282	32.50061	3.130913	3.130913
39.91	1.412431	3.323062	0.7867475	32.43855	3.14699	3.14699
40.04	1.412868	3.333906	0.7904708	32.44859	3.161883	3.161883
40.17	1.41271	3.344729	0.7946869	32.44494	3.178747	3.178747
40.3	1.413743	3.355562	0.798434	32.46867	3.193736	3.193736
40.43	1.410166	3.366396	0.8025388	32.38654	3.210155	3.210155
40.56	1.4112	3.377229	0.8063455	32.41026	3.225382	3.225382
40.69	1.410325	3.388052	0.8105318	32.39019	3.242127	3.242127
40.82	1.410087	3.398906	0.814112	32.38471	3.256448	3.256448
40.95	1.409292	3.409719	0.8182764	32.36646	3.273106	3.273106
41.08	1.408617	3.420552	0.8220434	32.35094	3.288174	3.288174
41.21	1.40814	3.431396	0.8263786	32.33999	3.305515	3.305515
41.34	1.407305	3.44224	0.8301258	32.32083	3.320503	3.320503
41.47	1.409809	3.453063	0.8339007	32.37832	3.335603	3.335603
41.6	1.407703	3.463917	0.8378585	32.32996	3.351434	3.351434
41.73	1.408021	3.47475	0.8420865	32.33725	3.368346	3.368346
41.86	1.406749	3.485583	0.8457343	32.30805	3.382937	3.382937
41.99	1.406471	3.496417	0.8500397	32.30166	3.400159	3.400159
42.12	1.406789	3.50726	0.8540313	32.30896	3.416125	3.416125
42.25	1.407901	3.518094	0.8578519	32.33451	3.431408	3.431408
42.38	1.406471	3.528917	0.8616567	32.30166	3.446627	3.446627
42.51	1.405438	3.53975	0.8655608	32.27794	3.462243	3.462243
42.64	1.405915	3.550573	0.8697391	32.28889	3.478956	3.478956
42.77	1.405597	3.561406	0.8735001	32.28159	3.494	3.494
42.9	1.403411	3.572229	0.8776088	32.23139	3.510435	3.510435
43.03	1.403491	3.583073	0.8815964	32.23322	3.526386	3.526386
43.16	1.404484	3.593896	0.8853137	32.25603	3.541255	3.541255
43.29	1.401901	3.604729	0.8892894	32.19671	3.557158	3.557158
43.42	1.403133	3.615552	0.8932869	32.225	3.573148	3.573148
43.55	1.404127	3.626396	0.897336	32.24782	3.589344	3.589344
43.68	1.40357	3.637219	0.9011884	32.23504	3.604754	3.604754
43.81	1.404842	3.648073	0.905323	32.26425	3.621292	3.621292
43.94	1.402736	3.658885	0.9090583	32.21588	3.636233	3.636233
44.07	1.404285	3.669719	0.9129723	32.25147	3.651889	3.651889
44.2	1.402696	3.680552	0.9169261	32.21497	3.667704	3.667704
44.33	1.401345	3.691406	0.9209017	32.18393	3.683607	3.683607
44.46	1.401981	3.702219	0.9249806	32.19854	3.699923	3.699923
44.59	1.402418	3.713083	0.9284695	32.20858	3.713878	3.713878
44.72	1.401266	3.723906	0.9331385	32.18211	3.732554	3.732554
44.85	1.40353	3.73475	0.9368201	32.23413	3.74728	3.74728
44.98	1.403332	3.745573	0.9409487	32.22956	3.763795	3.763795
45.11	1.403133	3.756427	0.944988	32.225	3.779952	3.779952
45.24	1.402934	3.76725	0.9488364	32.22044	3.795346	3.795346
45.37	1.402656	3.778094	0.952665	32.21405	3.81066	3.81066
45.5	1.402458	3.788917	0.9569108	32.20949	3.827643	3.827643
45.63	1.40214	3.79975	0.9607494	32.20219	3.842998	3.842998
45.76	1.401941	3.810583	0.9647449	32.19762	3.858979	3.858979
45.89	1.401703	3.821417	0.9687424	32.19215	3.874969	3.874969
46.02	1.401464	3.83224	0.9727736	32.18667	3.891094	3.891094
46.15	1.401266	3.843073	0.976487	32.18211	3.905948	3.905948
46.28	1.401186	3.853896	0.9808242	32.18029	3.923297	3.923297
46.41	1.400987	3.864729	0.9845555	32.17572	3.938222	3.938222
46.54	1.400828	3.875562	0.9887278	32.17207	3.954911	3.954911
46.67	1.400669	3.886396	0.9926637	32.16842	3.970655	3.970655
46.8	1.40059	3.897239	0.9964764	32.1666	3.985906	3.985906
46.93	1.400391	3.908052	1.000595	32.16203	4.00238	4.00238
47.06	1.400272	3.918885	1.004614	32.15929	4.018458	4.018458
47.19	1.400113	3.929719	1.00883	32.15564	4.035322	4.035322
47.32	1.399994	3.940562	1.012516	32.1529	4.050064	4.050064
47.45	1.399795	3.951385	1.016668	32.14834	4.066674	4.066674
47.58	1.399597	3.96224	1.020616	32.14378	4.082465	4.082465
47.71	1.399517	3.973063	1.02461	32.14196	4.098439	4.098439
47.84	1.399358	3.983896	1.028784	32.13831	4.115137	4.115137
47.97	1.399199	3.99474	1.032398	32.13465	4.129592	4.129592
48.1	1.39912	4.005583	1.036646	32.13283	4.146584	4.146584
48.23	1.399001	4.016406	1.040492	32.13009	4.16197	4.16197
48.36	1.398921	4.02726	1.044607	32.12827	4.178429	4.178429
48.49	1.398802	4.038083	1.048938	32.12553	4.195754	4.195754
48.62	1.398722	4.048917	1.052475	32.1237	4.2099	4.2099
48.75	1.398643	4.05975	1.056772	32.12188	4.22709	4.22709
48.88	1.398524	4.070594	1.060593	32.11914	4.242373	4.242373
49.01	1.398444	4.081417	1.064756	32.11731	4.259022	4.259022
49.14	1.398325	4.092239	1.068666	32.11458	4.274662	4.274662
49.27	1.398245	4.103073	1.072647	32.11275	4.290589	4.290589
49.4	1.398126	4.113896	1.076754	32.11001	4.307016	4.307016
49.53	1.398047	4.124729	1.080749	32.10819	4.322998	4.322998
49.66	1.397928	4.135562	1.084612	32.10545	4.338447	4.338447
49.79	1.397928	4.146406	1.088738	32.10545	4.354954	4.354954
49.92	1.397848	4.157229	1.092629	32.10363	4.370514	4.370514
50.05	1.397729	4.168063	1.096853	32.10089	4.387411	4.387411
50.18	1.397689	4.178885	1.100556	32.09998	4.402224	4.402224
50.31	1.397649	4.189729	1.104738	32.09906	4.418953	4.418953
50.44	1.39753	4.200552	1.108539	32.09632	4.434156	4.434156
50.57	1.397451	4.211406	1.11257	32.0945	4.450282	4.450282
50.7	1.397451	4.222219	1.116721	32.0945	4.466883	4.466883
50.83	1.397332	4.233062	1.120438	32.09176	4.481753	4.481753
50.96	1.397252	4.243896	1.124779	32.08994	4.499117	4.499117
51.09	1.397133	4.25474	1.128761	32.0872	4.515044	4.515044
51.22	1.397053	4.265563	1.13251	32.08537	4.53004	4.53004
51.35	1.396974	4.276427	1.136879	32.08355	4.547516	4.547516
51.48	1.396855	4.28725	1.140781	32.08081	4.563125	4.563125
51.61	1.396775	4.298083	1.144969	32.07898	4.579878	4.579878
51.74	1.396775	4.308917	1.148744	32.07898	4.594978	4.594978
51.87	1.396656	4.31976	1.152702	32.07625	4.610809	4.610809
52	1.396656	4.330583	1.156936	32.07625	4.627744	4.627744
52.13	1.396656	4.341427	1.160828	32.07625	4.643313	4.643313
52.26	1.396577	4.35225	1.164865	32.07442	4.659462	4.659462
52.39	1.396457	4.363073	1.168996	32.07168	4.675984	4.675984
52.52	1.396457	4.373906	1.172994	32.07168	4.691974	4.691974
52.65	1.396378	4.384739	1.177192	32.06986	4.708767	4.708767
52.78	1.396259	4.395573	1.181161	32.06712	4.724646	4.724646
52.91	1.396259	4.406406	1.185366	32.06712	4.741462	4.741462
53.04	1.396219	4.417229	1.188916	32.06621	4.755664	4.755664
53.17	1.396259	4.428062	1.192848	32.06712	4.771391	4.771391
53.3	1.396179	4.438896	1.197225	32.0653	4.788899	4.788899
53.43	1.396179	4.449718	1.201425	32.0653	4.8057	4.8057
53.56	1.396179	4.460573	1.205268	32.0653	4.82107	4.82107
53.69	1.396179	4.471385	1.20945	32.0653	4.837799	4.837799
53.82	1.396179	4.482219	1.213113	32.0653	4.852454	4.852454
53.95	1.39606	4.493052	1.217365	32.06256	4.869461	4.869461
54.08	1.39606	4.503906	1.221385	32.06256	4.885539	4.885539
54.21	1.39598	4.514729	1.225418	32.06073	4.901671	4.901671
54.34	1.395861	4.525583	1.22938	32.058	4.917518	4.917518
54.47	1.395782	4.536406	1.233407	32.05617	4.933628	4.933628
54.6	1.395663	4.547239	1.237599	32.05343	4.950396	4.950396
54.73	1.395583	4.558083	1.241601	32.05161	4.966402	4.966402
54.86	1.395583	4.568927	1.245505	32.05161	4.982018	4.982018
54.99	1.395464	4.57975	1.249776	32.04887	4.999105	4.999105
55.12	1.395384	4.590594	1.253742	32.04704	5.014968	5.014968
55.25	1.395384	4.601417	1.257747	32.04704	5.03099	5.03099
55.38	1.395305	4.61225	1.261654	32.04522	5.046614	5.046614
55.51	1.395305	4.623083	1.265869	32.04522	5.063478	5.063478
55.64	1.395186	4.633906	1.269919	32.04248	5.079675	5.079675
55.77	1.395106	4.64474	1.273827	32.04066	5.095307	5.095307
55.9	1.394987	4.655562	1.277812	32.03792	5.111249	5.111249
56.03	1.394908	4.666406	1.28212	32.03609	5.128479	5.128479
56.16	1.394788	4.677229	1.285557	32.03336	5.142228	5.142228
56.29	1.394788	4.688063	1.290443	32.03336	5.16177	5.16177
56.42	1.394709	4.698896	1.293814	32.03153	5.175257	5.175257
56.55	1.394709	4.70974	1.297808	32.03153	5.191231	5.191231
56.68	1.394709	4.720552	1.302379	32.03153	5.209517	5.209517
56.81	1.394709	4.731385	1.306333	32.03153	5.225333	5.225333
56.94	1.394788	4.742218	1.3101	32.03336	5.240401	5.240401
57.07	1.394788	4.753062	1.314378	32.03336	5.257511	5.257511
57.2	1.394788	4.763885	1.318175	32.03336	5.272698	5.272698
57.33	1.394908	4.77474	1.322526	32.03609	5.290103	5.290103
57.46	1.394908	4.785563	1.326507	32.03609	5.306029	5.306029
57.59	1.394908	4.796406	1.330519	32.03609	5.322075	5.322075
57.72	1.394788	4.80724	1.334796	32.03336	5.339185	5.339185
57.85	1.394788	4.818094	1.338468	32.03336	5.353872	5.353872
57.98	1.394788	4.828917	1.342815	32.03336	5.371261	5.371261
58.11	1.394788	4.83976	1.346926	32.03336	5.387703	5.387703
58.24	1.394788	4.850583	1.350812	32.03336	5.403248	5.403248
58.37	1.394788	4.861417	1.354786	32.03336	5.419143	5.419143
58.5	1.394788	4.87225	1.358696	32.03336	5.434783	5.434783
58.63	1.394788	4.883094	1.362828	32.03336	5.451313	5.451313
58.76	1.394788	4.893917	1.367042	32.03336	5.46817	5.46817
58.89	1.394788	4.90475	1.371179	32.03336	5.484716	5.484716
59.02	1.394709	4.915573	1.375053	32.03153	5.500213	5.500213
59.15	1.39459	4.926396	1.379003	32.02879	5.516013	5.516013
59.28	1.39459	4.937229	1.38308	32.02879	5.53232	5.53232
59.41	1.39451	4.948062	1.387105	32.02697	5.548421	5.548421
59.54	1.39451	4.958906	1.391343	32.02697	5.565373	5.565373
59.67	1.394431	4.969719	1.395327	32.02514	5.581307	5.581307
59.8	1.394391	4.980562	1.399608	32.02423	5.598434	5.598434
59.93	1.394391	4.991385	1.403362	32.02423	5.613446	5.613446
60.06	1.39451	5.002229	1.407782	32.02697	5.631129	5.631129
60.19	1.394391	5.013052	1.411664	32.02423	5.646658	5.646658
60.32	1.394391	5.023896	1.415551	32.02423	5.662203	5.662203
60.45	1.394391	5.034729	1.419822	32.02423	5.679289	5.679289
60.58	1.394391	5.045562	1.423566	32.02423	5.694262	5.694262
60.71	1.394391	5.056396	1.427954	32.02423	5.711818	5.711818
60.84	1.394312	5.06725	1.431978	32.0224	5.727911	5.727911
60.97	1.394312	5.078073	1.435951	32.0224	5.743805	5.743805
61.1	1.394312	5.088927	1.440271	32.0224	5.761083	5.761083
61.23	1.394192	5.09975	1.443956	32.01967	5.775825	5.775825
61.36	1.394312	5.110583	1.448268	32.0224	5.793071	5.793071
61.49	1.394192	5.121417	1.452231	32.01967	5.808926	5.808926
61.62	1.394312	5.13226	1.45641	32.0224	5.825639	5.825639
61.75	1.394312	5.143083	1.460314	32.0224	5.841255	5.841255
61.88	1.394312	5.153927	1.464385	32.0224	5.857539	5.857539
62.01	1.394391	5.16475	1.468414	32.02423	5.873656	5.873656
62.14	1.39451	5.175573	1.47238	32.02697	5.889519	5.889519
62.27	1.39451	5.186406	1.47654	32.02697	5.906161	5.906161
62.4	1.39459	5.197239	1.480496	32.02879	5.921984	5.921984
62.53	1.39459	5.208073	1.484658	32.02879	5.938633	5.938633
62.66	1.39459	5.218896	1.488715	32.02879	5.954862	5.954862
62.79	1.394629	5.229729	1.492818	32.02971	5.971273	5.971273
62.92	1.39459	5.240562	1.496559	32.02879	5.986238	5.986238
63.05	1.39459	5.251396	1.500793	32.02879	6.003173	6.003173
63.18	1.39451	5.262218	1.504908	32.02697	6.019632	6.019632
63.31	1.39451	5.273073	1.508737	32.02697	6.034946	6.034946
63.44	1.39451	5.283896	1.513406	32.02697	6.053623	6.053623
63.57	1.39451	5.294729	1.517415	32.02697	6.06966	6.06966
63.7	1.39451	5.305562	1.521256	32.02697	6.085022	6.085022
63.83	1.39459	5.316406	1.525362	32.02879	6.101449	6.101449
63.96	1.39459	5.327229	1.529264	32.02879	6.117058	6.117058
64.09	1.39459	5.338083	1.533397	32.02879	6.133588	6.133588
64.22	1.39459	5.348906	1.537325	32.02879	6.1493	6.1493
64.35	1.39459	5.35975	1.541185	32.02879	6.164742	6.164742
64.48	1.39459	5.370583	1.545725	32.02879	6.182901	6.182901
64.61	1.39459	5.381427	1.550051	32.02879	6.200202	6.200202
64.74	1.394709	5.39225	1.553875	32.03153	6.215501	6.215501
64.87	1.394709	5.403094	1.557998	32.03153	6.231991	6.231991
65	1.394709	5.413917	1.561765	32.03153	6.247059	6.247059
65.13	1.394709	5.42475	1.565886	32.03153	6.263542	6.263542
65.26	1.394788	5.435583	1.570072	32.03336	6.280287	6.280287
65.39	1.394788	5.446416	1.573827	32.03336	6.295308	6.295308
65.52	1.394908	5.45724	1.578275	32.03609	6.313101	6.313101
65.65	1.394908	5.468073	1.582148	32.03609	6.328591	6.328591
65.78	1.394987	5.478896	1.586419	32.03792	6.345677	6.345677
65.91	1.395027	5.489739	1.590325	32.03883	6.361302	6.361302
66.04	1.395106	5.500573	1.594214	32.04066	6.376854	6.376854
66.17	1.395186	5.511396	1.598501	32.04248	6.394005	6.394005
66.3	1.395305	5.52224	1.602451	32.04522	6.409804	6.409804
66.43	1.395305	5.533062	1.606476	32.04522	6.425905	6.425905
66.56	1.395305	5.543885	1.61101	32.04522	6.444041	6.444041
66.69	1.395345	5.554729	1.614716	32.04613	6.458863	6.458863
66.82	1.395384	5.565552	1.61886	32.04704	6.475441	6.475441
66.95	1.395305	5.576375	1.622989	32.04522	6.491955	6.491955
67.08	1.395305	5.58724	1.626899	32.04522	6.507596	6.507596
67.21	1.395305	5.598052	1.631167	32.04522	6.524666	6.524666
67.34	1.395305	5.608896	1.635041	32.04522	6.540164	6.540164
67.47	1.395186	5.61974	1.639221	32.04248	6.556884	6.556884
67.6	1.395186	5.630583	1.643354	32.04248	6.573415	6.573415
67.73	1.395186	5.641406	1.6475	32.04248	6.590001	6.590001
67.86	1.395305	5.65225	1.651553	32.04522	6.606213	6.606213
67.99	1.395305	5.663073	1.655406	32.04522	6.621623	6.621623
68.12	1.395305	5.673917	1.659914	32.04522	6.639656	6.639656
68.25	1.395305	5.68474	1.663758	32.04522	6.655034	6.655034
68.38	1.395384	5.695583	1.668	32.04704	6.672001	6.672001
68.51	1.395384	5.706406	1.671731	32.04704	6.686926	6.686926
68.64	1.395384	5.717239	1.676003	32.04704	6.704012	6.704012
68.77	1.395384	5.728063	1.679522	32.04704	6.718087	6.718087
68.9	1.395384	5.738896	1.684101	32.04704	6.736406	6.736406
69.03	1.395384	5.749719	1.688047	32.04704	6.752189	6.752189
69.16	1.395464	5.760562	1.6921	32.04887	6.768402	6.768402
69.29	1.395464	5.771396	1.696229	32.04887	6.784916	6.784916
69.42	1.395464	5.782218	1.700429	32.04887	6.801716	6.801716
69.55	1.395583	5.793052	1.704301	32.05161	6.817206	6.817206
69.68	1.395583	5.803885	1.708333	32.05161	6.833331	6.833331
69.81	1.395663	5.814719	1.712714	32.05343	6.850854	6.850854
69.94	1.395782	5.825541	1.716503	32.05617	6.86601	6.86601
70.07	1.395782	5.836396	1.720736	32.05617	6.882946	6.882946
70.2	1.395782	5.847219	1.724706	32.05617	6.898824	6.898824
70.33	1.395782	5.858052	1.728741	32.05617	6.914965	6.914965
70.46	1.395861	5.868896	1.73263	32.058	6.930518	6.930518
70.59	1.395861	5.879739	1.737209	32.058	6.948837	6.948837
70.72	1.395861	5.890563	1.741401	32.058	6.965605	6.965605
70.85	1.395861	5.901417	1.74517	32.058	6.980681	6.980681
70.98	1.395861	5.91225	1.74946	32.058	6.997839	6.997839
71.11	1.395861	5.923083	1.753139	32.058	7.012558	7.012558
71.24	1.395861	5.933917	1.75762	32.058	7.030479	7.030479
71.37	1.395861	5.94476	1.761375	32.058	7.045499	7.045499
71.5	1.395861	5.955583	1.765307	32.058	7.061227	7.061227
71.63	1.395782	5.966406	1.769714	32.05617	7.078854	7.078854
71.76	1.395782	5.97724	1.773874	32.05617	7.095496	7.095496
71.89	1.395663	5.988062	1.777967	32.05343	7.111867	7.111867
72.02	1.395663	5.998896	1.781974	32.05343	7.127897	7.127897
72.15	1.395663	6.009729	1.785932	32.05343	7.143728	7.143728
72.28	1.395663	6.020563	1.790156	32.05343	7.160624	7.160624
72.41	1.395663	6.031396	1.794289	32.05343	7.177154	7.177154
72.54	1.395663	6.042219	1.798463	32.05343	7.193851	7.193851
72.67	1.395663	6.053052	1.802222	32.05343	7.208888	7.208888
72.8	1.395663	6.063885	1.806116	32.05343	7.224464	7.224464
72.93	1.395663	6.074718	1.810503	32.05343	7.242012	7.242012
73.06	1.395782	6.085562	1.814393	32.05617	7.257573	7.257573
73.19	1.395782	6.096385	1.818522	32.05617	7.274087	7.274087
73.32	1.395861	6.107219	1.822553	32.058	7.290212	7.290212
73.45	1.39598	6.118052	1.826557	32.06073	7.306226	7.306226
73.58	1.39598	6.128896	1.830608	32.06073	7.322431	7.322431
73.71	1.39606	6.139729	1.83474	32.06256	7.338961	7.338961
73.84	1.39606	6.150583	1.83897	32.06256	7.355881	7.355881
73.97	1.39606	6.161396	1.842543	32.06256	7.37017	7.37017
74.1	1.396179	6.172239	1.846778	32.0653	7.387114	7.387114
74.23	1.396179	6.183083	1.850905	32.0653	7.40362	7.40362
74.36	1.396179	6.193927	1.85503	32.0653	7.420119	7.420119
74.49	1.396259	6.20475	1.85916	32.06712	7.436641	7.436641
74.62	1.396259	6.215594	1.863052	32.06712	7.45221	7.45221
74.75	1.396378	6.226417	1.866996	32.06986	7.467985	7.467985
74.88	1.396378	6.237239	1.8712	32.06986	7.484802	7.484802
75.01	1.396378	6.248073	1.875236	32.06986	7.500943	7.500943
75.14	1.396457	6.258896	1.879227	32.07168	7.516909	7.516909
75.27	1.396378	6.26974	1.88339	32.06986	7.533558	7.533558
75.4	1.396457	6.280562	1.887147	32.07168	7.548586	7.548586
75.53	1.396457	6.291396	1.89143	32.07168	7.565721	7.565721
75.66	1.396457	6.302229	1.895658	32.07168	7.582633	7.582633
75.79	1.396577	6.313063	1.89925	32.07442	7.597002	7.597002
75.92	1.396577	6.323896	1.903731	32.07442	7.614923	7.614923
76.05	1.396577	6.334729	1.907454	32.07442	7.629816	7.629816
76.18	1.396656	6.345552	1.911734	32.07625	7.646934	7.646934
76.31	1.396656	6.356385	1.916011	32.07625	7.664045	7.664045
76.44	1.396656	6.367218	1.919854	32.07625	7.679415	7.679415
76.57	1.396656	6.378062	1.924103	32.07625	7.696414	7.696414
76.7	1.396577	6.388885	1.927783	32.07442	7.711133	7.711133
76.83	1.396577	6.39974	1.931991	32.07442	7.727965	7.727965
76.96	1.396577	6.410563	1.936038	32.07442	7.744153	7.744153
77.09	1.396577	6.421396	1.940177	32.07442	7.760707	7.760707
77.22	1.396577	6.432229	1.944488	32.07442	7.777953	7.777953
77.35	1.396577	6.443083	1.948148	32.07442	7.792592	7.792592
77.48	1.396577	6.453906	1.952521	32.07442	7.810084	7.810084
77.61	1.396577	6.46476	1.956817	32.07442	7.827266	7.827266
77.74	1.396656	6.475583	1.960395	32.07625	7.841579	7.841579
77.87	1.396656	6.486417	1.964744	32.07625	7.858976	7.858976
78	1.396656	6.49725	1.96838	32.07625	7.873519	7.873519
78.13	1.396775	6.508083	1.972284	32.07898	7.889136	7.889136
78.26	1.396775	6.518917	1.976732	32.07898	7.906929	7.906929
78.39	1.396775	6.529739	1.98072	32.07898	7.92288	7.92288
78.52	1.396855	6.540573	1.984682	32.08081	7.938727	7.938727
78.65	1.396855	6.551396	1.988798	32.08081	7.955194	7.955194
78.78	1.396974	6.562229	1.992935	32.08355	7.97174	7.97174
78.91	1.396974	6.573062	1.996648	32.08355	7.986593	7.986593
79.04	1.396974	6.583906	2.001381	32.08355	8.005524	8.005524
79.17	1.397053	6.594718	2.004977	32.08537	8.019908	8.019908
79.3	1.397053	6.605562	2.008885	32.08537	8.035541	8.035541
79.43	1.397133	6.616385	2.012811	32.0872	8.051245	8.051245
79.56	1.397133	6.627229	2.017109	32.0872	8.068435	8.068435
79.69	1.397133	6.638041	2.02104	32.0872	8.084162	8.084162
79.82	1.397173	6.648906	2.025269	32.08811	8.101074	8.101074
79.95	1.397252	6.659719	2.029155	32.08994	8.116619	8.116619
80.08	1.397252	6.670552	2.033424	32.08994	8.133698	8.133698
80.21	1.397252	6.681396	2.037473	32.08994	8.149894	8.149894
80.34	1.397252	6.692239	2.04124	32.08994	8.164962	8.164962
80.47	1.397252	6.703063	2.045427	32.08994	8.181707	8.181707
80.6	1.397252	6.713917	2.049561	32.08994	8.198245	8.198245
80.73	1.397252	6.72474	2.053326	32.08994	8.213305	8.213305
80.86	1.397252	6.735583	2.057298	32.08994	8.229192	8.229192
80.99	1.397252	6.746417	2.061439	32.08994	8.245754	8.245754
81.12	1.397252	6.75726	2.065605	32.08994	8.26242	8.26242
81.25	1.397252	6.768083	2.069722	32.08994	8.278887	8.278887
81.38	1.397252	6.778916	2.073858	32.08994	8.295433	8.295433
81.51	1.397252	6.78974	2.077822	32.08994	8.311288	8.311288
81.64	1.397332	6.800573	2.081859	32.09176	8.327436	8.327436
81.77	1.397332	6.811406	2.08601	32.09176	8.344038	8.344038
81.9	1.397451	6.822239	2.089733	32.0945	8.358932	8.358932
82.03	1.39753	6.833073	2.093778	32.09632	8.375113	8.375113
82.16	1.397649	6.843896	2.097811	32.09906	8.391245	8.391245
82.29	1.397729	6.854729	2.102208	32.10089	8.408833	8.408833
82.42	1.397729	6.865562	2.1059	32.10089	8.423598	8.423598
[...]
67.05	1.34027	5.58474	1.361074	30.67919	5.444296	5.444296
67.2	1.340389	5.597229	1.365316	30.68192	5.461264	5.461264
67.35	1.340389	5.609708	1.369707	30.68192	5.478827	5.478827
67.5	1.340389	5.622208	1.37399	30.68192	5.495962	5.495962
67.65	1.340469	5.634739	1.37858	30.68374	5.51432	5.51432
67.8	1.340389	5.64724	1.382911	30.68192	5.531645	5.531645
67.95	1.340389	5.659729	1.387572	30.68192	5.550289	5.550289
68.1	1.34027	5.672208	1.391745	30.67919	5.566978	5.566978
68.25	1.34027	5.684719	1.396088	30.67919	5.584351	5.584351
68.4	1.340191	5.697229	1.400415	30.67737	5.60166	5.60166
68.55	1.340071	5.70974	1.405015	30.67465	5.620059	5.620059
68.7	1.339992	5.722229	1.40962	30.67283	5.63848	5.63848
68.85	1.339992	5.734708	1.413745	30.67283	5.654979	5.654979
69	1.339992	5.747219	1.418239	30.67283	5.672956	5.672956
69.15	1.340071	5.759739	1.422731	30.67465	5.690924	5.690924
69.3	1.340071	5.77224	1.427136	30.67465	5.708543	5.708543
69.45	1.340191	5.784729	1.431549	30.67737	5.726194	5.726194
69.6	1.34027	5.797208	1.435858	30.67919	5.743432	5.743432
69.75	1.34027	5.809719	1.440362	30.67919	5.761448	5.761448
69.9	1.340389	5.822239	1.444395	30.68192	5.777582	5.777582
70.05	1.340389	5.83474	1.449299	30.68192	5.797195	5.797195
70.2	1.340469	5.847229	1.453652	30.68374	5.814608	5.814608
70.35	1.340469	5.859708	1.457967	30.68374	5.83187	5.83187
70.5	1.340469	5.872219	1.462618	30.68374	5.850474	5.850474
70.65	1.340469	5.884729	1.467156	30.68374	5.868626	5.868626
70.8	1.340469	5.89724	1.471128	30.68374	5.884512	5.884512
70.95	1.340469	5.909729	1.475791	30.68374	5.903164	5.903164
71.1	1.340389	5.922208	1.479967	30.68192	5.91987	5.91987
71.25	1.340389	5.934719	1.484503	30.68192	5.938014	5.938014
71.4	1.340389	5.947239	1.488791	30.68192	5.955163	5.955163
71.55	1.340389	5.95975	1.493595	30.68192	5.97438	5.97438
71.7	1.340469	5.972229	1.497954	30.68374	5.991817	5.991817
71.85	1.340469	5.984708	1.502224	30.68374	6.008895	6.008895
72	1.340469	5.997219	1.50666	30.68374	6.026641	6.026641
72.15	1.340469	6.009739	1.511327	30.68374	6.04531	6.04531
72.3	1.340508	6.02224	1.515591	30.68465	6.062365	6.062365
72.45	1.340588	6.034729	1.520091	30.68647	6.080365	6.080365
72.6	1.340588	6.047208	1.52457	30.68647	6.098279	6.098279
72.75	1.340588	6.059719	1.529201	30.68647	6.116804	6.116804
72.9	1.340588	6.072239	1.533385	30.68647	6.133541	6.133541
73.05	1.340588	6.08474	1.537774	30.68647	6.151096	6.151096
73.2	1.340588	6.097229	1.542278	30.68647	6.169113	6.169113
73.35	1.340588	6.109708	1.546749	30.68647	6.186994	6.186994
73.5	1.340588	6.122219	1.551036	30.68647	6.204144	6.204144
73.65	1.340588	6.134739	1.555739	30.68647	6.222955	6.222955
73.8	1.340667	6.14724	1.559957	30.68829	6.239828	6.239828
73.95	1.340667	6.159729	1.564687	30.68829	6.25875	6.25875
74.1	1.340747	6.172208	1.5688	30.69011	6.275201	6.275201
74.25	1.340866	6.184719	1.573559	30.69284	6.294235	6.294235
74.4	1.340866	6.197239	1.578365	30.69284	6.313459	6.313459
74.55	1.340946	6.20974	1.582609	30.69466	6.330434	6.330434
74.7	1.340946	6.222229	1.587011	30.69466	6.348046	6.348046
74.85	1.341065	6.234708	1.591557	30.69739	6.366229	6.366229
75	1.341065	6.247219	1.59597	30.69739	6.38388	6.38388
75.15	1.341065	6.259739	1.600569	30.69739	6.402278	6.402278
75.3	1.341065	6.27225	1.605056	30.69739	6.420223	6.420223
75.45	1.341065	6.284729	1.609711	30.69739	6.438843	6.438843
75.6	1.341065	6.297208	1.613969	30.69739	6.455874	6.455874
75.75	1.341065	6.309719	1.618246	30.69739	6.472985	6.472985
75.9	1.341144	6.322239	1.622822	30.69921	6.491288	6.491288
76.05	1.341144	6.33475	1.627388	30.69921	6.509551	6.509551
76.2	1.341263	6.347229	1.631739	30.70193	6.526955	6.526955
76.35	1.341343	6.359708	1.636221	30.70375	6.544884	6.544884
76.5	1.341343	6.372208	1.640904	30.70375	6.563616	6.563616
76.65	1.341462	6.384739	1.645323	30.70648	6.581291	6.581291
76.8	1.341462	6.39724	1.649668	30.70648	6.598671	6.598671
76.95	1.341462	6.409729	1.654287	30.70648	6.617149	6.617149
77.1	1.341343	6.422208	1.658455	30.70375	6.633822	6.633822
77.25	1.341343	6.434719	1.663323	30.70375	6.653293	6.653293
77.4	1.341263	6.447239	1.667784	30.70193	6.671134	6.671134
77.55	1.341144	6.45975	1.672226	30.69921	6.688905	6.688905
77.7	1.341144	6.472229	1.676824	30.69921	6.707295	6.707295
77.85	1.341144	6.484708	1.681646	30.69921	6.726583	6.726583
78	1.341144	6.497219	1.685659	30.69921	6.742636	6.742636
78.15	1.341263	6.509739	1.690014	30.70193	6.760057	6.760057
78.3	1.341343	6.52224	1.694534	30.70375	6.778137	6.778137
78.45	1.341343	6.534729	1.699535	30.70375	6.79814	6.79814
78.6	1.341462	6.547208	1.703705	30.70648	6.814822	6.814822
78.75	1.341542	6.559719	1.707804	30.7083	6.831217	6.831217
78.9	1.341661	6.572239	1.712314	30.71103	6.849257	6.849257
79.05	1.341701	6.58474	1.71724	30.71194	6.868958	6.868958
79.2	1.341661	6.597229	1.721825	30.71103	6.887301	6.887301
79.35	1.34174	6.609708	1.726127	30.71285	6.904507	6.904507
79.5	1.34174	6.622219	1.73047	30.71285	6.921879	6.921879
79.65	1.34174	6.634739	1.735145	30.71285	6.940579	6.940579
79.8	1.341859	6.64724	1.739715	30.71558	6.958858	6.958858
79.95	1.341859	6.659729	1.744376	30.71558	6.977502	6.977502
80.1	1.341859	6.672208	1.748689	30.71558	6.994756	6.994756
80.25	1.341859	6.684719	1.753269	30.71558	7.013074	7.013074
80.4	1.34174	6.697229	1.757715	30.71285	7.03086	7.03086
80.55	1.341859	6.70974	1.762209	30.71558	7.048837	7.048837
80.7	1.34174	6.722229	1.766843	30.71285	7.06737	7.06737
80.85	1.34174	6.734708	1.771295	30.71285	7.08518	7.08518
81	1.34174	6.747219	1.776032	30.71285	7.104126	7.104126
81.15	1.34174	6.759739	1.780399	30.71285	7.121595	7.121595
81.3	1.341859	6.77224	1.784875	30.71558	7.1395	7.1395
81.45	1.341939	6.784729	1.789488	30.7174	7.157954	7.157954
81.6	1.341939	6.797208	1.793951	30.7174	7.175803	7.175803
81.75	1.342058	6.809719	1.798069	30.72013	7.192278	7.192278
81.9	1.342058	6.822239	1.802669	30.72013	7.210676	7.210676
82.05	1.342138	6.83475	1.807475	30.72194	7.2299	7.2299
82.2	1.342058	6.847229	1.811828	30.72013	7.247313	7.247313
82.35	1.342138	6.859708	1.816436	30.72194	7.265743	7.265743
82.5	1.342177	6.872219	1.821105	30.72285	7.284419	7.284419
82.65	1.342257	6.884739	1.825821	30.72467	7.303286	7.303286
82.8	1.342336	6.89725	1.82995	30.72649	7.3198	7.3198
82.95	1.342336	6.909729	1.834607	30.72649	7.338428	7.338428
83.1	1.342376	6.922208	1.839008	30.7274	7.356032	7.356032
83.25	1.342416	6.934719	1.843683	30.72831	7.374732	7.374732
83.4	1.342416	6.947239	1.848014	30.72831	7.392057	7.392057
83.55	1.342535	6.95975	1.852703	30.73104	7.410812	7.410812
83.7	1.342615	6.972229	1.85703	30.73286	7.428122	7.428122
83.85	1.342734	6.984708	1.861602	30.73559	7.446408	7.446408
84	1.342813	6.997219	1.866212	30.73741	7.464846	7.464846
84.15	1.342813	7.009739	1.870517	30.73741	7.482068	7.482068
84.3	1.342932	7.02224	1.875389	30.74014	7.501554	7.501554
84.45	1.342932	7.034729	1.880004	30.74014	7.520016	7.520016
84.6	1.342932	7.047208	1.884647	30.74014	7.538589	7.538589
84.75	1.342932	7.059719	1.888905	30.74014	7.55562	7.55562
84.9	1.342932	7.072239	1.893193	30.74014	7.57277	7.57277
85.05	1.342932	7.08474	1.898219	30.74014	7.592877	7.592877
85.2	1.342932	7.097229	1.902807	30.74014	7.611227	7.611227
85.35	1.342932	7.109719	1.907251	30.74014	7.629005	7.629005
85.5	1.342932	7.122219	1.91167	30.74014	7.64668	7.64668
85.65	1.342932	7.134739	1.916069	30.74014	7.664275	7.664275
85.8	1.342932	7.14725	1.920833	30.74014	7.683333	7.683333
85.95	1.342932	7.159729	1.925429	30.74014	7.701715	7.701715
86.1	1.342932	7.172208	1.929832	30.74014	7.719326	7.719326
86.25	1.343012	7.184719	1.934439	30.74196	7.737756	7.737756
86.4	1.343012	7.197239	1.939009	30.74196	7.756034	7.756034
86.55	1.343211	7.20975	1.943618	30.7465	7.774472	7.774472
86.7	1.343211	7.222229	1.94818	30.7465	7.792719	7.792719
86.85	1.34333	7.234708	1.952603	30.74923	7.81041	7.81041
87	1.34333	7.247219	1.957166	30.74923	7.828665	7.828665
87.15	1.34333	7.259739	1.961553	30.74923	7.846212	7.846212
87.3	1.34333	7.27225	1.965922	30.74923	7.863688	7.863688
87.45	1.343211	7.284729	1.970806	30.7465	7.883223	7.883223
87.6	1.34333	7.297219	1.975201	30.74923	7.900802	7.900802
87.75	1.343211	7.309708	1.979909	30.7465	7.919637	7.919637
87.9	1.34333	7.322239	1.984302	30.74923	7.937209	7.937209
88.05	1.34333	7.33475	1.988924	30.74923	7.955694	7.955694
88.2	1.34333	7.347229	1.99373	30.74923	7.974919	7.974919
88.35	1.34333	7.359708	1.998093	30.74923	7.992371	7.992371
88.5	1.34333	7.372219	2.002947	30.74923	8.011786	8.011786
88.65	1.343409	7.384739	2.007393	30.75105	8.029572	8.029572
88.8	1.343409	7.39725	2.012032	30.75105	8.048129	8.048129
88.95	1.343528	7.409729	2.016407	30.75378	8.065629	8.065629
89.1	1.343528	7.422208	2.020987	30.75378	8.083947	8.083947
89.25	1.343608	7.434719	2.025616	30.7556	8.102465	8.102465
89.4	1.343727	7.44725	2.02984	30.75833	8.119361	8.119361
89.55	1.343727	7.45975	2.034519	30.75833	8.138077	8.138077
89.7	1.343727	7.472229	2.038856	30.75833	8.155425	8.155425
89.85	1.343807	7.484708	2.043607	30.76015	8.174427	8.174427
90	1.343727	7.497219	2.048038	30.75833	8.19215	8.19215
90.15	1.343807	7.509739	2.053136	30.76015	8.212543	8.212543
90.3	1.343727	7.52224	2.057211	30.75833	8.228843	8.228843
90.45	1.343727	7.534729	2.06155	30.75833	8.2462	8.2462
90.6	1.343727	7.547208	2.066479	30.75833	8.265917	8.265917
90.75	1.343727	7.559719	2.07123	30.75833	8.284919	8.284919
90.9	1.343727	7.57225	2.075456	30.75833	8.301823	8.301823
91.05	1.343727	7.58474	2.080003	30.75833	8.320014	8.320014
91.2	1.343807	7.597229	2.084857	30.76015	8.339429	8.339429
91.35	1.343807	7.609719	2.089338	30.76015	8.35735	8.35735
91.5	1.343886	7.622208	2.093852	30.76196	8.375406	8.375406
91.65	1.343886	7.634729	2.098304	30.76196	8.393216	8.393216
91.8	1.344005	7.647229	2.102943	30.76469	8.411773	8.411773
91.95	1.344085	7.659729	2.1073	30.76651	8.429201	8.429201
92.1	1.344085	7.672198	2.112077	30.76651	8.448307	8.448307
92.25	1.344085	7.684708	2.116609	30.76651	8.466434	8.466434
92.4	1.344085	7.697229	2.121339	30.76651	8.485357	8.485357
92.55	1.344085	7.709729	2.125708	30.76651	8.502833	8.502833
92.7	1.344085	7.722219	2.130252	30.76651	8.521008	8.521008
92.85	1.344085	7.734698	2.134816	30.76651	8.539264	8.539264
93	1.344085	7.747208	2.139062	30.76651	8.556247	8.556247
93.15	1.344085	7.759739	2.143979	30.76651	8.575916	8.575916
93.3	1.344085	7.77224	2.148495	30.76651	8.593981	8.593981
93.45	1.344204	7.784729	2.152969	30.76924	8.611877	8.611877
93.6	1.344204	7.797208	2.15766	30.76924	8.630641	8.630641
93.75	1.344283	7.809719	2.162248	30.77106	8.648992	8.648992
93.9	1.344283	7.822229	2.166877	30.77106	8.667509	8.667509
94.05	1.344403	7.83474	2.171574	30.77379	8.686296	8.686296
94.2	1.344403	7.847219	2.176271	30.77379	8.705084	8.705084
94.35	1.344482	7.859708	2.180513	30.77561	8.722051	8.722051
94.5	1.344482	7.872219	2.185315	30.77561	8.74126	8.74126
94.65	1.344403	7.884729	2.189789	30.77379	8.759157	8.759157
94.8	1.344482	7.89724	2.194222	30.77561	8.776887	8.776887
94.95	1.344403	7.909729	2.198772	30.77379	8.795087	8.795087
95.1	1.344482	7.922198	2.20321	30.77561	8.81284	8.81284
95.25	1.344482	7.934719	2.207746	30.77561	8.830984	8.830984
95.4	1.344482	7.947239	2.212435	30.77561	8.84974	8.84974
95.55	1.344601	7.95974	2.217255	30.77834	8.86902	8.86902
95.7	1.344601	7.972219	2.221676	30.77834	8.886703	8.886703
95.85	1.344681	7.984698	2.226025	30.78016	8.904099	8.904099
96	1.344681	7.997219	2.230901	30.78016	8.923602	8.923602
96.15	1.344681	8.00974	2.235286	30.78016	8.941142	8.941142
96.3	1.3448	8.022229	2.239994	30.78289	8.959977	8.959977
96.45	1.3448	8.034719	2.244514	30.78289	8.978057	8.978057
96.6	1.3448	8.047208	2.248998	30.78289	8.995994	8.995994
96.75	1.34488	8.059719	2.253691	30.78471	9.014766	9.014766
96.9	1.34488	8.07224	2.258166	30.78471	9.032662	9.032662
97.05	1.344999	8.084729	2.262707	30.78743	9.05083	9.05083
97.2	1.344999	8.097229	2.267432	30.78743	9.069729	9.069729
97.35	1.344999	8.109708	2.271771	30.78743	9.087086	9.087086
97.5	1.344999	8.122209	2.27651	30.78743	9.10604	9.10604
97.65	1.344999	8.13474	2.281044	30.78743	9.124176	9.124176
97.8	1.344999	8.14724	2.285759	30.78743	9.143035	9.143035
97.95	1.345078	8.159729	2.290116	30.78925	9.160463	9.160463
98.1	1.345078	8.172208	2.294932	30.78925	9.179728	9.179728
98.25	1.345197	8.184719	2.29951	30.79198	9.198038	9.198038
98.4	1.345197	8.19724	2.304157	30.79198	9.216626	9.216626
98.55	1.345396	8.20974	2.30875	30.79653	9.235001	9.235001
98.7	1.345396	8.222229	2.313038	30.79653	9.252151	9.252151
98.85	1.345476	8.234708	2.317828	30.79835	9.271312	9.271312
99	1.345476	8.247219	2.32234	30.79835	9.28936	9.28936
99.15	1.345476	8.25974	2.326602	30.79835	9.306407	9.306407
99.3	1.345476	8.27224	2.331535	30.79835	9.32614	9.32614
99.45	1.345436	8.284729	2.335823	30.79744	9.34329	9.34329
99.6	1.345396	8.297208	2.340251	30.79653	9.361005	9.361005
99.75	1.345396	8.309709	2.345312	30.79653	9.381247	9.381247
99.9	1.345396	8.32224	2.349631	30.79653	9.398524	9.398524
100.05	1.345396	8.33474	2.354356	30.79653	9.417422	9.417422
100.2	1.345476	8.347219	2.358985	30.79835	9.43594	9.43594
100.35	1.345476	8.359708	2.363243	30.79835	9.452971	9.452971
100.5	1.345555	8.372209	2.368269	30.80017	9.473078	9.473078
100.65	1.345555	8.38474	2.372764	30.80017	9.491055	9.491055
100.8	1.345555	8.39724	2.377232	30.80017	9.508927	9.508927
100.95	1.345555	8.409729	2.381812	30.80017	9.527246	9.527246
101.1	1.345555	8.422208	2.386385	30.80017	9.545541	9.545541
101.25	1.345555	8.434719	2.390857	30.80017	9.56343	9.56343
101.4	1.345476	8.44724	2.395493	30.79835	9.581971	9.581971
101.55	1.345476	8.45974	2.400092	30.79835	9.600369	9.600369
101.7	1.345396	8.472229	2.404581	30.79653	9.618322	9.618322
101.85	1.345476	8.484708	2.409111	30.79835	9.636442	9.636442
102	1.345476	8.497219	2.413901	30.79835	9.655602	9.655602
102.15	1.345476	8.50974	2.418204	30.79835	9.672816	9.672816
102.3	1.345555	8.52224	2.422823	30.80017	9.691294	9.691294
102.45	1.345674	8.534729	2.4275	30.8029	9.710002	9.710002
102.6	1.345754	8.547208	2.432029	30.80472	9.728114	9.728114
102.75	1.345873	8.559719	2.436316	30.80745	9.745264	9.745264
102.9	1.345913	8.57224	2.441416	30.80835	9.765665	9.765665
103.05	1.345952	8.58474	2.445602	30.80927	9.78241	9.78241
103.2	1.345952	8.597229	2.45045	30.80927	9.801801	9.801801
103.35	1.346072	8.609708	2.454932	30.81199	9.81973	9.81973
103.5	1.346072	8.622219	2.459462	30.81199	9.83785	9.83785
103.65	1.346072	8.63474	2.464149	30.81199	9.856598	9.856598
103.8	1.346072	8.64724	2.468421	30.81199	9.873684	9.873684
103.95	1.346072	8.659729	2.473344	30.81199	9.893377	9.893377
104.1	1.346072	8.672208	2.477692	30.81199	9.910767	9.910767
104.25	1.346072	8.684719	2.482212	30.81199	9.928846	9.928846
104.4	1.346072	8.697229	2.48642	30.81199	9.945679	9.945679
104.55	1.346072	8.70974	2.491238	30.81199	9.964951	9.964951
104.7	1.346072	8.722229	2.495944	30.81199	9.983778	9.983778
104.85	1.346072	8.734708	2.500186	30.81199	10.00075	10.00075
105	1.346072	8.747219	2.504949	30.81199	10.0198	10.0198
105.15	1.345952	8.759729	2.509602	30.80927	10.03841	10.03841
105.3	1.345952	8.77224	2.514315	30.80927	10.05726	10.05726
105.45	1.345952	8.784729	2.518662	30.80927	10.07465	10.07465
105.6	1.345952	8.797208	2.523301	30.80927	10.0932	10.0932
105.75	1.345952	8.809719	2.527579	30.80927	10.11031	10.11031
105.9	1.345952	8.82224	2.53249	30.80927	10.12996	10.12996
106.05	1.345952	8.83475	2.536778	30.80927	10.14711	10.14711
106.2	1.345952	8.847229	2.541286	30.80927	10.16514	10.16514
106.35	1.345952	8.859708	2.546231	30.80927	10.18492	10.18492
106.5	1.345952	8.872219	2.550542	30.80927	10.20217	10.20217
106.65	1.346072	8.884729	2.555213	30.81199	10.22085	10.22085
106.8	1.346072	8.89724	2.559666	30.81199	10.23866	10.23866
106.95	1.346072	8.909729	2.564238	30.81199	10.25695	10.25695
107.1	1.346072	8.922208	2.568835	30.81199	10.27534	10.27534
107.25	1.346151	8.934719	2.573293	30.81381	10.29317	10.29317
107.4	1.346151	8.94724	2.578129	30.81381	10.31252	10.31252
107.55	1.34627	8.95974	2.5823	30.81654	10.3292	10.3292
107.7	1.34627	8.972229	2.586812	30.81654	10.34725	10.34725
107.85	1.34627	8.984708	2.591413	30.81654	10.36565	10.36565
108	1.34627	8.997219	2.596003	30.81654	10.38401	10.38401
108.15	1.346151	9.00974	2.600475	30.81381	10.4019	10.4019
108.3	1.346151	9.02224	2.605267	30.81381	10.42107	10.42107
108.45	1.346072	9.034729	2.609682	30.81199	10.43873	10.43873
108.6	1.345952	9.047208	2.614041	30.80927	10.45616	10.45616
108.75	1.345952	9.059719	2.618436	30.80927	10.47374	10.47374
108.9	1.345873	9.07224	2.623224	30.80745	10.4929	10.4929
109.05	1.345873	9.08474	2.627798	30.80745	10.51119	10.51119
109.2	1.345754	9.097229	2.631956	30.80472	10.52783	10.52783
109.35	1.345754	9.109718	2.636858	30.80472	10.54743	10.54743
109.5	1.345754	9.122219	2.641181	30.80472	10.56472	10.56472
109.65	1.345674	9.13474	2.645477	30.8029	10.58191	10.58191
109.8	1.345754	9.14724	2.650337	30.80472	10.60135	10.60135
109.95	1.345674	9.159729	2.654864	30.8029	10.61946	10.61946
110.1	1.345674	9.172208	2.659301	30.8029	10.6372	10.6372
110.25	1.345674	9.184719	2.663543	30.8029	10.65417	10.65417
110.4	1.345674	9.19724	2.668412	30.8029	10.67365	10.67365
110.55	1.345555	9.20974	2.673107	30.80017	10.69243	10.69243
110.7	1.345555	9.222229	2.677204	30.80017	10.70882	10.70882
110.85	1.345555	9.234708	2.681839	30.80017	10.72736	10.72736
111	1.345555	9.247219	2.686505	30.80017	10.74602	10.74602
111.15	1.345674	9.25974	2.691076	30.8029	10.76431	10.76431
111.3	1.345674	9.27225	2.695415	30.8029	10.78166	10.78166
111.45	1.345674	9.284729	2.699912	30.8029	10.79965	10.79965
111.6	1.345674	9.297208	2.704384	30.8029	10.81754	10.81754
111.75	1.345674	9.309719	2.708827	30.8029	10.83531	10.83531
111.9	1.345634	9.32224	2.713126	30.80199	10.8525	10.8525
112.05	1.345555	9.33475	2.717729	30.80017	10.87092	10.87092
112.2	1.345476	9.347229	2.722136	30.79835	10.88855	10.88855
112.35	1.345396	9.359708	2.726386	30.79653	10.90554	10.90554
112.5	1.345396	9.372219	2.730852	30.79653	10.92341	10.92341
112.65	1.345277	9.38474	2.735788	30.7938	10.94315	10.94315
112.8	1.345197	9.39724	2.739839	30.79198	10.95936	10.95936
112.95	1.345078	9.409729	2.744389	30.78925	10.97755	10.97755
113.1	1.345078	9.422208	2.748982	30.78925	10.99593	10.99593
113.25	1.344919	9.434719	2.753289	30.78561	11.01316	11.01316
113.4	1.3448	9.44724	2.757941	30.78289	11.03176	11.03176
113.55	1.344681	9.45974	2.762504	30.78016	11.05002	11.05002
113.7	1.344601	9.472229	2.767036	30.77834	11.06815	11.06815
113.85	1.344482	9.484708	2.771338	30.77561	11.08535	11.08535
114	1.344403	9.497219	2.775637	30.77379	11.10255	11.10255
114.15	1.344283	9.50974	2.780187	30.77106	11.12075	11.12075
114.3	1.344204	9.52224	2.784806	30.76924	11.13923	11.13923
114.45	1.344085	9.534729	2.789116	30.76651	11.15646	11.15646
114.6	1.344005	9.547208	2.793397	30.76469	11.17359	11.17359
114.75	1.343886	9.559719	2.797908	30.76196	11.19163	11.19163
114.9	1.343807	9.57224	2.802348	30.76015	11.20939	11.20939
115.05	1.343807	9.58475	2.806435	30.76015	11.22574	11.22574
115.2	1.343727	9.597229	2.810929	30.75833	11.24372	11.24372
115.35	1.343608	9.609708	2.815342	30.7556	11.26137	11.26137
115.5	1.343528	9.622219	2.81989	30.75378	11.27956	11.27956
115.65	1.343409	9.63474	2.824142	30.75105	11.29657	11.29657
115.8	1.343131	9.64724	2.828648	30.74468	11.31459	11.31459
115.95	1.342932	9.659729	2.83278	30.74014	11.33112	11.33112
116.1	1.342535	9.672208	2.836907	30.73104	11.34763	11.34763
116.25	1.342217	9.684719	2.840974	30.72376	11.3639	11.3639
116.4	1.34174	9.69724	2.844902	30.71285	11.37961	11.37961
116.55	1.341263	9.70974	2.848685	30.70193	11.39474	11.39474
116.7	1.340667	9.722229	2.852444	30.68829	11.40978	11.40978
116.85	1.339992	9.734708	2.855851	30.67283	11.4234	11.4234
117	1.339277	9.747219	2.858845	30.65646	11.43538	11.43538
117.15	1.338442	9.75974	2.861428	30.63736	11.44571	11.44571
117.3	1.321912	9.77225	2.863485	30.25897	11.45394	11.45394
117.45	1.315554	9.784729	2.86267	30.11344	11.45068	11.45068
117.6	0.3290971	9.797218	3.631602	7.533134	14.52641	14.52641
117.64	0.01474222	9.800146	3.570243	0.3374538	14.28097	14.28097